Workbook
Name PH: [1]TARIF!#REF!
Name PH: [1]TARIF!#REF!
Name PH: [1]TARIF!#REF!
Name PH: [1]TARIF!#REF!
Name PH: TARIF!#REF!
Name PH: [1]TARIF!#REF!
Name PH: [2]TARIF!#REF!
Name PH: [1]TARIF!#REF!
Name PH: [1]TARIF!#REF!
Name PH: [1]TARIF!#REF!
Name PH: [1]TARIF!#REF!
Name PH: [1]TARIF!#REF!
Name PH: [1]TARIF!#REF!
Name PH: TARIF!#REF!
Name PTKP: [1]TARIF!#REF!
Name PTKP: [1]TARIF!#REF!
Name PTKP: [1]TARIF!#REF!
Name PTKP: [1]TARIF!#REF!
Name PTKP: TARIF!#REF!
Name PTKP: [1]TARIF!#REF!
Name PTKP: [2]TARIF!#REF!
Name PTKP: [1]TARIF!#REF!
Name PTKP: [1]TARIF!#REF!
Name PTKP: [1]TARIF!#REF!
Name PTKP: [1]TARIF!#REF!
Name PTKP: [1]TARIF!#REF!
Name PTKP: [1]TARIF!#REF!
Name PTKP: TARIF!#REF!
Name Ter_A: [1]TARIF!$B$3:$E$46
Name Ter_A: [1]TARIF!$B$3:$E$46
Name Ter_A: [1]TARIF!$B$3:$E$46
Name Ter_A: [1]TARIF!$B$3:$E$46
Name Ter_A: [1]TARIF!$B$3:$E$46
Name Ter_A: [2]TARIF!$B$3:$E$46
Name Ter_A: [1]TARIF!$B$3:$E$46
Name Ter_A: [1]TARIF!$B$3:$E$46
Name Ter_A: [1]TARIF!$B$3:$E$46
Name Ter_A: [1]TARIF!$B$3:$E$46
Name Ter_A: [1]TARIF!$B$3:$E$46
Name Ter_A: [1]TARIF!$B$3:$E$46
Name Ter_A: TARIF!$B$3:$E$46
Name Ter_B: [1]TARIF!$H$3:$K$42
Name Ter_B: [1]TARIF!$H$3:$K$42
Name Ter_B: [1]TARIF!$H$3:$K$42
Name Ter_B: [1]TARIF!$H$3:$K$42
Name Ter_B: [1]TARIF!$H$3:$K$42
Name Ter_B: [2]TARIF!$H$3:$K$42
Name Ter_B: [1]TARIF!$H$3:$K$42
Name Ter_B: [1]TARIF!$H$3:$K$42
Name Ter_B: [1]TARIF!$H$3:$K$42
Name Ter_B: [1]TARIF!$H$3:$K$42
Name Ter_B: [1]TARIF!$H$3:$K$42
Name Ter_B: [1]TARIF!$H$3:$K$42
Name Ter_B: TARIF!$H$3:$K$42
Name Ter_C: [1]TARIF!$N$3:$Q$43
Name Ter_C: [1]TARIF!$N$3:$Q$43
Name Ter_C: [1]TARIF!$N$3:$Q$43
Name Ter_C: [1]TARIF!$N$3:$Q$43
Name Ter_C: [1]TARIF!$N$3:$Q$43
Name Ter_C: [2]TARIF!$N$3:$Q$43

Sheet TARIF
A1: PTKP (TK/0, TK/1, K/0) | G1: PTKP (TK/2, TK/3, K/1, K/2) | M1: PTKP (K/3) | S1: HARIAN
A2: No | B2: Lapisan Penghasilan bruto (Rp.) | E2: TER A | G2: No | H2: Lapisan Penghasilan bruto (Rp.) | K2: TER B | M2: No | N2: Lapisan Penghasilan bruto (Rp.) | Q2: TER C | S2: Penghasilan Bruto | V2: Tarif
A3: 1 | B3: 0 | C3: s.d | D3: 5400000 | E3: 0 | G3: 1 | H3: 0 | I3: s.d | J3: 6200000 | K3: 0 | M3: 1 | N3: 0 | O3: s.d | P3: 6600000 | Q3: 0 | S3: 0 | T3: s.d | U3: 450000 | V3: 0
A4: =A3+1 -> 2 | B4: =D3+1 -> 5400001 | C4: s.d | D4: 5650000 | E4: 0.0025 | G4: =G3+1 -> 2 | H4: =J3+1 -> 6200001 | I4: s.d | J4: 6500000 | K4: 0.0025 | M4: =M3+1 -> 2 | N4: =P3+1 -> 6600001 | O4: s.d | P4: 6950000 | Q4: 0.0025 | S4: 450001 | T4: s.d | U4: 2500000 | V4: 0.005
A5: =A4+1 -> 3 | B5: =D4+1 -> 5650001 | C5: s.d | D5: 5950000 | E5: 0.005 | G5: =G4+1 -> 3 | H5: =J4+1 -> 6500001 | I5: s.d | J5: 6850000 | K5: 0.005 | M5: =M4+1 -> 3 | N5: =P4+1 -> 6950001 | O5: s.d | P5: 7350000 | Q5: 0.005
A6: =A5+1 -> 4 | B6: =D5+1 -> 5950001 | C6: s.d | D6: 6300000 | E6: 0.0075 | G6: =G5+1 -> 4 | H6: =J5+1 -> 6850001 | I6: s.d | J6: 7300000 | K6: 0.0075 | M6: =M5+1 -> 4 | N6: =P5+1 -> 7350001 | O6: s.d | P6: 7800000 | Q6: 0.0075
A7: =A6+1 -> 5 | B7: =D6+1 -> 6300001 | C7: s.d | D7: 6750000 | E7: 0.01 | G7: =G6+1 -> 5 | H7: =J6+1 -> 7300001 | I7: s.d | J7: 9200000 | K7: 0.01 | M7: =M6+1 -> 5 | N7: =P6+1 -> 7800001 | O7: s.d | P7: 8850000 | Q7: 0.01 | S7: TARIF PASAL 17 WPOP
A8: =A7+1 -> 6 | B8: =D7+1 -> 6750001 | C8: s.d | D8: 7500000 | E8: 0.0125 | G8: =G7+1 -> 6 | H8: =J7+1 -> 9200001 | I8: s.d | J8: 10750000 | K8: 0.015 | M8: =M7+1 -> 6 | N8: =P7+1 -> 8850001 | O8: s.d | P8: 9800000 | Q8: 0.0125 | S8: Lapisan PKP | V8: Tarif
A9: =A8+1 -> 7 | B9: =D8+1 -> 7500001 | C9: s.d | D9: 8550000 | E9: 0.015 | G9: =G8+1 -> 7 | H9: =J8+1 -> 10750001 | I9: s.d | J9: 11250000 | K9: 0.02 | M9: =M8+1 -> 7 | N9: =P8+1 -> 9800001 | O9: s.d | P9: 10950000 | Q9: 0.015 | S9: 0 | T9: s.d | U9: 60000000 | V9: 0.05
A10: =A9+1 -> 8 | B10: =D9+1 -> 8550001 | C10: s.d | D10: 9650000 | E10: 0.0175 | G10: =G9+1 -> 8 | H10: =J9+1 -> 11250001 | I10: s.d | J10: 11600000 | K10: 0.025 | M10: =M9+1 -> 8 | N10: =P9+1 -> 10950001 | O10: s.d | P10: 11200000 | Q10: 0.0175 | S10: =U9+1 -> 60000001 | T10: s.d | U10: 250000000 | V10: 0.15
A11: =A10+1 -> 9 | B11: =D10+1 -> 9650001 | C11: s.d | D11: 10050000 | E11: 0.02 | G11: =G10+1 -> 9 | H11: =J10+1 -> 11600001 | I11: s.d | J11: 12600000 | K11: 0.03 | M11: =M10+1 -> 9 | N11: =P10+1 -> 11200001 | O11: s.d | P11: 12050000 | Q11: 0.02 | S11: =U10+1 -> 250000001 | T11: s.d | U11: 500000000 | V11: 0.25
A12: =A11+1 -> 10 | B12: =D11+1 -> 10050001 | C12: s.d | D12: 10350000 | E12: 0.0225 | G12: =G11+1 -> 10 | H12: =J11+1 -> 12600001 | I12: s.d | J12: 13600000 | K12: 0.04 | M12: =M11+1 -> 10 | N12: =P11+1 -> 12050001 | O12: s.d | P12: 12950000 | Q12: 0.03 | S12: =U11+1 -> 500000001 | T12: s.d | U12: 5000000000 | V12: 0.3
A13: =A12+1 -> 11 | B13: =D12+1 -> 10350001 | C13: s.d | D13: 10700000 | E13: 0.025 | G13: =G12+1 -> 11 | H13: =J12+1 -> 13600001 | I13: s.d | J13: 14950000 | K13: 0.05 | M13: =M12+1 -> 11 | N13: =P12+1 -> 12950001 | O13: s.d | P13: 14150000 | Q13: 0.04 | S13: =U12+1 -> 5000000001 | T13: s.d | U13: ~~ | V13: 0.35
A14: =A13+1 -> 12 | B14: =D13+1 -> 10700001 | C14: s.d | D14: 11050000 | E14: 0.03 | G14: =G13+1 -> 12 | H14: =J13+1 -> 14950001 | I14: s.d | J14: 16400000 | K14: 0.06 | M14: =M13+1 -> 12 | N14: =P13+1 -> 14150001 | O14: s.d | P14: 1550000 | Q14: 0.05
A15: =A14+1 -> 13 | B15: =D14+1 -> 11050001 | C15: s.d | D15: 11600000 | E15: 0.035 | G15: =G14+1 -> 13 | H15: =J14+1 -> 16400001 | I15: s.d | J15: 18450000 | K15: 0.07 | M15: =M14+1 -> 13 | N15: =P14+1 -> 1550001 | O15: s.d | P15: 17050000 | Q15: 0.06
A16: =A15+1 -> 14 | B16: =D15+1 -> 11600001 | C16: s.d | D16: 12500000 | E16: 0.04 | G16: =G15+1 -> 14 | H16: =J15+1 -> 18450001 | I16: s.d | J16: 21850000 | K16: 0.08 | M16: =M15+1 -> 14 | N16: =P15+1 -> 17050001 | O16: s.d | P16: 19500000 | Q16: 0.07 | S16: PTKP
A17: =A16+1 -> 15 | B17: =D16+1 -> 12500001 | C17: s.d | D17: 13750000 | E17: 0.05 | G17: =G16+1 -> 15 | H17: =J16+1 -> 21850001 | I17: s.d | J17: 26000000 | K17: 0.09 | M17: =M16+1 -> 15 | N17: =P16+1 -> 19500001 | O17: s.d | P17: 22700000 | Q17: 0.08 | S17: Status | U17: Jumlah
A18: =A17+1 -> 16 | B18: =D17+1 -> 13750001 | C18: s.d | D18: 15100000 | E18: 0.06 | G18: =G17+1 -> 16 | H18: =J17+1 -> 26000001 | I18: s.d | J18: 27700000 | K18: 0.1 | M18: =M17+1 -> 16 | N18: =P17+1 -> 22700001 | O18: s.d | P18: 26600000 | Q18: 0.09 | S18: TK/0 | U18: 54000000
A19: =A18+1 -> 17 | B19: =D18+1 -> 15100001 | C19: s.d | D19: 16950000 | E19: 0.07 | G19: =G18+1 -> 17 | H19: =J18+1 -> 27700001 | I19: s.d | J19: 29350000 | K19: 0.11 | M19: =M18+1 -> 17 | N19: =P18+1 -> 26600001 | O19: s.d | P19: 28100000 | Q19: 0.1 | S19: TK/1 | U19: 58500000
A20: =A19+1 -> 18 | B20: =D19+1 -> 16950001 | C20: s.d | D20: 19750000 | E20: 0.08 | G20: =G19+1 -> 18 | H20: =J19+1 -> 29350001 | I20: s.d | J20: 31450000 | K20: 0.12 | M20: =M19+1 -> 18 | N20: =P19+1 -> 28100001 | O20: s.d | P20: 30100000 | Q20: 0.11 | S20: TK/2 | U20: 63000000
A21: =A20+1 -> 19 | B21: =D20+1 -> 19750001 | C21: s.d | D21: 24150000 | E21: 0.09 | G21: =G20+1 -> 19 | H21: =J20+1 -> 31450001 | I21: s.d | J21: 33950000 | K21: 0.13 | M21: =M20+1 -> 19 | N21: =P20+1 -> 30100001 | O21: s.d | P21: 32600000 | Q21: 0.12 | S21: TK/3 | U21: 67500000
A22: =A21+1 -> 20 | B22: =D21+1 -> 24150001 | C22: s.d | D22: 26450000 | E22: 0.1 | G22: =G21+1 -> 20 | H22: =J21+1 -> 33950001 | I22: s.d | J22: 37100000 | K22: 0.14 | M22: =M21+1 -> 20 | N22: =P21+1 -> 32600001 | O22: s.d | P22: 35400000 | Q22: 0.13 | S22: K/0 | U22: 58500000
A23: =A22+1 -> 21 | B23: =D22+1 -> 26450001 | C23: s.d | D23: 28000000 | E23: 0.11 | G23: =G22+1 -> 21 | H23: =J22+1 -> 37100001 | I23: s.d | J23: 41100000 | K23: 0.15 | M23: =M22+1 -> 21 | N23: =P22+1 -> 35400001 | O23: s.d | P23: 38900000 | Q23: 0.14 | S23: K/1 | U23: 63000000
A24: =A23+1 -> 22 | B24: =D23+1 -> 28000001 | C24: s.d | D24: 30050000 | E24: 0.12 | G24: =G23+1 -> 22 | H24: =J23+1 -> 41100001 | I24: s.d | J24: 45800000 | K24: 0.16 | M24: =M23+1 -> 22 | N24: =P23+1 -> 38900001 | O24: s.d | P24: 43000000 | Q24: 0.15 | S24: K/2 | U24: 67500000
A25: =A24+1 -> 23 | B25: =D24+1 -> 30050001 | C25: s.d | D25: 32400000 | E25: 0.13 | G25: =G24+1 -> 23 | H25: =J24+1 -> 45800001 | I25: s.d | J25: 49500000 | K25: 0.17 | M25: =M24+1 -> 23 | N25: =P24+1 -> 43000001 | O25: s.d | P25: 47400000 | Q25: 0.16 | S25: K/3 | U25: 72000000
A26: =A25+1 -> 24 | B26: =D25+1 -> 32400001 | C26: s.d | D26: 35400000 | E26: 0.14 | G26: =G25+1 -> 24 | H26: =J25+1 -> 49500001 | I26: s.d | J26: 53800000 | K26: 0.18 | M26: =M25+1 -> 24 | N26: =P25+1 -> 47400001 | O26: s.d | P26: 51200000 | Q26: 0.17
A27: =A26+1 -> 25 | B27: =D26+1 -> 35400001 | C27: s.d | D27: 39100000 | E27: 0.15 | G27: =G26+1 -> 25 | H27: =J26+1 -> 53800001 | I27: s.d | J27: 58500000 | K27: 0.19 | M27: =M26+1 -> 25 | N27: =P26+1 -> 51200001 | O27: s.d | P27: 55800000 | Q27: 0.18
A28: =A27+1 -> 26 | B28: =D27+1 -> 39100001 | C28: s.d | D28: 43850000 | E28: 0.16 | G28: =G27+1 -> 26 | H28: =J27+1 -> 58500001 | I28: s.d | J28: 64000000 | K28: 0.2 | M28: =M27+1 -> 26 | N28: =P27+1 -> 55800001 | O28: s.d | P28: 60400000 | Q28: 0.19
A29: =A28+1 -> 27 | B29: =D28+1 -> 43850001 | C29: s.d | D29: 47800000 | E29: 0.17 | G29: =G28+1 -> 27 | H29: =J28+1 -> 64000001 | I29: s.d | J29: 71000000 | K29: 0.21 | M29: =M28+1 -> 27 | N29: =P28+1 -> 60400001 | O29: s.d | P29: 66700000 | Q29: 0.2
A30: =A29+1 -> 28 | B30: =D29+1 -> 47800001 | C30: s.d | D30: 51400000 | E30: 0.18 | G30: =G29+1 -> 28 | H30: =J29+1 -> 71000001 | I30: s.d | J30: 80000000 | K30: 0.22 | M30: =M29+1 -> 28 | N30: =P29+1 -> 66700001 | O30: s.d | P30: 74500000 | Q30: 0.21
A31: =A30+1 -> 29 | B31: =D30+1 -> 51400001 | C31: s.d | D31: 56300000 | E31: 0.19 | G31: =G30+1 -> 29 | H31: =J30+1 -> 80000001 | I31: s.d | J31: 93000000 | K31: 0.23 | M31: =M30+1 -> 29 | N31: =P30+1 -> 74500001 | O31: s.d | P31: 83200000 | Q31: 0.22
A32: =A31+1 -> 30 | B32: =D31+1 -> 56300001 | C32: s.d | D32: 62200000 | E32: 0.2 | G32: =G31+1 -> 30 | H32: =J31+1 -> 93000001 | I32: s.d | J32: 109000000 | K32: 0.24 | M32: =M31+1 -> 30 | N32: =P31+1 -> 83200001 | O32: s.d | P32: 95600000 | Q32: 0.23
A33: =A32+1 -> 31 | B33: =D32+1 -> 62200001 | C33: s.d | D33: 68600000 | E33: 0.21 | G33: =G32+1 -> 31 | H33: =J32+1 -> 109000001 | I33: s.d | J33: 129000000 | K33: 0.25 | M33: =M32+1 -> 31 | N33: =P32+1 -> 95600001 | O33: s.d | P33: 110000000 | Q33: 0.24
A34: =A33+1 -> 32 | B34: =D33+1 -> 68600001 | C34: s.d | D34: 77500000 | E34: 0.22 | G34: =G33+1 -> 32 | H34: =J33+1 -> 129000001 | I34: s.d | J34: 163000000 | K34: 0.26 | M34: =M33+1 -> 32 | N34: =P33+1 -> 110000001 | O34: s.d | P34: 134000000 | Q34: 0.25
A35: =A34+1 -> 33 | B35: =D34+1 -> 77500001 | C35: s.d | D35: 89000000 | E35: 0.23 | G35: =G34+1 -> 33 | H35: =J34+1 -> 163000001 | I35: s.d | J35: 211000000 | K35: 0.27 | M35: =M34+1 -> 33 | N35: =P34+1 -> 134000001 | O35: s.d | P35: 169000000 | Q35: 0.26
A36: =A35+1 -> 34 | B36: =D35+1 -> 89000001 | C36: s.d | D36: 103000000 | E36: 0.24 | G36: =G35+1 -> 34 | H36: =J35+1 -> 211000001 | I36: s.d | J36: 374000000 | K36: 0.28 | M36: =M35+1 -> 34 | N36: =P35+1 -> 169000001 | O36: s.d | P36: 221000000 | Q36: 0.27
A37: =A36+1 -> 35 | B37: =D36+1 -> 103000001 | C37: s.d | D37: 125000000 | E37: 0.25 | G37: =G36+1 -> 35 | H37: =J36+1 -> 374000001 | I37: s.d | J37: 459000000 | K37: 0.29 | M37: =M36+1 -> 35 | N37: =P36+1 -> 221000001 | O37: s.d | P37: 390000000 | Q37: 0.28
... A41: =A40+1 -> 39 | B41: =D40+1 -> 337000001 | C41: s.d | D41: 454000000 | E41: 0.29 | G41: =G40+1 -> 39 | H41: =J40+1 -> 957000001 | I41: s.d | J41: 1405000000 | K41: 0.33 | M41: =M40+1 -> 39 | N41: =P40+1 -> 709000001 | O41: s.d | P41: 965000000 | Q41: 0.32
A42: =A41+1 -> 40 | B42: =D41+1 -> 454000001 | C42: s.d | D42: 550000000 | E42: 0.3 | G42: =G41+1 -> 40 | H42: =J41+1 -> 1405000001 | I42: s.d | J42: ~~ | K42: 0.34 | M42: =M41+1 -> 40 | N42: =P41+1 -> 965000001 | O42: s.d | P42: 1419000000 | Q42: 0.33
A43: =A42+1 -> 41 | B43: =D42+1 -> 550000001 | C43: s.d | D43: 695000000 | E43: 0.31 | M43: =M42+1 -> 41 | N43: =P42+1 -> 1419000001 | O43: s.d | P43: ~~ | Q43: 0.34
...

Sheet Des
C1: yang berwarna ini rumus
B2: Nomor Urut | C2: NAMA KARYAWAN | D2: N I K / PASPOR | E2: N P W P | F2: A L A M A T | G2: JABATAN | H2: STATUS KARYAWAN | M2: DESEMBER | R2: P T K P | S2: P K P | T2: PPH PASAL 21 | V2: PPH PASAL 21 JAN S.D NOP | W2: PPH PASAL 21 DESEMBER
M3: Gaji Pokok | N3: Total Tunjangan | O3: Premi JKK, JKM, Kes | P3: Tunjangan PPh | Q3: Penghasilan Bruto
H4: L/P | I4: PTKP | J4: TER | K4: MASA KERJA | T4: SETAHUN | U4: INCLUDE NON NPWP
B5: 1 | C5: 2 | D5: 3 | E5: 4 | F5: 5 | G5: 6 | H5: 7 | I5: 8 | J5: 9 | K5: 10 | L5: 11 | M5: 12 | N5: 13 | O5: 14 | P5: 15 | Q5: 16 | R5: 30 | S5: 31 | T5: 32 | U5: 33 | V5: 34 | W5: 35
B6: 1 | C6: AGUS SRI ASTUTI | H6: P | I6: TK/0 | J6: =IF(ISBLANK(I6),"",IF(OR(I6="TK/0",I6="TK/1",I6="K/0"),"TER A",IF(I6="K/3","TER C","TER B"))) -> TER A | K6: 1 | L6: 1 | M6: 7006344 | N6: 0 | O6: =38871+185100 -> 223971 | P6: 0 | Q6: =SUM(M6:P6) -> 7230315 | R6: =IFERROR(VLOOKUP(I6,PTKP,3,FALSE),0) -> 0 | S6: =ROUNDDOWN(IF(#REF!>R6,#REF!-R6,0),-3) -> #REF! | T6: =IF(S6>5000000000,S6*35%-306000000,IF(S6>500000000,S6*30%-56000000,IF(S6>250000000,S6*25%-31000000,IF(S6>60000000,S6*15%-6000000,S6*5%)))) -> #REF! | U6: =ROUND(IF(E6=0,T6*120%,T6),0) -> #REF! | W6: =U6-V6 -> #REF!
B7: 2 | J7: =IF(ISBLANK(I7),"",IF(OR(I7="TK/0",I7="TK/1",I7="K/0"),"TER A",IF(I7="K/3","TER C","TER B"))) | P7: =W7 -> #REF! | Q7: =SUM(M7:P7) -> #REF! | R7: =IFERROR(VLOOKUP(I7,PTKP,3,FALSE),0) -> 0 | S7: =ROUNDDOWN(IF(#REF!>R7,#REF!-R7,0),-3) -> #REF! | T7: =IF(S7>5000000000,S7*35%-306000000,IF(S7>500000000,S7*30%-56000000,IF(S7>250000000,S7*25%-31000000,IF(S7>60000000,S7*15%-6000000,S7*5%)))) -> #REF! | U7: =ROUND(IF(E7=0,T7*120%,T7),0) -> #REF! | W7: =U7-V7 -> #REF!
B8: 3 | J8: =IF(ISBLANK(I8),"",IF(OR(I8="TK/0",I8="TK/1",I8="K/0"),"TER A",IF(I8="K/3","TER C","TER B"))) | P8: =W8 -> #REF! | Q8: =SUM(M8:P8) -> #REF! | R8: =IFERROR(VLOOKUP(I8,PTKP,3,FALSE),0) -> 0 | S8: =ROUNDDOWN(IF(#REF!>R8,#REF!-R8,0),-3) -> #REF! | T8: =IF(S8>5000000000,S8*35%-306000000,IF(S8>500000000,S8*30%-56000000,IF(S8>250000000,S8*25%-31000000,IF(S8>60000000,S8*15%-6000000,S8*5%)))) -> #REF! | U8: =ROUND(IF(E8=0,T8*120%,T8),0) -> #REF! | W8: =U8-V8 -> #REF!
B9: 4 | J9: =IF(ISBLANK(I9),"",IF(OR(I9="TK/0",I9="TK/1",I9="K/0"),"TER A",IF(I9="K/3","TER C","TER B"))) | P9: =W9 -> #REF! | Q9: =SUM(M9:P9) -> #REF! | R9: =IFERROR(VLOOKUP(I9,PTKP,3,FALSE),0) -> 0 | S9: =ROUNDDOWN(IF(#REF!>R9,#REF!-R9,0),-3) -> #REF! | T9: =IF(S9>5000000000,S9*35%-306000000,IF(S9>500000000,S9*30%-56000000,IF(S9>250000000,S9*25%-31000000,IF(S9>60000000,S9*15%-6000000,S9*5%)))) -> #REF! | U9: =ROUND(IF(E9=0,T9*120%,T9),0) -> #REF! | W9: =U9-V9 -> #REF!
B10: 5 | J10: =IF(ISBLANK(I10),"",IF(OR(I10="TK/0",I10="TK/1",I10="K/0"),"TER A",IF(I10="K/3","TER C","TER B"))) | P10: =W10 -> #REF! | Q10: =SUM(M10:P10) -> #REF! | R10: =IFERROR(VLOOKUP(I10,PTKP,3,FALSE),0) -> 0 | S10: =ROUNDDOWN(IF(#REF!>R10,#REF!-R10,0),-3) -> #REF! | T10: =IF(S10>5000000000,S10*35%-306000000,IF(S10>500000000,S10*30%-56000000,IF(S10>250000000,S10*25%-31000000,IF(S10>60000000,S10*15%-6000000,S10*5%)))) -> #REF! | U10: =ROUND(IF(E10=0,T10*120%,T10),0) -> #REF! | W10: =U10-V10 -> #REF!
B11: 6 | J11: =IF(ISBLANK(I11),"",IF(OR(I11="TK/0",I11="TK/1",I11="K/0"),"TER A",IF(I11="K/3","TER C","TER B"))) | P11: =W11 -> #REF! | Q11: =SUM(M11:P11) -> #REF! | R11: =IFERROR(VLOOKUP(I11,PTKP,3,FALSE),0) -> 0 | S11: =ROUNDDOWN(IF(#REF!>R11,#REF!-R11,0),-3) -> #REF! | T11: =IF(S11>5000000000,S11*35%-306000000,IF(S11>500000000,S11*30%-56000000,IF(S11>250000000,S11*25%-31000000,IF(S11>60000000,S11*15%-6000000,S11*5%)))) -> #REF! | U11: =ROUND(IF(E11=0,T11*120%,T11),0) -> #REF! | W11: =U11-V11 -> #REF!
B12: 7 | J12: =IF(ISBLANK(I12),"",IF(OR(I12="TK/0",I12="TK/1",I12="K/0"),"TER A",IF(I12="K/3","TER C","TER B"))) | P12: =W12 -> #REF! | Q12: =SUM(M12:P12) -> #REF! | R12: =IFERROR(VLOOKUP(I12,PTKP,3,FALSE),0) -> 0 | S12: =ROUNDDOWN(IF(#REF!>R12,#REF!-R12,0),-3) -> #REF! | T12: =IF(S12>5000000000,S12*35%-306000000,IF(S12>500000000,S12*30%-56000000,IF(S12>250000000,S12*25%-31000000,IF(S12>60000000,S12*15%-6000000,S12*5%)))) -> #REF! | U12: =ROUND(IF(E12=0,T12*120%,T12),0) -> #REF! | W12: =U12-V12 -> #REF!
B13: 8 | J13: =IF(ISBLANK(I13),"",IF(OR(I13="TK/0",I13="TK/1",I13="K/0"),"TER A",IF(I13="K/3","TER C","TER B"))) | P13: =W13 -> #REF! | Q13: =SUM(M13:P13) -> #REF! | R13: =IFERROR(VLOOKUP(I13,PTKP,3,FALSE),0) -> 0 | S13: =ROUNDDOWN(IF(#REF!>R13,#REF!-R13,0),-3) -> #REF! | T13: =IF(S13>5000000000,S13*35%-306000000,IF(S13>500000000,S13*30%-56000000,IF(S13>250000000,S13*25%-31000000,IF(S13>60000000,S13*15%-6000000,S13*5%)))) -> #REF! | U13: =ROUND(IF(E13=0,T13*120%,T13),0) -> #REF! | W13: =U13-V13 -> #REF!
B14: 9 | J14: =IF(ISBLANK(I14),"",IF(OR(I14="TK/0",I14="TK/1",I14="K/0"),"TER A",IF(I14="K/3","TER C","TER B"))) | P14: =W14 -> #REF! | Q14: =SUM(M14:P14) -> #REF! | R14: =IFERROR(VLOOKUP(I14,PTKP,3,FALSE),0) -> 0 | S14: =ROUNDDOWN(IF(#REF!>R14,#REF!-R14,0),-3) -> #REF! | T14: =IF(S14>5000000000,S14*35%-306000000,IF(S14>500000000,S14*30%-56000000,IF(S14>250000000,S14*25%-31000000,IF(S14>60000000,S14*15%-6000000,S14*5%)))) -> #REF! | U14: =ROUND(IF(E14=0,T14*120%,T14),0) -> #REF! | W14: =U14-V14 -> #REF!
B15: 10 | J15: =IF(ISBLANK(I15),"",IF(OR(I15="TK/0",I15="TK/1",I15="K/0"),"TER A",IF(I15="K/3","TER C","TER B"))) | P15: =W15 -> #REF! | Q15: =SUM(M15:P15) -> #REF! | R15: =IFERROR(VLOOKUP(I15,PTKP,3,FALSE),0) -> 0 | S15: =ROUNDDOWN(IF(#REF!>R15,#REF!-R15,0),-3) -> #REF! | T15: =IF(S15>5000000000,S15*35%-306000000,IF(S15>500000000,S15*30%-56000000,IF(S15>250000000,S15*25%-31000000,IF(S15>60000000,S15*15%-6000000,S15*5%)))) -> #REF! | U15: =ROUND(IF(E15=0,T15*120%,T15),0) -> #REF! | W15: =U15-V15 -> #REF!
J16: =IF(ISBLANK(I16),"",IF(OR(I16="TK/0",I16="TK/1",I16="K/0"),"TER A",IF(I16="K/3","TER C","TER B"))) | P16: =W16 -> #REF! | Q16: =SUM(M16:P16) -> #REF! | R16: =IFERROR(VLOOKUP(I16,PTKP,3,FALSE),0) -> 0 | S16: =ROUNDDOWN(IF(#REF!>R16,#REF!-R16,0),-3) -> #REF! | T16: =IF(S16>5000000000,S16*35%-306000000,IF(S16>500000000,S16*30%-56000000,IF(S16>250000000,S16*25%-31000000,IF(S16>60000000,S16*15%-6000000,S16*5%)))) -> #REF! | U16: =ROUND(IF(E16=0,T16*120%,T16),0) -> #REF! | W16: =U16-V16 -> #REF!
M17: =SUM(M6:M16) -> 7006344 | N17: =SUM(N6:N16) -> 0 | O17: =SUM(O6:O16) -> 223971 | P17: =SUM(P6:P16) -> #REF! | Q17: =SUM(Q6:Q16) -> #REF! | R17: =SUM(R6:R16) -> 0 | S17: =SUM(S6:S16) -> #REF! | T17: =SUM(T6:T16) -> #REF! | ... W17: =SUM(W6:W16) -> #REF! | Y17: DD
B19: Catatan :
B20: 1. yang berwarna adalah rumus
B21: 2. dalam hal terdapat tunjangan PPh, maka ceklis "enable iterative calculation" pada menu (option => formula => pada bagian kanan atas)
B22: 3. kolom pengurang JHT/JP tetap wajib diisi, sebagai pengurang pada masa pajak desember
B23: 4. komponen penghasilan bruto dapat disesuaikan/ditambahkan kolom, sesuai dengan kebutuhan masing2 perusahaan
B24: 5. perubahan status PTKP ditentukan keadaan awal tahun, misal nikah/punya anak ditanggal 2 januari 2024, maka berubah status PTKP nya tahun 2025 | U24: =SUM(U19:U23) -> 0
B25: 6. PPh 21 terutang tersebut sudah memperhitungkan bagi yang tidak memiliki NPWP dengan jumlah PPh Terutang 20% lebih besar.
B26: 7. untuk yang tidak mempunyai NPWP dapat diisi dengan angka Nol
B27: 8. khusus untuk perhitungan pph 21 masa pajak desember, dapat di cek kembali total per komponen penghasilan brutonya

Sheet THR'24
B1: PT. REBINMAS JAYA
B2: INCOME TAX ARTICLE 21 FOR FEB 2024
B3: PGE 1A (AIR KUNDO)
C4: yang berwarna ini rumus | N4: T.Beras | O4: T.Jabatan | P4: Lembur
B5: NO. | C5: NAMA KARYAWAN | D5: N I K / PASPOR | E5: N P W P | F5: A L A M A T | G5: JABATAN | H5: L/P | I5: PTKP | J5: TER | K5: Gaji Pokok | L5: Astek Ins (0,84%) | M5: BPJS KESEHATAN (4%) | N5: Rice Allow | O5: Structural Allow | P5: Service Time Allow | Q5: Premi Transport | R5: Premi Harvesting | S5: Premi Brondol | T5: Premi Pruning | U5: Premi Kontanan | V5: Incentive Panen | W5: Pengembalian Uang Tiket | X5: Masa Kerja | Y5: Potongan Premi (Koreksi) | Z5: Lembur Bayar HK Penjagaan HGU | AA5: Bensin Patroli | AB5: POT. ALPA & POT. CTH ( CUTI TANPA HK ) | AC5: THR | AD5: Bonus | AE5: Penghasilan Bruto | AF5: Tarif TER | AG5: PPh 21 GAJI+THR | AH5: Pajak GAJI Feb'24 | AI5: PPh 21 THR | AJ5: PPh 21 Pot Jan'24 | AK5: Selisih | AL5: Ket | AN5: g.kotor daftar upah | AO5: astek+bpjs | AP5: bruto
B6: 1 | C6: MARTONO | D6: 1902050504860001 | E6: 97.237.826.9-305.000 | F6: JL MANGGAR KM 28 DSN BUKIT INDAH RT. 011 RW. 004 DESA KACANG BUTOR BADAU | G6: MANDOR PERAWATAN | H6: L | I6: K/2 | J6: =IF(ISBLANK(I6),"",IF(OR(I6="TK/0",I6="TK/1",I6="K/0"),"TER A",IF(I6="K/3","TER C","TER B"))) -> TER B | K6: =29*122333.33 -> 3547666.6 | L6: =3670000*0.84% -> 30828 | M6: =[3]MAINTENANCE!AK10 -> 148680 | N6: =[3]MAINTENANCE!$W10 -> 156600 | O6: =[3]MAINTENANCE!Z10 -> 66000 | P6: =[3]MAINTENANCE!AE10 -> 137890.18 | Q6: =[3]MAINTENANCE!AC10 -> 0 | X6: =[3]MAINTENANCE!AB10 -> 47000 | AB6: =-[3]MAINTENANCE!BA10 -> 0 | AC6: =[4]MAINTENANCE!$M11 -> 3878999.9 | AE6: =ROUNDDOWN(SUM(K6:AD6),0) -> 8013664 | AF6: =IF(J6="TER A",VLOOKUP(AE6,Ter_A,4,TRUE),IF(J6="TER B",VLOOKUP(AE6,Ter_B,4,TRUE),VLOOKUP(AE6,Ter_C,4,TRUE))) -> 0.01 | AG6: =ROUNDDOWN(IF(H6=0,AE6*AF6*120%,AE6*AF6),0) -> 80136 | AH6: =#REF! -> #REF! | AI6: =AG6-AH6 -> #REF! | AK6: =AJ6-AI6 -> #REF! | AN6: =[3]MAINTENANCE!$AF10 -> 3955156.8 | AO6: =L6+M6 -> 179508 | AP6: =AN6+AO6 -> 4134664.8 | AQ6: =AP6-AE6 -> -3878999.2
B7: 2 | C7: YUNIARTI | D7: 1902016806780001 | E7: 75.585.294.4-305.000 | F7: BULUH TUMBANG RT 019 RW 005 DESA BULUH TUMNAH KEC. TANJUNG PANDAN | G7: PERAWATAN | H7: P | I7: TK/0 | J7: =IF(ISBLANK(I7),"",IF(OR(I7="TK/0",I7="TK/1",I7="K/0"),"TER A",IF(I7="K/3","TER C","TER B"))) -> TER A | K7: =29*121333.33 -> 3518666.6 | L7: =3640000*0.84% -> 30576 | M7: =[3]MAINTENANCE!AK11 -> 146680 | N7: =[3]MAINTENANCE!$W11 -> 65250 | O7: =[3]MAINTENANCE!Z11 -> 0 | P7: =[3]MAINTENANCE!AE11 -> 0 | Q7: =[3]MAINTENANCE!AC11 -> 0 | X7: =[3]MAINTENANCE!AB11 -> 27000 | AB7: =-[3]MAINTENANCE!BA11 -> 0 | AC7: =[4]MAINTENANCE!$M12 -> 3734499.9 | AE7: =ROUNDDOWN(SUM(K7:AD7),0) -> 7522672 | AF7: =IF(J7="TER A",VLOOKUP(AE7,Ter_A,4,TRUE),IF(J7="TER B",VLOOKUP(AE7,Ter_B,4,TRUE),VLOOKUP(AE7,Ter_C,4,TRUE))) -> 0.015 | AG7: =ROUNDDOWN(IF(H7=0,AE7*AF7*120%,AE7*AF7),0) -> 112840 | AH7: =#REF! -> #REF! | AI7: =AG7-AH7 -> #REF! | AK7: =AJ7-AI7 -> #REF! | AN7: =[3]MAINTENANCE!$AF11 -> 3610916.6 | AO7: =L7+M7 -> 177256 | AP7: =AN7+AO7 -> 3788172.6 | AQ7: =AP7-AE7 -> -3734499.4
B8: 3 | C8: ATIK KUSMIATI | D8: 1902056004860002 | E8: 54.533.929.3-305.000 | F8: JLN MANGGAR DSN KEPAYANG RT. 006 RW. 002 DS KACANG BUTOR BADAU | G8: PERAWATAN | H8: P | I8: TK/0 | J8: =IF(ISBLANK(I8),"",IF(OR(I8="TK/0",I8="TK/1",I8="K/0"),"TER A",IF(I8="K/3","TER C","TER B"))) -> TER A | K8: =29*121333.33 -> 3518666.6 | L8: =3640000*0.84% -> 30576 | M8: =[3]MAINTENANCE!AK12 -> 146800 | N8: =[3]MAINTENANCE!$W12 -> 63000 | O8: =[3]MAINTENANCE!Z12 -> 0 | P8: =[3]MAINTENANCE!AE12 -> 0 | Q8: =[3]MAINTENANCE!AC12 -> 0 | X8: =[3]MAINTENANCE!AB12 -> 30000 | AB8: =-[3]MAINTENANCE!BA12 -> -121333.33 | AC8: =[4]MAINTENANCE!$M13 -> 3737499.9 | AE8: =ROUNDDOWN(SUM(K8:AD8),0) -> 7405209 | AF8: =IF(J8="TER A",VLOOKUP(AE8,Ter_A,4,TRUE),IF(J8="TER B",VLOOKUP(AE8,Ter_B,4,TRUE),VLOOKUP(AE8,Ter_C,4,TRUE))) -> 0.0125 | AG8: =ROUNDDOWN(IF(H8=0,AE8*AF8*120%,AE8*AF8),0) -> 92565 | AH8: =#REF! -> #REF! | AI8: =AG8-AH8 -> #REF! | AK8: =AJ8-AI8 -> #REF! | AN8: =[3]MAINTENANCE!$AF12 -> 3490333.2 | AO8: =L8+M8 -> 177376 | AP8: =AN8+AO8 -> 3667709.2 | AQ8: =AP8-AE8 -> -3737499.8 | AS8: =AB8+AQ8 -> -3858833.1
B9: 4 | C9: SALMIAH | D9: 1902054908770002 | E9: 97.237.535.6-305.000 | F9: JL MANGGAR DSN PARIT GUNUNG RT. 005 RW. 003 DS AIR BATU BUDING KEC BADAU | G9: PERAWATAN | H9: P | I9: TK/0 | J9: =IF(ISBLANK(I9),"",IF(OR(I9="TK/0",I9="TK/1",I9="K/0"),"TER A",IF(I9="K/3","TER C","TER B"))) -> TER A | K9: =29*121333.33 -> 3518666.6 | L9: =3640000*0.84% -> 30576 | M9: =[3]MAINTENANCE!AK13 -> 147480 | N9: =[3]MAINTENANCE!$W13 -> 60750 | O9: =[3]MAINTENANCE!Z13 -> 0 | P9: =[3]MAINTENANCE!AE13 -> 0 | Q9: =[3]MAINTENANCE!AC13 -> 0 | X9: =[3]MAINTENANCE!AB13 -> 47000 | AB9: =-[3]MAINTENANCE!BA13 -> -242666.66 | AC9: =[4]MAINTENANCE!$M14 -> 3754499.9 | AE9: =ROUNDDOWN(SUM(K9:AD9),0) -> 7316305 | AF9: =IF(J9="TER A",VLOOKUP(AE9,Ter_A,4,TRUE),IF(J9="TER B",VLOOKUP(AE9,Ter_B,4,TRUE),VLOOKUP(AE9,Ter_C,4,TRUE))) -> 0.0125 | AG9: =ROUNDDOWN(IF(H9=0,AE9*AF9*120%,AE9*AF9),0) -> 91453 | AH9: =#REF! -> #REF! | AI9: =AG9-AH9 -> #REF! | AK9: =AJ9-AI9 -> #REF! | AN9: =[3]MAINTENANCE!$AF13 -> 3383749.9 | AO9: =L9+M9 -> 178056 | AP9: =AN9+AO9 -> 3561805.9 | AQ9: =AP9-AE9 -> -3754499.1 | AS9: =AB9+AQ9 -> -3997165.8
B10: 5 | C10: NURAINI | D10: 1906026909880002 | E10: 54.533.747.9-305.000 | F10: DSN CENDIL RT 005 RW 002 DESA CENDIL KEC.KELAPA KAMPIT | G10: PERAWATAN | H10: P | I10: TK/0 | J10: =IF(ISBLANK(I10),"",IF(OR(I10="TK/0",I10="TK/1",I10="K/0"),"TER A",IF(I10="K/3","TER C","TER B"))) -> TER A | K10: =29*121333.33 -> 3518666.6 | L10: =3640000*0.84% -> 30576 | M10: =[3]MAINTENANCE!AK14 -> 146800 | N10: =[3]MAINTENANCE!$W14 -> 65250 | O10: =[3]MAINTENANCE!Z14 -> 0 | P10: =[3]MAINTENANCE!AE14 -> 0 | Q10: =[3]MAINTENANCE!AC14 -> 0 | X10: =[3]MAINTENANCE!AB14 -> 30000 | AB10: =-[3]MAINTENANCE!BA14 -> 0 | AC10: =[4]MAINTENANCE!$M15 -> 3737499.9 | AE10: =ROUNDDOWN(SUM(K10:AD10),0) -> 7528792 | AF10: =IF(J10="TER A",VLOOKUP(AE10,Ter_A,4,TRUE),IF(J10="TER B",VLOOKUP(AE10,Ter_B,4,TRUE),VLOOKUP(AE10,Ter_C,4,TRUE))) -> 0.015 | AG10: =ROUNDDOWN(IF(H10=0,AE10*AF10*120%,AE10*AF10),0) -> 112931 | AH10: =#REF! -> #REF! | AI10: =AG10-AH10 -> #REF! | AK10: =AJ10-AI10 -> #REF! | AN10: =[3]MAINTENANCE!$AF14 -> 3613916.6 | AO10: =L10+M10 -> 177376 | AP10: =AN10+AO10 -> 3791292.6 | AQ10: =AP10-AE10 -> -3737499.4
B11: 6 | C11: ELYANI | D11: 1902055206760002 | E11: 97.237.582.8-305.000 | F11: DSN PARIT GUNUNG RT. 005 RW. 003 DS AIR BATU BUDING BADAU | G11: PERAWATAN | H11: P | I11: TK/0 | J11: =IF(ISBLANK(I11),"",IF(OR(I11="TK/0",I11="TK/1",I11="K/0"),"TER A",IF(I11="K/3","TER C","TER B"))) -> TER A | K11: =29*121333.33 -> 3518666.6 | L11: =3640000*0.84% -> 30576 | M11: =[3]MAINTENANCE!AK15 -> 147340 | N11: =[3]MAINTENANCE!$W15 -> 63000 | O11: =[3]MAINTENANCE!Z15 -> 0 | P11: =[3]MAINTENANCE!AE15 -> 0 | Q11: =[3]MAINTENANCE!AC15 -> 0 | X11: =[3]MAINTENANCE!AB15 -> 43500 | AB11: =-[3]MAINTENANCE!BA15 -> -121333.33 | AC11: =[4]MAINTENANCE!$M16 -> 3750999.9 | AE11: =ROUNDDOWN(SUM(K11:AD11),0) -> 7432749 | AF11: =IF(J11="TER A",VLOOKUP(AE11,Ter_A,4,TRUE),IF(J11="TER B",VLOOKUP(AE11,Ter_B,4,TRUE),VLOOKUP(AE11,Ter_C,4,TRUE))) -> 0.0125 | AG11: =ROUNDDOWN(IF(H11=0,AE11*AF11*120%,AE11*AF11),0) -> 92909 | AH11: =#REF! -> #REF! | AI11: =AG11-AH11 -> #REF! | AK11: =AJ11-AI11 -> #REF! | AN11: =[3]MAINTENANCE!$AF15 -> 3503833.2 | AO11: =L11+M11 -> 177916 | AP11: =AN11+AO11 -> 3681749.2 | AQ11: =AP11-AE11 -> -3750999.8
B12: 7 | C12: SUSINAH | D12: 1902055109700001 | E12: 97.228.366.7-305.000 | F12: JL MANGGAR RT. 012 RW. 004 DESA KACANG BUTOR KEC. BADAU | G12: PERAWATAN | H12: P | I12: TK/0 | J12: =IF(ISBLANK(I12),"",IF(OR(I12="TK/0",I12="TK/1",I12="K/0"),"TER A",IF(I12="K/3","TER C","TER B"))) -> TER A | K12: =29*121333.33 -> 3518666.6 | L12: =3640000*0.84% -> 30576 | M12: =[3]MAINTENANCE!AK16 -> 147480 | N12: =[3]MAINTENANCE!$W16 -> 65250 | O12: =[3]MAINTENANCE!Z16 -> 0 | P12: =[3]MAINTENANCE!AE16 -> 0 | Q12: =[3]MAINTENANCE!AC16 -> 0 | X12: =[3]MAINTENANCE!AB16 -> 47000 | AB12: =-[3]MAINTENANCE!BA16 -> 0 | AC12: =[4]MAINTENANCE!$M17 -> 3754499.9 | AE12: =ROUNDDOWN(SUM(K12:AD12),0) -> 7563472 | AF12: =IF(J12="TER A",VLOOKUP(AE12,Ter_A,4,TRUE),IF(J12="TER B",VLOOKUP(AE12,Ter_B,4,TRUE),VLOOKUP(AE12,Ter_C,4,TRUE))) -> 0.015 | AG12: =ROUNDDOWN(IF(H12=0,AE12*AF12*120%,AE12*AF12),0) -> 113452 | AH12: =#REF! -> #REF! | AI12: =AG12-AH12 -> #REF! | AK12: =AJ12-AI12 -> #REF! | AN12: =[3]MAINTENANCE!$AF16 -> 3630916.6 | AO12: =L12+M12 -> 178056 | AP12: =AN12+AO12 -> 3808972.6 | AQ12: =AP12-AE12 -> -3754499.4
B13: 8 | C13: JUMIA | D13: 1902055205740001 | E13: 97.237.569.5-305.000 | F13: JL MANGGAR AIR BEGANTUNG RT. 008 RW. 003 DESA KACANG BUTOR KEC. BADAU | G13: PERAWATAN | H13: P | I13: TK/0 | J13: =IF(ISBLANK(I13),"",IF(OR(I13="TK/0",I13="TK/1",I13="K/0"),"TER A",IF(I13="K/3","TER C","TER B"))) -> TER A | K13: =29*121333.33 -> 3518666.6 | L13: =3640000*0.84% -> 30576 | M13: =[3]MAINTENANCE!AK17 -> 147340 | N13: =[3]MAINTENANCE!$W17 -> 65250 | O13: =[3]MAINTENANCE!Z17 -> 0 | P13: =[3]MAINTENANCE!AE17 -> 0 | Q13: =[3]MAINTENANCE!AC17 -> 0 | X13: =[3]MAINTENANCE!AB17 -> 43500 | AB13: =-[3]MAINTENANCE!BA17 -> 0 | AC13: =[4]MAINTENANCE!$M18 -> 3754499.9 | AE13: =ROUNDDOWN(SUM(K13:AD13),0) -> 7559832 | AF13: =IF(J13="TER A",VLOOKUP(AE13,Ter_A,4,TRUE),IF(J13="TER B",VLOOKUP(AE13,Ter_B,4,TRUE),VLOOKUP(AE13,Ter_C,4,TRUE))) -> 0.015 | AG13: =ROUNDDOWN(IF(H13=0,AE13*AF13*120%,AE13*AF13),0) -> 113397 | AH13: =#REF! -> #REF! | AI13: =AG13-AH13 -> #REF! | AK13: =AJ13-AI13 -> #REF! | AN13: =[3]MAINTENANCE!$AF17 -> 3627416.6 | AO13: =L13+M13 -> 177916 | AP13: =AN13+AO13 -> 3805332.6 | AQ13: =AP13-AE13 -> -3754499.4
B14: 9 | C14: NELI LISMANA | D14: 1902055212860002 | E14: 97.237.563.8-305.000 | F14: DSN PARIT GUNUNG RT. 005 RW. 003 DS AIR BATU BUDING BADAU | G14: PERAWATAN | H14: P | I14: TK/0 | J14: =IF(ISBLANK(I14),"",IF(OR(I14="TK/0",I14="TK/1",I14="K/0"),"TER A",IF(I14="K/3","TER C","TER B"))) -> TER A | K14: =29*121333.33 -> 3518666.6 | L14: =3640000*0.84% -> 30576 | M14: =[3]MAINTENANCE!AK18 -> 147480 | N14: =[3]MAINTENANCE!$W18 -> 65250 | O14: =[3]MAINTENANCE!Z18 -> 0 | P14: =[3]MAINTENANCE!AE18 -> 0 | Q14: =[3]MAINTENANCE!AC18 -> 0 | X14: =[3]MAINTENANCE!AB18 -> 47000 | AB14: =-[3]MAINTENANCE!BA18 -> 0 | AC14: =[4]MAINTENANCE!$M19 -> 3754499.9 | AE14: =ROUNDDOWN(SUM(K14:AD14),0) -> 7563472 | AF14: =IF(J14="TER A",VLOOKUP(AE14,Ter_A,4,TRUE),IF(J14="TER B",VLOOKUP(AE14,Ter_B,4,TRUE),VLOOKUP(AE14,Ter_C,4,TRUE))) -> 0.015 | AG14: =ROUNDDOWN(IF(H14=0,AE14*AF14*120%,AE14*AF14),0) -> 113452 | AH14: =#REF! -> #REF! | AI14: =AG14-AH14 -> #REF! | AK14: =AJ14-AI14 -> #REF! | AN14: =[3]MAINTENANCE!$AF18 -> 3630916.6 | AO14: =L14+M14 -> 178056 | AP14: =AN14+AO14 -> 3808972.6 | AQ14: =AP14-AE14 -> -3754499.4
B15: 10 | C15: KARMILA | D15: 1902056009750001 | E15: 97.237.568.7-305.000 | F15: AIR BEGANTUNG RT. 009 RW. 003 DESA KACANG BUTOR KEC. BADAU | G15: PERAWATAN | H15: P | I15: TK/0 | J15: =IF(ISBLANK(I15),"",IF(OR(I15="TK/0",I15="TK/1",I15="K/0"),"TER A",IF(I15="K/3","TER C","TER B"))) -> TER A | K15: =29*121333.33 -> 3518666.6 | L15: =3640000*0.84% -> 30576 | M15: =[3]MAINTENANCE!AK19 -> 147620 | N15: =[3]MAINTENANCE!$W19 -> 60750 | O15: =[3]MAINTENANCE!Z19 -> 0 | P15: =[3]MAINTENANCE!AE19 -> 0 | Q15: =[3]MAINTENANCE!AC19 -> 0 | X15: =[3]MAINTENANCE!AB19 -> 50500 | AB15: =-[3]MAINTENANCE!BA19 -> -242666.66 | AC15: =[4]MAINTENANCE!$M20 -> 3757999.9 | AE15: =ROUNDDOWN(SUM(K15:AD15),0) -> 7323445 | AF15: =IF(J15="TER A",VLOOKUP(AE15,Ter_A,4,TRUE),IF(J15="TER B",VLOOKUP(AE15,Ter_B,4,TRUE),VLOOKUP(AE15,Ter_C,4,TRUE))) -> 0.0125 | AG15: =ROUNDDOWN(IF(H15=0,AE15*AF15*120%,AE15*AF15),0) -> 91543 | AH15: =#REF! -> #REF! | AI15: =AG15-AH15 -> #REF! | AK15: =AJ15-AI15 -> #REF! | AN15: =[3]MAINTENANCE!$AF19 -> 3387249.9 | AO15: =L15+M15 -> 178196 | AP15: =AN15+AO15 -> 3565445.9 | AQ15: =AP15-AE15 -> -3757999.1
B16: 11 | C16: SADIAH | D16: 1902054808730002 | E16: 97.237.536.4-305.000 | F16: JL MANGGAR KM 28 DSN BUKIT INDAH RT. 011 RW. 004 DESA KACANG BUTOR KEC. BADAU | G16: PERAWATAN | H16: P | I16: TK/0 | J16: =IF(ISBLANK(I16),"",IF(OR(I16="TK/0",I16="TK/1",I16="K/0"),"TER A",IF(I16="K/3","TER C","TER B"))) -> TER A | K16: =29*121333.33 -> 3518666.6 | L16: =3640000*0.84% -> 30576 | M16: =[3]MAINTENANCE!AK20 -> 147480 | N16: =[3]MAINTENANCE!$W20 -> 63000 | O16: =[3]MAINTENANCE!Z20 -> 0 | P16: =[3]MAINTENANCE!AE20 -> 0 | Q16: =[3]MAINTENANCE!AC20 -> 0 | X16: =[3]MAINTENANCE!AB20 -> 47000 | AB16: =-[3]MAINTENANCE!BA20 -> -121333.33 | AC16: =[4]MAINTENANCE!$M21 -> 3754499.9 | AE16: =ROUNDDOWN(SUM(K16:AD16),0) -> 7439889 | AF16: =IF(J16="TER A",VLOOKUP(AE16,Ter_A,4,TRUE),IF(J16="TER B",VLOOKUP(AE16,Ter_B,4,TRUE),VLOOKUP(AE16,Ter_C,4,TRUE))) -> 0.0125 | AG16: =ROUNDDOWN(IF(H16=0,AE16*AF16*120%,AE16*AF16),0) -> 92998 | AH16: =#REF! -> #REF! | AI16: =AG16-AH16 -> #REF! | AK16: =AJ16-AI16 -> #REF! | AN16: =[3]MAINTENANCE!$AF20 -> 3507333.2 | AO16: =L16+M16 -> 178056 | AP16: =AN16+AO16 -> 3685389.2 | AQ16: =AP16-AE16 -> -3754499.8
B17: 12 | C17: PERA SUSANTI | D17: 1902056301790001 | E17: 97.237.532.3-305.000 | F17: JL MANGGAR AIR BEGANTUNG RT. 010 RW. 003 DESA KACANG BUTOR KEC. BADAU | G17: PERAWATAN | H17: P | I17: TK/0 | J17: =IF(ISBLANK(I17),"",IF(OR(I17="TK/0",I17="TK/1",I17="K/0"),"TER A",IF(I17="K/3","TER C","TER B"))) -> TER A | K17: =29*121333.33 -> 3518666.6 | L17: =3640000*0.84% -> 30576 | M17: =[3]MAINTENANCE!AK21 -> 147340 | N17: =[3]MAINTENANCE!$W21 -> 47250 | O17: =[3]MAINTENANCE!Z21 -> 0 | P17: =[3]MAINTENANCE!AE21 -> 0 | Q17: =[3]MAINTENANCE!AC21 -> 0 | X17: =[3]MAINTENANCE!AB21 -> 43500 | AB17: =-[3]MAINTENANCE!BA21 -> -970666.64 | AC17: =[4]MAINTENANCE!$M22 -> 3750999.9 | AE17: =ROUNDDOWN(SUM(K17:AD17),0) -> 6567665 | AF17: =IF(J17="TER A",VLOOKUP(AE17,Ter_A,4,TRUE),IF(J17="TER B",VLOOKUP(AE17,Ter_B,4,TRUE),VLOOKUP(AE17,Ter_C,4,TRUE))) -> 0.01 | AG17: =ROUNDDOWN(IF(H17=0,AE17*AF17*120%,AE17*AF17),0) -> 65676 | AH17: =#REF! -> #REF! | AI17: =AG17-AH17 -> #REF! | AK17: =AJ17-AI17 -> #REF! | AN17: =[3]MAINTENANCE!$AF21 -> 2638749.9 | AO17: =L17+M17 -> 177916 | AP17: =AN17+AO17 -> 2816665.9 | AQ17: =AP17-AE17 -> -3750999.1
B18: 13 | C18: MARYOTO | D18: 1902050908740001 | E18: 97.237.599.2-305.000 | F18: JL MANGGAR RT. 012 RW. 004 DS KACANG BUTOR KEC. BADAU | G18: PERAWATAN | H18: L | I18: TK/0 | J18: =IF(ISBLANK(I18),"",IF(OR(I18="TK/0",I18="TK/1",I18="K/0"),"TER A",IF(I18="K/3","TER C","TER B"))) -> TER A | K18: =29*121333.33 -> 3518666.6 | L18: =3640000*0.84% -> 30576 | M18: =[3]MAINTENANCE!AK22 -> 147340 | N18: =[3]MAINTENANCE!$W22 -> 65250 | O18: =[3]MAINTENANCE!Z22 -> 0 | P18: =[3]MAINTENANCE!AE22 -> 0 | Q18: =[3]MAINTENANCE!AC22 -> 0 | X18: =[3]MAINTENANCE!AB22 -> 43500 | AB18: =-[3]MAINTENANCE!BA22 -> 0 | AC18: =[4]MAINTENANCE!$M23 -> 3750999.9 | AE18: =ROUNDDOWN(SUM(K18:AD18),0) -> 7556332 | AF18: =IF(J18="TER A",VLOOKUP(AE18,Ter_A,4,TRUE),IF(J18="TER B",VLOOKUP(AE18,Ter_B,4,TRUE),VLOOKUP(AE18,Ter_C,4,TRUE))) -> 0.015 | AG18: =ROUNDDOWN(IF(H18=0,AE18*AF18*120%,AE18*AF18),0) -> 113344 | AH18: =#REF! -> #REF! | AI18: =AG18-AH18 -> #REF! | AK18: =AJ18-AI18 -> #REF! | AN18: =[3]MAINTENANCE!$AF22 -> 3627416.6 | AO18: =L18+M18 -> 177916 | AP18: =AN18+AO18 -> 3805332.6 | AQ18: =AP18-AE18 -> -3750999.4
B19: 14 | C19: FENTI APRIANTI | D19: 1902014204930001 | E19: 97.237.578.6-305.000 | F19: AIR BEGANTUNG RT. 010 RW. 003 DESA KACANG BUTOR KEC. BADAU | G19: PERAWATAN | H19: P | I19: TK/0 | J19: =IF(ISBLANK(I19),"",IF(OR(I19="TK/0",I19="TK/1",I19="K/0"),"TER A",IF(I19="K/3","TER C","TER B"))) -> TER A | K19: =29*121333.33 -> 3518666.6 | L19: =3640000*0.84% -> 30576 | M19: =[3]MAINTENANCE!AK23 -> 146920 | N19: =[3]MAINTENANCE!$W23 -> 63000 | O19: =[3]MAINTENANCE!Z23 -> 0 | P19: =[3]MAINTENANCE!AE23 -> 0 | Q19: =[3]MAINTENANCE!AC23 -> 0 | X19: =[3]MAINTENANCE!AB23 -> 33000 | AB19: =-[3]MAINTENANCE!BA23 -> -121333.33 | AC19: =[4]MAINTENANCE!$M24 -> 3740499.9 | AE19: =ROUNDDOWN(SUM(K19:AD19),0) -> 7411329 | AF19: =IF(J19="TER A",VLOOKUP(AE19,Ter_A,4,TRUE),IF(J19="TER B",VLOOKUP(AE19,Ter_B,4,TRUE),VLOOKUP(AE19,Ter_C,4,TRUE))) -> 0.0125 | AG19: =ROUNDDOWN(IF(H19=0,AE19*AF19*120%,AE19*AF19),0) -> 92641 | AH19: =#REF! -> #REF! | AI19: =AG19-AH19 -> #REF! | AK19: =AJ19-AI19 -> #REF! | AN19: =[3]MAINTENANCE!$AF23 -> 3493333.2 | AO19: =L19+M19 -> 177496 | AP19: =AN19+AO19 -> 3670829.2 | AQ19: =AP19-AE19 -> -3740499.8
B20: 15 | C20: YUSPANDI | D20: 1902011410690002 | E20: 97.237.828.5-305.000 | F20: JL PILANG GG MELATI RT. 007 RW. 002 DESA DUKONG KEC. TANJUNGPANDAN | G20: PERAWATAN | H20: L | I20: K/3 | J20: =IF(ISBLANK(I20),"",IF(OR(I20="TK/0",I20="TK/1",I20="K/0"),"TER A",IF(I20="K/3","TER C","TER B"))) -> TER C | K20: =29*121333.33 -> 3518666.6 | L20: =3640000*0.84% -> 30576 | M20: =[3]MAINTENANCE!AK24 -> 147340 | N20: =[3]MAINTENANCE!$W24 -> 126000 | O20: =[3]MAINTENANCE!Z24 -> 0 | P20: =[3]MAINTENANCE!AE24 -> 0 | Q20: =[3]MAINTENANCE!AC24 -> 0 | X20: =[3]MAINTENANCE!AB24 -> 43500 | AB20: =-[3]MAINTENANCE!BA24 -> -121333.33 | AC20: =[4]MAINTENANCE!$M25 -> 3818499.9 | AE20: =ROUNDDOWN(SUM(K20:AD20),0) -> 7563249 | AF20: =IF(J20="TER A",VLOOKUP(AE20,Ter_A,4,TRUE),IF(J20="TER B",VLOOKUP(AE20,Ter_B,4,TRUE),VLOOKUP(AE20,Ter_C,4,TRUE))) -> 0.0075 | AG20: =ROUNDDOWN(IF(H20=0,AE20*AF20*120%,AE20*AF20),0) -> 56724 | AH20: =#REF! -> #REF! | AI20: =AG20-AH20 -> #REF! | AK20: =AJ20-AI20 -> #REF! | AN20: =[3]MAINTENANCE!$AF24 -> 3566833.2 | AO20: =L20+M20 -> 177916 | AP20: =AN20+AO20 -> 3744749.2 | AQ20: =AP20-AE20 -> -3818499.8
B21: 16 | C21: JEMU | D21: 1902051001810001 | E21: 72.110.458.6-305.000 | F21: DUSUN BUKIT INDAH RT. 011 RW. 004 DESA KACANG BUTOR KEC. BADAU | G21: PERAWATAN | H21: L | I21: K/1 | J21: =IF(ISBLANK(I21),"",IF(OR(I21="TK/0",I21="TK/1",I21="K/0"),"TER A",IF(I21="K/3","TER C","TER B"))) -> TER B | K21: =29*121333.33 -> 3518666.6 | L21: =3640000*0.84% -> 30576 | M21: =[3]MAINTENANCE!AK25 -> 146680 | N21: =[3]MAINTENANCE!$W25 -> 126000 | O21: =[3]MAINTENANCE!Z25 -> 0 | P21: =[3]MAINTENANCE!AE25 -> 357687.82 | Q21: =[3]MAINTENANCE!AC25 -> 335250 | X21: =[3]MAINTENANCE!AB25 -> 27000 | AB21: =-[3]MAINTENANCE!BA25 -> -121333.33 | AC21: =[4]MAINTENANCE!$M26 -> 3801999.9 | AE21: =ROUNDDOWN(SUM(K21:AD21),0) -> 8222526 | AF21: =IF(J21="TER A",VLOOKUP(AE21,Ter_A,4,TRUE),IF(J21="TER B",VLOOKUP(AE21,Ter_B,4,TRUE),VLOOKUP(AE21,Ter_C,4,TRUE))) -> 0.01 | AG21: =ROUNDDOWN(IF(H21=0,AE21*AF21*120%,AE21*AF21),0) -> 82225 | AH21: =#REF! -> #REF! | AI21: =AG21-AH21 -> #REF! | AK21: =AJ21-AI21 -> #REF! | AN21: =[3]MAINTENANCE!$AF25 -> 4243271.1 | AO21: =L21+M21 -> 177256 | AP21: =AN21+AO21 -> 4420527.1 | AQ21: =AP21-AE21 -> -3801998.9
... B27: 22 | C27: NOVIANTI | D27: 1902054101820001 | E27: 97.228.396.4-305.000 | F27: DSN AIR BATU BUDING RT.002 RW.001 DESA AIR BATU BUDING KEC. BADAU | G27: PERAWATAN | H27: P | I27: TK/0 | J27: =IF(ISBLANK(I27),"",IF(OR(I27="TK/0",I27="TK/1",I27="K/0"),"TER A",IF(I27="K/3","TER C","TER B"))) -> TER A | K27: =29*121333.33 -> 3518666.6 | L27: =3640000*0.84% -> 30576 | M27: =[3]MAINTENANCE!AK31 -> 147620 | N27: =[3]MAINTENANCE!$W31 -> 65250 | O27: =[3]MAINTENANCE!Z31 -> 0 | P27: =[3]MAINTENANCE!AE31 -> 0 | Q27: =[3]MAINTENANCE!AC31 -> 0 | X27: =[3]MAINTENANCE!AB31 -> 50500 | AB27: =-[3]MAINTENANCE!BA31 -> 0 | AC27: =[4]MAINTENANCE!$M32 -> 3757999.9 | AE27: =ROUNDDOWN(SUM(K27:AD27),0) -> 7570612 | AF27: =IF(J27="TER A",VLOOKUP(AE27,Ter_A,4,TRUE),IF(J27="TER B",VLOOKUP(AE27,Ter_B,4,TRUE),VLOOKUP(AE27,Ter_C,4,TRUE))) -> 0.015 | AG27: =ROUNDDOWN(IF(H27=0,AE27*AF27*120%,AE27*AF27),0) -> 113559 | AH27: =#REF! -> #REF! | AI27: =AG27-AH27 -> #REF! | AK27: =AJ27-AI27 -> #REF! | AN27: =[3]MAINTENANCE!$AF31 -> 3634416.6 | AO27: =L27+M27 -> 178196 | AP27: =AN27+AO27 -> 3812612.6 | AQ27: =AP27-AE27 -> -3757999.4
B28: 23 | C28: YULI TRIANTO | D28: 1902050304890002 | E28: 97.228.397.2-305.000 | F28: JL MANGGAR DSN BUKIT INDAH RT. 011 RW. 004 DESA KACANG BUTOR KEC. BADAU | G28: MANDOR PANEN | H28: L | I28: K/2 | J28: =IF(ISBLANK(I28),"",IF(OR(I28="TK/0",I28="TK/1",I28="K/0"),"TER A",IF(I28="K/3","TER C","TER B"))) -> TER B | K28: =29*123833.33 -> 3591166.6 | L28: =3715000*0.84% -> 31206 | M28: ='[3]HARVESTING KHT'!AQ10 -> 150340 | N28: ='[3]HARVESTING KHT'!U10 -> 145800 | O28: ='[3]HARVESTING KHT'!X10 -> 54000 | P28: ='[3]HARVESTING KHT'!AD10 -> 1481705.2 | Q28: ='[3]HARVESTING KHT'!AE10 -> 0 | R28: ='[3]HARVESTING KHT'!AA10 -> 0 | S28: ='[3]HARVESTING KHT'!AB10 -> 0 | T28: ='[3]HARVESTING KHT'!AC10 -> 0 | U28: ='[3]HARVESTING KHT'!AF10 -> 120000 | V28: ='[3]HARVESTING KHT'!AH10 -> 0 | W28: ='[3]HARVESTING KHT'!AK10 -> 0 | X28: ='[3]HARVESTING KHT'!Z10 -> 43500 | Y28: =-'[3]HARVESTING KHT'!AI10 -> 0 | AB28: =-'[3]HARVESTING KHT'!BI10 -> -247666.66 | AC28: ='[4]HARVESTING KHT'!$M11 -> 3920499.9 | AE28: =ROUNDDOWN(SUM(K28:AD28),0) -> 9290551 | AF28: =IF(J28="TER A",VLOOKUP(AE28,Ter_A,4,TRUE),IF(J28="TER B",VLOOKUP(AE28,Ter_B,4,TRUE),VLOOKUP(AE28,Ter_C,4,TRUE))) -> 0.015 | AG28: =ROUNDDOWN(IF(H28=0,AE28*AF28*120%,AE28*AF28),0) -> 139358 | AH28: =#REF! -> #REF! | AI28: =AG28-AH28 -> #REF! | AK28: =AJ28-AI28 -> #REF! | AN28: ='[3]HARVESTING KHT'!$AL10 -> 5188505.1 | AO28: =L28+M28 -> 181546 | AP28: =AN28+AO28 -> 5370051.1 | AQ28: =AP28-AE28 -> -3920499.9
B29: 24 | C29: SALASATUN | D29: 1902054509770001 | E29: 97.237.607.3-305.000 | F29: DSN BUKIT INDAH RT. 011 RW. 004 DESA KACANG BUTOR DESA BADAU | G29: KERANI PANEN | H29: P | I29: TK/0 | J29: =IF(ISBLANK(I29),"",IF(OR(I29="TK/0",I29="TK/1",I29="K/0"),"TER A",IF(I29="K/3","TER C","TER B"))) -> TER A | K29: =29*121333.33 -> 3518666.6 | L29: =3640000*0.84% -> 30576 | M29: ='[3]HARVESTING KHT'!AQ11 -> 147620 | N29: ='[3]HARVESTING KHT'!U11 -> 65250 | O29: ='[3]HARVESTING KHT'!X11 -> 40000 | P29: ='[3]HARVESTING KHT'!AD11 -> 1556994 | Q29: ='[3]HARVESTING KHT'!AE11 -> 0 | R29: ='[3]HARVESTING KHT'!AA11 -> 0 | S29: ='[3]HARVESTING KHT'!AB11 -> 0 | T29: ='[3]HARVESTING KHT'!AC11 -> 0 | U29: ='[3]HARVESTING KHT'!AF11 -> 0 | V29: ='[3]HARVESTING KHT'!AH11 -> 0 | W29: ='[3]HARVESTING KHT'!AK11 -> 0 | X29: ='[3]HARVESTING KHT'!Z11 -> 50500 | Y29: =-'[3]HARVESTING KHT'!AI11 -> 0 | AB29: =-'[3]HARVESTING KHT'!BI11 -> 0 | AC29: ='[4]HARVESTING KHT'!$M12 -> 3757999.9 | AE29: =ROUNDDOWN(SUM(K29:AD29),0) -> 9167606 | AF29: =IF(J29="TER A",VLOOKUP(AE29,Ter_A,4,TRUE),IF(J29="TER B",VLOOKUP(AE29,Ter_B,4,TRUE),VLOOKUP(AE29,Ter_C,4,TRUE))) -> 0.0175 | AG29: =ROUNDDOWN(IF(H29=0,AE29*AF29*120%,AE29*AF29),0) -> 160433 | AH29: =#REF! -> #REF! | AI29: =AG29-AH29 -> #REF! | AK29: =AJ29-AI29 -> #REF! | AN29: ='[3]HARVESTING KHT'!$AL11 -> 5231410.6 | AO29: =L29+M29 -> 178196 | AP29: =AN29+AO29 -> 5409606.6 | AQ29: =AP29-AE29 -> -3757999.4
B30: 25 | C30: MUHAMMAD SAID | D30: 5203041206820007 | E30: - | F30: DASAN PETUNG DESA KOTARAJA KEC. SIKUR LOMBOK TIMUR | G30: PANEN | H30: L | I30: K/1 | J30: =IF(ISBLANK(I30),"",IF(OR(I30="TK/0",I30="TK/1",I30="K/0"),"TER A",IF(I30="K/3","TER C","TER B"))) -> TER B | K30: =29*121333.33 -> 3518666.6 | L30: =3640000*0.84% -> 30576 | M30: ='[3]HARVESTING KHT'!AQ12 -> 146440 | N30: ='[3]HARVESTING KHT'!U12 -> 121500 | O30: ='[3]HARVESTING KHT'!X12 -> 0 | P30: ='[3]HARVESTING KHT'!AD12 -> 0 | Q30: ='[3]HARVESTING KHT'!AE12 -> 0 | R30: ='[3]HARVESTING KHT'!AA12 -> 0 | S30: ='[3]HARVESTING KHT'!AB12 -> 174300 | T30: ='[3]HARVESTING KHT'!AC12 -> 303050 | U30: ='[3]HARVESTING KHT'!AF12 -> 153825 | V30: ='[3]HARVESTING KHT'!AH12 -> 0 | W30: ='[3]HARVESTING KHT'!AK12 -> 0 | X30: ='[3]HARVESTING KHT'!Z12 -> 21000 | Y30: =-'[3]HARVESTING KHT'!AI12 -> -284870 | AB30: =-'[3]HARVESTING KHT'!BI12 -> -242666.66 | AC30: ='[4]HARVESTING KHT'!$M13 -> 3795999.9 | AE30: =ROUNDDOWN(SUM(K30:AD30),0) -> 7737820 | AF30: =IF(J30="TER A",VLOOKUP(AE30,Ter_A,4,TRUE),IF(J30="TER B",VLOOKUP(AE30,Ter_B,4,TRUE),VLOOKUP(AE30,Ter_C,4,TRUE))) -> 0.01 | AG30: =ROUNDDOWN(IF(H30=0,AE30*AF30*120%,AE30*AF30),0) -> 77378 | AH30: =#REF! -> #REF! | AI30: =AG30-AH30 -> #REF! | AK30: =AJ30-AI30 -> #REF! | AN30: ='[3]HARVESTING KHT'!$AL12 -> 3764804.9 | AO30: =L30+M30 -> 177016 | AP30: =AN30+AO30 -> 3941820.9 | AQ30: =AP30-AE30 -> -3795999.1
B31: 26 | C31: NANO | D31: 3313162910710002 | E31: - | F31: GONDANGREJO RT. 001 RW. 008 DESA KARANG REJO KEC. KERJO KARANGANYAR JAWA TENGAH | G31: PANEN | H31: L | I31: K/1 | J31: =IF(ISBLANK(I31),"",IF(OR(I31="TK/0",I31="TK/1",I31="K/0"),"TER A",IF(I31="K/3","TER C","TER B"))) -> TER B | K31: =29*121333.33 -> 3518666.6 | L31: =3640000*0.84% -> 30576 | M31: ='[3]HARVESTING KHT'!AQ13 -> 146440 | N31: ='[3]HARVESTING KHT'!U13 -> 130500 | O31: ='[3]HARVESTING KHT'!X13 -> 0 | P31: ='[3]HARVESTING KHT'!AD13 -> 0 | Q31: ='[3]HARVESTING KHT'!AE13 -> 0 | R31: ='[3]HARVESTING KHT'!AA13 -> 111471 | S31: ='[3]HARVESTING KHT'!AB13 -> 190050 | T31: ='[3]HARVESTING KHT'!AC13 -> 471900 | U31: ='[3]HARVESTING KHT'!AF13 -> 156030 | V31: ='[3]HARVESTING KHT'!AH13 -> 0 | W31: ='[3]HARVESTING KHT'!AK13 -> 0 | X31: ='[3]HARVESTING KHT'!Z13 -> 21000 | Y31: =-'[3]HARVESTING KHT'!AI13 -> -101551 | AB31: =-'[3]HARVESTING KHT'!BI13 -> 0 | AC31: ='[4]HARVESTING KHT'!$M14 -> 3795999.9 | AE31: =ROUNDDOWN(SUM(K31:AD31),0) -> 8471082 | AF31: =IF(J31="TER A",VLOOKUP(AE31,Ter_A,4,TRUE),IF(J31="TER B",VLOOKUP(AE31,Ter_B,4,TRUE),VLOOKUP(AE31,Ter_C,4,TRUE))) -> 0.01 | AG31: =ROUNDDOWN(IF(H31=0,AE31*AF31*120%,AE31*AF31),0) -> 84710 | AH31: =#REF! -> #REF! | AI31: =AG31-AH31 -> #REF! | AK31: =AJ31-AI31 -> #REF! | AN31: ='[3]HARVESTING KHT'!$AL13 -> 4498066.6 | AO31: =L31+M31 -> 177016 | AP31: =AN31+AO31 -> 4675082.6 | AQ31: =AP31-AE31 -> -3795999.4
B32: 27 | C32: SUHAELI | D32: 5203144107750742 | E32: - | F32: BEAK DAYA DESA WANASAB KEC. WANASABA KEC. LOMBOK TIMUR | G32: PANEN | H32: L | I32: K/2 | J32: =IF(ISBLANK(I32),"",IF(OR(I32="TK/0",I32="TK/1",I32="K/0"),"TER A",IF(I32="K/3","TER C","TER B"))) -> TER B | K32: =29*121333.33 -> 3518666.6 | L32: =3640000*0.84% -> 30576 | M32: ='[3]HARVESTING KHT'!AQ14 -> 146440 | N32: ='[3]HARVESTING KHT'!U14 -> 58500 | O32: ='[3]HARVESTING KHT'!X14 -> 0 | P32: ='[3]HARVESTING KHT'!AD14 -> 0 | Q32: ='[3]HARVESTING KHT'!AE14 -> 0 | R32: ='[3]HARVESTING KHT'!AA14 -> 0 | S32: ='[3]HARVESTING KHT'!AB14 -> 136500 | T32: ='[3]HARVESTING KHT'!AC14 -> 303050 | U32: ='[3]HARVESTING KHT'!AF14 -> 104055 | V32: ='[3]HARVESTING KHT'!AH14 -> 0 | W32: ='[3]HARVESTING KHT'!AK14 -> 0 | X32: ='[3]HARVESTING KHT'!Z14 -> 21000 | Y32: =-'[3]HARVESTING KHT'!AI14 -> -303333 | AB32: =-'[3]HARVESTING KHT'!BI14 -> -363999.99 | AC32: ='[4]HARVESTING KHT'!$M15 -> 3728499.9 | AE32: =ROUNDDOWN(SUM(K32:AD32),0) -> 7379954 | AF32: =IF(J32="TER A",VLOOKUP(AE32,Ter_A,4,TRUE),IF(J32="TER B",VLOOKUP(AE32,Ter_B,4,TRUE),VLOOKUP(AE32,Ter_C,4,TRUE))) -> 0.01 | AG32: =ROUNDDOWN(IF(H32=0,AE32*AF32*120%,AE32*AF32),0) -> 73799 | AH32: =#REF! -> #REF! | AI32: =AG32-AH32 -> #REF! | AK32: =AJ32-AI32 -> #REF! | AN32: ='[3]HARVESTING KHT'!$AL14 -> 3474438.6 | AO32: =L32+M32 -> 177016 | AP32: =AN32+AO32 -> 3651454.6 | AQ32: =AP32-AE32 -> -3728499.4
B33: 28 | C33: RUSTAM | D33: 5203183112790211 | E33: - | F33: BARE LUNGKAK DESA GERENENG KEC. SAKRA TIMUR KAB. LOMBOK TIMUR | G33: PANEN | H33: L | I33: K/1 | J33: =IF(ISBLANK(I33),"",IF(OR(I33="TK/0",I33="TK/1",I33="K/0"),"TER A",IF(I33="K/3","TER C","TER B"))) -> TER B | K33: =29*121333.33 -> 3518666.6 | L33: =3640000*0.84% -> 30576 | M33: ='[3]HARVESTING KHT'!AQ15 -> 146440 | N33: ='[3]HARVESTING KHT'!U15 -> 100800 | O33: ='[3]HARVESTING KHT'!X15 -> 0 | P33: ='[3]HARVESTING KHT'!AD15 -> 0 | Q33: ='[3]HARVESTING KHT'!AE15 -> 0 | R33: ='[3]HARVESTING KHT'!AA15 -> 0 | S33: ='[3]HARVESTING KHT'!AB15 -> 163800 | T33: ='[3]HARVESTING KHT'!AC15 -> 467500 | U33: ='[3]HARVESTING KHT'!AF15 -> 0 | V33: ='[3]HARVESTING KHT'!AH15 -> 0 | W33: ='[3]HARVESTING KHT'!AK15 -> 0 | X33: ='[3]HARVESTING KHT'!Z15 -> 21000 | Y33: =-'[3]HARVESTING KHT'!AI15 -> -97594 | AB33: =-'[3]HARVESTING KHT'!BI15 -> -121333.33 | AC33: ='[4]HARVESTING KHT'!$M16 -> 3768999.9 | AE33: =ROUNDDOWN(SUM(K33:AD33),0) -> 7998855 | AF33: =IF(J33="TER A",VLOOKUP(AE33,Ter_A,4,TRUE),IF(J33="TER B",VLOOKUP(AE33,Ter_B,4,TRUE),VLOOKUP(AE33,Ter_C,4,TRUE))) -> 0.01 | AG33: =ROUNDDOWN(IF(H33=0,AE33*AF33*120%,AE33*AF33),0) -> 79988 | AH33: =#REF! -> #REF! | AI33: =AG33-AH33 -> #REF! | AK33: =AJ33-AI33 -> #REF! | AN33: ='[3]HARVESTING KHT'!$AL15 -> 4052839.2 | AO33: =L33+M33 -> 177016 | AP33: =AN33+AO33 -> 4229855.2 | AQ33: =AP33-AE33 -> -3768999.8
B34: 29 | C34: SAPRIANTO | D34: 1902052605910003 | E34: - | F34: DSN PESARAKAN RT. 007 RW. 003 DESA CENDIL KEC. KELAPA KAMPIT | G34: PANEN | H34: L | I34: K/1 | J34: =IF(ISBLANK(I34),"",IF(OR(I34="TK/0",I34="TK/1",I34="K/0"),"TER A",IF(I34="K/3","TER C","TER B"))) -> TER B | K34: =29*121333.33 -> 3518666.6 | L34: =3640000*0.84% -> 30576 | M34: ='[3]HARVESTING KHT'!AQ16 -> 146200 | N34: ='[3]HARVESTING KHT'!U16 -> 126000 | O34: ='[3]HARVESTING KHT'!X16 -> 0 | P34: ='[3]HARVESTING KHT'!AD16 -> 0 | Q34: ='[3]HARVESTING KHT'!AE16 -> 0 | R34: ='[3]HARVESTING KHT'!AA16 -> 7635 | S34: ='[3]HARVESTING KHT'!AB16 -> 130200 | T34: ='[3]HARVESTING KHT'!AC16 -> 421850 | U34: ='[3]HARVESTING KHT'!AF16 -> 0 | V34: ='[3]HARVESTING KHT'!AH16 -> 0 | W34: ='[3]HARVESTING KHT'!AK16 -> 0 | X34: ='[3]HARVESTING KHT'!Z16 -> 15000 | Y34: =-'[3]HARVESTING KHT'!AI16 -> -304652 | AB34: =-'[3]HARVESTING KHT'!BI16 -> -121333.33 | AC34: ='[4]HARVESTING KHT'!$M17 -> 3789999.9 | AE34: =ROUNDDOWN(SUM(K34:AD34),0) -> 7760142 | AF34: =IF(J34="TER A",VLOOKUP(AE34,Ter_A,4,TRUE),IF(J34="TER B",VLOOKUP(AE34,Ter_B,4,TRUE),VLOOKUP(AE34,Ter_C,4,TRUE))) -> 0.01 | AG34: =ROUNDDOWN(IF(H34=0,AE34*AF34*120%,AE34*AF34),0) -> 77601 | AH34: =#REF! -> #REF! | AI34: =AG34-AH34 -> #REF! | AK34: =AJ34-AI34 -> #REF! | AN34: ='[3]HARVESTING KHT'!$AL16 -> 3793366.2 | AO34: =L34+M34 -> 176776 | AP34: =AN34+AO34 -> 3970142.2 | AQ34: =AP34-AE34 -> -3789999.8
B35: 30 | C35: NANDAR ASMARA | D35: 3202262009710002 | E35: - | F35: KP NYALINDUNG RT. 034 RW. 008 DESA CIRACAP KEC. CIRACAP KAB. SUKABUMI JAWA BARAT | G35: PANEN | H35: L | I35: K/0 | J35: =IF(ISBLANK(I35),"",IF(OR(I35="TK/0",I35="TK/1",I35="K/0"),"TER A",IF(I35="K/3","TER C","TER B"))) -> TER A | K35: =29*121333.33 -> 3518666.6 | L35: =3640000*0.84% -> 30576 | M35: ='[3]HARVESTING KHT'!AQ17 -> 145900 | N35: ='[3]HARVESTING KHT'!U17 -> 97200 | O35: ='[3]HARVESTING KHT'!X17 -> 0 | P35: ='[3]HARVESTING KHT'!AD17 -> 0 | Q35: ='[3]HARVESTING KHT'!AE17 -> 0 | R35: ='[3]HARVESTING KHT'!AA17 -> 0 | S35: ='[3]HARVESTING KHT'!AB17 -> 184800 | T35: ='[3]HARVESTING KHT'!AC17 -> 453200 | U35: ='[3]HARVESTING KHT'!AF17 -> 0 | V35: ='[3]HARVESTING KHT'!AH17 -> 0 | W35: ='[3]HARVESTING KHT'!AK17 -> 0 | X35: ='[3]HARVESTING KHT'!Z17 -> 7500 | Y35: =-'[3]HARVESTING KHT'!AI17 -> 0 | AB35: =-'[3]HARVESTING KHT'!BI17 -> -242666.66 | AC35: ='[4]HARVESTING KHT'!$M18 -> 3755499.9 | AE35: =ROUNDDOWN(SUM(K35:AD35),0) -> 7950675 | AF35: =IF(J35="TER A",VLOOKUP(AE35,Ter_A,4,TRUE),IF(J35="TER B",VLOOKUP(AE35,Ter_B,4,TRUE),VLOOKUP(AE35,Ter_C,4,TRUE))) -> 0.015 | AG35: =ROUNDDOWN(IF(H35=0,AE35*AF35*120%,AE35*AF35),0) -> 119260 | AH35: =#REF! -> #REF! | AI35: =AG35-AH35 -> #REF! | AK35: =AJ35-AI35 -> #REF! | AN35: ='[3]HARVESTING KHT'!$AL17 -> 4018699.9 | AO35: =L35+M35 -> 176476 | AP35: =AN35+AO35 -> 4195175.9 | AQ35: =AP35-AE35 -> -3755499.1
B36: 31 | C36: JUPRI | D36: 5203120107650934 | E36: - | F36: MONTOR DAKOK DESA PENGADANGAN KEC. PRINGGASELA KAB. LOMBOK TIMUR | G36: PANEN | H36: L | I36: K/2 | J36: =IF(ISBLANK(I36),"",IF(OR(I36="TK/0",I36="TK/1",I36="K/0"),"TER A",IF(I36="K/3","TER C","TER B"))) -> TER B | K36: =29*121333.33 -> 3518666.6 | L36: =3640000*0.84% -> 30576 | M36: ='[3]HARVESTING KHT'!AQ18 -> 145800 | N36: ='[3]HARVESTING KHT'!U18 -> 151200 | O36: ='[3]HARVESTING KHT'!X18 -> 0 | P36: ='[3]HARVESTING KHT'!AD18 -> 0 | Q36: ='[3]HARVESTING KHT'!AE18 -> 0 | R36: ='[3]HARVESTING KHT'!AA18 -> 297765 | S36: ='[3]HARVESTING KHT'!AB18 -> 149100 | T36: ='[3]HARVESTING KHT'!AC18 -> 314600 | U36: ='[3]HARVESTING KHT'!AF18 -> 138390 | V36: ='[3]HARVESTING KHT'!AH18 -> 0 | W36: ='[3]HARVESTING KHT'!AK18 -> 0 | X36: ='[3]HARVESTING KHT'!Z18 -> 5000 | Y36: =-'[3]HARVESTING KHT'!AI18 -> -320478 | AB36: =-'[3]HARVESTING KHT'!BI18 -> -121333.33 | AC36: ='[4]HARVESTING KHT'!$M19 -> 3806999.9 | AE36: =ROUNDDOWN(SUM(K36:AD36),0) -> 8116286 | AF36: =IF(J36="TER A",VLOOKUP(AE36,Ter_A,4,TRUE),IF(J36="TER B",VLOOKUP(AE36,Ter_B,4,TRUE),VLOOKUP(AE36,Ter_C,4,TRUE))) -> 0.01 | AG36: =ROUNDDOWN(IF(H36=0,AE36*AF36*120%,AE36*AF36),0) -> 81162 | AH36: =#REF! -> #REF! | AI36: =AG36-AH36 -> #REF! | AK36: =AJ36-AI36 -> #REF! | AN36: ='[3]HARVESTING KHT'!$AL18 -> 4132910.2 | AO36: =L36+M36 -> 176376 | AP36: =AN36+AO36 -> 4309286.2 | AQ36: =AP36-AE36 -> -3806999.8
B37: 32 | C37: HERNAWADI | D37: 5203100912940002 | E37: 04.970.518.9-305.000 | F37: KOKOK RAJAK RT.003/RW.000 DESA DADAP KEC. SAMBELIA KAB. LOMBOK TIMUR | G37: PANEN | H37: L | I37: K/1 | J37: =IF(ISBLANK(I37),"",IF(OR(I37="TK/0",I37="TK/1",I37="K/0"),"TER A",IF(I37="K/3","TER C","TER B"))) -> TER B | K37: =29*121333.33 -> 3518666.6 | L37: =3640000*0.84% -> 30576 | M37: ='[3]HARVESTING KHT'!AQ19 -> 145700 | N37: ='[3]HARVESTING KHT'!U19 -> 130500 | O37: ='[3]HARVESTING KHT'!X19 -> 0 | P37: ='[3]HARVESTING KHT'!AD19 -> 0 | Q37: ='[3]HARVESTING KHT'!AE19 -> 0 | R37: ='[3]HARVESTING KHT'!AA19 -> 317616 | S37: ='[3]HARVESTING KHT'!AB19 -> 220500 | T37: ='[3]HARVESTING KHT'!AC19 -> 471900 | U37: ='[3]HARVESTING KHT'!AF19 -> 0 | V37: ='[3]HARVESTING KHT'!AH19 -> 0 | W37: ='[3]HARVESTING KHT'!AK19 -> 0 | X37: ='[3]HARVESTING KHT'!Z19 -> 2500 | Y37: =-'[3]HARVESTING KHT'!AI19 -> 0 | AB37: =-'[3]HARVESTING KHT'!BI19 -> 0 | AC37: ='[4]HARVESTING KHT'!$M20 -> 3779999.9 | AE37: =ROUNDDOWN(SUM(K37:AD37),0) -> 8617958 | AF37: =IF(J37="TER A",VLOOKUP(AE37,Ter_A,4,TRUE),IF(J37="TER B",VLOOKUP(AE37,Ter_B,4,TRUE),VLOOKUP(AE37,Ter_C,4,TRUE))) -> 0.01 | AG37: =ROUNDDOWN(IF(H37=0,AE37*AF37*120%,AE37*AF37),0) -> 86179 | AH37: =#REF! -> #REF! | AI37: =AG37-AH37 -> #REF! | AK37: =AJ37-AI37 -> #REF! | AN37: ='[3]HARVESTING KHT'!$AL19 -> 4661682.6 | AO37: =L37+M37 -> 176276 | AP37: =AN37+AO37 -> 4837958.6 | AQ37: =AP37-AE37 -> -3779999.4
B38: 33 | C38: JAHARUDIN | D38: 5203173112780193 | E38: - | F38: GUNUNG TIMBA RT.006/ RW.003 DESA DENGGAN TIMUR KEC. SELONG KAB. LOMBOK TIMUR | G38: PANEN | H38: L | I38: K/1 | J38: =IF(ISBLANK(I38),"",IF(OR(I38="TK/0",I38="TK/1",I38="K/0"),"TER A",IF(I38="K/3","TER C","TER B"))) -> TER B | K38: =29*121333.33 -> 3518666.6 | L38: =3640000*0.84% -> 30576 | M38: ='[3]HARVESTING KHT'!AQ20 -> 145700 | N38: ='[3]HARVESTING KHT'!U20 -> 130500 | O38: ='[3]HARVESTING KHT'!X20 -> 0 | P38: ='[3]HARVESTING KHT'!AD20 -> 0 | Q38: ='[3]HARVESTING KHT'!AE20 -> 0 | R38: ='[3]HARVESTING KHT'!AA20 -> 108417 | S38: ='[3]HARVESTING KHT'!AB20 -> 129150 | T38: ='[3]HARVESTING KHT'!AC20 -> 470800 | U38: ='[3]HARVESTING KHT'!AF20 -> 0 | V38: ='[3]HARVESTING KHT'!AH20 -> 0 | W38: ='[3]HARVESTING KHT'!AK20 -> 0 | X38: ='[3]HARVESTING KHT'!Z20 -> 2500 | Y38: =-'[3]HARVESTING KHT'!AI20 -> 0 | AB38: =-'[3]HARVESTING KHT'!BI20 -> 0 | AC38: ='[4]HARVESTING KHT'!$M21 -> 3779999.9 | AE38: =ROUNDDOWN(SUM(K38:AD38),0) -> 8316309 | AF38: =IF(J38="TER A",VLOOKUP(AE38,Ter_A,4,TRUE),IF(J38="TER B",VLOOKUP(AE38,Ter_B,4,TRUE),VLOOKUP(AE38,Ter_C,4,TRUE))) -> 0.01 | AG38: =ROUNDDOWN(IF(H38=0,AE38*AF38*120%,AE38*AF38),0) -> 83163 | AH38: =#REF! -> #REF! | AI38: =AG38-AH38 -> #REF! | AK38: =AJ38-AI38 -> #REF! | AN38: ='[3]HARVESTING KHT'!$AL20 -> 4360033.6 | AO38: =L38+M38 -> 176276 | AP38: =AN38+AO38 -> 4536309.6 | AQ38: =AP38-AE38 -> -3779999.4
B39: 34 | C39: BAHARI | D39: 5203070107770764 | E39: - | F39: DASAN GEDANG DAYA DESA DENGGEN KEC. SELONG KAB. LOMBOK TIMUR | G39: PANEN | H39: L | I39: K/2 | J39: =IF(ISBLANK(I39),"",IF(OR(I39="TK/0",I39="TK/1",I39="K/0"),"TER A",IF(I39="K/3","TER C","TER B"))) -> TER B | K39: =29*121333.33 -> 3518666.6 | L39: =3640000*0.84% -> 30576 | M39: ='[3]HARVESTING KHT'!AQ21 -> 145700 | N39: ='[3]HARVESTING KHT'!U21 -> 130500 | O39: ='[3]HARVESTING KHT'!X21 -> 0 | P39: ='[3]HARVESTING KHT'!AD21 -> 0 | Q39: ='[3]HARVESTING KHT'!AE21 -> 0 | R39: ='[3]HARVESTING KHT'!AA21 -> 517653 | S39: ='[3]HARVESTING KHT'!AB21 -> 157500 | T39: ='[3]HARVESTING KHT'!AC21 -> 437800 | U39: ='[3]HARVESTING KHT'!AF21 -> 0 | V39: ='[3]HARVESTING KHT'!AH21 -> 150000 | W39: ='[3]HARVESTING KHT'!AK21 -> 0 | X39: ='[3]HARVESTING KHT'!Z21 -> 2500 | Y39: =-'[3]HARVESTING KHT'!AI21 -> 0 | AB39: =-'[3]HARVESTING KHT'!BI21 -> 0 | AC39: ='[4]HARVESTING KHT'!$M22 -> 3779999.9 | AE39: =ROUNDDOWN(SUM(K39:AD39),0) -> 8870895 | AF39: =IF(J39="TER A",VLOOKUP(AE39,Ter_A,4,TRUE),IF(J39="TER B",VLOOKUP(AE39,Ter_B,4,TRUE),VLOOKUP(AE39,Ter_C,4,TRUE))) -> 0.01 | AG39: =ROUNDDOWN(IF(H39=0,AE39*AF39*120%,AE39*AF39),0) -> 88708 | AH39: =#REF! -> #REF! | AI39: =AG39-AH39 -> #REF! | AK39: =AJ39-AI39 -> #REF! | AN39: ='[3]HARVESTING KHT'!$AL21 -> 4914619.6 | AO39: =L39+M39 -> 176276 | AP39: =AN39+AO39 -> 5090895.6 | AQ39: =AP39-AE39 -> -3779999.4
B40: 35 | C40: SAPARUDIN | D40: 5202090109840002 | E40: - | F40: PENGKORES RT.005/RW.- DESA KOPANG REMBIGA KEC. KOPANG KAB. LOMBOK TENGAH | G40: PANEN | H40: L | I40: TK/0 | J40: =IF(ISBLANK(I40),"",IF(OR(I40="TK/0",I40="TK/1",I40="K/0"),"TER A",IF(I40="K/3","TER C","TER B"))) -> TER A | K40: =29*121333.33 -> 3518666.6 | L40: =3640000*0.84% -> 30576 | M40: ='[3]HARVESTING KHT'!AQ22 -> 145700 | N40: ='[3]HARVESTING KHT'!U22 -> 60750 | O40: ='[3]HARVESTING KHT'!X22 -> 0 | P40: ='[3]HARVESTING KHT'!AD22 -> 0 | Q40: ='[3]HARVESTING KHT'!AE22 -> 0 | R40: ='[3]HARVESTING KHT'!AA22 -> 42756 | S40: ='[3]HARVESTING KHT'!AB22 -> 171150 | T40: ='[3]HARVESTING KHT'!AC22 -> 301950 | U40: ='[3]HARVESTING KHT'!AF22 -> 0 | V40: ='[3]HARVESTING KHT'!AH22 -> 0 | W40: ='[3]HARVESTING KHT'!AK22 -> 0 | X40: ='[3]HARVESTING KHT'!Z22 -> 2500 | Y40: =-'[3]HARVESTING KHT'!AI22 -> -105507 | AB40: =-'[3]HARVESTING KHT'!BI22 -> -242666.66 | AC40: ='[4]HARVESTING KHT'!$M23 -> 3709999.9 | AE40: =ROUNDDOWN(SUM(K40:AD40),0) -> 7635874 | AF40: =IF(J40="TER A",VLOOKUP(AE40,Ter_A,4,TRUE),IF(J40="TER B",VLOOKUP(AE40,Ter_B,4,TRUE),VLOOKUP(AE40,Ter_C,4,TRUE))) -> 0.015 | AG40: =ROUNDDOWN(IF(H40=0,AE40*AF40*120%,AE40*AF40),0) -> 114538 | AH40: =#REF! -> #REF! | AI40: =AG40-AH40 -> #REF! | AK40: =AJ40-AI40 -> #REF! | AN40: ='[3]HARVESTING KHT'!$AL22 -> 3749598.9 | AO40: =L40+M40 -> 176276 | AP40: =AN40+AO40 -> 3925874.9 | AQ40: =AP40-AE40 -> -3709999.1
... B62: 57 | C62: JUMADIL | D62: 5203010107780410 | E62: - | F62: DASAN BARU DESA SENYIUR KEC. KERUAK KAB. LOMBOK TIMUR | G62: PANEN | H62: L | I62: K/2 | J62: =IF(ISBLANK(I62),"",IF(OR(I62="TK/0",I62="TK/1",I62="K/0"),"TER A",IF(I62="K/3","TER C","TER B"))) -> TER B | K62: =29*121333.33 -> 3518666.6 | L62: =3640000*0.84% -> 30576 | M62: ='[3]HARVESTING KHT'!AQ44 -> 145900 | N62: ='[3]HARVESTING KHT'!U44 -> 156600 | O62: ='[3]HARVESTING KHT'!X44 -> 0 | P62: ='[3]HARVESTING KHT'!AD44 -> 0 | Q62: ='[3]HARVESTING KHT'!AE44 -> 0 | R62: ='[3]HARVESTING KHT'!AA44 -> 563463 | S62: ='[3]HARVESTING KHT'!AB44 -> 245700 | T62: ='[3]HARVESTING KHT'!AC44 -> 451000 | U62: ='[3]HARVESTING KHT'!AF44 -> 0 | V62: ='[3]HARVESTING KHT'!AH44 -> 150000 | W62: ='[3]HARVESTING KHT'!AK44 -> 0 | X62: ='[3]HARVESTING KHT'!Z44 -> 7500 | Y62: =-'[3]HARVESTING KHT'!AI44 -> -88362 | AB62: =-'[3]HARVESTING KHT'!BI44 -> 0 | AC62: ='[4]HARVESTING KHT'!$M45 -> 3809499.9 | AE62: =ROUNDDOWN(SUM(K62:AD62),0) -> 8990543 | AF62: =IF(J62="TER A",VLOOKUP(AE62,Ter_A,4,TRUE),IF(J62="TER B",VLOOKUP(AE62,Ter_B,4,TRUE),VLOOKUP(AE62,Ter_C,4,TRUE))) -> 0.01 | AG62: =ROUNDDOWN(IF(H62=0,AE62*AF62*120%,AE62*AF62),0) -> 89905 | AH62: =#REF! -> #REF! | AI62: =AG62-AH62 -> #REF! | AK62: =AJ62-AI62 -> #REF! | AN62: ='[3]HARVESTING KHT'!$AL44 -> 5004567.6 | AO62: =L62+M62 -> 176476 | AP62: =AN62+AO62 -> 5181043.6 | AQ62: =AP62-AE62 -> -3809499.4
