Workbook
Name Ter_A: [1]TARIF!$B$3:$E$46
Name Ter_B: [1]TARIF!$H$3:$K$42
Name Ter_C: [1]TARIF!$N$3:$Q$43

Sheet CKROL PHT
A1: DATA HASIL PANEN
A2: KARYAWAN KHT
A3: No | B3: Nama Karyawan | C3: Tanggal | AH3: Total | AI3: HARGA | AJ3: PREMI | AK3: CT | AL3: CS | AM3: CM | AN3: CN | AO3: CI | AP3: TOTAL | AQ3: CTH | AR3: A
C4: 1 | D4: 2 | E4: 3 | F4: 4 | G4: 5 | H4: 6 | I4: 7 | J4: 8 | K4: 9 | L4: 10 | M4: 11 | N4: 12 | O4: 13 | P4: 14 | Q4: 15 | R4: 16 | S4: 17 | T4: 18 | U4: 19 | V4: 20 | W4: 21 | X4: 22 | Y4: 23 | Z4: 24 | AA4: 25 | AB4: 26 | AC4: 27 | AD4: 28 | AE4: 29 | AF4: 30 | AG4: 31 | AI4: PREMI | AP4: HK
A5: 1 | B5: DICKY PRATAMA | D5: CS | E5: CS | G5: CS | H5: CS | I5: CS | J5: CS | K5: CS | L5: CS | N5: CS | O5: CS | P5: CS | Q5: CS | S5: CS | U5: 1 | V5: 1 | W5: 1 | X5: 1 | Y5: 1 | Z5: 1 | AB5: 1 | AC5: 1 | AD5: 1 | AE5: 1 | AF5: 1 | AG5: 1 | AH5: =SUM(C5:AG5) -> 12 | AK5: =COUNTIF(C5:AG5,"CT") -> 0 | AL5: =COUNTIF(C5:AG5,"CS") -> 13 | AM5: 4 | AN5: 2 | AO5: =COUNTIF(C5:AG5,"CI") -> 0 | AP5: =AH5+AK5+AL5+AM5+AN5+AO5 -> 31 | AQ5: =COUNTIF(C5:AG5,"CTH") -> 0 | AR5: =COUNTIF(C5:AG5,"A") -> 0
B6: LEMBUR 1 | AH6: =SUM(C6:AG6) -> 0 | AI6: 33612.14 | AJ6: =AH6*AI6 -> 0
B7: 2 | AH7: =SUM(C7:AG7) -> 0 | AI7: 44816.18 | AJ7: =AH7*AI7 -> 0
AJ8: =SUM(AJ6:AJ7) -> 0
A9: 2 | B9: RIDHO APRIZAL | D9: 1 | E9: 1 | G9: 1 | H9: 1 | I9: 1 | J9: 1 | K9: 1 | L9: 1 | N9: 1 | O9: 1 | P9: 1 | Q9: 1 | S9: 1 | U9: CT | V9: CT | W9: CT | X9: CT | Y9: CT | Z9: CT | AB9: 1 | AC9: 1 | AD9: 1 | AE9: 1 | AF9: 1 | AG9: 1 | AH9: =SUM(C9:AG9) -> 19 | AK9: =COUNTIF(C9:AG9,"CT") -> 6 | AL9: =COUNTIF(C9:AG9,"CS") -> 0 | AM9: 4 | AN9: 2 | AO9: =COUNTIF(C9:AG9,"CI") -> 0 | AP9: =AH9+AK9+AL9+AM9+AN9+AO9 -> 31 | AQ9: =COUNTIF(C9:AG9,"CTH") -> 0 | AR9: =COUNTIF(C9:AG9,"A") -> 0
B10: LEMBUR 1 | AH10: =SUM(C10:AG10) -> 0 | AI10: 33612.14 | AJ10: =AH10*AI10 -> 0
B11: 2 | AH11: =SUM(C11:AG11) -> 0 | AI11: 44816.18 | AJ11: =AH11*AI11 -> 0
AJ12: =SUM(AJ10:AJ11) -> 0
A13: 3 | B13: SUIP | D13: 1 | E13: 1 | G13: 1 | H13: 1 | I13: 1 | J13: 1 | K13: 1 | L13: 1 | N13: 1 | O13: 1 | P13: 1 | Q13: CT | S13: 1 | U13: 1 | V13: 1 | W13: 1 | X13: 1 | Y13: 1 | Z13: 1 | AB13: 1 | AC13: 1 | AD13: 1 | AE13: 1 | AF13: 1 | AG13: 1 | AH13: =SUM(C13:AG13) -> 24 | AK13: =COUNTIF(C13:AG13,"CT") -> 1 | AL13: =COUNTIF(C13:AG13,"CS") -> 0 | AM13: 4 | AN13: 2 | AO13: =COUNTIF(C13:AG13,"CI") -> 0 | AP13: =AH13+AK13+AL13+AM13+AN13+AO13 -> 31 | AQ13: =COUNTIF(C13:AG13,"CTH") -> 0 | AR13: =COUNTIF(C13:AG13,"A") -> 0
B14: BLOCK | D14: 07/01 | E14: 13/01 | G14: 12/01 | H14: 97/04 | I14: 97/03 | J14: 13/01 | K14: 98/01 | L14: 07/02 | N14: 07/01 | O14: 08/01 | P14: 97/04 | S14: 12/01 | U14: 13/01 | V14: 98/01 | W14: 07/02 | X14: 07/01 | Y14: 97/04 | Z14: 97/03 | AB14: 12/01 | AC14: 97/15 | AD14: 12/01 | AE14: 13/01 | AF14: 98/01 | AG14: 07/02
B15: Basis | D15: 90 | E15: 103 | G15: 103 | H15: 90 | I15: 90 | J15: 103 | K15: 90 | L15: 90 | N15: 90 | O15: 90 | P15: 90 | S15: 103 | U15: 103 | V15: 90 | W15: 90 | X15: 90 | Y15: 90 | Z15: 90 | AB15: 103 | AC15: 90 | AD15: 103 | AE15: 103 | AF15: 90 | AG15: 90
B16: Janjang | D16: 42 | E16: 48 | G16: 61 | H16: 39 | I16: 54 | J16: 64 | K16: 49 | L16: 31 | N16: 55 | O16: 57 | P16: 31 | S16: 50 | U16: 27 | V16: 50 | W16: 23 | X16: 23 | Y16: 28 | Z16: 16 | AB16: 54 | AC16: 20 | AD16: 31 | AE16: 36 | AF16: 27 | AG16: 32 | AH16: =SUM(C16:AG16) -> 948
B17: Premi 90 | AH17: =SUM(C17:AG17) -> 0 | AI17: 1409 | AJ17: =AH17*AI17 -> 0
B18: Premi 103 | E18: 48 | J18: 64 | AH18: =SUM(C18:AG18) -> 112 | AI18: 1322 | AJ18: =AH18*AI18 -> 148064
B19: Premi 114 | AH19: =SUM(C19:AG19) -> 0 | AI19: 1233 | AJ19: =AH19*AI19 -> 0
AH20: TOTAL PREMI | AJ20: =SUM(AJ17:AJ19) -> 148064
B21: Brondol | D21: 11 | E21: 15 | G21: 12 | H21: 7 | I21: 27 | J21: 13 | K21: 15 | L21: 17 | N21: 12 | O21: 8 | P21: 10 | S21: 6 | U21: 2 | V21: 12 | W21: 6 | X21: 3 | Y21: 3 | Z21: 4 | AB21: 6 | AC21: 2 | AD21: 2 | AE21: 2 | AF21: 4 | AG21: 4 | AH21: =SUM(C21:AG21) -> 203 | AI21: 1750 | AJ21: =AH21*AI21 -> 355250
B22: Koreksi | W22: =134500/W15*W16-134500 -> -100127.78 | AH22: =SUM(C22:AG22) -> -100127.78
A24: 4 | B24: ROBIN DINATA | D24: 1 | E24: 1 | G24: 1 | H24: 1 | I24: 1 | J24: 1 | K24: 1 | L24: 1 | N24: 1 | O24: 1 | P24: 1 | Q24: 1 | S24: 1 | U24: 1 | V24: 1 | W24: 1 | X24: 1 | Y24: 1 | Z24: 1 | AB24: 1 | AC24: 1 | AD24: 1 | AE24: 1 | AF24: 1 | AG24: 1 | AH24: =SUM(C24:AG24) -> 25 | AK24: =COUNTIF(C24:AG24,"CT") -> 0 | AL24: =COUNTIF(C24:AG24,"CS") -> 0 | AM24: 4 | AN24: 2 | AO24: =COUNTIF(C24:AG24,"CI") -> 0 | AP24: =AH24+AK24+AL24+AM24+AN24+AO24 -> 31 | AQ24: =COUNTIF(C24:AG24,"CTH") -> 0 | AR24: =COUNTIF(C24:AG24,"A") -> 0
B25: BLOCK | D25: 07/01 | E25: 07/01 | G25: 12/01 | H25: 97/04 | I25: 97/03 | J25: 13/01 | K25: 98/01 | L25: 07/02 | N25: 07/01 | O25: 08/01 | P25: 97/04 | Q25: 12/01 | S25: 12/01 | U25: 13/01 | V25: 98/01 | W25: 07/02 | X25: 07/02 | Y25: 97/04 | Z25: 97/03 | AB25: 12/01 | AC25: 97/15 | AD25: 12/01 | AE25: 13/01 | AF25: 98/01 | AG25: 07/02
B26: Basis | D26: 90 | E26: 90 | G26: 103 | H26: 90 | I26: 90 | J26: 103 | K26: 90 | L26: 90 | N26: 90 | O26: 90 | P26: 90 | Q26: 103 | S26: 103 | U26: 103 | V26: 90 | W26: 90 | X26: 90 | Y26: 90 | Z26: 90 | AB26: 103 | AC26: 90 | AD26: 103 | AE26: 103 | AF26: 90 | AG26: 90
B27: Janjang | D27: 50 | E27: 49 | G27: 87 | H27: 43 | I27: 48 | J27: 53 | K27: 50 | L27: 30 | N27: 50 | O27: 54 | P27: 39 | Q27: 35 | S27: 51 | U27: 46 | V27: 41 | W27: 29 | X27: 26 | Y27: 22 | Z27: 21 | AB27: 55 | AC27: 22 | AD27: 46 | AE27: 43 | AF27: 24 | AG27: 23 | AH27: =SUM(C27:AG27) -> 1037
B28: Premi 90 | E28: 49 | AH28: =SUM(C28:AG28) -> 49 | AI28: 1409 | AJ28: =AH28*AI28 -> 69041
B29: Premi 103 | J29: 53 | AH29: =SUM(C29:AG29) -> 53 | AI29: 1322 | AJ29: =AH29*AI29 -> 70066
B30: Premi 114 | AH30: =SUM(C30:AG30) -> 0 | AI30: 1233 | AJ30: =AH30*AI30 -> 0
AH31: TOTAL PREMI | AJ31: =SUM(AJ28:AJ30) -> 139107
B32: Brondol | D32: 9 | E32: 15 | G32: 19 | H32: 13 | I32: 20 | J32: 6 | K32: 13 | L32: 5 | N32: 10 | O32: 14 | P32: 13 | Q32: 14 | S32: 6 | U32: 4 | V32: 8 | W32: 3 | X32: 3 | Y32: 8 | Z32: 6 | AB32: 4 | AC32: 3 | AD32: 6 | AE32: 4 | AF32: 7 | AG32: 5 | AH32: =SUM(C32:AG32) -> 218 | AI32: 1750 | AJ32: =AH32*AI32 -> 381500
B33: Koreksi | N33: =134500/N26*N27-134500 -> -59777.778 | AH33: =SUM(C33:AG33) -> -59777.778
A35: 5 | B35: SAPARUDIN | D35: 1 | E35: 1 | G35: 1 | H35: 1 | I35: 1 | J35: 1 | K35: 1 | L35: CT | N35: 1 | O35: 1 | P35: CT | Q35: CT | S35: 1 | U35: 1 | V35: 1 | W35: 1 | X35: 1 | Y35: 1 | Z35: 1 | AB35: 1 | AC35: 1 | AD35: 1 | AE35: 1 | AF35: 1 | AG35: 1 | AH35: =SUM(C35:AG35) -> 22 | AK35: =COUNTIF(C35:AG35,"CT") -> 3 | AL35: =COUNTIF(C35:AG35,"CS") -> 0 | AM35: 4 | AN35: 2 | AO35: =COUNTIF(C35:AG35,"CI") -> 0 | AP35: =AH35+AK35+AL35+AM35+AN35+AO35 -> 31 | AQ35: =COUNTIF(C35:AG35,"CTH") -> 0 | AR35: =COUNTIF(C35:AG35,"A") -> 0
B36: BLOCK | D36: 07/01 | E36: 13/01 | G36: 12/01 | H36: 97/04 | I36: 97/03 | J36: 98/01 | K36: 98/01 | N36: 07/01 | O36: 08/01 | S36: 12/01 | U36: 13/01 | V36: 98/01 | W36: 07/02 | X36: 07/01 | Y36: 97/04 | Z36: 97/03 | AB36: 12/01 | AC36: 97/15 | AD36: 12/01 | AE36: 13/01 | AF36: 98/01 | AG36: 07/02 | AH36: 91
B37: Basis | D37: 90 | E37: 103 | G37: 103 | H37: 90 | I37: 90 | J37: 90 | K37: 90 | N37: 90 | O37: 90 | S37: 103 | U37: 103 | V37: 90 | W37: 90 | X37: 90 | Y37: 90 | Z37: 90 | AB37: 103 | AC37: 90 | AD37: 103 | AE37: 103 | AF37: 90 | AG37: 90
B38: Janjang | D38: 83 | E38: 74 | G38: 90 | H38: 51 | I38: 65 | J38: 67 | K38: 59 | N38: 37 | O38: 22 | S38: 60 | U38: 46 | V38: 34 | W38: 21 | X38: 30 | Y38: 41 | Z38: 35 | AB38: 110 | AC38: 20 | AD38: 19 | AE38: 30 | AF38: 41 | AG38: 28 | AH38: =SUM(C38:AG38) -> 1063
B39: Premi 90 | J39: 67 | AH39: =SUM(C39:AG39) -> 67 | AI39: 1409 | AJ39: =AH39*AI39 -> 94403
B40: Premi 103 | E40: 74 | AB40: 7 | AH40: =SUM(C40:AG40) -> 81 | AI40: 1322 | AJ40: =AH40*AI40 -> 107082
B41: Premi 114 | AH41: =SUM(C41:AG41) -> 0 | AI41: 1233 | AJ41: =AH41*AI41 -> 0
AH42: TOTAL PREMI | AJ42: =SUM(AJ39:AJ41) -> 201485
...

Sheet Sheet2
B3: HK PREMI PANEN DAN BRONDOL PEMANEN
B4: DIVISI : AIR JANGKAT
B6: NO | C6: NAMA | D6: HK | J6: TOTAL HK | K6: CTH | L6: A | M6: LEMBUR | N6: PREMI | P6: KOREKSI
D7: HK | E7: CT | F7: CS | G7: CM | H7: CN | I7: CI | N7: TANDAN | O7: BRD
B8: 1 | C8: ='CKROL PHT'!B5 -> DICKY PRATAMA | D8: ='CKROL PHT'!AH5 -> 12 | E8: ='CKROL PHT'!AK5 -> 0 | F8: ='CKROL PHT'!AL5 -> 13 | G8: 4 | H8: 2 | I8: ='CKROL PHT'!AO5 -> 0 | J8: ='CKROL PHT'!AP5 -> 31 | K8: ='CKROL PHT'!AQ5 -> 0 | L8: ='CKROL PHT'!AR5 -> 0 | M8: ='CKROL PHT'!AJ8 -> 0
B9: 2 | C9: ='CKROL PHT'!B9 -> RIDHO APRIZAL | D9: ='CKROL PHT'!AH9 -> 19 | E9: ='CKROL PHT'!AK9 -> 6 | F9: ='CKROL PHT'!AL9 -> 0 | G9: 4 | H9: 2 | I9: ='CKROL PHT'!AO9 -> 0 | J9: ='CKROL PHT'!AP9 -> 31 | K9: ='CKROL PHT'!AQ9 -> 0 | L9: ='CKROL PHT'!AR9 -> 0 | M9: ='CKROL PHT'!AJ12 -> 0
B10: 3 | C10: ='CKROL PHT'!B13 -> SUIP | D10: ='CKROL PHT'!AH13 -> 24 | E10: ='CKROL PHT'!AK13 -> 1 | F10: ='CKROL PHT'!AL13 -> 0 | G10: 4 | H10: 2 | I10: ='CKROL PHT'!AO13 -> 0 | J10: ='CKROL PHT'!AP13 -> 31 | K10: ='CKROL PHT'!AQ13 -> 0 | L10: ='CKROL PHT'!AR13 -> 0 | N10: ='CKROL PHT'!AJ20 -> 148064 | O10: ='CKROL PHT'!AJ21 -> 355250 | P10: ='CKROL PHT'!AH22 -> -100127.78
B11: 4 | C11: ='CKROL PHT'!B24 -> ROBIN DINATA | D11: ='CKROL PHT'!AH24 -> 25 | E11: ='CKROL PHT'!AK24 -> 0 | F11: ='CKROL PHT'!AL24 -> 0 | G11: 4 | H11: 2 | I11: ='CKROL PHT'!AO24 -> 0 | J11: ='CKROL PHT'!AP24 -> 31 | K11: ='CKROL PHT'!AQ24 -> 0 | L11: ='CKROL PHT'!AR24 -> 0 | N11: ='CKROL PHT'!AJ31 -> 139107 | O11: ='CKROL PHT'!AJ32 -> 381500 | P11: ='CKROL PHT'!AH33 -> -59777.778
B12: 5 | C12: ='CKROL PHT'!B35 -> SAPARUDIN | D12: ='CKROL PHT'!AH35 -> 22 | E12: ='CKROL PHT'!AK35 -> 3 | F12: ='CKROL PHT'!AL35 -> 0 | G12: 4 | H12: 2 | I12: ='CKROL PHT'!AO35 -> 0 | J12: ='CKROL PHT'!AP35 -> 31 | K12: ='CKROL PHT'!AQ35 -> 0 | L12: ='CKROL PHT'!AR35 -> 0 | N12: ='CKROL PHT'!AJ42 -> 201485 | O12: ='CKROL PHT'!AJ43 -> 490000 | P12: ='CKROL PHT'!AH44 -> -46327.778
B13: 6 | C13: ='CKROL PHT'!B46 -> SONJA PRIYOGA | D13: ='CKROL PHT'!AH46 -> 25 | E13: ='CKROL PHT'!AK46 -> 0 | F13: ='CKROL PHT'!AL46 -> 0 | G13: 4 | H13: 2 | I13: ='CKROL PHT'!AO46 -> 0 | J13: ='CKROL PHT'!AP46 -> 31 | K13: ='CKROL PHT'!AQ46 -> 0 | L13: ='CKROL PHT'!AR46 -> 0 | N13: ='CKROL PHT'!AJ53 -> 170538 | O13: ='CKROL PHT'!AJ54 -> 444500 | P13: ='CKROL PHT'!AH55 -> -44833.333
B14: 7 | C14: ='CKROL PHT'!B57 -> AHAP | D14: ='CKROL PHT'!AH57 -> 23 | E14: ='CKROL PHT'!AK57 -> 2 | F14: ='CKROL PHT'!AL57 -> 0 | G14: 4 | H14: 2 | I14: ='CKROL PHT'!AO57 -> 0 | J14: ='CKROL PHT'!AP57 -> 31 | K14: ='CKROL PHT'!AQ57 -> 0 | L14: ='CKROL PHT'!AR57 -> 0 | N14: ='CKROL PHT'!AJ64 -> 271292 | O14: ='CKROL PHT'!AJ65 -> 554750 | P14: ='CKROL PHT'!AH66 -> 0
B15: 8 | C15: ='CKROL PHT'!B68 -> IHSAN | D15: ='CKROL PHT'!AH68 -> 24 | E15: ='CKROL PHT'!AK68 -> 1 | F15: ='CKROL PHT'!AL68 -> 0 | G15: 4 | H15: 2 | I15: ='CKROL PHT'!AO68 -> 0 | J15: ='CKROL PHT'!AP68 -> 31 | K15: ='CKROL PHT'!AQ68 -> 0 | L15: ='CKROL PHT'!AR68 -> 0 | N15: ='CKROL PHT'!AJ75 -> 275360 | O15: ='CKROL PHT'!AJ76 -> 393750 | P15: ='CKROL PHT'!AH77 -> -113577.78
B16: 9 | C16: ='CKROL PHT'!B79 -> QISTAHAM | D16: ='CKROL PHT'!AH79 -> 25 | E16: ='CKROL PHT'!AK79 -> 0 | F16: ='CKROL PHT'!AL79 -> 0 | G16: 4 | H16: 2 | I16: ='CKROL PHT'!AO79 -> 0 | J16: ='CKROL PHT'!AP79 -> 31 | K16: ='CKROL PHT'!AQ79 -> 0 | L16: ='CKROL PHT'!AR79 -> 0 | M16: ='CKROL PHT'!AJ265 -> 209913.3 | N16: ='CKROL PHT'!AJ86 -> 810804 | O16: ='CKROL PHT'!AJ87 -> 588000 | P16: ='CKROL PHT'!AH88 -> 0
B17: 10 | C17: ='CKROL PHT'!B90 -> JAYADI | D17: ='CKROL PHT'!AH90 -> 24 | E17: ='CKROL PHT'!AK90 -> 1 | F17: ='CKROL PHT'!AL90 -> 0 | G17: 4 | H17: 2 | I17: ='CKROL PHT'!AO90 -> 0 | J17: ='CKROL PHT'!AP90 -> 31 | K17: ='CKROL PHT'!AQ90 -> 0 | L17: ='CKROL PHT'!AR90 -> 0 | N17: ='CKROL PHT'!AJ97 -> 484688 | O17: ='CKROL PHT'!AJ98 -> 514500 | P17: ='CKROL PHT'!AH99 -> 0
B18: 11 | C18: ='CKROL PHT'!B101 -> M.AMIN | D18: ='CKROL PHT'!AH101 -> 23 | E18: ='CKROL PHT'!AK101 -> 2 | F18: ='CKROL PHT'!AL101 -> 0 | G18: 4 | H18: 2 | I18: ='CKROL PHT'!AO101 -> 0 | J18: ='CKROL PHT'!AP101 -> 31 | K18: ='CKROL PHT'!AQ101 -> 0 | L18: ='CKROL PHT'!AR101 -> 0 | N18: ='CKROL PHT'!AJ108 -> 146742 | O18: ='CKROL PHT'!AJ109 -> 292250 | P18: ='CKROL PHT'!AH110 -> -107077.67
B19: 12 | C19: ='CKROL PHT'!B112 -> SAMSUL HADI | D19: ='CKROL PHT'!AH112 -> 24 | E19: ='CKROL PHT'!AK112 -> 1 | F19: ='CKROL PHT'!AL112 -> 0 | G19: 4 | H19: 2 | I19: ='CKROL PHT'!AO112 -> 0 | J19: ='CKROL PHT'!AP112 -> 31 | K19: ='CKROL PHT'!AQ112 -> 0 | L19: ='CKROL PHT'!AR112 -> 0 | M19: ='CKROL PHT'!AJ268 -> 338193.65 | N19: ='CKROL PHT'!AJ119 -> 415057 | O19: ='CKROL PHT'!AJ120 -> 493500 | P19: ='CKROL PHT'!AH121 -> 0
B20: 13 | C20: ='CKROL PHT'!B123 -> SAPARUDIN | D20: ='CKROL PHT'!AH123 -> 25 | E20: ='CKROL PHT'!AK123 -> 0 | F20: ='CKROL PHT'!AL123 -> 0 | G20: 4 | H20: 2 | I20: ='CKROL PHT'!AO123 -> 0 | J20: ='CKROL PHT'!AP123 -> 31 | K20: ='CKROL PHT'!AQ123 -> 0 | L20: ='CKROL PHT'!AR123 -> 0 | N20: ='CKROL PHT'!AJ130 -> 327856 | O20: ='CKROL PHT'!AJ131 -> 518000 | P20: ='CKROL PHT'!AH132 -> 0
B21: 14 | C21: ='CKROL PHT'!B134 -> FAHRUDIN | D21: ='CKROL PHT'!AH134 -> 23 | E21: ='CKROL PHT'!AK134 -> 2 | F21: ='CKROL PHT'!AL134 -> 0 | G21: 4 | H21: 2 | I21: ='CKROL PHT'!AO134 -> 0 | J21: ='CKROL PHT'!AP134 -> 31 | K21: ='CKROL PHT'!AQ134 -> 0 | L21: ='CKROL PHT'!AR134 -> 0 | N21: ='CKROL PHT'!AJ141 -> 1595654 | O21: ='CKROL PHT'!AJ142 -> 651000 | P21: ='CKROL PHT'!AH143 -> 0
B22: 15 | C22: ='CKROL PHT'!B145 -> HERIANTO ARBI | D22: ='CKROL PHT'!AH145 -> 24 | E22: ='CKROL PHT'!AK145 -> 1 | F22: ='CKROL PHT'!AL145 -> 0 | G22: 4 | H22: 2 | I22: ='CKROL PHT'!AO145 -> 0 | J22: ='CKROL PHT'!AP145 -> 31 | K22: ='CKROL PHT'!AQ145 -> 0 | L22: ='CKROL PHT'!AR145 -> 0 | N22: ='CKROL PHT'!AJ152 -> 183170 | O22: ='CKROL PHT'!AJ153 -> 446250 | P22: ='CKROL PHT'!AH154 -> -121441.75
B23: 16 | C23: ='CKROL PHT'!B156 -> RIDUAN | D23: ='CKROL PHT'!AH156 -> 25 | E23: ='CKROL PHT'!AK156 -> 0 | F23: ='CKROL PHT'!AL156 -> 0 | G23: 4 | H23: 2 | I23: ='CKROL PHT'!AO156 -> 0 | J23: ='CKROL PHT'!AP156 -> 31 | K23: ='CKROL PHT'!AQ156 -> 0 | L23: ='CKROL PHT'!AR156 -> 0 | N23: ='CKROL PHT'!AJ163 -> 119538 | O23: ='CKROL PHT'!AJ164 -> 344750 | P23: ='CKROL PHT'!AH165 -> -103116.67
B24: 17 | C24: ='CKROL PHT'!B167 -> DEKI FRANZA | D24: ='CKROL PHT'!AH167 -> 16 | E24: ='CKROL PHT'!AK167 -> 2 | F24: ='CKROL PHT'!AL167 -> 1 | G24: 4 | H24: 2 | I24: ='CKROL PHT'!AO167 -> 0 | J24: ='CKROL PHT'!AP167 -> 25 | K24: ='CKROL PHT'!AQ167 -> 1 | L24: ='CKROL PHT'!AR167 -> 5 | N24: ='CKROL PHT'!AJ174 -> 0 | O24: ='CKROL PHT'!AJ175 -> 175000 | P24: ='CKROL PHT'!AH176 -> -347480.1
B25: 18 | C25: ='CKROL PHT'!B178 -> FRANSISKO GAUTAMA | D25: ='CKROL PHT'!AH178 -> 22 | E25: ='CKROL PHT'!AK178 -> 1 | F25: ='CKROL PHT'!AL178 -> 1 | G25: 4 | H25: 2 | I25: ='CKROL PHT'!AO178 -> 0 | J25: ='CKROL PHT'!AP178 -> 30 | K25: ='CKROL PHT'!AQ178 -> 0 | L25: ='CKROL PHT'!AR178 -> 1 | N25: ='CKROL PHT'!AJ185 -> 162712 | O25: ='CKROL PHT'!AJ186 -> 313250 | P25: ='CKROL PHT'!AH187 -> -101622.22
B26: 19 | C26: ='CKROL PHT'!B189 -> M.IDRIS PRATAMA | D26: ='CKROL PHT'!AH189 -> 21 | E26: ='CKROL PHT'!AK189 -> 2 | F26: ='CKROL PHT'!AL189 -> 0 | G26: 4 | H26: 2 | I26: ='CKROL PHT'!AO189 -> 0 | J26: ='CKROL PHT'!AP189 -> 29 | K26: ='CKROL PHT'!AQ189 -> 0 | L26: ='CKROL PHT'!AR189 -> 2 | N26: ='CKROL PHT'!AJ196 -> 136028 | O26: ='CKROL PHT'!AJ197 -> 337750 | P26: ='CKROL PHT'!AH198 -> -393038.89
B27: 20 | C27: ='CKROL PHT'!B200 -> SUTRA PRAYOGI | D27: ='CKROL PHT'!AH200 -> 25 | E27: ='CKROL PHT'!AK200 -> 0 | F27: ='CKROL PHT'!AL200 -> 0 | G27: 4 | H27: 2 | I27: ='CKROL PHT'!AO200 -> 0 | J27: ='CKROL PHT'!AP200 -> 31 | K27: ='CKROL PHT'!AQ200 -> 0 | L27: ='CKROL PHT'!AR200 -> 0 | N27: ='CKROL PHT'!AJ207 -> 149386 | O27: ='CKROL PHT'!AJ208 -> 455000 | P27: ='CKROL PHT'!AH209 -> -114912.62
B28: TOTAL | D28: =SUM(D8:D27) -> 451 | E28: =SUM(E8:E27) -> 25 | F28: =SUM(F8:F27) -> 15 | G28: =SUM(G8:G27) -> 80 | H28: =SUM(H8:H27) -> 40 | I28: =SUM(I8:I27) -> 0 | J28: =SUM(J8:J27) -> 611 | K28: =SUM(K8:K27) -> 1 | ... P28: =SUM(P8:P27) -> -1653334.4
B29: 21 | C29: HAERUDIN | D29: ='CKROL PHT'!AH211 -> 18 | E29: ='CKROL PHT'!AK211 -> 0 | F29: ='CKROL PHT'!AL211 -> 0 | G29: 3 | H29: 2 | I29: ='CKROL PHT'!AO211 -> 0 | J29: ='CKROL PHT'!AP211 -> 23 | K29: ='CKROL PHT'!AQ211 -> 0 | L29: ='CKROL PHT'!AR211 -> 0 | N29: ='CKROL PHT'!AJ218 -> 0 | O29: ='CKROL PHT'!AJ219 -> 238000 | P29: ='CKROL PHT'!AH220 -> 0
B30: TOTAL | D30: =D28+D29 -> 469 | E30: =E28+E29 -> 25 | F30: =F28+F29 -> 15 | G30: =G28+G29 -> 83 | H30: =H28+H29 -> 42 | I30: =I28+I29 -> 0 | J30: =J28+J29 -> 634 | K30: =K28+K29 -> 1 | ... P30: =P28+P29 -> -1653334.4

Sheet OUTPUT-HK
B2: LAPORAN HASIL PANEN PGE 2A
B3: DIVISI : AIR JANGKAT
B4: BULAN : AGUSTUS 2025
B5: NAMA | C5: TANGGAL | BM5: TOTAL
C6: 1 | E6: 2 | G6: 3 | I6: 4 | K6: 5 | M6: 6 | O6: 7 | Q6: 8 | S6: 9 | U6: 10 | W6: 11 | Y6: 12 | AA6: 13 | AC6: 14 | AE6: 15 | AG6: 16 | AI6: 17 | AK6: 18 | AM6: 19 | AO6: 20 | AQ6: 21 | AS6: 22 | AU6: 23 | AW6: 24 | AY6: 25 | BA6: 26 | BC6: 27 | BE6: 28 | BG6: 29 | BI6: 30 | BK6: 31
C7: JJG | D7: MT | E7: JJG | F7: MT | G7: JJG | H7: MT | I7: JJG | J7: MT | K7: JJG | L7: MT | M7: JJG | N7: MT | O7: JJG | P7: MT | Q7: JJG | R7: MT | S7: JJG | T7: MT | U7: JJG | V7: MT | W7: JJG | X7: MT | Y7: JJG | Z7: MT | AA7: JJG | AB7: MT | AC7: JJG | AD7: MT | AE7: JJG | AF7: MT | AG7: JJG | AH7: MT | AI7: JJG | AJ7: MT | AK7: JJG | AL7: MT | AM7: JJG | AN7: MT | AO7: JJG | AP7: MT | AQ7: JJG | AR7: MT | AS7: JJG | AT7: MT | AU7: JJG | AV7: MT | AW7: JJG | AX7: MT | AY7: JJG | AZ7: MT | BA7: JJG | BB7: MT | BC7: JJG | BD7: MT | BE7: JJG | BF7: MT | BG7: JJG | BH7: MT | BI7: JJG | BJ7: MT | BK7: JJG | BL7: MT | BM7: JJG | BN7: MT
B8: =Sheet2!C10 -> SUIP | C8: ='CKROL PHT'!C16 -> 0 | E8: ='CKROL PHT'!D16 -> 42 | F8: =E8*14.99/1000 -> 0.62958 | G8: ='CKROL PHT'!E16 -> 48 | H8: =G8*14.99/1000 -> 0.71952 | I8: ='CKROL PHT'!F16 -> 0 | K8: ='CKROL PHT'!G16 -> 61 | L8: =K8*14.99/1000 -> 0.91439 | M8: ='CKROL PHT'!H16 -> 39 | N8: =M8*14.99/1000 -> 0.58461 | O8: ='CKROL PHT'!I16 -> 54 | P8: =O8*14.99/1000 -> 0.80946 | Q8: ='CKROL PHT'!J16 -> 64 | R8: =Q8*14.99/1000 -> 0.95936 | S8: ='CKROL PHT'!K16 -> 49 | T8: =S8*14.99/1000 -> 0.73451 | U8: ='CKROL PHT'!L16 -> 31 | V8: =U8*14.99/1000 -> 0.46469 | W8: ='CKROL PHT'!M16 -> 0 | Y8: ='CKROL PHT'!N16 -> 55 | AA8: ='CKROL PHT'!O16 -> 57 | AB8: =AA8*14.99/1000 -> 0.85443 | AC8: ='CKROL PHT'!P16 -> 31 | AE8: ='CKROL PHT'!Q16 -> 0 | AG8: ='CKROL PHT'!R16 -> 0 | AI8: ='CKROL PHT'!S16 -> 50 | AK8: ='CKROL PHT'!T16 -> 0 | AM8: ='CKROL PHT'!U16 -> 27 | AO8: ='CKROL PHT'!V16 -> 50 | AQ8: ='CKROL PHT'!W16 -> 23 | AS8: ='CKROL PHT'!X16 -> 23 | AU8: ='CKROL PHT'!Y16 -> 28 | AW8: ='CKROL PHT'!Z16 -> 16 | AY8: ='CKROL PHT'!AA16 -> 0 | BA8: ='CKROL PHT'!AB16 -> 54 | BC8: ='CKROL PHT'!AC16 -> 20 | BE8: ='CKROL PHT'!AD16 -> 31 | BG8: ='CKROL PHT'!AE16 -> 36 | BI8: ='CKROL PHT'!AF16 -> 27 | BK8: ='CKROL PHT'!AG16 -> 32 | BM8: =C8+E8+G8+I8+K8+M8+O8+Q8+S8+U8+W8+Y8+AA8+AC8+AE8+AG8+AI8+AK8+AM8+AO8+AQ8+AS8+AU8+AW8+AY8+BA8+BC8+BE8+BG8+BI8+BK8 -> 948 | BN8: =BM8*14.99/1000 -> 14.21052
B9: =Sheet2!C11 -> ROBIN DINATA | C9: ='CKROL PHT'!C27 -> 0 | E9: ='CKROL PHT'!D27 -> 50 | F9: =E9*14.99/1000 -> 0.7495 | G9: ='CKROL PHT'!E27 -> 49 | H9: =G9*14.99/1000 -> 0.73451 | I9: ='CKROL PHT'!F27 -> 0 | K9: ='CKROL PHT'!G27 -> 87 | L9: =K9*14.99/1000 -> 1.30413 | M9: ='CKROL PHT'!H27 -> 43 | N9: =M9*14.99/1000 -> 0.64457 | O9: ='CKROL PHT'!I27 -> 48 | P9: =O9*14.99/1000 -> 0.71952 | Q9: ='CKROL PHT'!J27 -> 53 | R9: =Q9*14.99/1000 -> 0.79447 | S9: ='CKROL PHT'!K27 -> 50 | T9: =S9*14.99/1000 -> 0.7495 | U9: ='CKROL PHT'!L27 -> 30 | V9: =U9*14.99/1000 -> 0.4497 | W9: ='CKROL PHT'!M27 -> 0 | Y9: ='CKROL PHT'!N27 -> 50 | AA9: ='CKROL PHT'!O27 -> 54 | AB9: =AA9*14.99/1000 -> 0.80946 | AC9: ='CKROL PHT'!P27 -> 39 | AE9: ='CKROL PHT'!Q27 -> 35 | AG9: ='CKROL PHT'!R27 -> 0 | AI9: ='CKROL PHT'!S27 -> 51 | AK9: ='CKROL PHT'!T27 -> 0 | AM9: ='CKROL PHT'!U27 -> 46 | AO9: ='CKROL PHT'!V27 -> 41 | AQ9: ='CKROL PHT'!W27 -> 29 | AS9: ='CKROL PHT'!X27 -> 26 | AU9: ='CKROL PHT'!Y27 -> 22 | AW9: ='CKROL PHT'!Z27 -> 21 | AY9: ='CKROL PHT'!AA27 -> 0 | BA9: ='CKROL PHT'!AB27 -> 55 | BC9: ='CKROL PHT'!AC27 -> 22 | BE9: ='CKROL PHT'!AD27 -> 46 | BG9: ='CKROL PHT'!AE27 -> 43 | BI9: ='CKROL PHT'!AF27 -> 24 | BK9: ='CKROL PHT'!AG27 -> 23 | BM9: =C9+E9+G9+I9+K9+M9+O9+Q9+S9+U9+W9+Y9+AA9+AC9+AE9+AG9+AI9+AK9+AM9+AO9+AQ9+AS9+AU9+AW9+AY9+BA9+BC9+BE9+BG9+BI9+BK9 -> 1037 | BN9: =BM9*14.99/1000 -> 15.54463
B10: =Sheet2!C12 -> SAPARUDIN | C10: ='CKROL PHT'!C38 -> 0 | E10: ='CKROL PHT'!D38 -> 83 | F10: =E10*14.99/1000 -> 1.24417 | G10: ='CKROL PHT'!E38 -> 74 | H10: =G10*14.99/1000 -> 1.10926 | I10: ='CKROL PHT'!F38 -> 0 | K10: ='CKROL PHT'!G38 -> 90 | L10: =K10*14.99/1000 -> 1.3491 | M10: ='CKROL PHT'!H38 -> 51 | N10: =M10*14.99/1000 -> 0.76449 | O10: ='CKROL PHT'!I38 -> 65 | P10: =O10*14.99/1000 -> 0.97435 | Q10: ='CKROL PHT'!J38 -> 67 | R10: =Q10*14.99/1000 -> 1.00433 | S10: ='CKROL PHT'!K38 -> 59 | T10: =S10*14.99/1000 -> 0.88441 | U10: ='CKROL PHT'!L38 -> 0 | V10: =U10*14.99/1000 -> 0 | W10: ='CKROL PHT'!M38 -> 0 | Y10: ='CKROL PHT'!N38 -> 37 | AA10: ='CKROL PHT'!O38 -> 22 | AB10: =AA10*14.99/1000 -> 0.32978 | AC10: ='CKROL PHT'!P38 -> 0 | AE10: ='CKROL PHT'!Q38 -> 0 | AG10: ='CKROL PHT'!R38 -> 0 | AI10: ='CKROL PHT'!S38 -> 60 | AK10: ='CKROL PHT'!T38 -> 0 | AM10: ='CKROL PHT'!U38 -> 46 | AO10: ='CKROL PHT'!V38 -> 34 | AQ10: ='CKROL PHT'!W38 -> 21 | AS10: ='CKROL PHT'!X38 -> 30 | AU10: ='CKROL PHT'!Y38 -> 41 | AW10: ='CKROL PHT'!Z38 -> 35 | AY10: ='CKROL PHT'!AA38 -> 0 | BA10: ='CKROL PHT'!AB38 -> 110 | BC10: ='CKROL PHT'!AC38 -> 20 | BE10: ='CKROL PHT'!AD38 -> 19 | BG10: ='CKROL PHT'!AE38 -> 30 | BI10: ='CKROL PHT'!AF38 -> 41 | BK10: ='CKROL PHT'!AG38 -> 28 | BM10: =C10+E10+G10+I10+K10+M10+O10+Q10+S10+U10+W10+Y10+AA10+AC10+AE10+AG10+AI10+AK10+AM10+AO10+AQ10+AS10+AU10+AW10+AY10+BA10+BC10+BE10+BG10+BI10+BK10 -> 1063 | BN10: =BM10*14.99/1000 -> 15.93437
B11: =Sheet2!C13 -> SONJA PRIYOGA | C11: ='CKROL PHT'!C49 -> 0 | E11: ='CKROL PHT'!D49 -> 54 | F11: =E11*14.99/1000 -> 0.80946 | G11: ='CKROL PHT'!E49 -> 69 | H11: =G11*14.99/1000 -> 1.03431 | I11: ='CKROL PHT'!F49 -> 0 | K11: ='CKROL PHT'!G49 -> 87 | L11: =K11*14.99/1000 -> 1.30413 | M11: ='CKROL PHT'!H49 -> 42 | N11: =M11*14.99/1000 -> 0.62958 | O11: ='CKROL PHT'!I49 -> 49 | P11: =O11*14.99/1000 -> 0.73451 | Q11: ='CKROL PHT'!J49 -> 60 | R11: =Q11*14.99/1000 -> 0.8994 | S11: ='CKROL PHT'!K49 -> 43 | T11: =S11*14.99/1000 -> 0.64457 | U11: ='CKROL PHT'!L49 -> 44 | V11: =U11*14.99/1000 -> 0.65956 | W11: ='CKROL PHT'!M49 -> 0 | Y11: ='CKROL PHT'!N49 -> 60 | AA11: ='CKROL PHT'!O49 -> 68 | AB11: =AA11*14.99/1000 -> 1.01932 | AC11: ='CKROL PHT'!P49 -> 37 | AE11: ='CKROL PHT'!Q49 -> 34 | AG11: ='CKROL PHT'!R49 -> 0 | AI11: ='CKROL PHT'!S49 -> 51 | AK11: ='CKROL PHT'!T49 -> 0 | AM11: ='CKROL PHT'!U49 -> 53 | AO11: ='CKROL PHT'!V49 -> 39 | AQ11: ='CKROL PHT'!W49 -> 28 | AS11: ='CKROL PHT'!X49 -> 29 | AU11: ='CKROL PHT'!Y49 -> 22 | AW11: ='CKROL PHT'!Z49 -> 20 | AY11: ='CKROL PHT'!AA49 -> 0 | BA11: ='CKROL PHT'!AB49 -> 58 | BC11: ='CKROL PHT'!AC49 -> 20 | BE11: ='CKROL PHT'!AD49 -> 27 | BG11: ='CKROL PHT'!AE49 -> 43 | BI11: ='CKROL PHT'!AF49 -> 43 | BK11: ='CKROL PHT'!AG49 -> 20 | BM11: =C11+E11+G11+I11+K11+M11+O11+Q11+S11+U11+W11+Y11+AA11+AC11+AE11+AG11+AI11+AK11+AM11+AO11+AQ11+AS11+AU11+AW11+AY11+BA11+BC11+BE11+BG11+BI11+BK11 -> 1100 | BN11: =BM11*14.99/1000 -> 16.489
B12: =Sheet2!C14 -> AHAP | C12: ='CKROL PHT'!C60 -> 0 | E12: ='CKROL PHT'!D60 -> 75 | F12: =E12*14.99/1000 -> 1.12425 | G12: ='CKROL PHT'!E60 -> 140 | H12: =G12*14.99/1000 -> 2.0986 | I12: ='CKROL PHT'!F60 -> 0 | K12: ='CKROL PHT'!G60 -> 74 | L12: =K12*14.99/1000 -> 1.10926 | M12: ='CKROL PHT'!H60 -> 53 | N12: =M12*14.99/1000 -> 0.79447 | O12: ='CKROL PHT'!I60 -> 90 | P12: =O12*14.99/1000 -> 1.3491 | Q12: ='CKROL PHT'!J60 -> 56 | R12: =Q12*14.99/1000 -> 0.83944 | S12: ='CKROL PHT'!K60 -> 0 | T12: =S12*14.99/1000 -> 0 | U12: ='CKROL PHT'!L60 -> 55 | V12: =U12*14.99/1000 -> 0.82445 | W12: ='CKROL PHT'!M60 -> 0 | Y12: ='CKROL PHT'!N60 -> 71 | AA12: ='CKROL PHT'!O60 -> 36 | AB12: =AA12*14.99/1000 -> 0.53964 | AC12: ='CKROL PHT'!P60 -> 38 | AE12: ='CKROL PHT'!Q60 -> 79 | AG12: ='CKROL PHT'!R60 -> 0 | AI12: ='CKROL PHT'!S60 -> 76 | AK12: ='CKROL PHT'!T60 -> 0 | AM12: ='CKROL PHT'!U60 -> 43 | AO12: ='CKROL PHT'!V60 -> 43 | AQ12: ='CKROL PHT'!W60 -> 42 | AS12: ='CKROL PHT'!X60 -> 31 | AU12: ='CKROL PHT'!Y60 -> 35 | AW12: ='CKROL PHT'!Z60 -> 29 | AY12: ='CKROL PHT'!AA60 -> 0 | BA12: ='CKROL PHT'!AB60 -> 40 | BC12: ='CKROL PHT'!AC60 -> 25 | BE12: ='CKROL PHT'!AD60 -> 36 | BG12: ='CKROL PHT'!AE60 -> 31 | BI12: ='CKROL PHT'!AF60 -> 0 | BK12: ='CKROL PHT'!AG60 -> 36 | BM12: =C12+E12+G12+I12+K12+M12+O12+Q12+S12+U12+W12+Y12+AA12+AC12+AE12+AG12+AI12+AK12+AM12+AO12+AQ12+AS12+AU12+AW12+AY12+BA12+BC12+BE12+BG12+BI12+BK12 -> 1234 | BN12: =BM12*14.99/1000 -> 18.49766
B13: =Sheet2!C15 -> IHSAN | C13: ='CKROL PHT'!C71 -> 0 | E13: ='CKROL PHT'!D71 -> 46 | F13: =E13*14.99/1000 -> 0.68954 | G13: ='CKROL PHT'!E71 -> 50 | H13: =G13*14.99/1000 -> 0.7495 | I13: ='CKROL PHT'!F71 -> 0 | K13: ='CKROL PHT'!G71 -> 208 | L13: =K13*14.99/1000 -> 3.11792 | M13: ='CKROL PHT'!H71 -> 27 | N13: =M13*14.99/1000 -> 0.40473 | O13: ='CKROL PHT'!I71 -> 57 | P13: =O13*14.99/1000 -> 0.85443 | Q13: ='CKROL PHT'!J71 -> 50 | R13: =Q13*14.99/1000 -> 0.7495 | S13: ='CKROL PHT'!K71 -> 53 | T13: =S13*14.99/1000 -> 0.79447 | U13: ='CKROL PHT'!L71 -> 0 | V13: =U13*14.99/1000 -> 0 | W13: ='CKROL PHT'!M71 -> 0 | Y13: ='CKROL PHT'!N71 -> 56 | AA13: ='CKROL PHT'!O71 -> 29 | AB13: =AA13*14.99/1000 -> 0.43471 | AC13: ='CKROL PHT'!P71 -> 16 | AE13: ='CKROL PHT'!Q71 -> 36 | AG13: ='CKROL PHT'!R71 -> 0 | AI13: ='CKROL PHT'!S71 -> 58 | AK13: ='CKROL PHT'!T71 -> 0 | AM13: ='CKROL PHT'!U71 -> 63 | AO13: ='CKROL PHT'!V71 -> 43 | AQ13: ='CKROL PHT'!W71 -> 48 | AS13: ='CKROL PHT'!X71 -> 23 | AU13: ='CKROL PHT'!Y71 -> 14 | AW13: ='CKROL PHT'!Z71 -> 25 | AY13: ='CKROL PHT'!AA71 -> 0 | BA13: ='CKROL PHT'!AB71 -> 51 | BC13: ='CKROL PHT'!AC71 -> 20 | BE13: ='CKROL PHT'!AD71 -> 17 | BG13: ='CKROL PHT'!AE71 -> 40 | BI13: ='CKROL PHT'!AF71 -> 30 | BK13: ='CKROL PHT'!AG71 -> 22 | BM13: =C13+E13+G13+I13+K13+M13+O13+Q13+S13+U13+W13+Y13+AA13+AC13+AE13+AG13+AI13+AK13+AM13+AO13+AQ13+AS13+AU13+AW13+AY13+BA13+BC13+BE13+BG13+BI13+BK13 -> 1082 | BN13: =BM13*14.99/1000 -> 16.21918
B14: =Sheet2!C16 -> QISTAHAM | C14: ='CKROL PHT'!C82 -> 0 | E14: ='CKROL PHT'!D82 -> 81 | F14: =E14*14.99/1000 -> 1.21419 | G14: ='CKROL PHT'!E82 -> 60 | H14: =G14*14.99/1000 -> 0.8994 | I14: ='CKROL PHT'!F82 -> 0 | K14: ='CKROL PHT'!G82 -> 50 | L14: =K14*14.99/1000 -> 0.7495 | M14: ='CKROL PHT'!H82 -> 223 | N14: =M14*14.99/1000 -> 3.34277 | O14: ='CKROL PHT'!I82 -> 36 | P14: =O14*14.99/1000 -> 0.53964 | Q14: ='CKROL PHT'!J82 -> 20 | R14: =Q14*14.99/1000 -> 0.2998 | S14: ='CKROL PHT'!K82 -> 46 | T14: =S14*14.99/1000 -> 0.68954 | U14: ='CKROL PHT'!L82 -> 23 | V14: =U14*14.99/1000 -> 0.34477 | W14: ='CKROL PHT'!M82 -> 0 | Y14: ='CKROL PHT'!N82 -> 61 | AA14: ='CKROL PHT'!O82 -> 36 | AB14: =AA14*14.99/1000 -> 0.53964 | AC14: ='CKROL PHT'!P82 -> 27 | AE14: ='CKROL PHT'!Q82 -> 37 | AG14: ='CKROL PHT'!R82 -> 0 | AI14: ='CKROL PHT'!S82 -> 318 | AK14: ='CKROL PHT'!T82 -> 0 | AM14: ='CKROL PHT'!U82 -> 30 | AO14: ='CKROL PHT'!V82 -> 45 | AQ14: ='CKROL PHT'!W82 -> 41 | AS14: ='CKROL PHT'!X82 -> 42 | AU14: ='CKROL PHT'!Y82 -> 25 | AW14: ='CKROL PHT'!Z82 -> 25 | AY14: ='CKROL PHT'!AA82 -> 0 | BA14: ='CKROL PHT'!AB82 -> 300 | BC14: ='CKROL PHT'!AC82 -> 26 | BE14: ='CKROL PHT'!AD82 -> 17 | BG14: ='CKROL PHT'!AE82 -> 27 | BI14: ='CKROL PHT'!AF82 -> 38 | BK14: ='CKROL PHT'!AG82 -> 29 | BM14: =C14+E14+G14+I14+K14+M14+O14+Q14+S14+U14+W14+Y14+AA14+AC14+AE14+AG14+AI14+AK14+AM14+AO14+AQ14+AS14+AU14+AW14+AY14+BA14+BC14+BE14+BG14+BI14+BK14 -> 1663 | BN14: =BM14*14.99/1000 -> 24.92837
B15: =Sheet2!C17 -> JAYADI | C15: ='CKROL PHT'!C93 -> 0 | E15: ='CKROL PHT'!D93 -> 75 | F15: =E15*14.99/1000 -> 1.12425 | G15: ='CKROL PHT'!E93 -> 41 | H15: =G15*14.99/1000 -> 0.61459 | I15: ='CKROL PHT'!F93 -> 0 | K15: ='CKROL PHT'!G93 -> 23 | L15: =K15*14.99/1000 -> 0.34477 | M15: ='CKROL PHT'!H93 -> 54 | N15: =M15*14.99/1000 -> 0.80946 | O15: ='CKROL PHT'!I93 -> 55 | P15: =O15*14.99/1000 -> 0.82445 | Q15: ='CKROL PHT'!J93 -> 63 | R15: =Q15*14.99/1000 -> 0.94437 | S15: ='CKROL PHT'!K93 -> 81 | T15: =S15*14.99/1000 -> 1.21419 | U15: ='CKROL PHT'!L93 -> 57 | V15: =U15*14.99/1000 -> 0.85443 | W15: ='CKROL PHT'!M93 -> 0 | Y15: ='CKROL PHT'!N93 -> 130 | AA15: ='CKROL PHT'!O93 -> 35 | AB15: =AA15*14.99/1000 -> 0.52465 | AC15: ='CKROL PHT'!P93 -> 26 | AE15: ='CKROL PHT'!Q93 -> 60 | AG15: ='CKROL PHT'!R93 -> 0 | AI15: ='CKROL PHT'!S93 -> 323 | AK15: ='CKROL PHT'!T93 -> 0 | AM15: ='CKROL PHT'!U93 -> 45 | AO15: ='CKROL PHT'!V93 -> 51 | AQ15: ='CKROL PHT'!W93 -> 26 | AS15: ='CKROL PHT'!X93 -> 29 | AU15: ='CKROL PHT'!Y93 -> 15 | AW15: ='CKROL PHT'!Z93 -> 20 | AY15: ='CKROL PHT'!AA93 -> 0 | BA15: ='CKROL PHT'!AB93 -> 25 | BC15: ='CKROL PHT'!AC93 -> 20 | BE15: ='CKROL PHT'!AD93 -> 0 | BG15: ='CKROL PHT'!AE93 -> 19 | BI15: ='CKROL PHT'!AF93 -> 21 | BK15: ='CKROL PHT'!AG93 -> 28 | BM15: =C15+E15+G15+I15+K15+M15+O15+Q15+S15+U15+W15+Y15+AA15+AC15+AE15+AG15+AI15+AK15+AM15+AO15+AQ15+AS15+AU15+AW15+AY15+BA15+BC15+BE15+BG15+BI15+BK15 -> 1322 | BN15: =BM15*14.99/1000 -> 19.81678
B16: =Sheet2!C18 -> M.AMIN | C16: ='CKROL PHT'!C104 -> 0 | E16: ='CKROL PHT'!D104 -> 0 | F16: =E16*14.99/1000 -> 0 | G16: ='CKROL PHT'!E104 -> 56 | H16: =G16*14.99/1000 -> 0.83944 | I16: ='CKROL PHT'!F104 -> 0 | K16: ='CKROL PHT'!G104 -> 40 | L16: =K16*14.99/1000 -> 0.5996 | M16: ='CKROL PHT'!H104 -> 50 | N16: =M16*14.99/1000 -> 0.7495 | O16: ='CKROL PHT'!I104 -> 64 | P16: =O16*14.99/1000 -> 0.95936 | Q16: ='CKROL PHT'!J104 -> 55 | R16: =Q16*14.99/1000 -> 0.82445 | S16: ='CKROL PHT'!K104 -> 46 | T16: =S16*14.99/1000 -> 0.68954 | U16: ='CKROL PHT'!L104 -> 48 | V16: =U16*14.99/1000 -> 0.71952 | W16: ='CKROL PHT'!M104 -> 0 | Y16: ='CKROL PHT'!N104 -> 50 | AA16: ='CKROL PHT'!O104 -> 29 | AB16: =AA16*14.99/1000 -> 0.43471 | AC16: ='CKROL PHT'!P104 -> 61 | AE16: ='CKROL PHT'!Q104 -> 63 | AG16: ='CKROL PHT'!R104 -> 0 | AI16: ='CKROL PHT'!S104 -> 0 | AK16: ='CKROL PHT'!T104 -> 0 | AM16: ='CKROL PHT'!U104 -> 21 | AO16: ='CKROL PHT'!V104 -> 34 | AQ16: ='CKROL PHT'!W104 -> 40 | AS16: ='CKROL PHT'!X104 -> 31 | AU16: ='CKROL PHT'!Y104 -> 37 | AW16: ='CKROL PHT'!Z104 -> 36 | AY16: ='CKROL PHT'!AA104 -> 0 | BA16: ='CKROL PHT'!AB104 -> 30 | BC16: ='CKROL PHT'!AC104 -> 20 | BE16: ='CKROL PHT'!AD104 -> 28 | BG16: ='CKROL PHT'!AE104 -> 16 | BI16: ='CKROL PHT'!AF104 -> 6 | BK16: ='CKROL PHT'!AG104 -> 26 | BM16: =C16+E16+G16+I16+K16+M16+O16+Q16+S16+U16+W16+Y16+AA16+AC16+AE16+AG16+AI16+AK16+AM16+AO16+AQ16+AS16+AU16+AW16+AY16+BA16+BC16+BE16+BG16+BI16+BK16 -> 887 | BN16: =BM16*14.99/1000 -> 13.29613
B17: =Sheet2!C19 -> SAMSUL HADI | C17: ='CKROL PHT'!C115 -> 0 | E17: ='CKROL PHT'!D115 -> 95 | F17: =E17*14.99/1000 -> 1.42405 | G17: ='CKROL PHT'!E115 -> 40 | H17: =G17*14.99/1000 -> 0.5996 | I17: ='CKROL PHT'!F115 -> 0 | K17: ='CKROL PHT'!G115 -> 60 | L17: =K17*14.99/1000 -> 0.8994 | M17: ='CKROL PHT'!H115 -> 60 | N17: =M17*14.99/1000 -> 0.8994 | O17: ='CKROL PHT'!I115 -> 62 | P17: =O17*14.99/1000 -> 0.92938 | Q17: ='CKROL PHT'!J115 -> 78 | R17: =Q17*14.99/1000 -> 1.16922 | S17: ='CKROL PHT'!K115 -> 45 | T17: =S17*14.99/1000 -> 0.67455 | U17: ='CKROL PHT'!L115 -> 58 | V17: =U17*14.99/1000 -> 0.86942 | W17: ='CKROL PHT'!M115 -> 0 | Y17: ='CKROL PHT'!N115 -> 74 | AA17: ='CKROL PHT'!O115 -> 27 | AB17: =AA17*14.99/1000 -> 0.40473 | AC17: ='CKROL PHT'!P115 -> 34 | AE17: ='CKROL PHT'!Q115 -> 47 | AG17: ='CKROL PHT'!R115 -> 0 | AI17: ='CKROL PHT'!S115 -> 52 | AK17: ='CKROL PHT'!T115 -> 0 | AM17: ='CKROL PHT'!U115 -> 60 | AO17: ='CKROL PHT'!V115 -> 40 | AQ17: ='CKROL PHT'!W115 -> 33 | AS17: ='CKROL PHT'!X115 -> 27 | AU17: ='CKROL PHT'!Y115 -> 27 | AW17: ='CKROL PHT'!Z115 -> 38 | AY17: ='CKROL PHT'!AA115 -> 0 | BA17: ='CKROL PHT'!AB115 -> 291 | BC17: ='CKROL PHT'!AC115 -> 0 | BE17: ='CKROL PHT'!AD115 -> 17 | BG17: ='CKROL PHT'!AE115 -> 60 | BI17: ='CKROL PHT'!AF115 -> 18 | BK17: ='CKROL PHT'!AG115 -> 56 | BM17: =C17+E17+G17+I17+K17+M17+O17+Q17+S17+U17+W17+Y17+AA17+AC17+AE17+AG17+AI17+AK17+AM17+AO17+AQ17+AS17+AU17+AW17+AY17+BA17+BC17+BE17+BG17+BI17+BK17 -> 1399 | BN17: =BM17*14.99/1000 -> 20.97101
B18: =Sheet2!C20 -> SAPARUDIN | C18: ='CKROL PHT'!C126 -> 0 | E18: ='CKROL PHT'!D126 -> 45 | F18: =E18*14.99/1000 -> 0.67455 | G18: ='CKROL PHT'!E126 -> 50 | H18: =G18*14.99/1000 -> 0.7495 | I18: ='CKROL PHT'!F126 -> 0 | K18: ='CKROL PHT'!G126 -> 72 | L18: =K18*14.99/1000 -> 1.07928 | M18: ='CKROL PHT'!H126 -> 58 | N18: =M18*14.99/1000 -> 0.86942 | O18: ='CKROL PHT'!I126 -> 33 | P18: =O18*14.99/1000 -> 0.49467 | Q18: ='CKROL PHT'!J126 -> 151 | R18: =Q18*14.99/1000 -> 2.26349 | S18: ='CKROL PHT'!K126 -> 46 | T18: =S18*14.99/1000 -> 0.68954 | U18: ='CKROL PHT'!L126 -> 50 | V18: =U18*14.99/1000 -> 0.7495 | W18: ='CKROL PHT'!M126 -> 0 | Y18: ='CKROL PHT'!N126 -> 46 | AA18: ='CKROL PHT'!O126 -> 25 | AB18: =AA18*14.99/1000 -> 0.37475 | AC18: ='CKROL PHT'!P126 -> 26 | AE18: ='CKROL PHT'!Q126 -> 45 | AG18: ='CKROL PHT'!R126 -> 0 | AI18: ='CKROL PHT'!S126 -> 89 | AK18: ='CKROL PHT'!T126 -> 0 | AM18: ='CKROL PHT'!U126 -> 89 | AO18: ='CKROL PHT'!V126 -> 31 | AQ18: ='CKROL PHT'!W126 -> 53 | AS18: ='CKROL PHT'!X126 -> 30 | AU18: ='CKROL PHT'!Y126 -> 20 | AW18: ='CKROL PHT'!Z126 -> 40 | AY18: ='CKROL PHT'!AA126 -> 0 | BA18: ='CKROL PHT'!AB126 -> 150 | BC18: ='CKROL PHT'!AC126 -> 20 | BE18: ='CKROL PHT'!AD126 -> 21 | BG18: ='CKROL PHT'!AE126 -> 65 | BI18: ='CKROL PHT'!AF126 -> 39 | BK18: ='CKROL PHT'!AG126 -> 28 | BM18: =C18+E18+G18+I18+K18+M18+O18+Q18+S18+U18+W18+Y18+AA18+AC18+AE18+AG18+AI18+AK18+AM18+AO18+AQ18+AS18+AU18+AW18+AY18+BA18+BC18+BE18+BG18+BI18+BK18 -> 1322 | BN18: =BM18*14.99/1000 -> 19.81678
B19: =Sheet2!C21 -> FAHRUDIN | C19: ='CKROL PHT'!C137 -> 0 | E19: ='CKROL PHT'!D137 -> 79 | F19: =E19*14.99/1000 -> 1.18421 | G19: ='CKROL PHT'!E137 -> 119 | H19: =G19*14.99/1000 -> 1.78381 | I19: ='CKROL PHT'!F137 -> 0 | K19: ='CKROL PHT'!G137 -> 949 | L19: =K19*14.99/1000 -> 14.22551 | M19: ='CKROL PHT'!H137 -> 59 | N19: =M19*14.99/1000 -> 0.88441 | O19: ='CKROL PHT'!I137 -> 80 | P19: =O19*14.99/1000 -> 1.1992 | Q19: ='CKROL PHT'!J137 -> 51 | R19: =Q19*14.99/1000 -> 0.76449 | S19: ='CKROL PHT'!K137 -> 65 | T19: =S19*14.99/1000 -> 0.97435 | U19: ='CKROL PHT'!L137 -> 28 | V19: =U19*14.99/1000 -> 0.41972 | W19: ='CKROL PHT'!M137 -> 0 | Y19: ='CKROL PHT'!N137 -> 89 | AA19: ='CKROL PHT'!O137 -> 26 | AB19: =AA19*14.99/1000 -> 0.38974 | AC19: ='CKROL PHT'!P137 -> 44 | AE19: ='CKROL PHT'!Q137 -> 43 | AG19: ='CKROL PHT'!R137 -> 0 | AI19: ='CKROL PHT'!S137 -> 55 | AK19: ='CKROL PHT'!T137 -> 0 | AM19: ='CKROL PHT'!U137 -> 294 | AO19: ='CKROL PHT'!V137 -> 0 | AQ19: ='CKROL PHT'!W137 -> 49 | AS19: ='CKROL PHT'!X137 -> 36 | AU19: ='CKROL PHT'!Y137 -> 38 | AW19: ='CKROL PHT'!Z137 -> 52 | AY19: ='CKROL PHT'!AA137 -> 0 | BA19: ='CKROL PHT'!AB137 -> 67 | BC19: ='CKROL PHT'!AC137 -> 21 | BE19: ='CKROL PHT'!AD137 -> 17 | BG19: ='CKROL PHT'!AE137 -> 15 | BI19: ='CKROL PHT'!AF137 -> 0 | BK19: ='CKROL PHT'!AG137 -> 32 | BM19: =C19+E19+G19+I19+K19+M19+O19+Q19+S19+U19+W19+Y19+AA19+AC19+AE19+AG19+AI19+AK19+AM19+AO19+AQ19+AS19+AU19+AW19+AY19+BA19+BC19+BE19+BG19+BI19+BK19 -> 2308 | BN19: =BM19*14.99/1000 -> 34.59692
B20: =Sheet2!C22 -> HERIANTO ARBI | C20: ='CKROL PHT'!C148 -> 0 | E20: ='CKROL PHT'!D148 -> 72 | F20: =E20*14.99/1000 -> 1.07928 | G20: ='CKROL PHT'!E148 -> 40 | H20: =G20*14.99/1000 -> 0.5996 | I20: ='CKROL PHT'!F148 -> 0 | K20: ='CKROL PHT'!G148 -> 85 | L20: =K20*14.99/1000 -> 1.27415 | M20: ='CKROL PHT'!H148 -> 53 | N20: =M20*14.99/1000 -> 0.79447 | O20: ='CKROL PHT'!I148 -> 44 | P20: =O20*14.99/1000 -> 0.65956 | Q20: ='CKROL PHT'!J148 -> 90 | R20: =Q20*14.99/1000 -> 1.3491 | S20: ='CKROL PHT'!K148 -> 56 | T20: =S20*14.99/1000 -> 0.83944 | U20: ='CKROL PHT'!L148 -> 38 | V20: =U20*14.99/1000 -> 0.56962 | W20: ='CKROL PHT'!M148 -> 0 | Y20: ='CKROL PHT'!N148 -> 67 | AA20: ='CKROL PHT'!O148 -> 36 | AB20: =AA20*14.99/1000 -> 0.53964 | AC20: ='CKROL PHT'!P148 -> 44 | AE20: ='CKROL PHT'!Q148 -> 59 | AG20: ='CKROL PHT'!R148 -> 0 | AI20: ='CKROL PHT'!S148 -> 49 | AK20: ='CKROL PHT'!T148 -> 0 | AM20: ='CKROL PHT'!U148 -> 45 | AO20: ='CKROL PHT'!V148 -> 40 | AQ20: ='CKROL PHT'!W148 -> 0 | AS20: ='CKROL PHT'!X148 -> 30 | AU20: ='CKROL PHT'!Y148 -> 34 | AW20: ='CKROL PHT'!Z148 -> 44 | AY20: ='CKROL PHT'!AA148 -> 0 | BA20: ='CKROL PHT'!AB148 -> 10 | BC20: ='CKROL PHT'!AC148 -> 20 | BE20: ='CKROL PHT'!AD148 -> 36 | BG20: ='CKROL PHT'!AE148 -> 40 | BI20: ='CKROL PHT'!AF148 -> 55 | BK20: ='CKROL PHT'!AG148 -> 25 | BM20: =C20+E20+G20+I20+K20+M20+O20+Q20+S20+U20+W20+Y20+AA20+AC20+AE20+AG20+AI20+AK20+AM20+AO20+AQ20+AS20+AU20+AW20+AY20+BA20+BC20+BE20+BG20+BI20+BK20 -> 1112 | BN20: =BM20*14.99/1000 -> 16.66888
B21: =Sheet2!C23 -> RIDUAN | C21: ='CKROL PHT'!C159 -> 0 | E21: ='CKROL PHT'!D159 -> 37 | F21: =E21*14.99/1000 -> 0.55463 | G21: ='CKROL PHT'!E159 -> 35 | H21: =G21*14.99/1000 -> 0.52465 | I21: ='CKROL PHT'!F159 -> 0 | K21: ='CKROL PHT'!G159 -> 29 | L21: =K21*14.99/1000 -> 0.43471 | M21: ='CKROL PHT'!H159 -> 21 | N21: =M21*14.99/1000 -> 0.31479 | O21: ='CKROL PHT'!I159 -> 43 | P21: =O21*14.99/1000 -> 0.64457 | Q21: ='CKROL PHT'!J159 -> 52 | R21: =Q21*14.99/1000 -> 0.77948 | S21: ='CKROL PHT'!K159 -> 26 | T21: =S21*14.99/1000 -> 0.38974 | U21: ='CKROL PHT'!L159 -> 35 | V21: =U21*14.99/1000 -> 0.52465 | W21: ='CKROL PHT'!M159 -> 0 | Y21: ='CKROL PHT'!N159 -> 56 | AA21: ='CKROL PHT'!O159 -> 18 | AB21: =AA21*14.99/1000 -> 0.26982 | AC21: ='CKROL PHT'!P159 -> 25 | AE21: ='CKROL PHT'!Q159 -> 31 | AG21: ='CKROL PHT'!R159 -> 0 | AI21: ='CKROL PHT'!S159 -> 47 | AK21: ='CKROL PHT'!T159 -> 0 | AM21: ='CKROL PHT'!U159 -> 52 | AO21: ='CKROL PHT'!V159 -> 30 | AQ21: ='CKROL PHT'!W159 -> 53 | AS21: ='CKROL PHT'!X159 -> 31 | AU21: ='CKROL PHT'!Y159 -> 21 | AW21: ='CKROL PHT'!Z159 -> 25 | AY21: ='CKROL PHT'!AA159 -> 0 | BA21: ='CKROL PHT'!AB159 -> 27 | BC21: ='CKROL PHT'!AC159 -> 20 | BE21: ='CKROL PHT'!AD159 -> 17 | BG21: ='CKROL PHT'!AE159 -> 35 | BI21: ='CKROL PHT'!AF159 -> 47 | BK21: ='CKROL PHT'!AG159 -> 25 | BM21: =C21+E21+G21+I21+K21+M21+O21+Q21+S21+U21+W21+Y21+AA21+AC21+AE21+AG21+AI21+AK21+AM21+AO21+AQ21+AS21+AU21+AW21+AY21+BA21+BC21+BE21+BG21+BI21+BK21 -> 838 | BN21: =BM21*14.99/1000 -> 12.56162

Sheet CKROL PERAWATAN
A2: PT.REBINMAS JAYA
A3: POCKET CHECKROLL UNTUK BULAN : JANUARI 2026
A4: PERKEBUNAN : PGE 2A | AL4: DIVISI : AIR JANGKAT
A6: NO | B6: NAMA KARYAWAN | C6: TANGGAL | AH6: JML | AI6: JUMLAH CUTI /LIBUR | AP6: JUML | AQ6: CTH | AR6: A | AS6: RP
C7: 1 | D7: 2 | E7: 3 | F7: 4 | G7: 5 | H7: 6 | I7: 7 | J7: 8 | K7: 9 | L7: 10 | M7: 11 | N7: 12 | O7: 13 | P7: 14 | Q7: 15 | R7: 16 | S7: 17 | T7: 18 | U7: 19 | V7: 20 | W7: 21 | X7: 22 | Y7: 23 | Z7: 24 | AA7: 25 | AB7: 26 | AC7: 27 | AD7: 28 | AE7: 29 | AF7: 30 | AG7: 31 | AH7: HK | AI7: THN | AJ7: SKT | AK7: HAID | AL7: MG | AM7: NAS | AN7: H/M | AO7: IZIN | AS7: LEMBUR
A8: 1 | B8: GUNAWAN | D8: 1 | E8: 1 | G8: 1 | H8: 1 | I8: 1 | J8: 1 | K8: 1 | L8: 1 | N8: 1 | O8: 1 | P8: 1 | Q8: 1 | S8: 1 | U8: 1 | V8: 1 | W8: 1 | X8: CT | Y8: 1 | Z8: 1 | AB8: 1 | AC8: 1 | AD8: 1 | AE8: 1 | AF8: 1 | AG8: 1 | AH8: =SUM(C8:AG8) -> 24 | AI8: =COUNTIF(C8:AG8,"CT") -> 1 | AJ8: =COUNTIF(C8:AG8,"CS") -> 0 | AK8: =COUNTIF(C8:AG8,"CH") -> 0 | AL8: 4 | AM8: 2 | AN8: =COUNTIF(C8:AL8,"hm") -> 0 | AO8: =COUNTIF(C8:AM8,"CI") -> 0 | AP8: =AH8+AI8+AJ8+AK8+AL8+AM8+AN8+AO8 -> 31 | AQ8: =COUNTIF(C8:AG8,"CTH") -> 0 | AR8: =COUNTIF(C8:AG8,"A") -> 0
A9: 2 | B9: RILYANI | D9: 1 | E9: 1 | G9: 1 | H9: 1 | I9: 1 | J9: 1 | K9: 1 | L9: 1 | N9: 1 | O9: 1 | P9: 1 | Q9: 1 | S9: 1 | U9: 1 | V9: 1 | W9: 1 | X9: 1 | Y9: 1 | Z9: 1 | AB9: 1 | AC9: 1 | AD9: 1 | AE9: 1 | AF9: 1 | AG9: 1 | AH9: =SUM(C9:AG9) -> 25 | AI9: =COUNTIF(C9:AG9,"CT") -> 0 | AJ9: =COUNTIF(C9:AG9,"CS") -> 0 | AK9: =COUNTIF(C9:AG9,"CH") -> 0 | AL9: 4 | AM9: 2 | AN9: =COUNTIF(C9:AL9,"hm") -> 0 | AO9: =COUNTIF(C9:AM9,"CI") -> 0 | AP9: =AH9+AI9+AJ9+AK9+AL9+AM9+AN9+AO9 -> 31 | AQ9: =COUNTIF(C9:AG9,"CTH") -> 0 | AR9: =COUNTIF(C9:AG9,"A") -> 0
A10: 3 | B10: JUNAIDI | D10: 1 | E10: 1 | G10: 1 | H10: 1 | I10: 1 | J10: 1 | K10: 1 | L10: CT | N10: 1 | O10: 1 | P10: 1 | Q10: 1 | S10: 1 | U10: 1 | V10: 1 | W10: 1 | X10: 1 | Y10: 1 | Z10: 1 | AB10: 1 | AC10: 1 | AD10: 1 | AE10: 1 | AF10: 1 | AG10: 1 | AH10: =SUM(C10:AG10) -> 24 | AI10: =COUNTIF(C10:AG10,"CT") -> 1 | AJ10: =COUNTIF(C10:AG10,"CS") -> 0 | AK10: =COUNTIF(C10:AG10,"CH") -> 0 | AL10: 4 | AM10: 2 | AN10: =COUNTIF(C10:AL10,"hm") -> 0 | AO10: =COUNTIF(C10:AM10,"CI") -> 0 | AP10: =AH10+AI10+AJ10+AK10+AL10+AM10+AN10+AO10 -> 31 | AQ10: =COUNTIF(C10:AG10,"CTH") -> 0 | AR10: =COUNTIF(C10:AG10,"A") -> 0
A11: 4 | B11: ASUNTI | D11: 1 | E11: 1 | G11: 1 | H11: 1 | I11: 1 | J11: 1 | K11: 1 | L11: CT | N11: 1 | O11: 1 | P11: CT | Q11: 1 | S11: 1 | U11: 1 | V11: 1 | W11: 1 | X11: 1 | Y11: 1 | Z11: 1 | AB11: 1 | AC11: 1 | AD11: 1 | AE11: 1 | AF11: 1 | AG11: 1 | AH11: =SUM(C11:AG11) -> 23 | AI11: =COUNTIF(C11:AG11,"CT") -> 2 | AJ11: =COUNTIF(C11:AG11,"CS") -> 0 | AK11: =COUNTIF(C11:AG11,"CH") -> 0 | AL11: 4 | AM11: 2 | AN11: =COUNTIF(C11:AL11,"hm") -> 0 | AO11: =COUNTIF(C11:AM11,"CI") -> 0 | AP11: =AH11+AI11+AJ11+AK11+AL11+AM11+AN11+AO11 -> 31 | AQ11: =COUNTIF(C11:AG11,"CTH") -> 0 | AR11: =COUNTIF(C11:AG11,"A") -> 0
A12: 5 | B12: JONI | D12: 1 | E12: A | G12: 1 | H12: 1 | I12: 1 | J12: 1 | K12: 1 | L12: 1 | N12: 1 | O12: 1 | P12: 1 | Q12: 1 | S12: 1 | U12: 1 | V12: 1 | W12: 1 | X12: 1 | Y12: 1 | Z12: 1 | AB12: 1 | AC12: 1 | AD12: 1 | AE12: 1 | AF12: 1 | AG12: 1 | AH12: =SUM(C12:AG12) -> 24 | AI12: =COUNTIF(C12:AG12,"CT") -> 0 | AJ12: =COUNTIF(C12:AG12,"CS") -> 0 | AK12: =COUNTIF(C12:AG12,"CH") -> 0 | AL12: 4 | AM12: 2 | AN12: =COUNTIF(C12:AL12,"hm") -> 0 | AO12: =COUNTIF(C12:AM12,"CI") -> 0 | AP12: =AH12+AI12+AJ12+AK12+AL12+AM12+AN12+AO12 -> 30 | AQ12: =COUNTIF(C12:AG12,"CTH") -> 0 | AR12: =COUNTIF(C12:AG12,"A") -> 1
A13: 6 | B13: THAHA.S | D13: 1 | E13: 1 | G13: 1 | H13: 1 | I13: 1 | J13: 1 | K13: 1 | L13: 1 | N13: 1 | O13: 1 | P13: 1 | Q13: 1 | S13: 1 | U13: 1 | V13: 1 | W13: 1 | X13: 1 | Y13: 1 | Z13: 1 | AB13: 1 | AC13: 1 | AD13: 1 | AE13: 1 | AF13: 1 | AG13: 1 | AH13: =SUM(C13:AG13) -> 25 | AI13: =COUNTIF(C13:AG13,"CT") -> 0 | AJ13: =COUNTIF(C13:AG13,"CS") -> 0 | AK13: =COUNTIF(C13:AG13,"CH") -> 0 | AL13: 4 | AM13: 2 | AN13: =COUNTIF(C13:AL13,"hm") -> 0 | AO13: =COUNTIF(C13:AM13,"CI") -> 0 | AP13: =AH13+AI13+AJ13+AK13+AL13+AM13+AN13+AO13 -> 31 | AQ13: =COUNTIF(C13:AG13,"CTH") -> 0 | AR13: =COUNTIF(C13:AG13,"A") -> 0
A14: 7 | B14: ALEX | D14: 1 | E14: 1 | G14: 1 | H14: 1 | I14: 1 | J14: 1 | K14: 1 | L14: 1 | N14: 1 | O14: CT | P14: 1 | Q14: A | S14: 1 | U14: 1 | V14: 1 | W14: 1 | X14: 1 | Y14: 1 | Z14: 1 | AB14: 1 | AC14: 1 | AD14: 1 | AE14: 1 | AF14: 1 | AG14: 1 | AH14: =SUM(C14:AG14) -> 23 | AI14: =COUNTIF(C14:AG14,"CT") -> 1 | AJ14: =COUNTIF(C14:AG14,"CS") -> 0 | AK14: =COUNTIF(C14:AG14,"CH") -> 0 | AL14: 4 | AM14: 2 | AN14: =COUNTIF(C14:AL14,"hm") -> 0 | AO14: =COUNTIF(C14:AM14,"CI") -> 0 | AP14: =AH14+AI14+AJ14+AK14+AL14+AM14+AN14+AO14 -> 30 | AQ14: =COUNTIF(C14:AG14,"CTH") -> 0 | AR14: =COUNTIF(C14:AG14,"A") -> 1
A15: 8 | B15: SANDY | D15: 1 | E15: 1 | G15: 1 | H15: 1 | I15: 1 | J15: 1 | K15: 1 | L15: 1 | N15: CS | O15: 1 | P15: 1 | Q15: 1 | S15: 1 | U15: 1 | V15: 1 | W15: 1 | X15: 1 | Y15: 1 | Z15: 1 | AB15: 1 | AC15: 1 | AD15: CT | AE15: 1 | AF15: 1 | AG15: 1 | AH15: =SUM(C15:AG15) -> 23 | AI15: =COUNTIF(C15:AG15,"CT") -> 1 | AJ15: =COUNTIF(C15:AG15,"CS") -> 1 | AK15: =COUNTIF(C15:AG15,"CH") -> 0 | AL15: 4 | AM15: 2 | AN15: =COUNTIF(C15:AL15,"hm") -> 0 | AO15: =COUNTIF(C15:AM15,"CI") -> 0 | AP15: =AH15+AI15+AJ15+AK15+AL15+AM15+AN15+AO15 -> 31 | AQ15: =COUNTIF(C15:AG15,"CTH") -> 0 | AR15: =COUNTIF(C15:AG15,"A") -> 0
A16: 9 | B16: ANTON | D16: CT | E16: 1 | G16: 1 | H16: 1 | I16: 1 | J16: CS | K16: 1 | L16: 1 | N16: 1 | O16: 1 | P16: 1 | Q16: 1 | S16: 1 | U16: 1 | V16: 1 | W16: 1 | X16: 1 | Y16: 1 | Z16: 1 | AB16: 1 | AC16: 1 | AD16: 1 | AE16: 1 | AF16: 1 | AG16: 1 | AH16: =SUM(C16:AG16) -> 23 | AI16: =COUNTIF(C16:AG16,"CT") -> 1 | AJ16: =COUNTIF(C16:AG16,"CS") -> 1 | AK16: =COUNTIF(C16:AG16,"CH") -> 0 | AL16: 4 | AM16: 2 | AN16: =COUNTIF(C16:AL16,"hm") -> 0 | AO16: =COUNTIF(C16:AM16,"CI") -> 0 | AP16: =AH16+AI16+AJ16+AK16+AL16+AM16+AN16+AO16 -> 31 | AQ16: =COUNTIF(C16:AG16,"CTH") -> 0 | AR16: =COUNTIF(C16:AG16,"A") -> 0
A17: 10 | B17: EKA NOVIANTI | D17: 1 | E17: 1 | G17: 1 | H17: 1 | I17: 1 | J17: 1 | K17: 1 | L17: 1 | N17: CS | O17: 1 | P17: 1 | Q17: 1 | S17: 1 | U17: CH | V17: CH | W17: 1 | X17: 1 | Y17: 1 | Z17: 1 | AB17: 1 | AC17: 1 | AD17: 1 | AE17: 1 | AF17: 1 | AG17: 1 | AH17: =SUM(C17:AG17) -> 22 | AI17: =COUNTIF(C17:AG17,"CT") -> 0 | AJ17: =COUNTIF(C17:AG17,"CS") -> 1 | AK17: =COUNTIF(C17:AG17,"CH") -> 2 | AL17: 4 | AM17: 2 | AN17: =COUNTIF(C17:AL17,"hm") -> 0 | AO17: =COUNTIF(C17:AM17,"CI") -> 0 | AP17: =AH17+AI17+AJ17+AK17+AL17+AM17+AN17+AO17 -> 31 | AQ17: =COUNTIF(C17:AG17,"CTH") -> 0 | AR17: =COUNTIF(C17:AG17,"A") -> 0
A18: 11 | B18: JUMIATI | D18: 1 | E18: 1 | G18: 1 | H18: 1 | I18: CT | J18: 1 | K18: 1 | L18: 1 | N18: 1 | O18: 1 | P18: 1 | Q18: 1 | S18: 1 | U18: 1 | V18: CH | W18: CH | X18: 1 | Y18: 1 | Z18: 1 | AB18: 1 | AC18: 1 | AD18: 1 | AE18: 1 | AF18: 1 | AG18: 1 | AH18: =SUM(C18:AG18) -> 22 | AI18: =COUNTIF(C18:AG18,"CT") -> 1 | AJ18: =COUNTIF(C18:AG18,"CS") -> 0 | AK18: =COUNTIF(C18:AG18,"CH") -> 2 | AL18: 4 | AM18: 2 | AN18: =COUNTIF(C18:AL18,"hm") -> 0 | AO18: =COUNTIF(C18:AM18,"CI") -> 0 | AP18: =AH18+AI18+AJ18+AK18+AL18+AM18+AN18+AO18 -> 31 | AQ18: =COUNTIF(C18:AG18,"CTH") -> 0 | AR18: =COUNTIF(C18:AG18,"A") -> 0
A19: 12 | B19: SUPARDI | D19: 1 | E19: 1 | G19: 1 | H19: CT | I19: 1 | J19: 1 | K19: 1 | L19: 1 | N19: 1 | O19: 1 | P19: CT | Q19: 1 | S19: 1 | U19: 1 | V19: 1 | W19: 1 | X19: 1 | Y19: 1 | Z19: 1 | AB19: 1 | AC19: 1 | AD19: 1 | AE19: 1 | AF19: 1 | AG19: 1 | AH19: =SUM(C19:AG19) -> 23 | AI19: =COUNTIF(C19:AG19,"CT") -> 2 | AJ19: =COUNTIF(C19:AG19,"CS") -> 0 | AK19: =COUNTIF(C19:AG19,"CH") -> 0 | AL19: 4 | AM19: 2 | AN19: =COUNTIF(C19:AL19,"hm") -> 0 | AO19: =COUNTIF(C19:AM19,"CI") -> 0 | AP19: =AH19+AI19+AJ19+AK19+AL19+AM19+AN19+AO19 -> 31 | AQ19: =COUNTIF(C19:AG19,"CTH") -> 0 | AR19: =COUNTIF(C19:AG19,"A") -> 0
A20: 13 | B20: SUMARDI | D20: 1 | E20: 1 | G20: 1 | H20: 1 | I20: 1 | J20: 1 | K20: 1 | L20: 1 | N20: 1 | O20: 1 | P20: 1 | Q20: 1 | S20: 1 | U20: 1 | V20: 1 | W20: 1 | X20: 1 | Y20: 1 | Z20: 1 | AB20: 1 | AC20: 1 | AD20: 1 | AE20: 1 | AF20: 1 | AG20: 1 | AH20: =SUM(C20:AG20) -> 25 | AI20: =COUNTIF(C20:AG20,"CT") -> 0 | AJ20: =COUNTIF(C20:AG20,"CS") -> 0 | AK20: =COUNTIF(C20:AG20,"CH") -> 0 | AL20: 4 | AM20: 2 | AN20: =COUNTIF(C20:AL20,"hm") -> 0 | AO20: =COUNTIF(C20:AM20,"CI") -> 0 | AP20: =AH20+AI20+AJ20+AK20+AL20+AM20+AN20+AO20 -> 31 | AQ20: =COUNTIF(C20:AG20,"CTH") -> 0 | AR20: =COUNTIF(C20:AG20,"A") -> 0
A21: 14 | B21: ASBI | D21: 1 | E21: 1 | G21: 1 | H21: 1 | I21: 1 | J21: 1 | K21: 1 | L21: 1 | N21: 1 | O21: 1 | P21: 1 | Q21: 1 | S21: 1 | U21: 1 | V21: 1 | W21: 1 | X21: 1 | Y21: 1 | Z21: 1 | AB21: 1 | AC21: 1 | AD21: 1 | AE21: 1 | AF21: 1 | AG21: 1 | AH21: =SUM(C21:AG21) -> 25 | AI21: =COUNTIF(C21:AG21,"CT") -> 0 | AJ21: =COUNTIF(C21:AG21,"CS") -> 0 | AK21: =COUNTIF(C21:AG21,"CH") -> 0 | AL21: 4 | AM21: 2 | AN21: =COUNTIF(C21:AL21,"hm") -> 0 | AO21: =COUNTIF(C21:AM21,"CI") -> 0 | AP21: =AH21+AI21+AJ21+AK21+AL21+AM21+AN21+AO21 -> 31 | AQ21: =COUNTIF(C21:AG21,"CTH") -> 0 | AR21: =COUNTIF(C21:AG21,"A") -> 0
A22: 15 | B22: YANDI | D22: 1 | E22: 1 | G22: 1 | H22: 1 | I22: 1 | J22: 1 | K22: 1 | L22: 1 | N22: 1 | O22: 1 | P22: 1 | Q22: 1 | S22: 1 | U22: 1 | V22: 1 | W22: 1 | X22: 1 | Y22: 1 | Z22: 1 | AB22: 1 | AC22: 1 | AD22: 1 | AE22: 1 | AF22: 1 | AG22: 1 | AH22: =SUM(C22:AG22) -> 25 | AI22: =COUNTIF(C22:AG22,"CT") -> 0 | AJ22: =COUNTIF(C22:AG22,"CS") -> 0 | AK22: =COUNTIF(C22:AG22,"CH") -> 0 | AL22: 4 | AM22: 2 | AN22: =COUNTIF(C22:AL22,"hm") -> 0 | AO22: =COUNTIF(C22:AM22,"CI") -> 0 | AP22: =AH22+AI22+AJ22+AK22+AL22+AM22+AN22+AO22 -> 31 | AQ22: =COUNTIF(C22:AG22,"CTH") -> 0 | AR22: =COUNTIF(C22:AG22,"A") -> 0
A23: 16 | B23: APRIZAL | D23: 1 | E23: CT | G23: 1 | H23: 1 | I23: 1 | J23: 1 | K23: 1 | L23: 1 | N23: 1 | O23: 1 | P23: 1 | Q23: 1 | S23: 1 | U23: CT | V23: 1 | W23: 1 | X23: 1 | Y23: 1 | Z23: 1 | AB23: 1 | AC23: 1 | AD23: 1 | AE23: 1 | AF23: 1 | AG23: 1 | AH23: =SUM(C23:AG23) -> 23 | AI23: =COUNTIF(C23:AG23,"CT") -> 2 | AJ23: =COUNTIF(C23:AG23,"CS") -> 0 | AK23: =COUNTIF(C23:AG23,"CH") -> 0 | AL23: 4 | AM23: 2 | AN23: =COUNTIF(C23:AL23,"hm") -> 0 | AO23: =COUNTIF(C23:AM23,"CI") -> 0 | AP23: =AH23+AI23+AJ23+AK23+AL23+AM23+AN23+AO23 -> 31 | AQ23: =COUNTIF(C23:AG23,"CTH") -> 0 | AR23: =COUNTIF(C23:AG23,"A") -> 0
A24: 17 | B24: ERRY | D24: 1 | E24: CT | G24: 1 | H24: 1 | I24: 1 | J24: 1 | K24: 1 | L24: 1 | N24: 1 | O24: 1 | P24: 1 | Q24: 1 | S24: 1 | U24: 1 | V24: 1 | W24: 1 | X24: 1 | Y24: 1 | Z24: 1 | AB24: 1 | AC24: 1 | AD24: 1 | AE24: 1 | AF24: 1 | AG24: 1 | AH24: =SUM(C24:AG24) -> 24 | AI24: =COUNTIF(C24:AG24,"CT") -> 1 | AJ24: =COUNTIF(C24:AG24,"CS") -> 0 | AK24: =COUNTIF(C24:AG24,"CH") -> 0 | AL24: 4 | AM24: 2 | AN24: =COUNTIF(C24:AL24,"hm") -> 0 | AO24: =COUNTIF(C24:AM24,"CI") -> 0 | AP24: =AH24+AI24+AJ24+AK24+AL24+AM24+AN24+AO24 -> 31 | AQ24: =COUNTIF(C24:AG24,"CTH") -> 0 | AR24: =COUNTIF(C24:AG24,"A") -> 0
A25: 18 | B25: WIDODO | D25: CS | E25: CS | G25: 1 | H25: 1 | I25: 1 | J25: 1 | K25: 1 | L25: 1 | N25: 1 | O25: 1 | P25: 1 | Q25: 1 | S25: 1 | U25: 1 | V25: 1 | W25: 1 | X25: 1 | Y25: 1 | Z25: 1 | AB25: 1 | AC25: 1 | AD25: 1 | AE25: 1 | AF25: 1 | AG25: 1 | AH25: =SUM(C25:AG25) -> 23 | AI25: =COUNTIF(C25:AG25,"CT") -> 0 | AJ25: =COUNTIF(C25:AG25,"CS") -> 2 | AK25: =COUNTIF(C25:AG25,"CH") -> 0 | AL25: 4 | AM25: 2 | AN25: =COUNTIF(C25:AL25,"hm") -> 0 | AO25: =COUNTIF(C25:AM25,"CI") -> 0 | AP25: =AH25+AI25+AJ25+AK25+AL25+AM25+AN25+AO25 -> 31 | AQ25: =COUNTIF(C25:AG25,"CTH") -> 0 | AR25: =COUNTIF(C25:AG25,"A") -> 0
A26: 19 | B26: YANTI NOVITA | D26: 1 | E26: 1 | G26: 1 | H26: 1 | I26: 1 | J26: 1 | K26: 1 | L26: 1 | N26: 1 | O26: 1 | P26: 1 | Q26: CS | S26: 1 | U26: 1 | V26: CH | W26: CH | X26: 1 | Y26: 1 | Z26: 1 | AB26: 1 | AC26: 1 | AD26: 1 | AE26: 1 | AF26: 1 | AG26: 1 | AH26: =SUM(C26:AG26) -> 22 | AI26: =COUNTIF(C26:AG26,"CT") -> 0 | AJ26: =COUNTIF(C26:AG26,"CS") -> 1 | AK26: =COUNTIF(C26:AG26,"CH") -> 2 | AL26: 4 | AM26: 2 | AN26: =COUNTIF(C26:AL26,"hm") -> 0 | AO26: =COUNTIF(C26:AM26,"CI") -> 0 | AP26: =AH26+AI26+AJ26+AK26+AL26+AM26+AN26+AO26 -> 31 | AQ26: =COUNTIF(C26:AG26,"CTH") -> 0 | AR26: =COUNTIF(C26:AG26,"A") -> 0
A27: 20 | B27: RIJAL | D27: 1 | E27: 1 | G27: 1 | H27: 1 | I27: 1 | J27: 1 | K27: 1 | L27: CT | N27: 1 | O27: 1 | P27: 1 | Q27: 1 | S27: 1 | U27: 1 | V27: 1 | W27: 1 | X27: 1 | Y27: 1 | Z27: 1 | AB27: 1 | AC27: 1 | AD27: 1 | AE27: CT | AF27: 1 | AG27: 1 | AH27: =SUM(C27:AG27) -> 23 | AI27: =COUNTIF(C27:AG27,"CT") -> 2 | AJ27: =COUNTIF(C27:AG27,"CS") -> 0 | AK27: =COUNTIF(C27:AG27,"CH") -> 0 | AL27: 4 | AM27: 2 | AN27: =COUNTIF(C27:AL27,"hm") -> 0 | AO27: =COUNTIF(C27:AM27,"CI") -> 0 | AP27: =AH27+AI27+AJ27+AK27+AL27+AM27+AN27+AO27 -> 31 | AQ27: =COUNTIF(C27:AG27,"CTH") -> 0 | AR27: =COUNTIF(C27:AG27,"A") -> 0
A28: 21 | B28: SULTAN | D28: CS | E28: CS | G28: 1 | H28: 1 | I28: 1 | J28: 1 | K28: 1 | L28: 1 | N28: 1 | O28: 1 | P28: 1 | Q28: 1 | S28: 1 | U28: 1 | V28: 1 | W28: 1 | X28: 1 | Y28: 1 | Z28: 1 | AB28: 1 | AC28: 1 | AD28: 1 | AE28: 1 | AF28: 1 | AG28: 1 | AH28: =SUM(C28:AG28) -> 23 | AI28: =COUNTIF(C28:AG28,"CT") -> 0 | AJ28: =COUNTIF(C28:AG28,"CS") -> 2 | AK28: =COUNTIF(C28:AG28,"CH") -> 0 | AL28: 4 | AM28: 2 | AN28: =COUNTIF(C28:AL28,"hm") -> 0 | AO28: =COUNTIF(C28:AM28,"CI") -> 0 | AP28: =AH28+AI28+AJ28+AK28+AL28+AM28+AN28+AO28 -> 31 | AQ28: =COUNTIF(C28:AG28,"CTH") -> 0 | AR28: =COUNTIF(C28:AG28,"A") -> 0
A29: 22 | B29: EKO SUMANJAYA | D29: 1 | E29: A | G29: 1 | H29: 1 | I29: 1 | J29: 1 | K29: 1 | L29: 1 | N29: 1 | O29: 1 | P29: 1 | Q29: 1 | S29: 1 | U29: 1 | V29: 1 | W29: CT | X29: 1 | Y29: 1 | Z29: 1 | AB29: 1 | AC29: 1 | AD29: 1 | AE29: 1 | AF29: 1 | AG29: 1 | AH29: =SUM(C29:AG29) -> 23 | AI29: =COUNTIF(C29:AG29,"CT") -> 1 | AJ29: =COUNTIF(C29:AG29,"CS") -> 0 | AK29: =COUNTIF(C29:AG29,"CH") -> 0 | AL29: 4 | AM29: 2 | AN29: =COUNTIF(C29:AL29,"hm") -> 0 | AO29: =COUNTIF(C29:AM29,"CI") -> 0 | AP29: =AH29+AI29+AJ29+AK29+AL29+AM29+AN29+AO29 -> 30 | AQ29: =COUNTIF(C29:AG29,"CTH") -> 0 | AR29: =COUNTIF(C29:AG29,"A") -> 1
A30: 23 | B30: SUMARDI (hatijah ) | D30: 1 | E30: 1 | G30: 1 | H30: 1 | I30: 1 | J30: 1 | K30: 1 | L30: 1 | N30: 1 | O30: 1 | P30: 1 | Q30: 1 | S30: 1 | U30: 1 | V30: 1 | W30: 1 | X30: 1 | Y30: 1 | Z30: 1 | AB30: 1 | AC30: 1 | AD30: 1 | AE30: 1 | AF30: 1 | AG30: 1 | AH30: =SUM(C30:AG30) -> 25 | AI30: =COUNTIF(C30:AG30,"CT") -> 0 | AJ30: =COUNTIF(C30:AG30,"CS") -> 0 | AK30: =COUNTIF(C30:AG30,"CH") -> 0 | AL30: 4 | AM30: 2 | AN30: =COUNTIF(C30:AL30,"hm") -> 0 | AO30: =COUNTIF(C30:AM30,"CI") -> 0 | AP30: =AH30+AI30+AJ30+AK30+AL30+AM30+AN30+AO30 -> 31 | AQ30: =COUNTIF(C30:AG30,"CTH") -> 0 | AR30: =COUNTIF(C30:AG30,"A") -> 0
A31: 24 | B31: SUKARDI | D31: 1 | E31: A | G31: 1 | H31: 1 | I31: 1 | J31: 1 | K31: 1 | L31: 1 | N31: 1 | O31: 1 | P31: 1 | Q31: 1 | S31: CS | U31: CS | V31: 1 | W31: A | X31: 1 | Y31: 1 | Z31: 1 | AB31: 1 | AC31: 1 | AD31: 1 | AE31: 1 | AF31: 1 | AG31: 1 | AH31: =SUM(C31:AG31) -> 21 | AI31: =COUNTIF(C31:AG31,"CT") -> 0 | AJ31: =COUNTIF(C31:AG31,"CS") -> 2 | AK31: =COUNTIF(C31:AG31,"CH") -> 0 | AL31: 4 | AM31: 2 | AN31: =COUNTIF(C31:AL31,"hm") -> 0 | AO31: =COUNTIF(C31:AM31,"CI") -> 0 | AP31: =AH31+AI31+AJ31+AK31+AL31+AM31+AN31+AO31 -> 29 | AQ31: =COUNTIF(C31:AG31,"CTH") -> 0 | AR31: =COUNTIF(C31:AG31,"A") -> 2
A32: 25 | B32: MUSDI | D32: 1 | E32: 1 | G32: CT | H32: 1 | I32: 1 | J32: 1 | K32: 1 | L32: 1 | N32: 1 | O32: 1 | P32: 1 | Q32: 1 | S32: 1 | U32: 1 | V32: 1 | W32: 1 | X32: 1 | Y32: 1 | Z32: 1 | AB32: 1 | AC32: 1 | AD32: CS | AE32: 1 | AF32: 1 | AG32: 1 | AH32: =SUM(C32:AG32) -> 23 | AI32: =COUNTIF(C32:AG32,"CT") -> 1 | AJ32: =COUNTIF(C32:AG32,"CS") -> 1 | AK32: =COUNTIF(C32:AG32,"CH") -> 0 | AL32: 4 | AM32: 2 | AN32: =COUNTIF(C32:AL32,"hm") -> 0 | AO32: =COUNTIF(C32:AM32,"CI") -> 0 | AP32: =AH32+AI32+AJ32+AK32+AL32+AM32+AN32+AO32 -> 31 | AQ32: =COUNTIF(C32:AG32,"CTH") -> 0 | AR32: =COUNTIF(C32:AG32,"A") -> 0
A33: 26 | B33: NOLA WILANDA | D33: 1 | E33: CH | G33: 1 | H33: 1 | I33: 1 | J33: 1 | K33: 1 | L33: 1 | N33: 1 | O33: 1 | P33: 1 | Q33: 1 | S33: 1 | U33: 1 | V33: 1 | W33: 1 | X33: 1 | Y33: 1 | Z33: 1 | AB33: 1 | AC33: 1 | AD33: 1 | AE33: 1 | AF33: 1 | AG33: 1 | AH33: =SUM(C33:AG33) -> 24 | AI33: =COUNTIF(C33:AG33,"CT") -> 0 | AJ33: =COUNTIF(C33:AG33,"CS") -> 0 | AK33: =COUNTIF(C33:AG33,"CH") -> 1 | AL33: 4 | AM33: 2 | AN33: =COUNTIF(C33:AL33,"hm") -> 0 | AO33: =COUNTIF(C33:AM33,"CI") -> 0 | AP33: =AH33+AI33+AJ33+AK33+AL33+AM33+AN33+AO33 -> 31 | AQ33: =COUNTIF(C33:AG33,"CTH") -> 0 | AR33: =COUNTIF(C33:AG33,"A") -> 0
A34: 27 | B34: AGUSTIAN | D34: 1 | E34: 1 | G34: 1 | H34: 1 | I34: 1 | J34: CT | K34: A | L34: 1 | N34: 1 | O34: 1 | P34: 1 | Q34: 1 | S34: 1 | U34: 1 | V34: 1 | W34: 1 | X34: 1 | Y34: 1 | Z34: 1 | AB34: 1 | AC34: 1 | AD34: 1 | AE34: 1 | AF34: 1 | AG34: 1 | AH34: =SUM(C34:AG34) -> 23 | AI34: =COUNTIF(C34:AG34,"CT") -> 1 | AJ34: =COUNTIF(C34:AG34,"CS") -> 0 | AK34: =COUNTIF(C34:AG34,"CH") -> 0 | AL34: 4 | AM34: 2 | AN34: =COUNTIF(C34:AL34,"hm") -> 0 | AO34: =COUNTIF(C34:AM34,"CI") -> 0 | AP34: =AH34+AI34+AJ34+AK34+AL34+AM34+AN34+AO34 -> 30 | AQ34: =COUNTIF(C34:AG34,"CTH") -> 0 | AR34: =COUNTIF(C34:AG34,"A") -> 1
A35: 28 | B35: DWI MARZETI | D35: 1 | E35: 1 | G35: CTH | H35: 1 | I35: 1 | J35: 1 | K35: 1 | L35: 1 | N35: 1 | O35: 1 | P35: 1 | Q35: 1 | S35: 1 | U35: 1 | V35: 1 | W35: 1 | X35: 1 | Y35: 1 | Z35: 1 | AB35: 1 | AC35: 1 | AD35: 1 | AE35: CS | AF35: 1 | AG35: 1 | AH35: =SUM(C35:AG35) -> 23 | AI35: =COUNTIF(C35:AG35,"CT") -> 0 | AJ35: =COUNTIF(C35:AG35,"CS") -> 1 | AK35: =COUNTIF(C35:AG35,"CH") -> 0 | AL35: 4 | AM35: 2 | AN35: =COUNTIF(C35:AL35,"hm") -> 0 | AO35: =COUNTIF(C35:AM35,"CI") -> 0 | AP35: =AH35+AI35+AJ35+AK35+AL35+AM35+AN35+AO35 -> 30 | AQ35: =COUNTIF(C35:AG35,"CTH") -> 1 | AR35: =COUNTIF(C35:AG35,"A") -> 0
A36: 29 | B36: SAHARUDIN | D36: CT | E36: 1 | G36: 1 | H36: 1 | I36: 1 | J36: 1 | K36: 1 | L36: 1 | N36: 1 | O36: 1 | P36: 1 | Q36: 1 | S36: 1 | U36: 1 | V36: 1 | W36: 1 | X36: 1 | Y36: 1 | Z36: 1 | AB36: 1 | AC36: 1 | AD36: 1 | AE36: 1 | AF36: 1 | AG36: 1 | AH36: =SUM(C36:AG36) -> 24 | AI36: =COUNTIF(C36:AG36,"CT") -> 1 | AJ36: =COUNTIF(C36:AG36,"CS") -> 0 | AK36: =COUNTIF(C36:AG36,"CH") -> 0 | AL36: 4 | AM36: 2 | AN36: =COUNTIF(C36:AL36,"hm") -> 0 | AO36: =COUNTIF(C36:AM36,"CI") -> 0 | AP36: =AH36+AI36+AJ36+AK36+AL36+AM36+AN36+AO36 -> 31 | AQ36: =COUNTIF(C36:AG36,"CTH") -> 0 | AR36: =COUNTIF(C36:AG36,"A") -> 0
B37: HK TODAY | C37: =SUM(C8:C36) -> 0 | D37: =SUM(D8:D36) -> 25 | E37: =SUM(E8:E36) -> 21 | F37: =SUM(F8:F36) -> 0 | G37: =SUM(G8:G36) -> 27 | H37: =SUM(H8:H36) -> 28 | I37: =SUM(I8:I36) -> 28 | J37: =SUM(J8:J36) -> 27 | ... AR37: =SUM(AR8:AR36) -> 6 | AS37: =SUM(AS8:AS25) -> 0
B38: CT | AH38: =SUM(C38:AG38) -> 0
B39: CS | AH39: =SUM(C39:AG39) -> 0
B40: CH | AH40: =SUM(C40:AG40) -> 0
B41: CI | AH41: =SUM(C41:AG41) -> 0
B42: A+CTH | AH42: =SUM(C42:AG42) -> 0
...

Sheet INSENTIF PANEN
B2: HASIL PANEN ESTATE PGE 2A DIVISI AIR JANGKAT
B3: BULAN : JANUARI 2026
B4: NO | C4: NAMA | D4: PANEN PGE 2A | M4: BANTU AIR PAPAN | P4: TOTAL TONASE | Q4: INSENTIF | R4: POKOK > 12 METER | T4: POKOK 10-12 METER | V4: PREMI POKOK TINGGI DAN RENDAH | W4: TOTAL INSENTIF
D5: PANEN CKROL 2A | E5: 6 | F5: 13 | G5: 18 | H5: 20 | I5: PANEN KONTANAN | J5: TOTAL JANJANG | K5: BJR | L5: TONASE | M5: TANDAN | N5: BJR | O5: TON | R5: JML TDN | S5: Rp.5000(ton x harga ) | T5: JML TDN | U5: Rp.2.500( ton x harga )
B6: 1 | C6: =Sheet2!C10 -> SUIP | D6: ='CKROL PHT'!AH16 -> 948 | I6: =E6 -> 0 | J6: =D6+I6 -> 948 | K6: 16.7298 | L6: =D6*K6 -> 15859.85 | O6: =M6*N6 -> 0 | P6: =L6+O6 -> 15859.85 | V6: =S6+U6 -> 0 | W6: =Q6+V6 -> 0
B7: 2 | C7: =Sheet2!C11 -> ROBIN DINATA | D7: ='CKROL PHT'!AH27 -> 1037 | I7: =E7 -> 0 | J7: =D7+I7 -> 1037 | K7: 16.7298 | L7: =D7*K7 -> 17348.803 | O7: =M7*N7 -> 0 | P7: =L7+O7 -> 17348.803 | V7: =S7+U7 -> 0 | W7: =Q7+V7 -> 0
B8: 3 | C8: =Sheet2!C12 -> SAPARUDIN | D8: ='CKROL PHT'!AH38 -> 1063 | I8: =E8 -> 0 | J8: =D8+I8 -> 1063 | K8: 16.7298 | L8: =D8*K8 -> 17783.777 | O8: =M8*N8 -> 0 | P8: =L8+O8 -> 17783.777 | W8: =Q8+V8 -> 0 | Z8: =347980/21453 -> 16.220575
B9: 4 | C9: =Sheet2!C13 -> SONJA PRIYOGA | D9: ='CKROL PHT'!AH49 -> 1100 | I9: =E9 -> 0 | J9: =D9+I9 -> 1100 | K9: 16.7298 | L9: =D9*K9 -> 18402.78 | O9: =M9*N9 -> 0 | P9: =L9+O9 -> 18402.78 | W9: =Q9+V9 -> 0
B10: 5 | C10: =Sheet2!C14 -> AHAP | D10: ='CKROL PHT'!AH60 -> 1234 | I10: =E10 -> 0 | J10: =D10+I10 -> 1234 | K10: 16.7298 | L10: =D10*K10 -> 20644.573 | O10: =M10*N10 -> 0 | P10: =L10+O10 -> 20644.573 | W10: =Q10+V10 -> 0
B11: 6 | C11: =Sheet2!C15 -> IHSAN | D11: ='CKROL PHT'!AH71 -> 1082 | I11: =E11 -> 0 | J11: =D11+I11 -> 1082 | K11: 16.7298 | L11: =D11*K11 -> 18101.644 | O11: =M11*N11 -> 0 | P11: =L11+O11 -> 18101.644 | W11: =Q11+V11 -> 0
B12: 7 | C12: =Sheet2!C16 -> QISTAHAM | D12: ='CKROL PHT'!AH82 -> 1663 | I12: =E12 -> 0 | J12: =D12+I12 -> 1663 | K12: 16.7298 | L12: =D12*K12 -> 27821.657 | O12: =M12*N12 -> 0 | P12: =L12+O12 -> 27821.657 | Q12: 150000 | W12: =Q12+V12 -> 150000
B13: 8 | C13: =Sheet2!C17 -> JAYADI | D13: ='CKROL PHT'!AH93 -> 1322 | I13: =E13 -> 0 | J13: =D13+I13 -> 1322 | K13: 16.7298 | L13: =D13*K13 -> 22116.796 | O13: =M13*N13 -> 0 | P13: =L13+O13 -> 22116.796 | W13: =Q13+V13 -> 0
