Workbook
Name februari: TARIF!#REF!
Name februari: TARIF!#REF!
Name PH: [1]TARIF!#REF!
Name PH: TARIF!#REF!
Name PTKP: [1]TARIF!#REF!
Name PTKP: TARIF!#REF!
Name TARIF: [2]TARIF!$S$18:$U$25
Name Ter_A: [1]TARIF!$B$3:$E$46
Name Ter_A: TARIF!$B$3:$E$46
Name Ter_B: [1]TARIF!$H$3:$K$42
Name Ter_B: TARIF!$H$3:$K$42
Name Ter_C: [1]TARIF!$N$3:$Q$43
Name Ter_C: TARIF!$N$3:$Q$43

Sheet TARIF
A1: PTKP (TK/0, TK/1, K/0) | G1: PTKP (TK/2, TK/3, K/1, K/2) | M1: PTKP (K/3) | S1: HARIAN
A2: No | B2: Lapisan Penghasilan bruto (Rp.) | E2: TER A | G2: No | H2: Lapisan Penghasilan bruto (Rp.) | K2: TER B | M2: No | N2: Lapisan Penghasilan bruto (Rp.) | Q2: TER C | S2: Penghasilan Bruto | V2: Tarif
A3: 1 | B3: 0 | C3: s.d | D3: 5400000 | E3: 0 | G3: 1 | H3: 0 | I3: s.d | J3: 6200000 | K3: 0 | M3: 1 | N3: 0 | O3: s.d | P3: 6600000 | Q3: 0 | S3: 0 | T3: s.d | U3: 450000 | V3: 0
A4: =A3+1 -> 2 | B4: =D3+1 -> 5400001 | C4: s.d | D4: 5650000 | E4: 0.0025 | G4: =G3+1 -> 2 | H4: =J3+1 -> 6200001 | I4: s.d | J4: 6500000 | K4: 0.0025 | M4: =M3+1 -> 2 | N4: =P3+1 -> 6600001 | O4: s.d | P4: 6950000 | Q4: 0.0025 | S4: 450001 | T4: s.d | U4: 2500000 | V4: 0.005
A5: =A4+1 -> 3 | B5: =D4+1 -> 5650001 | C5: s.d | D5: 5950000 | E5: 0.005 | G5: =G4+1 -> 3 | H5: =J4+1 -> 6500001 | I5: s.d | J5: 6850000 | K5: 0.005 | M5: =M4+1 -> 3 | N5: =P4+1 -> 6950001 | O5: s.d | P5: 7350000 | Q5: 0.005
A6: =A5+1 -> 4 | B6: =D5+1 -> 5950001 | C6: s.d | D6: 6300000 | E6: 0.0075 | G6: =G5+1 -> 4 | H6: =J5+1 -> 6850001 | I6: s.d | J6: 7300000 | K6: 0.0075 | M6: =M5+1 -> 4 | N6: =P5+1 -> 7350001 | O6: s.d | P6: 7800000 | Q6: 0.0075
A7: =A6+1 -> 5 | B7: =D6+1 -> 6300001 | C7: s.d | D7: 6750000 | E7: 0.01 | G7: =G6+1 -> 5 | H7: =J6+1 -> 7300001 | I7: s.d | J7: 9200000 | K7: 0.01 | M7: =M6+1 -> 5 | N7: =P6+1 -> 7800001 | O7: s.d | P7: 8850000 | Q7: 0.01 | S7: TARIF PASAL 17 WPOP
A8: =A7+1 -> 6 | B8: =D7+1 -> 6750001 | C8: s.d | D8: 7500000 | E8: 0.0125 | G8: =G7+1 -> 6 | H8: =J7+1 -> 9200001 | I8: s.d | J8: 10750000 | K8: 0.015 | M8: =M7+1 -> 6 | N8: =P7+1 -> 8850001 | O8: s.d | P8: 9800000 | Q8: 0.0125 | S8: Lapisan PKP | V8: Tarif
A9: =A8+1 -> 7 | B9: =D8+1 -> 7500001 | C9: s.d | D9: 8550000 | E9: 0.015 | G9: =G8+1 -> 7 | H9: =J8+1 -> 10750001 | I9: s.d | J9: 11250000 | K9: 0.02 | M9: =M8+1 -> 7 | N9: =P8+1 -> 9800001 | O9: s.d | P9: 10950000 | Q9: 0.015 | S9: 0 | T9: s.d | U9: 60000000 | V9: 0.05
A10: =A9+1 -> 8 | B10: =D9+1 -> 8550001 | C10: s.d | D10: 9650000 | E10: 0.0175 | G10: =G9+1 -> 8 | H10: =J9+1 -> 11250001 | I10: s.d | J10: 11600000 | K10: 0.025 | M10: =M9+1 -> 8 | N10: =P9+1 -> 10950001 | O10: s.d | P10: 11200000 | Q10: 0.0175 | S10: =U9+1 -> 60000001 | T10: s.d | U10: 250000000 | V10: 0.15
A11: =A10+1 -> 9 | B11: =D10+1 -> 9650001 | C11: s.d | D11: 10050000 | E11: 0.02 | G11: =G10+1 -> 9 | H11: =J10+1 -> 11600001 | I11: s.d | J11: 12600000 | K11: 0.03 | M11: =M10+1 -> 9 | N11: =P10+1 -> 11200001 | O11: s.d | P11: 12050000 | Q11: 0.02 | S11: =U10+1 -> 250000001 | T11: s.d | U11: 500000000 | V11: 0.25
A12: =A11+1 -> 10 | B12: =D11+1 -> 10050001 | C12: s.d | D12: 10350000 | E12: 0.0225 | G12: =G11+1 -> 10 | H12: =J11+1 -> 12600001 | I12: s.d | J12: 13600000 | K12: 0.04 | M12: =M11+1 -> 10 | N12: =P11+1 -> 12050001 | O12: s.d | P12: 12950000 | Q12: 0.03 | S12: =U11+1 -> 500000001 | T12: s.d | U12: 5000000000 | V12: 0.3
A13: =A12+1 -> 11 | B13: =D12+1 -> 10350001 | C13: s.d | D13: 10700000 | E13: 0.025 | G13: =G12+1 -> 11 | H13: =J12+1 -> 13600001 | I13: s.d | J13: 14950000 | K13: 0.05 | M13: =M12+1 -> 11 | N13: =P12+1 -> 12950001 | O13: s.d | P13: 14150000 | Q13: 0.04 | S13: =U12+1 -> 5000000001 | T13: s.d | U13: ~~ | V13: 0.35
A14: =A13+1 -> 12 | B14: =D13+1 -> 10700001 | C14: s.d | D14: 11050000 | E14: 0.03 | G14: =G13+1 -> 12 | H14: =J13+1 -> 14950001 | I14: s.d | J14: 16400000 | K14: 0.06 | M14: =M13+1 -> 12 | N14: =P13+1 -> 14150001 | O14: s.d | P14: 1550000 | Q14: 0.05
A15: =A14+1 -> 13 | B15: =D14+1 -> 11050001 | C15: s.d | D15: 11600000 | E15: 0.035 | G15: =G14+1 -> 13 | H15: =J14+1 -> 16400001 | I15: s.d | J15: 18450000 | K15: 0.07 | M15: =M14+1 -> 13 | N15: =P14+1 -> 1550001 | O15: s.d | P15: 17050000 | Q15: 0.06
A16: =A15+1 -> 14 | B16: =D15+1 -> 11600001 | C16: s.d | D16: 12500000 | E16: 0.04 | G16: =G15+1 -> 14 | H16: =J15+1 -> 18450001 | I16: s.d | J16: 21850000 | K16: 0.08 | M16: =M15+1 -> 14 | N16: =P15+1 -> 17050001 | O16: s.d | P16: 19500000 | Q16: 0.07 | S16: PTKP
A17: =A16+1 -> 15 | B17: =D16+1 -> 12500001 | C17: s.d | D17: 13750000 | E17: 0.05 | G17: =G16+1 -> 15 | H17: =J16+1 -> 21850001 | I17: s.d | J17: 26000000 | K17: 0.09 | M17: =M16+1 -> 15 | N17: =P16+1 -> 19500001 | O17: s.d | P17: 22700000 | Q17: 0.08 | S17: Status | U17: Jumlah
A18: =A17+1 -> 16 | B18: =D17+1 -> 13750001 | C18: s.d | D18: 15100000 | E18: 0.06 | G18: =G17+1 -> 16 | H18: =J17+1 -> 26000001 | I18: s.d | J18: 27700000 | K18: 0.1 | M18: =M17+1 -> 16 | N18: =P17+1 -> 22700001 | O18: s.d | P18: 26600000 | Q18: 0.09 | S18: TK/0 | U18: 54000000
A19: =A18+1 -> 17 | B19: =D18+1 -> 15100001 | C19: s.d | D19: 16950000 | E19: 0.07 | G19: =G18+1 -> 17 | H19: =J18+1 -> 27700001 | I19: s.d | J19: 29350000 | K19: 0.11 | M19: =M18+1 -> 17 | N19: =P18+1 -> 26600001 | O19: s.d | P19: 28100000 | Q19: 0.1 | S19: TK/1 | U19: 58500000
A20: =A19+1 -> 18 | B20: =D19+1 -> 16950001 | C20: s.d | D20: 19750000 | E20: 0.08 | G20: =G19+1 -> 18 | H20: =J19+1 -> 29350001 | I20: s.d | J20: 31450000 | K20: 0.12 | M20: =M19+1 -> 18 | N20: =P19+1 -> 28100001 | O20: s.d | P20: 30100000 | Q20: 0.11 | S20: TK/2 | U20: 63000000
A21: =A20+1 -> 19 | B21: =D20+1 -> 19750001 | C21: s.d | D21: 24150000 | E21: 0.09 | G21: =G20+1 -> 19 | H21: =J20+1 -> 31450001 | I21: s.d | J21: 33950000 | K21: 0.13 | M21: =M20+1 -> 19 | N21: =P20+1 -> 30100001 | O21: s.d | P21: 32600000 | Q21: 0.12 | S21: TK/3 | U21: 67500000
A22: =A21+1 -> 20 | B22: =D21+1 -> 24150001 | C22: s.d | D22: 26450000 | E22: 0.1 | G22: =G21+1 -> 20 | H22: =J21+1 -> 33950001 | I22: s.d | J22: 37100000 | K22: 0.14 | M22: =M21+1 -> 20 | N22: =P21+1 -> 32600001 | O22: s.d | P22: 35400000 | Q22: 0.13 | S22: K/0 | U22: 58500000
A23: =A22+1 -> 21 | B23: =D22+1 -> 26450001 | C23: s.d | D23: 28000000 | E23: 0.11 | G23: =G22+1 -> 21 | H23: =J22+1 -> 37100001 | I23: s.d | J23: 41100000 | K23: 0.15 | M23: =M22+1 -> 21 | N23: =P22+1 -> 35400001 | O23: s.d | P23: 38900000 | Q23: 0.14 | S23: K/1 | U23: 63000000
A24: =A23+1 -> 22 | B24: =D23+1 -> 28000001 | C24: s.d | D24: 30050000 | E24: 0.12 | G24: =G23+1 -> 22 | H24: =J23+1 -> 41100001 | I24: s.d | J24: 45800000 | K24: 0.16 | M24: =M23+1 -> 22 | N24: =P23+1 -> 38900001 | O24: s.d | P24: 43000000 | Q24: 0.15 | S24: K/2 | U24: 67500000
A25: =A24+1 -> 23 | B25: =D24+1 -> 30050001 | C25: s.d | D25: 32400000 | E25: 0.13 | G25: =G24+1 -> 23 | H25: =J24+1 -> 45800001 | I25: s.d | J25: 49500000 | K25: 0.17 | M25: =M24+1 -> 23 | N25: =P24+1 -> 43000001 | O25: s.d | P25: 47400000 | Q25: 0.16 | S25: K/3 | U25: 72000000
A26: =A25+1 -> 24 | B26: =D25+1 -> 32400001 | C26: s.d | D26: 35400000 | E26: 0.14 | G26: =G25+1 -> 24 | H26: =J25+1 -> 49500001 | I26: s.d | J26: 53800000 | K26: 0.18 | M26: =M25+1 -> 24 | N26: =P25+1 -> 47400001 | O26: s.d | P26: 51200000 | Q26: 0.17
A27: =A26+1 -> 25 | B27: =D26+1 -> 35400001 | C27: s.d | D27: 39100000 | E27: 0.15 | G27: =G26+1 -> 25 | H27: =J26+1 -> 53800001 | I27: s.d | J27: 58500000 | K27: 0.19 | M27: =M26+1 -> 25 | N27: =P26+1 -> 51200001 | O27: s.d | P27: 55800000 | Q27: 0.18
A28: =A27+1 -> 26 | B28: =D27+1 -> 39100001 | C28: s.d | D28: 43850000 | E28: 0.16 | G28: =G27+1 -> 26 | H28: =J27+1 -> 58500001 | I28: s.d | J28: 64000000 | K28: 0.2 | M28: =M27+1 -> 26 | N28: =P27+1 -> 55800001 | O28: s.d | P28: 60400000 | Q28: 0.19
A29: =A28+1 -> 27 | B29: =D28+1 -> 43850001 | C29: s.d | D29: 47800000 | E29: 0.17 | G29: =G28+1 -> 27 | H29: =J28+1 -> 64000001 | I29: s.d | J29: 71000000 | K29: 0.21 | M29: =M28+1 -> 27 | N29: =P28+1 -> 60400001 | O29: s.d | P29: 66700000 | Q29: 0.2
A30: =A29+1 -> 28 | B30: =D29+1 -> 47800001 | C30: s.d | D30: 51400000 | E30: 0.18 | G30: =G29+1 -> 28 | H30: =J29+1 -> 71000001 | I30: s.d | J30: 80000000 | K30: 0.22 | M30: =M29+1 -> 28 | N30: =P29+1 -> 66700001 | O30: s.d | P30: 74500000 | Q30: 0.21
A31: =A30+1 -> 29 | B31: =D30+1 -> 51400001 | C31: s.d | D31: 56300000 | E31: 0.19 | G31: =G30+1 -> 29 | H31: =J30+1 -> 80000001 | I31: s.d | J31: 93000000 | K31: 0.23 | M31: =M30+1 -> 29 | N31: =P30+1 -> 74500001 | O31: s.d | P31: 83200000 | Q31: 0.22
A32: =A31+1 -> 30 | B32: =D31+1 -> 56300001 | C32: s.d | D32: 62200000 | E32: 0.2 | G32: =G31+1 -> 30 | H32: =J31+1 -> 93000001 | I32: s.d | J32: 109000000 | K32: 0.24 | M32: =M31+1 -> 30 | N32: =P31+1 -> 83200001 | O32: s.d | P32: 95600000 | Q32: 0.23
A33: =A32+1 -> 31 | B33: =D32+1 -> 62200001 | C33: s.d | D33: 68600000 | E33: 0.21 | G33: =G32+1 -> 31 | H33: =J32+1 -> 109000001 | I33: s.d | J33: 129000000 | K33: 0.25 | M33: =M32+1 -> 31 | N33: =P32+1 -> 95600001 | O33: s.d | P33: 110000000 | Q33: 0.24
A34: =A33+1 -> 32 | B34: =D33+1 -> 68600001 | C34: s.d | D34: 77500000 | E34: 0.22 | G34: =G33+1 -> 32 | H34: =J33+1 -> 129000001 | I34: s.d | J34: 163000000 | K34: 0.26 | M34: =M33+1 -> 32 | N34: =P33+1 -> 110000001 | O34: s.d | P34: 134000000 | Q34: 0.25
A35: =A34+1 -> 33 | B35: =D34+1 -> 77500001 | C35: s.d | D35: 89000000 | E35: 0.23 | G35: =G34+1 -> 33 | H35: =J34+1 -> 163000001 | I35: s.d | J35: 211000000 | K35: 0.27 | M35: =M34+1 -> 33 | N35: =P34+1 -> 134000001 | O35: s.d | P35: 169000000 | Q35: 0.26
A36: =A35+1 -> 34 | B36: =D35+1 -> 89000001 | C36: s.d | D36: 103000000 | E36: 0.24 | G36: =G35+1 -> 34 | H36: =J35+1 -> 211000001 | I36: s.d | J36: 374000000 | K36: 0.28 | M36: =M35+1 -> 34 | N36: =P35+1 -> 169000001 | O36: s.d | P36: 221000000 | Q36: 0.27
A37: =A36+1 -> 35 | B37: =D36+1 -> 103000001 | C37: s.d | D37: 125000000 | E37: 0.25 | G37: =G36+1 -> 35 | H37: =J36+1 -> 374000001 | I37: s.d | J37: 459000000 | K37: 0.29 | M37: =M36+1 -> 35 | N37: =P36+1 -> 221000001 | O37: s.d | P37: 390000000 | Q37: 0.28
... A41: =A40+1 -> 39 | B41: =D40+1 -> 337000001 | C41: s.d | D41: 454000000 | E41: 0.29 | G41: =G40+1 -> 39 | H41: =J40+1 -> 957000001 | I41: s.d | J41: 1405000000 | K41: 0.33 | M41: =M40+1 -> 39 | N41: =P40+1 -> 709000001 | O41: s.d | P41: 965000000 | Q41: 0.32
A42: =A41+1 -> 40 | B42: =D41+1 -> 454000001 | C42: s.d | D42: 550000000 | E42: 0.3 | G42: =G41+1 -> 40 | H42: =J41+1 -> 1405000001 | I42: s.d | J42: ~~ | K42: 0.34 | M42: =M41+1 -> 40 | N42: =P41+1 -> 965000001 | O42: s.d | P42: 1419000000 | Q42: 0.33
A43: =A42+1 -> 41 | B43: =D42+1 -> 550000001 | C43: s.d | D43: 695000000 | E43: 0.31 | M43: =M42+1 -> 41 | N43: =P42+1 -> 1419000001 | O43: s.d | P43: ~~ | Q43: 0.34
...

Sheet Des
C1: yang berwarna ini rumus
B2: Nomor Urut | C2: NAMA KARYAWAN | D2: N I K / PASPOR | E2: N P W P | F2: A L A M A T | G2: JABATAN | H2: STATUS KARYAWAN | M2: DESEMBER | R2: PENGHASILAN TIDAK TERATUR | U2: TOTAL GAJI POKOK | V2: TOTAL TUNJANGAN LAINNYA | W2: TOTAL PREMI ASURANSI | X2: TOTAL TUNJANGAN PPH | Y2: TOTAL NATURA / KENIKMATAN | Z2: TOTAL THR, BONUS, TANTIEM | AA2: PENGHASILAN BRUTO SETAHUN | AB2: PENGURANG | AD2: PENGHASILAN NETTO SETAHUN | AE2: P T K P | AF2: P K P | AG2: PPH PASAL 21 | AI2: PPH PASAL 21 JAN S.D NOP | AJ2: PPH PASAL 21 DESEMBER
M3: Gaji Pokok | N3: Total Tunjangan | O3: Premi JKK, JKM, Kes | P3: Tunjangan PPh | Q3: Penghasilan Bruto | R3: T H R | S3: B O N U S | T3: TANTIEM
H4: L/P | I4: PTKP | J4: TER | K4: MASA KERJA | AB4: BIAYA JABATAN | AC4: TOTAL IURAN JHT/THT/JP | AG4: SETAHUN | AH4: INCLUDE NON NPWP
B5: 1 | C5: 2 | D5: 3 | E5: 4 | F5: 5 | G5: 6 | H5: 7 | I5: 8 | J5: 9 | K5: 10 | L5: 11 | M5: 12 | N5: 13 | O5: 14 | P5: 15 | Q5: 16 | R5: 17 | S5: 18 | T5: 19 | U5: 20 | V5: 21 | W5: 22 | X5: 23 | Y5: 24 | Z5: 25 | AA5: 26 | AB5: 27 | AC5: 27 | AD5: 29 | AE5: 30 | AF5: 31 | AG5: 32 | AH5: 33 | AI5: 34 | AJ5: 35
B6: 1 | C6: =+PERBULAN!B6 -> GUNAWAN | D6: 1902040612940006 | E6: 66.907.954.3-305.000 | F6: AIR BATU BUDING RT. 002 RW. 001 DESA AIR BATU BUDING KEC. BADAU | G6: KRANI DIVISI | H6: L | I6: K/2 | J6: =IF(ISBLANK(I6),"",IF(OR(I6="TK/0",I6="TK/1",I6="K/0"),"TER A",IF(I6="K/3","TER C","TER B"))) -> TER B | K6: 1 | L6: 12 | M6: =31*129220 -> 4005820 | N6: 3740804.1 | O6: 189224.64 | P6: 0 | Q6: =SUM(M6:P6) -> 7935848.7 | R6: =+SETAHUN!H7 -> 4073100 | S6: =+SETAHUN!K7 -> 900000 | T6: 0 | U6: =+SETAHUN!F7+M6+N6 -> 88602848 | V6: 0 | W6: =+SETAHUN!U7+O6 -> 2268022.1 | X6: 0 | Y6: 0 | Z6: =SUM(R6:T6) -> 4973100 | AA6: =SUM(U6:Z6) -> 95843970 | AB6: =ROUND(IF((AA6)*5%>6000000,6000000,(AA6)*5%),0) -> 4792198 | AC6: =('ASTEK+PENSIUN-DIISI SMPAI DES'!O95+'ASTEK+PENSIUN-DIISI SMPAI DES'!O9) -> 1401336 | AD6: =AA6-AB6-AC6 -> 89650436 | AE6: =IFERROR(VLOOKUP(I6,TARIF,3,FALSE),0) -> 67500000 | AF6: =ROUNDDOWN(IF(AD6<=AE6,0,IF(AD6>AE6,AD6-AE6)),-3) -> 22150000 | AG6: =IF(AF6>5000000000,AF6*35%-306000000,IF(AF6>500000000,AF6*30%-56000000,IF(AF6>250000000,AF6*25%-31000000,IF(AF6>60000000,AF6*15%-6000000,AF6*5%)))) -> 1107500 | AH6: =ROUND(IF(E6=0,AG6*120%,AG6),0) -> 1107500 | AI6: =+'PAJAK JAN-NOV'!R3 -> 999664 | AJ6: =IF(AG6<=AI6,0,IF(AG6>AI6,AG6-AI6)) -> 107836 | AK6: =+'PAJAK JAN-NOV'!B3 -> GUNAWAN | AL6: =AI6-AH6 -> -107836
B7: 2 | C7: =+PERBULAN!B7 -> RILYANI | D7: 1906041207760003 | E7: 97.228.586.0-305.000 | F7: DSN CENDIL RT. 002 RW. 001 DS CENDIL KEC. KELAPA KAMPIT | G7: MANDOR PERAWATAN | H7: L | I7: K/0 | J7: =IF(ISBLANK(I7),"",IF(OR(I7="TK/0",I7="TK/1",I7="K/0"),"TER A",IF(I7="K/3","TER C","TER B"))) -> TER A | K7: 1 | L7: 12 | M7: =31*129220 -> 4005820 | N7: 273750 | O7: 191935.04 | P7: 0 | Q7: =SUM(M7:P7) -> 4471505 | R7: =+SETAHUN!H8 -> 4063100 | S7: =+SETAHUN!K8 -> 600000 | T7: 0 | U7: =+SETAHUN!F8+M7+N7 -> 50377447 | V7: 0 | W7: =+SETAHUN!U8+O7 -> 2297614.9 | X7: 0 | Y7: 0 | Z7: =SUM(R7:T7) -> 4663100 | AA7: =SUM(U7:Z7) -> 57338162 | AB7: =ROUND(IF((AA7)*5%>6000000,6000000,(AA7)*5%),0) -> 2866908 | AC7: =('ASTEK+PENSIUN-DIISI SMPAI DES'!O96+'ASTEK+PENSIUN-DIISI SMPAI DES'!O10) -> 1411596 | AD7: =AA7-AB7-AC7 -> 53059658 | AE7: =IFERROR(VLOOKUP(I7,TARIF,3,FALSE),0) -> 58500000 | AF7: =ROUNDDOWN(IF(AD7<=AE7,0,IF(AD7>AE7,AD7-AE7)),-3) -> 0 | AG7: =IF(AF7>5000000000,AF7*35%-306000000,IF(AF7>500000000,AF7*30%-56000000,IF(AF7>250000000,AF7*25%-31000000,IF(AF7>60000000,AF7*15%-6000000,AF7*5%)))) -> 0 | AH7: =ROUND(IF(E7=0,AG7*120%,AG7),0) -> 0 | AI7: =+'PAJAK JAN-NOV'!R4 -> 128008 | AJ7: =IF(AG7<=AI7,0,IF(AG7>AI7,AG7-AI7)) -> 0 | AK7: =+'PAJAK JAN-NOV'!B4 -> RILYANI | AL7: =AI7-AH7 -> 128008
B8: 3 | C8: =+PERBULAN!B8 -> JUNAIDI | D8: 1902010107770126 | E8: 97.228.531.6-305.000 | F8: KELEKAK USANG RT. 056 RW. 018 DESA PERAWAS KEC. TANJUNGPANDAN | G8: KARY PERAWATAN | H8: L | I8: K/0 | J8: =IF(ISBLANK(I8),"",IF(OR(I8="TK/0",I8="TK/1",I8="K/0"),"TER A",IF(I8="K/3","TER C","TER B"))) -> TER A | K8: 1 | L8: 12 | M8: =31*129220 -> 4005820 | N8: 1492919.3 | O8: 192104.44 | P8: 0 | Q8: =SUM(M8:P8) -> 5690843.8 | R8: =+SETAHUN!H9 -> 4066600 | S8: =+SETAHUN!K9 -> 900000 | T8: 0 | U8: =+SETAHUN!F9+M8+N8 -> 51550446 | V8: 0 | W8: =+SETAHUN!U9+O8 -> 2299331.3 | X8: 0 | Y8: 0 | Z8: =SUM(R8:T8) -> 4966600 | AA8: =SUM(U8:Z8) -> 58816378 | AB8: =ROUND(IF((AA8)*5%>6000000,6000000,(AA8)*5%),0) -> 2940819 | AC8: =('ASTEK+PENSIUN-DIISI SMPAI DES'!O97+'ASTEK+PENSIUN-DIISI SMPAI DES'!O11) -> 1412226 | AD8: =AA8-AB8-AC8 -> 54463333 | AE8: =IFERROR(VLOOKUP(I8,TARIF,3,FALSE),0) -> 58500000 | AF8: =ROUNDDOWN(IF(AD8<=AE8,0,IF(AD8>AE8,AD8-AE8)),-3) -> 0 | AG8: =IF(AF8>5000000000,AF8*35%-306000000,IF(AF8>500000000,AF8*30%-56000000,IF(AF8>250000000,AF8*25%-31000000,IF(AF8>60000000,AF8*15%-6000000,AF8*5%)))) -> 0 | AH8: =ROUND(IF(E8=0,AG8*120%,AG8),0) -> 0 | AI8: =+'PAJAK JAN-NOV'!R5 -> 126855 | AJ8: =IF(AG8<=AI8,0,IF(AG8>AI8,AG8-AI8)) -> 0 | AK8: =+'PAJAK JAN-NOV'!B5 -> JUNAIDI | AL8: =AI8-AH8 -> 126855
B9: 4 | C9: =+PERBULAN!B9 -> UMIYATI | D9: 1902055904700002 | E9: 97.228.520.9-305.000 | F9: JL. MANGGAR DSN BUKIT INDAH RT. 011 RW. 004 KACANG BUTOR BADAU | G9: KARY PERAWATAN | H9: P | I9: TK/0 | J9: =IF(ISBLANK(I9),"",IF(OR(I9="TK/0",I9="TK/1",I9="K/0"),"TER A",IF(I9="K/3","TER C","TER B"))) -> TER A | K9: 1 | L9: 4 | P9: 0 | Q9: =SUM(M9:P9) -> 0 | R9: =+SETAHUN!H10 -> 4036600 | S9: =+SETAHUN!K10 -> 0 | T9: 0 | U9: =+SETAHUN!F10+M9+N9 -> 14668728 | V9: 0 | W9: =+SETAHUN!U10+O9 -> 764049.76 | X9: 0 | Y9: 0 | Z9: =SUM(R9:T9) -> 4036600 | AA9: =SUM(U9:Z9) -> 19469378 | AB9: =ROUND(IF((AA9)*5%>6000000,6000000,(AA9)*5%),0) -> 973469 | AC9: =('ASTEK+PENSIUN-DIISI SMPAI DES'!O98+'ASTEK+PENSIUN-DIISI SMPAI DES'!O12) -> 465192 | AD9: =AA9-AB9-AC9 -> 18030717 | AE9: =IFERROR(VLOOKUP(I9,TARIF,3,FALSE),0) -> 54000000 | AF9: =ROUNDDOWN(IF(AD9<=AE9,0,IF(AD9>AE9,AD9-AE9)),-3) -> 0 | AG9: =IF(AF9>5000000000,AF9*35%-306000000,IF(AF9>500000000,AF9*30%-56000000,IF(AF9>250000000,AF9*25%-31000000,IF(AF9>60000000,AF9*15%-6000000,AF9*5%)))) -> 0 | AH9: =ROUND(IF(E9=0,AG9*120%,AG9),0) -> 0 | AI9: =+'PAJAK JAN-NOV'!R6 -> 125940 | AJ9: =IF(AG9<=AI9,0,IF(AG9>AI9,AG9-AI9)) -> 0 | AK9: =+'PAJAK JAN-NOV'!B6 -> UMIYATI | AL9: =AI9-AH9 -> 125940
B10: 5 | C10: =+PERBULAN!B10 -> ASUNTI | D10: 1902044606740003 | E10: 97.228.555.5-305.000 | F10: PELEPAK PUTIH RT. 022 RW. 011 DESA SIJUK KEC. SIJUK | G10: KARY PERAWATAN | H10: P | I10: TK/0 | J10: =IF(ISBLANK(I10),"",IF(OR(I10="TK/0",I10="TK/1",I10="K/0"),"TER A",IF(I10="K/3","TER C","TER B"))) -> TER A | K10: 1 | L10: 12 | M10: =31*129220 -> 4005820 | N10: 120250 | O10: 190071.64 | P10: 0 | Q10: =SUM(M10:P10) -> 4316141.6 | R10: =+SETAHUN!H11 -> 3991100 | S10: =+SETAHUN!K11 -> 200000 | T10: 0 | U10: =+SETAHUN!F11+M10+N10 -> 48436579 | V10: 0 | W10: =+SETAHUN!U11+O10 -> 2277305.1 | X10: 0 | Y10: 0 | Z10: =SUM(R10:T10) -> 4191100 | AA10: =SUM(U10:Z10) -> 54904984 | AB10: =ROUND(IF((AA10)*5%>6000000,6000000,(AA10)*5%),0) -> 2745249 | AC10: =('ASTEK+PENSIUN-DIISI SMPAI DES'!O99+'ASTEK+PENSIUN-DIISI SMPAI DES'!O13) -> 1404561 | AD10: =AA10-AB10-AC10 -> 50755174 | AE10: =IFERROR(VLOOKUP(I10,TARIF,3,FALSE),0) -> 54000000 | AF10: =ROUNDDOWN(IF(AD10<=AE10,0,IF(AD10>AE10,AD10-AE10)),-3) -> 0 | AG10: =IF(AF10>5000000000,AF10*35%-306000000,IF(AF10>500000000,AF10*30%-56000000,IF(AF10>250000000,AF10*25%-31000000,IF(AF10>60000000,AF10*15%-6000000,AF10*5%)))) -> 0 | AH10: =ROUND(IF(E10=0,AG10*120%,AG10),0) -> 0 | AI10: =+'PAJAK JAN-NOV'!R7 -> 124548 | AJ10: =IF(AG10<=AI10,0,IF(AG10>AI10,AG10-AI10)) -> 0 | AK10: =+'PAJAK JAN-NOV'!B7 -> ASUNTI | AL10: =AI10-AH10 -> 124548
B11: 6 | C11: =+PERBULAN!B11 -> JONI | D11: 1906040406810003 | E11: 97.387.455.5-305.000 | F11: DSN CENDIL RT. 001 RW. 001 DESA CENDIL KEC. KELAPA KAMPIT | G11: KARY PERAWATAN | H11: L | I11: K/1 | J11: =IF(ISBLANK(I11),"",IF(OR(I11="TK/0",I11="TK/1",I11="K/0"),"TER A",IF(I11="K/3","TER C","TER B"))) -> TER B | K11: 1 | L11: 12 | M11: =30*129220 -> 3876600 | N11: 193500 | O11: 190241.04 | P11: 0 | Q11: =SUM(M11:P11) -> 4260341 | R11: =+SETAHUN!H12 -> 4066600 | S11: =+SETAHUN!K12 -> 600000 | T11: 0 | U11: =+SETAHUN!F12+M11+N11 -> 48949417 | V11: 0 | W11: =+SETAHUN!U12+O11 -> 2279330.9 | X11: 0 | Y11: 0 | Z11: =SUM(R11:T11) -> 4666600 | AA11: =SUM(U11:Z11) -> 55895348 | AB11: =ROUND(IF((AA11)*5%>6000000,6000000,(AA11)*5%),0) -> 2794767 | AC11: =('ASTEK+PENSIUN-DIISI SMPAI DES'!O100+'ASTEK+PENSIUN-DIISI SMPAI DES'!O14) -> 1405296 | AD11: =AA11-AB11-AC11 -> 51695285 | AE11: =IFERROR(VLOOKUP(I11,TARIF,3,FALSE),0) -> 63000000 | AF11: =ROUNDDOWN(IF(AD11<=AE11,0,IF(AD11>AE11,AD11-AE11)),-3) -> 0 | AG11: =IF(AF11>5000000000,AF11*35%-306000000,IF(AF11>500000000,AF11*30%-56000000,IF(AF11>250000000,AF11*25%-31000000,IF(AF11>60000000,AF11*15%-6000000,AF11*5%)))) -> 0 | AH11: =ROUND(IF(E11=0,AG11*120%,AG11),0) -> 0 | AI11: =+'PAJAK JAN-NOV'!R8 -> 84567 | AJ11: =IF(AG11<=AI11,0,IF(AG11>AI11,AG11-AI11)) -> 0 | AK11: =+'PAJAK JAN-NOV'!B8 -> JONI | AL11: =AI11-AH11 -> 84567
B12: 7 | C12: =+PERBULAN!B12 -> THAHA.S | D12: 1906040903840002 | E12: 97.387.456.3-305.000 | F12: DSN CENDIL RT. 003 RW. 001 DESA CENDIL KEC. KELAPA KAMPIT | G12: KARY PERAWATAN | H12: L | I12: K/1 | J12: =IF(ISBLANK(I12),"",IF(OR(I12="TK/0",I12="TK/1",I12="K/0"),"TER A",IF(I12="K/3","TER C","TER B"))) -> TER B | K12: 1 | L12: 12 | M12: =31*129220 -> 4005820 | N12: 198150 | O12: 190241.04 | P12: 0 | Q12: =SUM(M12:P12) -> 4394211 | R12: =+SETAHUN!H13 -> 4066600 | S12: =+SETAHUN!K13 -> 200000 | T12: 0 | U12: =+SETAHUN!F13+M12+N12 -> 49484897 | V12: 0 | W12: =+SETAHUN!U13+O12 -> 2279330.9 | X12: 0 | Y12: 0 | Z12: =SUM(R12:T12) -> 4266600 | AA12: =SUM(U12:Z12) -> 56030828 | AB12: =ROUND(IF((AA12)*5%>6000000,6000000,(AA12)*5%),0) -> 2801541 | AC12: =('ASTEK+PENSIUN-DIISI SMPAI DES'!O101+'ASTEK+PENSIUN-DIISI SMPAI DES'!O15) -> 1405296 | AD12: =AA12-AB12-AC12 -> 51823991 | AE12: =IFERROR(VLOOKUP(I12,TARIF,3,FALSE),0) -> 63000000 | AF12: =ROUNDDOWN(IF(AD12<=AE12,0,IF(AD12>AE12,AD12-AE12)),-3) -> 0 | AG12: =IF(AF12>5000000000,AF12*35%-306000000,IF(AF12>500000000,AF12*30%-56000000,IF(AF12>250000000,AF12*25%-31000000,IF(AF12>60000000,AF12*15%-6000000,AF12*5%)))) -> 0 | AH12: =ROUND(IF(E12=0,AG12*120%,AG12),0) -> 0 | AI12: =+'PAJAK JAN-NOV'!R9 -> 84567 | AJ12: =IF(AG12<=AI12,0,IF(AG12>AI12,AG12-AI12)) -> 0 | AK12: =+'PAJAK JAN-NOV'!B9 -> THAHA.S | AL12: =AI12-AH12 -> 84567
B13: 8 | C13: =+PERBULAN!B13 -> ALEX | D13: 1902040407910001 | E13: 66.907.949.3-305.000 | F13: JL AIR SERKUK RT. 029 RW. 012 DESA AIR SAGA KEC. TANJUNGPANDAN | G13: KARY PERAWATAN | H13: L | I13: K/2 | J13: =IF(ISBLANK(I13),"",IF(OR(I13="TK/0",I13="TK/1",I13="K/0"),"TER A",IF(I13="K/3","TER C","TER B"))) -> TER B | K13: 1 | L13: 12 | M13: =30*129220 -> 3876600 | N13: 199500 | O13: 189224.64 | P13: 0 | Q13: =SUM(M13:P13) -> 4265324.6 | R13: =+SETAHUN!H14 -> 4073100 | S13: =+SETAHUN!K14 -> 200000 | T13: 0 | U13: =+SETAHUN!F14+M13+N13 -> 48749778 | V13: 0 | W13: =+SETAHUN!U14+O13 -> 2268022.1 | X13: 0 | Y13: 0 | Z13: =SUM(R13:T13) -> 4273100 | AA13: =SUM(U13:Z13) -> 55290900 | AB13: =ROUND(IF((AA13)*5%>6000000,6000000,(AA13)*5%),0) -> 2764545 | AC13: =('ASTEK+PENSIUN-DIISI SMPAI DES'!O102+'ASTEK+PENSIUN-DIISI SMPAI DES'!O16) -> 1401336 | AD13: =AA13-AB13-AC13 -> 51125019 | AE13: =IFERROR(VLOOKUP(I13,TARIF,3,FALSE),0) -> 67500000 | AF13: =ROUNDDOWN(IF(AD13<=AE13,0,IF(AD13>AE13,AD13-AE13)),-3) -> 0 | AG13: =IF(AF13>5000000000,AF13*35%-306000000,IF(AF13>500000000,AF13*30%-56000000,IF(AF13>250000000,AF13*25%-31000000,IF(AF13>60000000,AF13*15%-6000000,AF13*5%)))) -> 0 | AH13: =ROUND(IF(E13=0,AG13*120%,AG13),0) -> 0 | AI13: =+'PAJAK JAN-NOV'!R10 -> 84698 | AJ13: =IF(AG13<=AI13,0,IF(AG13>AI13,AG13-AI13)) -> 0 | AK13: =+'PAJAK JAN-NOV'!B10 -> ALEX | AL13: =AI13-AH13 -> 84698
B14: 9 | C14: =+PERBULAN!B14 -> SANDY | D14: 1902041602890001 | E14: 66.907.964.2-305.000 | F14: JL SIJUK RT. 022 RW. 008 DESA AIR SERUK KEC. SIJUK | G14: KARY PERAWATAN | H14: L | I14: K/1 | J14: =IF(ISBLANK(I14),"",IF(OR(I14="TK/0",I14="TK/1",I14="K/0"),"TER A",IF(I14="K/3","TER C","TER B"))) -> TER B | K14: 1 | L14: 12 | M14: =28*129220 -> 3618160 | N14: 163200 | O14: 189224.64 | P14: 0 | Q14: =SUM(M14:P14) -> 3970584.6 | R14: =+SETAHUN!H15 -> 4046100 | S14: =+SETAHUN!K15 -> 200000 | T14: 0 | U14: =+SETAHUN!F15+M14+N14 -> 48158938 | V14: 0 | W14: =+SETAHUN!U15+O14 -> 2268022.1 | X14: 0 | Y14: 0 | Z14: =SUM(R14:T14) -> 4246100 | AA14: =SUM(U14:Z14) -> 54673060 | AB14: =ROUND(IF((AA14)*5%>6000000,6000000,(AA14)*5%),0) -> 2733653 | AC14: =('ASTEK+PENSIUN-DIISI SMPAI DES'!O103+'ASTEK+PENSIUN-DIISI SMPAI DES'!O17) -> 1401336 | AD14: =AA14-AB14-AC14 -> 50538071 | AE14: =IFERROR(VLOOKUP(I14,TARIF,3,FALSE),0) -> 63000000 | AF14: =ROUNDDOWN(IF(AD14<=AE14,0,IF(AD14>AE14,AD14-AE14)),-3) -> 0 | AG14: =IF(AF14>5000000000,AF14*35%-306000000,IF(AF14>500000000,AF14*30%-56000000,IF(AF14>250000000,AF14*25%-31000000,IF(AF14>60000000,AF14*15%-6000000,AF14*5%)))) -> 0 | AH14: =ROUND(IF(E14=0,AG14*120%,AG14),0) -> 0 | AI14: =+'PAJAK JAN-NOV'!R11 -> 84149 | AJ14: =IF(AG14<=AI14,0,IF(AG14>AI14,AG14-AI14)) -> 0 | AK14: =+'PAJAK JAN-NOV'!B11 -> SANDY | AL14: =AI14-AH14 -> 84149
B15: 10 | C15: =+PERBULAN!B15 -> ANTON | D15: 1906042004880003 | E15: 97.228.589.4-305.000 | F15: DSN CENDIL RT. 004 RW. 002 DESA CENDIL KEC. KELAPA KAMPIT | G15: KARY PERAWATAN | H15: L | I15: K/1 | J15: =IF(ISBLANK(I15),"",IF(OR(I15="TK/0",I15="TK/1",I15="K/0"),"TER A",IF(I15="K/3","TER C","TER B"))) -> TER B | K15: 1 | L15: 12 | M15: =30*129220 -> 3876600 | N15: 193500 | O15: 190241.04 | P15: 0 | Q15: =SUM(M15:P15) -> 4260341 | R15: =+SETAHUN!H16 -> 4066600 | S15: =+SETAHUN!K16 -> 200000 | T15: 0 | U15: =+SETAHUN!F16+M15+N15 -> 49083287 | V15: 0 | W15: =+SETAHUN!U16+O15 -> 2279330.9 | X15: 0 | Y15: 0 | Z15: =SUM(R15:T15) -> 4266600 | AA15: =SUM(U15:Z15) -> 55629218 | AB15: =ROUND(IF((AA15)*5%>6000000,6000000,(AA15)*5%),0) -> 2781461 | AC15: =('ASTEK+PENSIUN-DIISI SMPAI DES'!O104+'ASTEK+PENSIUN-DIISI SMPAI DES'!O18) -> 1405296 | AD15: =AA15-AB15-AC15 -> 51442461 | AE15: =IFERROR(VLOOKUP(I15,TARIF,3,FALSE),0) -> 63000000 | AF15: =ROUNDDOWN(IF(AD15<=AE15,0,IF(AD15>AE15,AD15-AE15)),-3) -> 0 | AG15: =IF(AF15>5000000000,AF15*35%-306000000,IF(AF15>500000000,AF15*30%-56000000,IF(AF15>250000000,AF15*25%-31000000,IF(AF15>60000000,AF15*15%-6000000,AF15*5%)))) -> 0 | AH15: =ROUND(IF(E15=0,AG15*120%,AG15),0) -> 0 | AI15: =+'PAJAK JAN-NOV'!R12 -> 84567 | AJ15: =IF(AG15<=AI15,0,IF(AG15>AI15,AG15-AI15)) -> 0 | AK15: =+'PAJAK JAN-NOV'!B12 -> ANTON | AL15: =AI15-AH15 -> 84567
B16: 11 | C16: =+PERBULAN!B16 -> EKA NOPIYANTI | D16: 1906045111850004 | E16: 97.228.554.8.305.000 | F16: DSN SELINDANG RT. 005 RW. 002 DESA SENYUBUK KEC. KELAPA KAMPIT | G16: KARY PERAWATAN | H16: P | I16: TK/0 | J16: =IF(ISBLANK(I16),"",IF(OR(I16="TK/0",I16="TK/1",I16="K/0"),"TER A",IF(I16="K/3","TER C","TER B"))) -> TER A | K16: 1 | L16: 12 | M16: =31*129220 -> 4005820 | N16: 180700 | O16: 190071.64 | P16: 0 | Q16: =SUM(M16:P16) -> 4376591.6 | R16: =+SETAHUN!H17 -> 3991100 | S16: =+SETAHUN!K17 -> 600000 | T16: 0 | U16: =+SETAHUN!F17+M16+N16 -> 48974379 | V16: 0 | W16: =+SETAHUN!U17+O16 -> 2277474.5 | X16: 0 | Y16: 0 | Z16: =SUM(R16:T16) -> 4591100 | AA16: =SUM(U16:Z16) -> 55842954 | AB16: =ROUND(IF((AA16)*5%>6000000,6000000,(AA16)*5%),0) -> 2792148 | AC16: =('ASTEK+PENSIUN-DIISI SMPAI DES'!O105+'ASTEK+PENSIUN-DIISI SMPAI DES'!O19) -> 1404666 | AD16: =AA16-AB16-AC16 -> 51646140 | AE16: =IFERROR(VLOOKUP(I16,TARIF,3,FALSE),0) -> 54000000 | AF16: =ROUNDDOWN(IF(AD16<=AE16,0,IF(AD16>AE16,AD16-AE16)),-3) -> 0 | AG16: =IF(AF16>5000000000,AF16*35%-306000000,IF(AF16>500000000,AF16*30%-56000000,IF(AF16>250000000,AF16*25%-31000000,IF(AF16>60000000,AF16*15%-6000000,AF16*5%)))) -> 0 | AH16: =ROUND(IF(E16=0,AG16*120%,AG16),0) -> 0 | AI16: =+'PAJAK JAN-NOV'!R13 -> 124548 | AJ16: =IF(AG16<=AI16,0,IF(AG16>AI16,AG16-AI16)) -> 0 | AK16: =+'PAJAK JAN-NOV'!B13 -> EKA NOPIYANTI | AL16: =AI16-AH16 -> 124548
B17: 12 | C17: =+PERBULAN!B17 -> JUMIATI | D17: 1902054212790002 | E17: 84.484.558.6-305.000 | F17: JL MANGGAR DSN PARIT GUNUNG RT. 006 RW. 003 DS AIR BATU BUDING BADAU | G17: KARY PERAWATAN | H17: P | I17: TK/0 | J17: =IF(ISBLANK(I17),"",IF(OR(I17="TK/0",I17="TK/1",I17="K/0"),"TER A",IF(I17="K/3","TER C","TER B"))) -> TER A | K17: 1 | L17: 12 | M17: =31*129220 -> 4005820 | N17: 123750 | O17: 190241.04 | P17: 0 | Q17: =SUM(M17:P17) -> 4319811 | R17: =+SETAHUN!H18 -> 3994600 | S17: =+SETAHUN!K18 -> 600000 | T17: 0 | U17: =+SETAHUN!F18+M17+N17 -> 48613547 | V17: 0 | W17: =+SETAHUN!U18+O17 -> 2279330.9 | X17: 0 | Y17: 0 | Z17: =SUM(R17:T17) -> 4594600 | AA17: =SUM(U17:Z17) -> 55487478 | AB17: =ROUND(IF((AA17)*5%>6000000,6000000,(AA17)*5%),0) -> 2774374 | AC17: =('ASTEK+PENSIUN-DIISI SMPAI DES'!O106+'ASTEK+PENSIUN-DIISI SMPAI DES'!O20) -> 1405296 | AD17: =AA17-AB17-AC17 -> 51307808 | AE17: =IFERROR(VLOOKUP(I17,TARIF,3,FALSE),0) -> 54000000 | AF17: =ROUNDDOWN(IF(AD17<=AE17,0,IF(AD17>AE17,AD17-AE17)),-3) -> 0 | AG17: =IF(AF17>5000000000,AF17*35%-306000000,IF(AF17>500000000,AF17*30%-56000000,IF(AF17>250000000,AF17*25%-31000000,IF(AF17>60000000,AF17*15%-6000000,AF17*5%)))) -> 0 | AH17: =ROUND(IF(E17=0,AG17*120%,AG17),0) -> 0 | AI17: =+'PAJAK JAN-NOV'!R14 -> 124655 | AJ17: =IF(AG17<=AI17,0,IF(AG17>AI17,AG17-AI17)) -> 0 | AK17: =+'PAJAK JAN-NOV'!B14 -> JUMIATI | AL17: =AI17-AH17 -> 124655
B18: 13 | C18: =+PERBULAN!B18 -> SUPARDI | D18: 1906042707890002 | E18: 54.921.755.2-305.000 | F18: DSN BUKIT DURIAN RW. 003 RW. 002 DESA MENTAWAK KEC. KELAPA KAMPIT | G18: KARY PERAWATAN | H18: L | I18: K/2 | J18: =IF(ISBLANK(I18),"",IF(OR(I18="TK/0",I18="TK/1",I18="K/0"),"TER A",IF(I18="K/3","TER C","TER B"))) -> TER B | K18: 1 | L18: 12 | M18: =28*129220 -> 3618160 | N18: 188400 | O18: 189224.64 | P18: 0 | Q18: =SUM(M18:P18) -> 3995784.6 | R18: =+SETAHUN!H19 -> 4076100 | S18: =+SETAHUN!K19 -> 600000 | T18: 0 | U18: =+SETAHUN!F19+M18+N18 -> 49883945 | V18: 0 | W18: =+SETAHUN!U19+O18 -> 2269032.5 | X18: 0 | Y18: 0 | Z18: =SUM(R18:T18) -> 4676100 | AA18: =SUM(U18:Z18) -> 56829078 | AB18: =ROUND(IF((AA18)*5%>6000000,6000000,(AA18)*5%),0) -> 2841454 | AC18: =('ASTEK+PENSIUN-DIISI SMPAI DES'!O107+'ASTEK+PENSIUN-DIISI SMPAI DES'!O21) -> 1401516 | AD18: =AA18-AB18-AC18 -> 52586108 | AE18: =IFERROR(VLOOKUP(I18,TARIF,3,FALSE),0) -> 67500000 | AF18: =ROUNDDOWN(IF(AD18<=AE18,0,IF(AD18>AE18,AD18-AE18)),-3) -> 0 | AG18: =IF(AF18>5000000000,AF18*35%-306000000,IF(AF18>500000000,AF18*30%-56000000,IF(AF18>250000000,AF18*25%-31000000,IF(AF18>60000000,AF18*15%-6000000,AF18*5%)))) -> 0 | AH18: =ROUND(IF(E18=0,AG18*120%,AG18),0) -> 0 | AI18: =+'PAJAK JAN-NOV'!R15 -> 86328 | AJ18: =IF(AG18<=AI18,0,IF(AG18>AI18,AG18-AI18)) -> 0 | AK18: =+'PAJAK JAN-NOV'!B15 -> SUPARDI | AL18: =AI18-AH18 -> 86328
B19: 14 | C19: =+PERBULAN!B19 -> PARDI | D19: 1906041404700001 | E19: 97.228.536.5-305.000 | F19: DSN CENDIL RT. 005 RW. 002 DESA CENDIL KEC. KELAPA KAMPIT | G19: KARY PERAWATAN | H19: L | I19: K/1 | J19: =IF(ISBLANK(I19),"",IF(OR(I19="TK/0",I19="TK/1",I19="K/0"),"TER A",IF(I19="K/3","TER C","TER B"))) -> TER B | K19: 1 | L19: 4 | P19: 0 | Q19: =SUM(M19:P19) -> 0 | R19: =+SETAHUN!H20 -> 4101600 | S19: =+SETAHUN!K20 -> 0 | T19: 0 | U19: =+SETAHUN!F20+M19+N19 -> 13967588 | V19: 0 | W19: =+SETAHUN!U20+O19 -> 763209.76 | X19: 0 | Y19: 0 | Z19: =SUM(R19:T19) -> 4101600 | AA19: =SUM(U19:Z19) -> 18832398 | AB19: =ROUND(IF((AA19)*5%>6000000,6000000,(AA19)*5%),0) -> 941620 | AC19: =('ASTEK+PENSIUN-DIISI SMPAI DES'!O108+'ASTEK+PENSIUN-DIISI SMPAI DES'!O22) -> 465192 | AD19: =AA19-AB19-AC19 -> 17425586 | AE19: =IFERROR(VLOOKUP(I19,TARIF,3,FALSE),0) -> 63000000 | AF19: =ROUNDDOWN(IF(AD19<=AE19,0,IF(AD19>AE19,AD19-AE19)),-3) -> 0 | AG19: =IF(AF19>5000000000,AF19*35%-306000000,IF(AF19>500000000,AF19*30%-56000000,IF(AF19>250000000,AF19*25%-31000000,IF(AF19>60000000,AF19*15%-6000000,AF19*5%)))) -> 0 | AH19: =ROUND(IF(E19=0,AG19*120%,AG19),0) -> 0 | AI19: =+'PAJAK JAN-NOV'!R16 -> 85281 | AJ19: =IF(AG19<=AI19,0,IF(AG19>AI19,AG19-AI19)) -> 0 | AK19: =+'PAJAK JAN-NOV'!B16 -> PARDI | AL19: =AI19-AH19 -> 85281
B20: 15 | C20: =+PERBULAN!B20 -> SUMARDI | D20: 1906040306730003 | E20: 97.387.452.2-305.000 | F20: DSN CENDIL RT. 001 RW. 001 DESA CENDIL KEC. KELAPA KAMPIT | G20: KARY PERAWATAN | H20: L | I20: K/2 | J20: =IF(ISBLANK(I20),"",IF(OR(I20="TK/0",I20="TK/1",I20="K/0"),"TER A",IF(I20="K/3","TER C","TER B"))) -> TER B | K20: 1 | L20: 12 | M20: =31*129220 -> 4005820 | N20: 222550 | O20: 190071.64 | P20: 0 | Q20: =SUM(M20:P20) -> 4418441.6 | R20: =+SETAHUN!H21 -> 4090100 | S20: =+SETAHUN!K21 -> 600000 | T20: 0 | U20: =+SETAHUN!F21+M20+N20 -> 49774899 | V20: 0 | W20: =+SETAHUN!U21+O20 -> 2277614.5 | X20: 0 | Y20: 0 | Z20: =SUM(R20:T20) -> 4690100 | AA20: =SUM(U20:Z20) -> 56742614 | AB20: =ROUND(IF((AA20)*5%>6000000,6000000,(AA20)*5%),0) -> 2837131 | AC20: =('ASTEK+PENSIUN-DIISI SMPAI DES'!O109+'ASTEK+PENSIUN-DIISI SMPAI DES'!O23) -> 1404666 | AD20: =AA20-AB20-AC20 -> 52500817 | AE20: =IFERROR(VLOOKUP(I20,TARIF,3,FALSE),0) -> 67500000 | AF20: =ROUNDDOWN(IF(AD20<=AE20,0,IF(AD20>AE20,AD20-AE20)),-3) -> 0 | AG20: =IF(AF20>5000000000,AF20*35%-306000000,IF(AF20>500000000,AF20*30%-56000000,IF(AF20>250000000,AF20*25%-31000000,IF(AF20>60000000,AF20*15%-6000000,AF20*5%)))) -> 0 | AH20: =ROUND(IF(E20=0,AG20*120%,AG20),0) -> 0 | AI20: =+'PAJAK JAN-NOV'!R17 -> 85045 | AJ20: =IF(AG20<=AI20,0,IF(AG20>AI20,AG20-AI20)) -> 0 | AK20: =+'PAJAK JAN-NOV'!B17 -> SUMARDI | AL20: =AI20-AH20 -> 85045
B21: 16 | C21: =+PERBULAN!B21 -> WIDODO JP | D21: 1902041503800003 | E21: 97.237.824.4-305.000 | F21: DSN SUNGAI PADANG RT. 005 RW. 003 DESA SUNGAI PADANG KEC. SIJUK | G21: KARY PERAWATAN | H21: L | I21: TK/0 | J21: =IF(ISBLANK(I21),"",IF(OR(I21="TK/0",I21="TK/1",I21="K/0"),"TER A",IF(I21="K/3","TER C","TER B"))) -> TER A | K21: 1 | L21: 12 | M21: =31*129220 -> 4005820 | N21: 546003.74 | O21: 190071.64 | P21: 0 | Q21: =SUM(M21:P21) -> 4741895.4 | R21: =+SETAHUN!H22 -> 3991100 | S21: =+SETAHUN!K22 -> 600000 | T21: 0 | U21: =+SETAHUN!F22+M21+N21 -> 67584502 | V21: 0 | W21: =+SETAHUN!U22+O21 -> 2277614.5 | X21: 0 | Y21: 0 | Z21: =SUM(R21:T21) -> 4591100 | AA21: =SUM(U21:Z21) -> 74453216 | AB21: =ROUND(IF((AA21)*5%>6000000,6000000,(AA21)*5%),0) -> 3722661 | AC21: =('ASTEK+PENSIUN-DIISI SMPAI DES'!O110+'ASTEK+PENSIUN-DIISI SMPAI DES'!O24) -> 1404666 | AD21: =AA21-AB21-AC21 -> 69325889 | AE21: =IFERROR(VLOOKUP(I21,TARIF,3,FALSE),0) -> 54000000 | AF21: =ROUNDDOWN(IF(AD21<=AE21,0,IF(AD21>AE21,AD21-AE21)),-3) -> 15325000 | AG21: =IF(AF21>5000000000,AF21*35%-306000000,IF(AF21>500000000,AF21*30%-56000000,IF(AF21>250000000,AF21*25%-31000000,IF(AF21>60000000,AF21*15%-6000000,AF21*5%)))) -> 766250 | AH21: =ROUND(IF(E21=0,AG21*120%,AG21),0) -> 766250 | AI21: =+'PAJAK JAN-NOV'!R18 -> 619855 | AJ21: =IF(AG21<=AI21,0,IF(AG21>AI21,AG21-AI21)) -> 146395 | AK21: =+'PAJAK JAN-NOV'!B18 -> WIDODO JP | AL21: =AI21-AH21 -> -146395
B22: 17 | C22: =+PERBULAN!B22 -> ASBI ALGIFARI | D22: 1902040303980007 | E22: - | F22: JL SIJUK RT. 016 RW. 007 DESA AIR SELUMAR KEC. SIJUK | G22: KARY PERAWATAN | H22: L | I22: K/1 | J22: =IF(ISBLANK(I22),"",IF(OR(I22="TK/0",I22="TK/1",I22="K/0"),"TER A",IF(I22="K/3","TER C","TER B"))) -> TER B | K22: 1 | L22: 12 | M22: =28*129220 -> 3618160 | N22: 151200 | O22: 188643.84 | P22: 0 | Q22: =SUM(M22:P22) -> 3958003.8 | R22: =+SETAHUN!H23 -> 4034100 | S22: =+SETAHUN!K23 -> 200000 | T22: 0 | U22: =+SETAHUN!F23+M22+N22 -> 48534590 | V22: 0 | W22: =+SETAHUN!U23+O22 -> 2261947.7 | X22: 0 | Y22: 0 | Z22: =SUM(R22:T22) -> 4234100 | AA22: =SUM(U22:Z22) -> 55030638 | AB22: =ROUND(IF((AA22)*5%>6000000,6000000,(AA22)*5%),0) -> 2751532 | AC22: =('ASTEK+PENSIUN-DIISI SMPAI DES'!O111+'ASTEK+PENSIUN-DIISI SMPAI DES'!O25) -> 1399356 | AD22: =AA22-AB22-AC22 -> 50879750 | AE22: =IFERROR(VLOOKUP(I22,TARIF,3,FALSE),0) -> 63000000 | AF22: =ROUNDDOWN(IF(AD22<=AE22,0,IF(AD22>AE22,AD22-AE22)),-3) -> 0 | AG22: =IF(AF22>5000000000,AF22*35%-306000000,IF(AF22>500000000,AF22*30%-56000000,IF(AF22>250000000,AF22*25%-31000000,IF(AF22>60000000,AF22*15%-6000000,AF22*5%)))) -> 0 | AH22: =ROUND(IF(E22=0,AG22*120%,AG22),0) -> 0 | AI22: =+'PAJAK JAN-NOV'!R19 -> 84688 | AJ22: =IF(AG22<=AI22,0,IF(AG22>AI22,AG22-AI22)) -> 0 | AK22: =+'PAJAK JAN-NOV'!B19 -> ASBI ALGIFARI | AL22: =AI22-AH22 -> 84688
B23: 18 | C23: =+PERBULAN!B23 -> YANDI | D23: 1902050502910003 | E23: - | F23: PARANG BULUH RT. 015 RW. 007 DESA MEMBALONG KEC. MEMBALONG | G23: KARY PERAWATAN | H23: L | I23: K/0 | J23: =IF(ISBLANK(I23),"",IF(OR(I23="TK/0",I23="TK/1",I23="K/0"),"TER A",IF(I23="K/3","TER C","TER B"))) -> TER A | K23: 1 | L23: 12 | M23: =30*129220 -> 3876600 | N23: 144000 | O23: 189224.64 | P23: 0 | Q23: =SUM(M23:P23) -> 4209824.6 | R23: =+SETAHUN!H24 -> 4020600 | S23: =+SETAHUN!K24 -> 200000 | T23: 0 | U23: =+SETAHUN!F24+M23+N23 -> 48509939 | V23: 0 | W23: =+SETAHUN!U24+O23 -> 2269032.5 | X23: 0 | Y23: 0 | Z23: =SUM(R23:T23) -> 4220600 | AA23: =SUM(U23:Z23) -> 54999572 | AB23: =ROUND(IF((AA23)*5%>6000000,6000000,(AA23)*5%),0) -> 2749979 | AC23: =('ASTEK+PENSIUN-DIISI SMPAI DES'!O112+'ASTEK+PENSIUN-DIISI SMPAI DES'!O26) -> 1401516 | AD23: =AA23-AB23-AC23 -> 50848077 | AE23: =IFERROR(VLOOKUP(I23,TARIF,3,FALSE),0) -> 58500000 | AF23: =ROUNDDOWN(IF(AD23<=AE23,0,IF(AD23>AE23,AD23-AE23)),-3) -> 0 | AG23: =IF(AF23>5000000000,AF23*35%-306000000,IF(AF23>500000000,AF23*30%-56000000,IF(AF23>250000000,AF23*25%-31000000,IF(AF23>60000000,AF23*15%-6000000,AF23*5%)))) -> 0 | AH23: =ROUND(IF(E23=0,AG23*120%,AG23),0) -> 0 | AI23: =+'PAJAK JAN-NOV'!R20 -> 125446 | AJ23: =IF(AG23<=AI23,0,IF(AG23>AI23,AG23-AI23)) -> 0 | AK23: =+'PAJAK JAN-NOV'!B20 -> YANDI | AL23: =AI23-AH23 -> 125446
B24: 19 | C24: =+PERBULAN!B24 -> RIDHO AFRIZAL | D24: 1902040112910004 | E24: - | F24: JL SIJUK RT. 004 RW. 002 DESA AIR SERUK KEC. SIJUK | G24: KARY PERAWATAN | H24: L | I24: K/1 | J24: =IF(ISBLANK(I24),"",IF(OR(I24="TK/0",I24="TK/1",I24="K/0"),"TER A",IF(I24="K/3","TER C","TER B"))) -> TER B | K24: 1 | L24: 12 | M24: =31*129220 -> 4005820 | N24: 1810227 | O24: 189224.64 | P24: 0 | Q24: =SUM(M24:P24) -> 6005271.6 | R24: =+SETAHUN!H25 -> 4046100 | S24: =+SETAHUN!K25 -> 600000 | T24: 0 | U24: =+SETAHUN!F25+M24+N24 -> 67473969 | V24: 0 | W24: =+SETAHUN!U25+O24 -> 2268022.1 | X24: 0 | Y24: 0 | Z24: =SUM(R24:T24) -> 4646100 | AA24: =SUM(U24:Z24) -> 74388091 | AB24: =ROUND(IF((AA24)*5%>6000000,6000000,(AA24)*5%),0) -> 3719405 | AC24: =('ASTEK+PENSIUN-DIISI SMPAI DES'!O113+'ASTEK+PENSIUN-DIISI SMPAI DES'!O27) -> 1401336 | AD24: =AA24-AB24-AC24 -> 69267350 | AE24: =IFERROR(VLOOKUP(I24,TARIF,3,FALSE),0) -> 63000000 | AF24: =ROUNDDOWN(IF(AD24<=AE24,0,IF(AD24>AE24,AD24-AE24)),-3) -> 6267000 | AG24: =IF(AF24>5000000000,AF24*35%-306000000,IF(AF24>500000000,AF24*30%-56000000,IF(AF24>250000000,AF24*25%-31000000,IF(AF24>60000000,AF24*15%-6000000,AF24*5%)))) -> 313350 | AH24: =ROUND(IF(E24=0,AG24*120%,AG24),0) -> 313350 | AI24: =+'PAJAK JAN-NOV'!R21 -> 288231 | AJ24: =IF(AG24<=AI24,0,IF(AG24>AI24,AG24-AI24)) -> 25119 | AK24: =+'PAJAK JAN-NOV'!B21 -> RIDHO AFRIZAL | AL24: =AI24-AH24 -> -25119
B25: 20 | C25: =+PERBULAN!B25 -> APRIZAL | D25: 1902042708930002 | E25: - | F25: JL BUDING RT. 021 RW. 011 DESA PELEPAK PUTIH KEC. SIJUK | G25: KARY PERAWATAN | H25: L | I25: K/1 | J25: =IF(ISBLANK(I25),"",IF(OR(I25="TK/0",I25="TK/1",I25="K/0"),"TER A",IF(I25="K/3","TER C","TER B"))) -> TER B | K25: 1 | L25: 12 | M25: =31*129220 -> 4005820 | N25: 177150 | O25: 189224.64 | P25: 0 | Q25: =SUM(M25:P25) -> 4372194.6 | R25: =+SETAHUN!H26 -> 4046100 | S25: =+SETAHUN!K26 -> 600000 | T25: 0 | U25: =+SETAHUN!F26+M25+N25 -> 49386754 | V25: 0 | W25: =+SETAHUN!U26+O25 -> 2268022.1 | X25: 0 | Y25: 0 | Z25: =SUM(R25:T25) -> 4646100 | AA25: =SUM(U25:Z25) -> 56300876 | AB25: =ROUND(IF((AA25)*5%>6000000,6000000,(AA25)*5%),0) -> 2815044 | AC25: =('ASTEK+PENSIUN-DIISI SMPAI DES'!O114+'ASTEK+PENSIUN-DIISI SMPAI DES'!O28) -> 1401336 | AD25: =AA25-AB25-AC25 -> 52084496 | AE25: =IFERROR(VLOOKUP(I25,TARIF,3,FALSE),0) -> 63000000 | AF25: =ROUNDDOWN(IF(AD25<=AE25,0,IF(AD25>AE25,AD25-AE25)),-3) -> 0 | AG25: =IF(AF25>5000000000,AF25*35%-306000000,IF(AF25>500000000,AF25*30%-56000000,IF(AF25>250000000,AF25*25%-31000000,IF(AF25>60000000,AF25*15%-6000000,AF25*5%)))) -> 0 | AH25: =ROUND(IF(E25=0,AG25*120%,AG25),0) -> 0 | AI25: =+'PAJAK JAN-NOV'!R22 -> 84149 | AJ25: =IF(AG25<=AI25,0,IF(AG25>AI25,AG25-AI25)) -> 0 | AK25: =+'PAJAK JAN-NOV'!B22 -> APRIZAL | AL25: =AI25-AH25 -> 84149
B26: 21 | C26: =+PERBULAN!B26 -> ERRY SAPUTRA | D26: 1906041502890002 | E26: - | F26: DSN CENDIL RT. 005 RW. 002 DS CENDIL KEC. KELAPA KAMPIT | G26: KARY PERAWATAN | H26: L | I26: K/1 | J26: =IF(ISBLANK(I26),"",IF(OR(I26="TK/0",I26="TK/1",I26="K/0"),"TER A",IF(I26="K/3","TER C","TER B"))) -> TER B | K26: 1 | L26: 12 | M26: =30*129220 -> 3876600 | N26: 193500 | O26: 190241.04 | P26: 0 | Q26: =SUM(M26:P26) -> 4260341 | R26: =+SETAHUN!H27 -> 4066600 | S26: =+SETAHUN!K27 -> 600000 | T26: 0 | U26: =+SETAHUN!F27+M26+N26 -> 49065789 | V26: 0 | W26: =+SETAHUN!U27+O26 -> 2278483.9 | X26: 0 | Y26: 0 | Z26: =SUM(R26:T26) -> 4666600 | AA26: =SUM(U26:Z26) -> 56010873 | AB26: =ROUND(IF((AA26)*5%>6000000,6000000,(AA26)*5%),0) -> 2800544 | AC26: =('ASTEK+PENSIUN-DIISI SMPAI DES'!O115+'ASTEK+PENSIUN-DIISI SMPAI DES'!O29) -> 1404771 | AD26: =AA26-AB26-AC26 -> 51805558 | AE26: =IFERROR(VLOOKUP(I26,TARIF,3,FALSE),0) -> 63000000 | AF26: =ROUNDDOWN(IF(AD26<=AE26,0,IF(AD26>AE26,AD26-AE26)),-3) -> 0 | AG26: =IF(AF26>5000000000,AF26*35%-306000000,IF(AF26>500000000,AF26*30%-56000000,IF(AF26>250000000,AF26*25%-31000000,IF(AF26>60000000,AF26*15%-6000000,AF26*5%)))) -> 0 | AH26: =ROUND(IF(E26=0,AG26*120%,AG26),0) -> 0 | AI26: =+'PAJAK JAN-NOV'!R23 -> 84567 | AJ26: =IF(AG26<=AI26,0,IF(AG26>AI26,AG26-AI26)) -> 0 | AK26: =+'PAJAK JAN-NOV'!B23 -> ERRY SAPUTRA | AL26: =AI26-AH26 -> 84567
B27: 22 | C27: =+PERBULAN!B27 -> ARWANDI | D27: 1902050203790001 | E27: 97.228.565.4-305.000 | F27: JL MANGGAR RT. 008 RW. 003 DESA KACANG BUTOR KEC. BADAU | G27: OPERATOR | H27: L | I27: K/1 | J27: =IF(ISBLANK(I27),"",IF(OR(I27="TK/0",I27="TK/1",I27="K/0"),"TER A",IF(I27="K/3","TER C","TER B"))) -> TER B | K27: 1 | L27: 12 | M27: =31*129220 -> 4005820 | N27: 3229137.2 | O27: 192104.44 | P27: 0 | Q27: =SUM(M27:P27) -> 7427061.7 | R27: =+SETAHUN!H28 -> 4091600 | S27: =+SETAHUN!K28 -> 900000 | T27: 0 | U27: =+SETAHUN!F28+M27+N27 -> 94178256 | V27: 0 | W27: =+SETAHUN!U28+O27 -> 2299051.3 | X27: 0 | Y27: 0 | Z27: =SUM(R27:T27) -> 4991600 | AA27: =SUM(U27:Z27) -> 1.0146891e+08 | AB27: =ROUND(IF((AA27)*5%>6000000,6000000,(AA27)*5%),0) -> 5073445 | AC27: =('ASTEK+PENSIUN-DIISI SMPAI DES'!O116+'ASTEK+PENSIUN-DIISI SMPAI DES'!O30) -> 1412226 | AD27: =AA27-AB27-AC27 -> 94983237 | AE27: =IFERROR(VLOOKUP(I27,TARIF,3,FALSE),0) -> 63000000 | AF27: =ROUNDDOWN(IF(AD27<=AE27,0,IF(AD27>AE27,AD27-AE27)),-3) -> 31983000 | AG27: =IF(AF27>5000000000,AF27*35%-306000000,IF(AF27>500000000,AF27*30%-56000000,IF(AF27>250000000,AF27*25%-31000000,IF(AF27>60000000,AF27*15%-6000000,AF27*5%)))) -> 1599150 | AH27: =ROUND(IF(E27=0,AG27*120%,AG27),0) -> 1599150 | AI27: =+'PAJAK JAN-NOV'!R24 -> 1256040 | AJ27: =IF(AG27<=AI27,0,IF(AG27>AI27,AG27-AI27)) -> 343110 | AK27: =+'PAJAK JAN-NOV'!B24 -> ARWANDI | AL27: =AI27-AH27 -> -343110
B28: 23 | C28: =+PERBULAN!B28 -> RENDI PERJAYA | D28: 1902042302890003 | E28: 66.907.958.4-305.000 | F28: DSN CENDIL RT. 006 RW. 002 DESA CENDIL KEC. KELAPA KAMPIT | G28: HELPER | H28: L | I28: K/1 | J28: =IF(ISBLANK(I28),"",IF(OR(I28="TK/0",I28="TK/1",I28="K/0"),"TER A",IF(I28="K/3","TER C","TER B"))) -> TER B | K28: 1 | L28: 12 | M28: =31*129220 -> 4005820 | N28: 3274935.4 | O28: 189224.64 | P28: 0 | Q28: =SUM(M28:P28) -> 7469980.1 | R28: =+SETAHUN!H29 -> 4032600 | S28: =+SETAHUN!K29 -> 600000 | T28: 0 | U28: =+SETAHUN!F29+M28+N28 -> 89596834 | V28: 0 | W28: =+SETAHUN!U29+O28 -> 2268022.1 | X28: 0 | Y28: 0 | Z28: =SUM(R28:T28) -> 4632600 | AA28: =SUM(U28:Z28) -> 96497456 | AB28: =ROUND(IF((AA28)*5%>6000000,6000000,(AA28)*5%),0) -> 4824873 | AC28: =('ASTEK+PENSIUN-DIISI SMPAI DES'!O117+'ASTEK+PENSIUN-DIISI SMPAI DES'!O31) -> 1401336 | AD28: =AA28-AB28-AC28 -> 90271247 | AE28: =IFERROR(VLOOKUP(I28,TARIF,3,FALSE),0) -> 63000000 | AF28: =ROUNDDOWN(IF(AD28<=AE28,0,IF(AD28>AE28,AD28-AE28)),-3) -> 27271000 | AG28: =IF(AF28>5000000000,AF28*35%-306000000,IF(AF28>500000000,AF28*30%-56000000,IF(AF28>250000000,AF28*25%-31000000,IF(AF28>60000000,AF28*15%-6000000,AF28*5%)))) -> 1363550 | AH28: =ROUND(IF(E28=0,AG28*120%,AG28),0) -> 1363550 | AI28: =+'PAJAK JAN-NOV'!R25 -> 1074158 | AJ28: =IF(AG28<=AI28,0,IF(AG28>AI28,AG28-AI28)) -> 289392 | AK28: =+'PAJAK JAN-NOV'!B25 -> RENDI PERJAYA | AL28: =AI28-AH28 -> -289392
B29: 24 | C29: =+PERBULAN!B29 -> ANDI | D29: 1906041805780002 | E29: 97.228.598.5-305.000 | F29: DSN PESARAKAN RT. 008 RW. 003 DESA CENDIL KEC. KELAPA KAMPIT | G29: OPERATOR | H29: L | I29: K/1 | J29: =IF(ISBLANK(I29),"",IF(OR(I29="TK/0",I29="TK/1",I29="K/0"),"TER A",IF(I29="K/3","TER C","TER B"))) -> TER B | K29: 1 | L29: 12 | M29: =31*129220 -> 4005820 | N29: 3167221.2 | O29: 191935.04 | P29: 0 | Q29: =SUM(M29:P29) -> 7364976.2 | R29: =+SETAHUN!H30 -> 4101600 | S29: =+SETAHUN!K30 -> 900000 | T29: 0 | U29: =+SETAHUN!F30+M29+N29 -> 86782226 | V29: 0 | W29: =+SETAHUN!U30+O29 -> 2297054.9 | X29: 0 | Y29: 0 | Z29: =SUM(R29:T29) -> 5001600 | AA29: =SUM(U29:Z29) -> 94080881 | AB29: =ROUND(IF((AA29)*5%>6000000,6000000,(AA29)*5%),0) -> 4704044 | AC29: =('ASTEK+PENSIUN-DIISI SMPAI DES'!O118+'ASTEK+PENSIUN-DIISI SMPAI DES'!O32) -> 1411596 | AD29: =AA29-AB29-AC29 -> 87965241 | AE29: =IFERROR(VLOOKUP(I29,TARIF,3,FALSE),0) -> 63000000 | AF29: =ROUNDDOWN(IF(AD29<=AE29,0,IF(AD29>AE29,AD29-AE29)),-3) -> 24965000 | AG29: =IF(AF29>5000000000,AF29*35%-306000000,IF(AF29>500000000,AF29*30%-56000000,IF(AF29>250000000,AF29*25%-31000000,IF(AF29>60000000,AF29*15%-6000000,AF29*5%)))) -> 1248250 | AH29: =ROUND(IF(E29=0,AG29*120%,AG29),0) -> 1248250 | AI29: =+'PAJAK JAN-NOV'!R26 -> 975428 | AJ29: =IF(AG29<=AI29,0,IF(AG29>AI29,AG29-AI29)) -> 272822 | AK29: =+'PAJAK JAN-NOV'!B26 -> ANDI | AL29: =AI29-AH29 -> -272822
B30: 25 | C30: =+PERBULAN!B30 -> JULI | D30: 1902051805780002 | E30: 97.228.607.4-305.000 | F30: JL MANGGAR RT. 009 RW. 003 DESA KACANG BUTOR KEC. BADAU | G30: HELPER | H30: L | I30: K/2 | J30: =IF(ISBLANK(I30),"",IF(OR(I30="TK/0",I30="TK/1",I30="K/0"),"TER A",IF(I30="K/3","TER C","TER B"))) -> TER B | K30: 1 | L30: 12 | M30: =31*129220 -> 4005820 | N30: 3320969 | O30: 192104.44 | P30: 0 | Q30: =SUM(M30:P30) -> 7518893.4 | R30: =+SETAHUN!H31 -> 4135600 | S30: =+SETAHUN!K31 -> 900000 | T30: 0 | U30: =+SETAHUN!F31+M30+N30 -> 88243416 | V30: 0 | W30: =+SETAHUN!U31+O30 -> 2299331.3 | X30: 0 | Y30: 0 | Z30: =SUM(R30:T30) -> 5035600 | AA30: =SUM(U30:Z30) -> 95578347 | AB30: =ROUND(IF((AA30)*5%>6000000,6000000,(AA30)*5%),0) -> 4778917 | AC30: =('ASTEK+PENSIUN-DIISI SMPAI DES'!O119+'ASTEK+PENSIUN-DIISI SMPAI DES'!O33) -> 1412226 | AD30: =AA30-AB30-AC30 -> 89387204 | AE30: =IFERROR(VLOOKUP(I30,TARIF,3,FALSE),0) -> 67500000 | AF30: =ROUNDDOWN(IF(AD30<=AE30,0,IF(AD30>AE30,AD30-AE30)),-3) -> 21887000 | AG30: =IF(AF30>5000000000,AF30*35%-306000000,IF(AF30>500000000,AF30*30%-56000000,IF(AF30>250000000,AF30*25%-31000000,IF(AF30>60000000,AF30*15%-6000000,AF30*5%)))) -> 1094350 | AH30: =ROUND(IF(E30=0,AG30*120%,AG30),0) -> 1094350 | AI30: =+'PAJAK JAN-NOV'!R27 -> 1059558 | AJ30: =IF(AG30<=AI30,0,IF(AG30>AI30,AG30-AI30)) -> 34792 | AK30: =+'PAJAK JAN-NOV'!B27 -> JULI | AL30: =AI30-AH30 -> -34792
B31: 26 | C31: =+PERBULAN!B31 -> DICKY PRATAMA | D31: 1902043110000001 | E31: - | F31: PELEPAK PUTE RT.003/002 DESA PELEPAK PUTE KEC. SIJUK KAB. BELITUNG | G31: KRANI PANEN | H31: L | I31: K/0 | J31: =IF(ISBLANK(I31),"",IF(OR(I31="TK/0",I31="TK/1",I31="K/0"),"TER A",IF(I31="K/3","TER C","TER B"))) -> TER A | K31: 1 | L31: 12 | M31: =31*129220 -> 4005820 | N31: 986085 | O31: 187869.44 | P31: 0 | Q31: =SUM(M31:P31) -> 5179774.4 | R31: =+SETAHUN!H32 -> 3990100 | S31: =+SETAHUN!K32 -> 200000 | T31: 0 | U31: =+SETAHUN!F32+M31+N31 -> 68136916 | V31: 0 | W31: =+SETAHUN!U32+O31 -> 2253881.3 | X31: 0 | Y31: 0 | Z31: =SUM(R31:T31) -> 4190100 | AA31: =SUM(U31:Z31) -> 74580897 | AB31: =ROUND(IF((AA31)*5%>6000000,6000000,(AA31)*5%),0) -> 3729045 | AC31: =('ASTEK+PENSIUN-DIISI SMPAI DES'!O120+'ASTEK+PENSIUN-DIISI SMPAI DES'!O34) -> 1396476 | AD31: =AA31-AB31-AC31 -> 69455376 | AE31: =IFERROR(VLOOKUP(I31,TARIF,3,FALSE),0) -> 58500000 | AF31: =ROUNDDOWN(IF(AD31<=AE31,0,IF(AD31>AE31,AD31-AE31)),-3) -> 10955000 | AG31: =IF(AF31>5000000000,AF31*35%-306000000,IF(AF31>500000000,AF31*30%-56000000,IF(AF31>250000000,AF31*25%-31000000,IF(AF31>60000000,AF31*15%-6000000,AF31*5%)))) -> 547750 | AH31: =ROUND(IF(E31=0,AG31*120%,AG31),0) -> 547750 | AI31: =+'PAJAK JAN-NOV'!R28 -> 540900 | AJ31: =IF(AG31<=AI31,0,IF(AG31>AI31,AG31-AI31)) -> 6850 | AK31: =+'PAJAK JAN-NOV'!B28 -> DICKY PRATAMA | AL31: =AI31-AH31 -> -6850
B32: 27 | C32: =+PERBULAN!B32 -> SUIP | D32: 1902040107800096 | E32: - | F32: AIR KALA RT. 023 RW. 012 DESA SIJUK KEC. SIJUK | G32: PEMANEN | H32: L | I32: K/1 | J32: =IF(ISBLANK(I32),"",IF(OR(I32="TK/0",I32="TK/1",I32="K/0"),"TER A",IF(I32="K/3","TER C","TER B"))) -> TER B | K32: 1 | L32: 12 | M32: =30*129220 -> 3876600 | N32: 609048.18 | O32: 188789.04 | P32: 0 | Q32: =SUM(M32:P32) -> 4674437.2 | R32: =+SETAHUN!H33 -> 4037100 | S32: =+SETAHUN!K33 -> 900000 | T32: 0 | U32: =+SETAHUN!F33+M32+N32 -> 57389357 | V32: 0 | W32: =+SETAHUN!U33+O32 -> 2262958.1 | X32: 0 | Y32: 0 | Z32: =SUM(R32:T32) -> 4937100 | AA32: =SUM(U32:Z32) -> 64589415 | AB32: =ROUND(IF((AA32)*5%>6000000,6000000,(AA32)*5%),0) -> 3229471 | AC32: =('ASTEK+PENSIUN-DIISI SMPAI DES'!O121+'ASTEK+PENSIUN-DIISI SMPAI DES'!O35) -> 1399536 | AD32: =AA32-AB32-AC32 -> 59960408 | AE32: =IFERROR(VLOOKUP(I32,TARIF,3,FALSE),0) -> 63000000 | AF32: =ROUNDDOWN(IF(AD32<=AE32,0,IF(AD32>AE32,AD32-AE32)),-3) -> 0 | AG32: =IF(AF32>5000000000,AF32*35%-306000000,IF(AF32>500000000,AF32*30%-56000000,IF(AF32>250000000,AF32*25%-31000000,IF(AF32>60000000,AF32*15%-6000000,AF32*5%)))) -> 0 | AH32: =ROUND(IF(E32=0,AG32*120%,AG32),0) -> 0 | AI32: =+'PAJAK JAN-NOV'!R29 -> 142479 | AJ32: =IF(AG32<=AI32,0,IF(AG32>AI32,AG32-AI32)) -> 0 | AK32: =+'PAJAK JAN-NOV'!B29 -> SUIP | AL32: =AI32-AH32 -> 142479
B33: 28 | C33: =+PERBULAN!B33 -> ROBIN DINATA | D33: 1902042012900001 | E33: - | F33: JL BUDING AIK KALAK RT. 023 RW. 012 DESA SIJUK KEC. SIJUK | G33: PEMANEN | H33: L | I33: K/2 | J33: =IF(ISBLANK(I33),"",IF(OR(I33="TK/0",I33="TK/1",I33="K/0"),"TER A",IF(I33="K/3","TER C","TER B"))) -> TER B | K33: 1 | L33: 12 | M33: =31*129220 -> 4005820 | N33: 568147.56 | O33: 188789.04 | P33: 0 | Q33: =SUM(M33:P33) -> 4762756.6 | R33: =+SETAHUN!H34 -> 4064100 | S33: =+SETAHUN!K34 -> 900000 | T33: 0 | U33: =+SETAHUN!F34+M33+N33 -> 60296919 | V33: 0 | W33: =+SETAHUN!U34+O33 -> 2262958.1 | X33: 0 | Y33: 0 | Z33: =SUM(R33:T33) -> 4964100 | AA33: =SUM(U33:Z33) -> 67523977 | AB33: =ROUND(IF((AA33)*5%>6000000,6000000,(AA33)*5%),0) -> 3376199 | AC33: =('ASTEK+PENSIUN-DIISI SMPAI DES'!O122+'ASTEK+PENSIUN-DIISI SMPAI DES'!O36) -> 1399536 | AD33: =AA33-AB33-AC33 -> 62748242 | AE33: =IFERROR(VLOOKUP(I33,TARIF,3,FALSE),0) -> 67500000 | AF33: =ROUNDDOWN(IF(AD33<=AE33,0,IF(AD33>AE33,AD33-AE33)),-3) -> 0 | AG33: =IF(AF33>5000000000,AF33*35%-306000000,IF(AF33>500000000,AF33*30%-56000000,IF(AF33>250000000,AF33*25%-31000000,IF(AF33>60000000,AF33*15%-6000000,AF33*5%)))) -> 0 | AH33: =ROUND(IF(E33=0,AG33*120%,AG33),0) -> 0 | AI33: =+'PAJAK JAN-NOV'!R30 -> 178300 | AJ33: =IF(AG33<=AI33,0,IF(AG33>AI33,AG33-AI33)) -> 0 | AK33: =+'PAJAK JAN-NOV'!B30 -> ROBIN DINATA | AL33: =AI33-AH33 -> 178300
B34: 29 | C34: =+PERBULAN!B34 -> SAPARUDIN | D34: 1902040501800001 | E34: - | F34: PELEPAK PUTE RT. 003 RW. 002 DESA PELEPAK PUTE KEC. SIJUK | G34: PEMANEN | H34: L | I34: K/2 | J34: =IF(ISBLANK(I34),"",IF(OR(I34="TK/0",I34="TK/1",I34="K/0"),"TER A",IF(I34="K/3","TER C","TER B"))) -> TER B | K34: 1 | L34: 12 | M34: =31*129220 -> 4005820 | N34: 991017.68 | O34: 188643.84 | P34: 0 | Q34: =SUM(M34:P34) -> 5185481.5 | R34: =+SETAHUN!H35 -> 4061100 | S34: =+SETAHUN!K35 -> 200000 | T34: 0 | U34: =+SETAHUN!F35+M34+N34 -> 61322460 | V34: 0 | W34: =+SETAHUN!U35+O34 -> 2262067.7 | X34: 0 | Y34: 0 | Z34: =SUM(R34:T34) -> 4261100 | AA34: =SUM(U34:Z34) -> 67845628 | AB34: =ROUND(IF((AA34)*5%>6000000,6000000,(AA34)*5%),0) -> 3392281 | AC34: =('ASTEK+PENSIUN-DIISI SMPAI DES'!O123+'ASTEK+PENSIUN-DIISI SMPAI DES'!O37) -> 1399356 | AD34: =AA34-AB34-AC34 -> 63053991 | AE34: =IFERROR(VLOOKUP(I34,TARIF,3,FALSE),0) -> 67500000 | AF34: =ROUNDDOWN(IF(AD34<=AE34,0,IF(AD34>AE34,AD34-AE34)),-3) -> 0 | AG34: =IF(AF34>5000000000,AF34*35%-306000000,IF(AF34>500000000,AF34*30%-56000000,IF(AF34>250000000,AF34*25%-31000000,IF(AF34>60000000,AF34*15%-6000000,AF34*5%)))) -> 0 | AH34: =ROUND(IF(E34=0,AG34*120%,AG34),0) -> 0 | AI34: =+'PAJAK JAN-NOV'!R31 -> 141756 | AJ34: =IF(AG34<=AI34,0,IF(AG34>AI34,AG34-AI34)) -> 0 | AK34: =+'PAJAK JAN-NOV'!B31 -> SAPARUDIN | AL34: =AI34-AH34 -> 141756
B35: 30 | C35: =+PERBULAN!B35 -> SULTAN | D35: 2101092010780001 | E35: - | F35: KAMPUNG HILIR RT. 005 RW. 002 DESA KAMPUNG HILIR KEC. TAMBELAN | G35: PEMANEN | H35: L | I35: K/2 | J35: =IF(ISBLANK(I35),"",IF(OR(I35="TK/0",I35="TK/1",I35="K/0"),"TER A",IF(I35="K/3","TER C","TER B"))) -> TER B | K35: 1 | L35: 12 | M35: =31*129220 -> 4005820 | N35: 165150 | O35: 188643.84 | P35: 0 | Q35: =SUM(M35:P35) -> 4359613.8 | R35: =+SETAHUN!H36 -> 4061100 | S35: =+SETAHUN!K36 -> 200000 | T35: 0 | U35: =+SETAHUN!F36+M35+N35 -> 53392578 | V35: 0 | W35: =+SETAHUN!U36+O35 -> 2261802.5 | X35: 0 | Y35: 0 | Z35: =SUM(R35:T35) -> 4261100 | AA35: =SUM(U35:Z35) -> 59915481 | AB35: =ROUND(IF((AA35)*5%>6000000,6000000,(AA35)*5%),0) -> 2995774 | AC35: =('ASTEK+PENSIUN-DIISI SMPAI DES'!O124+'ASTEK+PENSIUN-DIISI SMPAI DES'!O38) -> 1399266 | AD35: =AA35-AB35-AC35 -> 55520441 | AE35: =IFERROR(VLOOKUP(I35,TARIF,3,FALSE),0) -> 67500000 | AF35: =ROUNDDOWN(IF(AD35<=AE35,0,IF(AD35>AE35,AD35-AE35)),-3) -> 0 | AG35: =IF(AF35>5000000000,AF35*35%-306000000,IF(AF35>500000000,AF35*30%-56000000,IF(AF35>250000000,AF35*25%-31000000,IF(AF35>60000000,AF35*15%-6000000,AF35*5%)))) -> 0 | AH35: =ROUND(IF(E35=0,AG35*120%,AG35),0) -> 0 | AI35: =+'PAJAK JAN-NOV'!R32 -> 89541 | AJ35: =IF(AG35<=AI35,0,IF(AG35>AI35,AG35-AI35)) -> 0 | AK35: =+'PAJAK JAN-NOV'!B32 -> SULTAN | AL35: =AI35-AH35 -> 89541
B36: 31 | C36: =+PERBULAN!B36 -> MANSUR | D36: 5203011105710001 | E36: - | F36: KETANGGA BARAT DESA KETANGGA JERAENG KEC. KERUAK KAB. LOMBOK TIMUR | G36: PEMANEN | H36: L | I36: K/1 | J36: =IF(ISBLANK(I36),"",IF(OR(I36="TK/0",I36="TK/1",I36="K/0"),"TER A",IF(I36="K/3","TER C","TER B"))) -> TER B | K36: 1 | L36: 12 | M36: =30*129220 -> 3876600 | N36: 404500 | O36: 188353.44 | P36: 0 | Q36: =SUM(M36:P36) -> 4469453.4 | R36: =+SETAHUN!H37 -> 4028600 | S36: =+SETAHUN!K37 -> 900000 | T36: 0 | U36: =+SETAHUN!F37+M36+N36 -> 58236384 | V36: 0 | W36: =+SETAHUN!U37+O36 -> 2258280.3 | X36: 0 | Y36: 0 | Z36: =SUM(R36:T36) -> 4928600 | AA36: =SUM(U36:Z36) -> 65423264 | AB36: =ROUND(IF((AA36)*5%>6000000,6000000,(AA36)*5%),0) -> 3271163 | AC36: =('ASTEK+PENSIUN-DIISI SMPAI DES'!O125+'ASTEK+PENSIUN-DIISI SMPAI DES'!O39) -> 1397901 | AD36: =AA36-AB36-AC36 -> 60754200 | AE36: =IFERROR(VLOOKUP(I36,TARIF,3,FALSE),0) -> 63000000 | AF36: =ROUNDDOWN(IF(AD36<=AE36,0,IF(AD36>AE36,AD36-AE36)),-3) -> 0 | AG36: =IF(AF36>5000000000,AF36*35%-306000000,IF(AF36>500000000,AF36*30%-56000000,IF(AF36>250000000,AF36*25%-31000000,IF(AF36>60000000,AF36*15%-6000000,AF36*5%)))) -> 0 | AH36: =ROUND(IF(E36=0,AG36*120%,AG36),0) -> 0 | AI36: =+'PAJAK JAN-NOV'!R33 -> 190495 | AJ36: =IF(AG36<=AI36,0,IF(AG36>AI36,AG36-AI36)) -> 0 | AK36: =+'PAJAK JAN-NOV'!B33 -> MANSUR | AL36: =AI36-AH36 -> 190495
B37: 32 | C37: =+PERBULAN!B37 -> RIDUAN | D37: 1906042202840002 | E37: - | F37: DSN PESARAKAN RT. 007 RW. 003 DESA CENDIL KEC. KELAPA KAMPIT | G37: PEMANEN | H37: L | I37: K/1 | J37: =IF(ISBLANK(I37),"",IF(OR(I37="TK/0",I37="TK/1",I37="K/0"),"TER A",IF(I37="K/3","TER C","TER B"))) -> TER B | K37: 1 | L37: 12 | M37: =31*129220 -> 4005820 | N37: 579057.67 | O37: 188232 | P37: 0 | Q37: =SUM(M37:P37) -> 4773109.7 | R37: =+SETAHUN!H38 -> 4026100 | S37: =+SETAHUN!K38 -> 900000 | T37: 0 | U37: =+SETAHUN!F38+M37+N37 -> 54547409 | V37: 0 | W37: =+SETAHUN!U38+O37 -> 2257437.8 | X37: 0 | Y37: 0 | Z37: =SUM(R37:T37) -> 4926100 | AA37: =SUM(U37:Z37) -> 61730947 | AB37: =ROUND(IF((AA37)*5%>6000000,6000000,(AA37)*5%),0) -> 3086547 | AC37: =('ASTEK+PENSIUN-DIISI SMPAI DES'!O126+'ASTEK+PENSIUN-DIISI SMPAI DES'!O40) -> 1397751 | AD37: =AA37-AB37-AC37 -> 57246649 | AE37: =IFERROR(VLOOKUP(I37,TARIF,3,FALSE),0) -> 63000000 | AF37: =ROUNDDOWN(IF(AD37<=AE37,0,IF(AD37>AE37,AD37-AE37)),-3) -> 0 | AG37: =IF(AF37>5000000000,AF37*35%-306000000,IF(AF37>500000000,AF37*30%-56000000,IF(AF37>250000000,AF37*25%-31000000,IF(AF37>60000000,AF37*15%-6000000,AF37*5%)))) -> 0 | AH37: =ROUND(IF(E37=0,AG37*120%,AG37),0) -> 0 | AI37: =+'PAJAK JAN-NOV'!R34 -> 91417 | AJ37: =IF(AG37<=AI37,0,IF(AG37>AI37,AG37-AI37)) -> 0 | AK37: =+'PAJAK JAN-NOV'!B34 -> RIDUAN | AL37: =AI37-AH37 -> 91417
B38: 33 | C38: =+PERBULAN!B38 -> SONJA PRIYOGA | D38: 1902041606020001 | E38: - | F38: JL RAYA PELEPAK PUTE RT. 007 RW. 004 DESA PELEPAK PUTE KEC. SIJUK | G38: PEMANEN | H38: L | I38: K/1 | J38: =IF(ISBLANK(I38),"",IF(OR(I38="TK/0",I38="TK/1",I38="K/0"),"TER A",IF(I38="K/3","TER C","TER B"))) -> TER B | K38: 1 | L38: 12 | M38: =31*129220 -> 4005820 | N38: 705180 | O38: 188111 | P38: 0 | Q38: =SUM(M38:P38) -> 4899111 | R38: =+SETAHUN!H39 -> 4023600 | S38: =+SETAHUN!K39 -> 900000 | T38: 0 | U38: =+SETAHUN!F39+M38+N38 -> 63842756 | V38: 0 | W38: =+SETAHUN!U39+O38 -> 2256432.8 | X38: 0 | Y38: 0 | Z38: =SUM(R38:T38) -> 4923600 | AA38: =SUM(U38:Z38) -> 71022789 | AB38: =ROUND(IF((AA38)*5%>6000000,6000000,(AA38)*5%),0) -> 3551139 | AC38: =('ASTEK+PENSIUN-DIISI SMPAI DES'!O127+'ASTEK+PENSIUN-DIISI SMPAI DES'!O41) -> 1397376 | AD38: =AA38-AB38-AC38 -> 66074274 | AE38: =IFERROR(VLOOKUP(I38,TARIF,3,FALSE),0) -> 63000000 | AF38: =ROUNDDOWN(IF(AD38<=AE38,0,IF(AD38>AE38,AD38-AE38)),-3) -> 3074000 | AG38: =IF(AF38>5000000000,AF38*35%-306000000,IF(AF38>500000000,AF38*30%-56000000,IF(AF38>250000000,AF38*25%-31000000,IF(AF38>60000000,AF38*15%-6000000,AF38*5%)))) -> 153700 | AH38: =ROUND(IF(E38=0,AG38*120%,AG38),0) -> 153700 | AI38: =+'PAJAK JAN-NOV'!R35 -> 250470 | AJ38: =IF(AG38<=AI38,0,IF(AG38>AI38,AG38-AI38)) -> 0 | AK38: =+'PAJAK JAN-NOV'!B35 -> SONJA PRIYOGA | AL38: =AI38-AH38 -> 96770
B39: 34 | C39: =+PERBULAN!B39 -> M.FAUZI | D39: 5203191607970006 | E39: 04.977.083.7-305.000 | F39: PERUM AIR PUTIH RT. 014 RW. 006 DESA BUDING KEC. KELAPA KAMPIT | G39: PEMANEN | H39: L | I39: TK/0 | J39: =IF(ISBLANK(I39),"",IF(OR(I39="TK/0",I39="TK/1",I39="K/0"),"TER A",IF(I39="K/3","TER C","TER B"))) -> TER A | K39: 1 | L39: 3 | P39: 0 | Q39: =SUM(M39:P39) -> 0 | R39: =+SETAHUN!H40 -> 3951600 | S39: =+SETAHUN!K40 -> 0 | T39: 0 | U39: =+SETAHUN!F40+M39+N39 -> 9156277.7 | V39: 0 | W39: =+SETAHUN!U40+O39 -> 563782.32 | X39: 0 | Y39: 0 | Z39: =SUM(R39:T39) -> 3951600 | AA39: =SUM(U39:Z39) -> 13671660 | AB39: =ROUND(IF((AA39)*5%>6000000,6000000,(AA39)*5%),0) -> 683583 | AC39: =('ASTEK+PENSIUN-DIISI SMPAI DES'!O128+'ASTEK+PENSIUN-DIISI SMPAI DES'!O42) -> 348894 | AD39: =AA39-AB39-AC39 -> 12639183 | AE39: =IFERROR(VLOOKUP(I39,TARIF,3,FALSE),0) -> 54000000 | AF39: =ROUNDDOWN(IF(AD39<=AE39,0,IF(AD39>AE39,AD39-AE39)),-3) -> 0 | AG39: =IF(AF39>5000000000,AF39*35%-306000000,IF(AF39>500000000,AF39*30%-56000000,IF(AF39>250000000,AF39*25%-31000000,IF(AF39>60000000,AF39*15%-6000000,AF39*5%)))) -> 0 | AH39: =ROUND(IF(E39=0,AG39*120%,AG39),0) -> 0 | AI39: =+'PAJAK JAN-NOV'!R36 -> 0 | AJ39: =IF(AG39<=AI39,0,IF(AG39>AI39,AG39-AI39)) -> 0 | AK39: =+'PAJAK JAN-NOV'!B36 -> M.FAUZI | AL39: =AI39-AH39 -> 0
B40: 35 | C40: =+PERBULAN!B40 -> DANI | D40: 5203100101860014 | E40: - | F40: GOTONG ROYONG RT.004/RW.001 DESA BAGIK PAYUNG SELATAN LOMBOK TIMUR | G40: PEMANEN | H40: L | I40: K/1 | J40: =IF(ISBLANK(I40),"",IF(OR(I40="TK/0",I40="TK/1",I40="K/0"),"TER A",IF(I40="K/3","TER C","TER B"))) -> TER B | K40: 1 | L40: 3 | P40: 0 | Q40: =SUM(M40:P40) -> 0 | R40: =+SETAHUN!H41 -> 4021100 | S40: =+SETAHUN!K41 -> 600000 | T40: 0 | U40: =+SETAHUN!F41+M40+N40 -> 12401586 | V40: 0 | W40: =+SETAHUN!U41+O40 -> 563482.32 | X40: 0 | Y40: 0 | Z40: =SUM(R40:T40) -> 4621100 | AA40: =SUM(U40:Z40) -> 17586168 | AB40: =ROUND(IF((AA40)*5%>6000000,6000000,(AA40)*5%),0) -> 879308 | AC40: =('ASTEK+PENSIUN-DIISI SMPAI DES'!O129+'ASTEK+PENSIUN-DIISI SMPAI DES'!O43) -> 348894 | AD40: =AA40-AB40-AC40 -> 16357966 | AE40: =IFERROR(VLOOKUP(I40,TARIF,3,FALSE),0) -> 63000000 | AF40: =ROUNDDOWN(IF(AD40<=AE40,0,IF(AD40>AE40,AD40-AE40)),-3) -> 0 | AG40: =IF(AF40>5000000000,AF40*35%-306000000,IF(AF40>500000000,AF40*30%-56000000,IF(AF40>250000000,AF40*25%-31000000,IF(AF40>60000000,AF40*15%-6000000,AF40*5%)))) -> 0 | AH40: =ROUND(IF(E40=0,AG40*120%,AG40),0) -> 0 | AI40: =+'PAJAK JAN-NOV'!R37 -> 52407 | AJ40: =IF(AG40<=AI40,0,IF(AG40>AI40,AG40-AI40)) -> 0 | AK40: =+'PAJAK JAN-NOV'!B37 -> DANI | AL40: =AI40-AH40 -> 52407
...

Sheet PPH EXGRATIA
B1: PT. REBINMAS JAYA
B2: INCOME TAX ARTICLE 21 FOR APRIL 2024
B3: PG 1A (INFRASTRUKTUR)
