Workbook
Name februari: TARIF!#REF!
Name februari: TARIF!#REF!
Name PH: [1]TARIF!#REF!
Name PH: TARIF!#REF!
Name PTKP: [1]TARIF!#REF!
Name PTKP: TARIF!#REF!
Name TARIF: [2]TARIF!$S$18:$U$25
Name Ter_A: [1]TARIF!$B$3:$E$46
Name Ter_A: TARIF!$B$3:$E$46
Name Ter_B: [1]TARIF!$H$3:$K$42
Name Ter_B: TARIF!$H$3:$K$42
Name Ter_C: [1]TARIF!$N$3:$Q$43
Name Ter_C: TARIF!$N$3:$Q$43

Sheet TARIF
A1: PTKP (TK/0, TK/1, K/0) | G1: PTKP (TK/2, TK/3, K/1, K/2) | M1: PTKP (K/3) | S1: HARIAN
A2: No | B2: Lapisan Penghasilan bruto (Rp.) | E2: TER A | G2: No | H2: Lapisan Penghasilan bruto (Rp.) | K2: TER B | M2: No | N2: Lapisan Penghasilan bruto (Rp.) | Q2: TER C | S2: Penghasilan Bruto | V2: Tarif
A3: 1 | B3: 0 | C3: s.d | D3: 5400000 | E3: 0 | G3: 1 | H3: 0 | I3: s.d | J3: 6200000 | K3: 0 | M3: 1 | N3: 0 | O3: s.d | P3: 6600000 | Q3: 0 | S3: 0 | T3: s.d | U3: 450000 | V3: 0
A4: =A3+1 -> 2 | B4: =D3+1 -> 5400001 | C4: s.d | D4: 5650000 | E4: 0.0025 | G4: =G3+1 -> 2 | H4: =J3+1 -> 6200001 | I4: s.d | J4: 6500000 | K4: 0.0025 | M4: =M3+1 -> 2 | N4: =P3+1 -> 6600001 | O4: s.d | P4: 6950000 | Q4: 0.0025 | S4: 450001 | T4: s.d | U4: 2500000 | V4: 0.005
A5: =A4+1 -> 3 | B5: =D4+1 -> 5650001 | C5: s.d | D5: 5950000 | E5: 0.005 | G5: =G4+1 -> 3 | H5: =J4+1 -> 6500001 | I5: s.d | J5: 6850000 | K5: 0.005 | M5: =M4+1 -> 3 | N5: =P4+1 -> 6950001 | O5: s.d | P5: 7350000 | Q5: 0.005
A6: =A5+1 -> 4 | B6: =D5+1 -> 5950001 | C6: s.d | D6: 6300000 | E6: 0.0075 | G6: =G5+1 -> 4 | H6: =J5+1 -> 6850001 | I6: s.d | J6: 7300000 | K6: 0.0075 | M6: =M5+1 -> 4 | N6: =P5+1 -> 7350001 | O6: s.d | P6: 7800000 | Q6: 0.0075
A7: =A6+1 -> 5 | B7: =D6+1 -> 6300001 | C7: s.d | D7: 6750000 | E7: 0.01 | G7: =G6+1 -> 5 | H7: =J6+1 -> 7300001 | I7: s.d | J7: 9200000 | K7: 0.01 | M7: =M6+1 -> 5 | N7: =P6+1 -> 7800001 | O7: s.d | P7: 8850000 | Q7: 0.01 | S7: TARIF PASAL 17 WPOP
A8: =A7+1 -> 6 | B8: =D7+1 -> 6750001 | C8: s.d | D8: 7500000 | E8: 0.0125 | G8: =G7+1 -> 6 | H8: =J7+1 -> 9200001 | I8: s.d | J8: 10750000 | K8: 0.015 | M8: =M7+1 -> 6 | N8: =P7+1 -> 8850001 | O8: s.d | P8: 9800000 | Q8: 0.0125 | S8: Lapisan PKP | V8: Tarif
A9: =A8+1 -> 7 | B9: =D8+1 -> 7500001 | C9: s.d | D9: 8550000 | E9: 0.015 | G9: =G8+1 -> 7 | H9: =J8+1 -> 10750001 | I9: s.d | J9: 11250000 | K9: 0.02 | M9: =M8+1 -> 7 | N9: =P8+1 -> 9800001 | O9: s.d | P9: 10950000 | Q9: 0.015 | S9: 0 | T9: s.d | U9: 60000000 | V9: 0.05
A10: =A9+1 -> 8 | B10: =D9+1 -> 8550001 | C10: s.d | D10: 9650000 | E10: 0.0175 | G10: =G9+1 -> 8 | H10: =J9+1 -> 11250001 | I10: s.d | J10: 11600000 | K10: 0.025 | M10: =M9+1 -> 8 | N10: =P9+1 -> 10950001 | O10: s.d | P10: 11200000 | Q10: 0.0175 | S10: =U9+1 -> 60000001 | T10: s.d | U10: 250000000 | V10: 0.15
A11: =A10+1 -> 9 | B11: =D10+1 -> 9650001 | C11: s.d | D11: 10050000 | E11: 0.02 | G11: =G10+1 -> 9 | H11: =J10+1 -> 11600001 | I11: s.d | J11: 12600000 | K11: 0.03 | M11: =M10+1 -> 9 | N11: =P10+1 -> 11200001 | O11: s.d | P11: 12050000 | Q11: 0.02 | S11: =U10+1 -> 250000001 | T11: s.d | U11: 500000000 | V11: 0.25
A12: =A11+1 -> 10 | B12: =D11+1 -> 10050001 | C12: s.d | D12: 10350000 | E12: 0.0225 | G12: =G11+1 -> 10 | H12: =J11+1 -> 12600001 | I12: s.d | J12: 13600000 | K12: 0.04 | M12: =M11+1 -> 10 | N12: =P11+1 -> 12050001 | O12: s.d | P12: 12950000 | Q12: 0.03 | S12: =U11+1 -> 500000001 | T12: s.d | U12: 5000000000 | V12: 0.3
A13: =A12+1 -> 11 | B13: =D12+1 -> 10350001 | C13: s.d | D13: 10700000 | E13: 0.025 | G13: =G12+1 -> 11 | H13: =J12+1 -> 13600001 | I13: s.d | J13: 14950000 | K13: 0.05 | M13: =M12+1 -> 11 | N13: =P12+1 -> 12950001 | O13: s.d | P13: 14150000 | Q13: 0.04 | S13: =U12+1 -> 5000000001 | T13: s.d | U13: ~~ | V13: 0.35
A14: =A13+1 -> 12 | B14: =D13+1 -> 10700001 | C14: s.d | D14: 11050000 | E14: 0.03 | G14: =G13+1 -> 12 | H14: =J13+1 -> 14950001 | I14: s.d | J14: 16400000 | K14: 0.06 | M14: =M13+1 -> 12 | N14: =P13+1 -> 14150001 | O14: s.d | P14: 1550000 | Q14: 0.05
A15: =A14+1 -> 13 | B15: =D14+1 -> 11050001 | C15: s.d | D15: 11600000 | E15: 0.035 | G15: =G14+1 -> 13 | H15: =J14+1 -> 16400001 | I15: s.d | J15: 18450000 | K15: 0.07 | M15: =M14+1 -> 13 | N15: =P14+1 -> 1550001 | O15: s.d | P15: 17050000 | Q15: 0.06
A16: =A15+1 -> 14 | B16: =D15+1 -> 11600001 | C16: s.d | D16: 12500000 | E16: 0.04 | G16: =G15+1 -> 14 | H16: =J15+1 -> 18450001 | I16: s.d | J16: 21850000 | K16: 0.08 | M16: =M15+1 -> 14 | N16: =P15+1 -> 17050001 | O16: s.d | P16: 19500000 | Q16: 0.07 | S16: PTKP
A17: =A16+1 -> 15 | B17: =D16+1 -> 12500001 | C17: s.d | D17: 13750000 | E17: 0.05 | G17: =G16+1 -> 15 | H17: =J16+1 -> 21850001 | I17: s.d | J17: 26000000 | K17: 0.09 | M17: =M16+1 -> 15 | N17: =P16+1 -> 19500001 | O17: s.d | P17: 22700000 | Q17: 0.08 | S17: Status | U17: Jumlah
A18: =A17+1 -> 16 | B18: =D17+1 -> 13750001 | C18: s.d | D18: 15100000 | E18: 0.06 | G18: =G17+1 -> 16 | H18: =J17+1 -> 26000001 | I18: s.d | J18: 27700000 | K18: 0.1 | M18: =M17+1 -> 16 | N18: =P17+1 -> 22700001 | O18: s.d | P18: 26600000 | Q18: 0.09 | S18: TK/0 | U18: 54000000
A19: =A18+1 -> 17 | B19: =D18+1 -> 15100001 | C19: s.d | D19: 16950000 | E19: 0.07 | G19: =G18+1 -> 17 | H19: =J18+1 -> 27700001 | I19: s.d | J19: 29350000 | K19: 0.11 | M19: =M18+1 -> 17 | N19: =P18+1 -> 26600001 | O19: s.d | P19: 28100000 | Q19: 0.1 | S19: TK/1 | U19: 58500000
A20: =A19+1 -> 18 | B20: =D19+1 -> 16950001 | C20: s.d | D20: 19750000 | E20: 0.08 | G20: =G19+1 -> 18 | H20: =J19+1 -> 29350001 | I20: s.d | J20: 31450000 | K20: 0.12 | M20: =M19+1 -> 18 | N20: =P19+1 -> 28100001 | O20: s.d | P20: 30100000 | Q20: 0.11 | S20: TK/2 | U20: 63000000
A21: =A20+1 -> 19 | B21: =D20+1 -> 19750001 | C21: s.d | D21: 24150000 | E21: 0.09 | G21: =G20+1 -> 19 | H21: =J20+1 -> 31450001 | I21: s.d | J21: 33950000 | K21: 0.13 | M21: =M20+1 -> 19 | N21: =P20+1 -> 30100001 | O21: s.d | P21: 32600000 | Q21: 0.12 | S21: TK/3 | U21: 67500000
A22: =A21+1 -> 20 | B22: =D21+1 -> 24150001 | C22: s.d | D22: 26450000 | E22: 0.1 | G22: =G21+1 -> 20 | H22: =J21+1 -> 33950001 | I22: s.d | J22: 37100000 | K22: 0.14 | M22: =M21+1 -> 20 | N22: =P21+1 -> 32600001 | O22: s.d | P22: 35400000 | Q22: 0.13 | S22: K/0 | U22: 58500000
A23: =A22+1 -> 21 | B23: =D22+1 -> 26450001 | C23: s.d | D23: 28000000 | E23: 0.11 | G23: =G22+1 -> 21 | H23: =J22+1 -> 37100001 | I23: s.d | J23: 41100000 | K23: 0.15 | M23: =M22+1 -> 21 | N23: =P22+1 -> 35400001 | O23: s.d | P23: 38900000 | Q23: 0.14 | S23: K/1 | U23: 63000000
A24: =A23+1 -> 22 | B24: =D23+1 -> 28000001 | C24: s.d | D24: 30050000 | E24: 0.12 | G24: =G23+1 -> 22 | H24: =J23+1 -> 41100001 | I24: s.d | J24: 45800000 | K24: 0.16 | M24: =M23+1 -> 22 | N24: =P23+1 -> 38900001 | O24: s.d | P24: 43000000 | Q24: 0.15 | S24: K/2 | U24: 67500000
A25: =A24+1 -> 23 | B25: =D24+1 -> 30050001 | C25: s.d | D25: 32400000 | E25: 0.13 | G25: =G24+1 -> 23 | H25: =J24+1 -> 45800001 | I25: s.d | J25: 49500000 | K25: 0.17 | M25: =M24+1 -> 23 | N25: =P24+1 -> 43000001 | O25: s.d | P25: 47400000 | Q25: 0.16 | S25: K/3 | U25: 72000000
A26: =A25+1 -> 24 | B26: =D25+1 -> 32400001 | C26: s.d | D26: 35400000 | E26: 0.14 | G26: =G25+1 -> 24 | H26: =J25+1 -> 49500001 | I26: s.d | J26: 53800000 | K26: 0.18 | M26: =M25+1 -> 24 | N26: =P25+1 -> 47400001 | O26: s.d | P26: 51200000 | Q26: 0.17
A27: =A26+1 -> 25 | B27: =D26+1 -> 35400001 | C27: s.d | D27: 39100000 | E27: 0.15 | G27: =G26+1 -> 25 | H27: =J26+1 -> 53800001 | I27: s.d | J27: 58500000 | K27: 0.19 | M27: =M26+1 -> 25 | N27: =P26+1 -> 51200001 | O27: s.d | P27: 55800000 | Q27: 0.18
A28: =A27+1 -> 26 | B28: =D27+1 -> 39100001 | C28: s.d | D28: 43850000 | E28: 0.16 | G28: =G27+1 -> 26 | H28: =J27+1 -> 58500001 | I28: s.d | J28: 64000000 | K28: 0.2 | M28: =M27+1 -> 26 | N28: =P27+1 -> 55800001 | O28: s.d | P28: 60400000 | Q28: 0.19
A29: =A28+1 -> 27 | B29: =D28+1 -> 43850001 | C29: s.d | D29: 47800000 | E29: 0.17 | G29: =G28+1 -> 27 | H29: =J28+1 -> 64000001 | I29: s.d | J29: 71000000 | K29: 0.21 | M29: =M28+1 -> 27 | N29: =P28+1 -> 60400001 | O29: s.d | P29: 66700000 | Q29: 0.2
A30: =A29+1 -> 28 | B30: =D29+1 -> 47800001 | C30: s.d | D30: 51400000 | E30: 0.18 | G30: =G29+1 -> 28 | H30: =J29+1 -> 71000001 | I30: s.d | J30: 80000000 | K30: 0.22 | M30: =M29+1 -> 28 | N30: =P29+1 -> 66700001 | O30: s.d | P30: 74500000 | Q30: 0.21
A31: =A30+1 -> 29 | B31: =D30+1 -> 51400001 | C31: s.d | D31: 56300000 | E31: 0.19 | G31: =G30+1 -> 29 | H31: =J30+1 -> 80000001 | I31: s.d | J31: 93000000 | K31: 0.23 | M31: =M30+1 -> 29 | N31: =P30+1 -> 74500001 | O31: s.d | P31: 83200000 | Q31: 0.22
A32: =A31+1 -> 30 | B32: =D31+1 -> 56300001 | C32: s.d | D32: 62200000 | E32: 0.2 | G32: =G31+1 -> 30 | H32: =J31+1 -> 93000001 | I32: s.d | J32: 109000000 | K32: 0.24 | M32: =M31+1 -> 30 | N32: =P31+1 -> 83200001 | O32: s.d | P32: 95600000 | Q32: 0.23
A33: =A32+1 -> 31 | B33: =D32+1 -> 62200001 | C33: s.d | D33: 68600000 | E33: 0.21 | G33: =G32+1 -> 31 | H33: =J32+1 -> 109000001 | I33: s.d | J33: 129000000 | K33: 0.25 | M33: =M32+1 -> 31 | N33: =P32+1 -> 95600001 | O33: s.d | P33: 110000000 | Q33: 0.24
A34: =A33+1 -> 32 | B34: =D33+1 -> 68600001 | C34: s.d | D34: 77500000 | E34: 0.22 | G34: =G33+1 -> 32 | H34: =J33+1 -> 129000001 | I34: s.d | J34: 163000000 | K34: 0.26 | M34: =M33+1 -> 32 | N34: =P33+1 -> 110000001 | O34: s.d | P34: 134000000 | Q34: 0.25
A35: =A34+1 -> 33 | B35: =D34+1 -> 77500001 | C35: s.d | D35: 89000000 | E35: 0.23 | G35: =G34+1 -> 33 | H35: =J34+1 -> 163000001 | I35: s.d | J35: 211000000 | K35: 0.27 | M35: =M34+1 -> 33 | N35: =P34+1 -> 134000001 | O35: s.d | P35: 169000000 | Q35: 0.26
A36: =A35+1 -> 34 | B36: =D35+1 -> 89000001 | C36: s.d | D36: 103000000 | E36: 0.24 | G36: =G35+1 -> 34 | H36: =J35+1 -> 211000001 | I36: s.d | J36: 374000000 | K36: 0.28 | M36: =M35+1 -> 34 | N36: =P35+1 -> 169000001 | O36: s.d | P36: 221000000 | Q36: 0.27
A37: =A36+1 -> 35 | B37: =D36+1 -> 103000001 | C37: s.d | D37: 125000000 | E37: 0.25 | G37: =G36+1 -> 35 | H37: =J36+1 -> 374000001 | I37: s.d | J37: 459000000 | K37: 0.29 | M37: =M36+1 -> 35 | N37: =P36+1 -> 221000001 | O37: s.d | P37: 390000000 | Q37: 0.28
... A41: =A40+1 -> 39 | B41: =D40+1 -> 337000001 | C41: s.d | D41: 454000000 | E41: 0.29 | G41: =G40+1 -> 39 | H41: =J40+1 -> 957000001 | I41: s.d | J41: 1405000000 | K41: 0.33 | M41: =M40+1 -> 39 | N41: =P40+1 -> 709000001 | O41: s.d | P41: 965000000 | Q41: 0.32
A42: =A41+1 -> 40 | B42: =D41+1 -> 454000001 | C42: s.d | D42: 550000000 | E42: 0.3 | G42: =G41+1 -> 40 | H42: =J41+1 -> 1405000001 | I42: s.d | J42: ~~ | K42: 0.34 | M42: =M41+1 -> 40 | N42: =P41+1 -> 965000001 | O42: s.d | P42: 1419000000 | Q42: 0.33
A43: =A42+1 -> 41 | B43: =D42+1 -> 550000001 | C43: s.d | D43: 695000000 | E43: 0.31 | M43: =M42+1 -> 41 | N43: =P42+1 -> 1419000001 | O43: s.d | P43: ~~ | Q43: 0.34
...

Sheet Des
C1: yang berwarna ini rumus | E1: Air Kunyal
B2: Nomor Urut | C2: NAMA KARYAWAN | D2: N I K / PASPOR | E2: N P W P | F2: A L A M A T | G2: JABATAN | H2: STATUS KARYAWAN | M2: DESEMBER | R2: PENGHASILAN TIDAK TERATUR | U2: TOTAL GAJI POKOK | V2: TOTAL TUNJANGAN LAINNYA | W2: TOTAL PREMI ASURANSI | X2: TOTAL TUNJANGAN PPH | Y2: TOTAL NATURA / KENIKMATAN | Z2: TOTAL THR, BONUS, TANTIEM | AA2: PENGHASILAN BRUTO SETAHUN | AB2: PENGURANG | AD2: PENGHASILAN NETTO SETAHUN | AE2: P T K P | AF2: P K P | AG2: PPH PASAL 21 | AI2: PPH PASAL 21 JAN S.D NOP | AJ2: PPH PASAL 21 DESEMBER
M3: Gaji Pokok | N3: Total Tunjangan | O3: Premi JKK, JKM, Kes | P3: Tunjangan PPh | Q3: Penghasilan Bruto | R3: T H R | S3: B O N U S | T3: TANTIEM
H4: L/P | I4: PTKP | J4: TER | K4: MASA KERJA | AB4: BIAYA JABATAN | AC4: TOTAL IURAN JHT/THT/JP | AG4: SETAHUN | AH4: INCLUDE NON NPWP
B5: 1 | C5: 2 | D5: 3 | E5: 4 | F5: 5 | G5: 6 | H5: 7 | I5: 8 | J5: 9 | K5: 10 | L5: 11 | M5: 12 | N5: 13 | O5: 14 | P5: 15 | Q5: 16 | R5: 17 | S5: 18 | T5: 19 | U5: 20 | V5: 21 | W5: 22 | X5: 23 | Y5: 24 | Z5: 25 | AA5: 26 | AB5: 27 | AC5: 27 | AD5: 29 | AE5: 30 | AF5: 31 | AG5: 32 | AH5: 33 | AI5: 34 | AJ5: 35
B6: 1 | C6: =+PERBULAN!B8 -> SUDARMONO | D6: 1902050811890001 | E6: - | F6: JL MANGGAR DSN PARIT GUNUNG RT. 006 RW. 003 DESA AIR BATU BUDING BADAU | G6: OPERATOR | H6: L | I6: K/2 | J6: =IF(ISBLANK(I6),"",IF(OR(I6="TK/0",I6="TK/1",I6="K/0"),"TER A",IF(I6="K/3","TER C","TER B"))) -> TER B | K6: 1 | L6: 12 | M6: =[3]PPH!K7 -> 4005820 | N6: 3103853 | O6: =[3]PPH!L7+[3]PPH!M7 -> 190241.04 | P6: 0 | Q6: =SUM(M6:P6) -> 7299914.1 | R6: =+PERBULAN!S8 -> 4093600 | S6: =+SETAHUN!J8 -> 200000 | T6: 0 | U6: =+SETAHUN!F8+M6+N6 -> 82957494 | V6: 0 | W6: =+SETAHUN!V8+O6 -> 2279330.9 | X6: 0 | Y6: 0 | Z6: =SUM(R6:T6) -> 4293600 | AA6: =SUM(U6:Z6) -> 89530425 | AB6: =ROUND(IF((AA6)*5%>6000000,6000000,(AA6)*5%),0) -> 4476521 | AC6: =('ASTEK-DIISI SMPAI DES'!O8+'ASTEK-DIISI SMPAI DES'!O123) -> 1405296 | AD6: =AA6-AB6-AC6 -> 83648608 | AE6: =IFERROR(VLOOKUP(I6,TARIF,3,FALSE),0) -> 67500000 | AF6: =ROUNDDOWN(IF(AD6<=AE6,0,IF(AD6>AE6,AD6-AE6)),-3) -> 16148000 | AG6: =IF(AF6>5000000000,AF6*35%-306000000,IF(AF6>500000000,AF6*30%-56000000,IF(AF6>250000000,AF6*25%-31000000,IF(AF6>60000000,AF6*15%-6000000,AF6*5%)))) -> 807400 | AH6: =ROUND(IF(E6=0,AG6*120%,AG6),0) -> 807400 | AI6: =+'PAJAK JAN-NOV'!R3 -> 767293 | AJ6: =IF(AG6<=AI6,0,IF(AG6>AI6,AG6-AI6)) -> 40107 | AL6: =AI6-AH6 -> -40107
B7: 2 | C7: =+PERBULAN!B9 -> ARDIYANSA | D7: 1902051704950001 | E7: - | F7: JL MANGGAR RT. 006 RW. 002 DESA KACANG BUTOR KEC. BADAU | G7: HELPER | H7: L | I7: TK/0 | J7: =IF(ISBLANK(I7),"",IF(OR(I7="TK/0",I7="TK/1",I7="K/0"),"TER A",IF(I7="K/3","TER C","TER B"))) -> TER A | K7: 1 | L7: 12 | M7: =[3]PPH!K8 -> 4005820 | N7: 2696949.2 | O7: =[3]PPH!L8+[3]PPH!M8 -> 189224.64 | P7: 0 | Q7: =SUM(M7:P7) -> 6891993.8 | R7: =+PERBULAN!S9 -> 3974100 | S7: =+SETAHUN!J9 -> 900000 | T7: 0 | U7: =+SETAHUN!F9+M7+N7 -> 82682032 | V7: 0 | W7: =+SETAHUN!V9+O7 -> 2268167.3 | X7: 0 | Y7: 0 | Z7: =SUM(R7:T7) -> 4874100 | AA7: =SUM(U7:Z7) -> 89824299 | AB7: =ROUND(IF((AA7)*5%>6000000,6000000,(AA7)*5%),0) -> 4491215 | AC7: =('ASTEK-DIISI SMPAI DES'!O9+'ASTEK-DIISI SMPAI DES'!O124) -> 1401426 | AD7: =AA7-AB7-AC7 -> 83931658 | AE7: =IFERROR(VLOOKUP(I7,TARIF,3,FALSE),0) -> 54000000 | AF7: =ROUNDDOWN(IF(AD7<=AE7,0,IF(AD7>AE7,AD7-AE7)),-3) -> 29931000 | AG7: =IF(AF7>5000000000,AF7*35%-306000000,IF(AF7>500000000,AF7*30%-56000000,IF(AF7>250000000,AF7*25%-31000000,IF(AF7>60000000,AF7*15%-6000000,AF7*5%)))) -> 1496550 | AH7: =ROUND(IF(E7=0,AG7*120%,AG7),0) -> 1496550 | AI7: =+'PAJAK JAN-NOV'!R4 -> 1294918 | AJ7: =IF(AG7<=AI7,0,IF(AG7>AI7,AG7-AI7)) -> 201632 | AL7: =AI7-AH7 -> -201632
B8: 3 | C8: =+PERBULAN!B10 -> INDRA JAYA | D8: 1902041104810005 | E8: 97.387.492.8-305.000 | F8: JL PEGARUN RT. 014 RW. 006 DESA AIR SELUMAR KEC. SIJUK | G8: OPERATOR | H8: L | I8: K/1 | J8: =IF(ISBLANK(I8),"",IF(OR(I8="TK/0",I8="TK/1",I8="K/0"),"TER A",IF(I8="K/3","TER C","TER B"))) -> TER B | K8: 1 | L8: 12 | M8: =28*129220 -> 3618160 | N8: 180700 | O8: =[3]PPH!L9+[3]PPH!M9 -> 190071.64 | P8: 0 | Q8: =SUM(M8:P8) -> 3988931.6 | R8: =+PERBULAN!S10 -> 4063100 | S8: =+SETAHUN!J10 -> 200000 | T8: 0 | U8: =+SETAHUN!F10+M8+N8 -> 56156458 | V8: 0 | W8: =+SETAHUN!V10+O8 -> 2277614.5 | X8: 0 | Y8: 0 | Z8: =SUM(R8:T8) -> 4263100 | AA8: =SUM(U8:Z8) -> 62697173 | AB8: =ROUND(IF((AA8)*5%>6000000,6000000,(AA8)*5%),0) -> 3134859 | AC8: =('ASTEK-DIISI SMPAI DES'!O10+'ASTEK-DIISI SMPAI DES'!O125) -> 1404666 | AD8: =AA8-AB8-AC8 -> 58157648 | AE8: =IFERROR(VLOOKUP(I8,TARIF,3,FALSE),0) -> 63000000 | AF8: =ROUNDDOWN(IF(AD8<=AE8,0,IF(AD8>AE8,AD8-AE8)),-3) -> 0 | AG8: =IF(AF8>5000000000,AF8*35%-306000000,IF(AF8>500000000,AF8*30%-56000000,IF(AF8>250000000,AF8*25%-31000000,IF(AF8>60000000,AF8*15%-6000000,AF8*5%)))) -> 0 | AH8: =ROUND(IF(E8=0,AG8*120%,AG8),0) -> 0 | AI8: =+'PAJAK JAN-NOV'!R5 -> 142783 | AJ8: =IF(AG8<=AI8,0,IF(AG8>AI8,AG8-AI8)) -> 0 | AL8: =AI8-AH8 -> 142783
B9: 4 | C9: =+PERBULAN!B11 -> USPANDI | D9: 1906042805800003 | E9: 97.228.657.9-305.000 | F9: DSN CENDIL RT. 001 RW. 001 DESA CENDIL KEC. KELAPA KAMPIT | G9: OPERATOR | H9: L | I9: K/2 | J9: =IF(ISBLANK(I9),"",IF(OR(I9="TK/0",I9="TK/1",I9="K/0"),"TER A",IF(I9="K/3","TER C","TER B"))) -> TER B | K9: 1 | L9: 12 | M9: =[3]PPH!K10 -> 4005820 | N9: 2284655.2 | O9: =[3]PPH!L10+[3]PPH!M10 -> 191765.64 | P9: 0 | Q9: =SUM(M9:P9) -> 6482240.8 | R9: =+PERBULAN!S11 -> 4128600 | S9: =+SETAHUN!J11 -> 900000 | T9: 0 | U9: =+SETAHUN!F11+M9+N9 -> 78541224 | V9: 0 | W9: =+SETAHUN!V11+O9 -> 2295898.5 | X9: 0 | Y9: 0 | Z9: =SUM(R9:T9) -> 5028600 | AA9: =SUM(U9:Z9) -> 85865723 | AB9: =ROUND(IF((AA9)*5%>6000000,6000000,(AA9)*5%),0) -> 4293286 | AC9: =('ASTEK-DIISI SMPAI DES'!O11+'ASTEK-DIISI SMPAI DES'!O126) -> 1410966 | AD9: =AA9-AB9-AC9 -> 80161471 | AE9: =IFERROR(VLOOKUP(I9,TARIF,3,FALSE),0) -> 67500000 | AF9: =ROUNDDOWN(IF(AD9<=AE9,0,IF(AD9>AE9,AD9-AE9)),-3) -> 12661000 | AG9: =IF(AF9>5000000000,AF9*35%-306000000,IF(AF9>500000000,AF9*30%-56000000,IF(AF9>250000000,AF9*25%-31000000,IF(AF9>60000000,AF9*15%-6000000,AF9*5%)))) -> 633050 | AH9: =ROUND(IF(E9=0,AG9*120%,AG9),0) -> 633050 | AI9: =+'PAJAK JAN-NOV'!R6 -> 613793 | AJ9: =IF(AG9<=AI9,0,IF(AG9>AI9,AG9-AI9)) -> 19257 | AL9: =AI9-AH9 -> -19257
B10: 5 | C10: =+PERBULAN!B12 -> NOVI SUHAIDI | D10: 1902011511890006 | E10: 97.228.313.9-305.000 | F10: JALAN AIR SERKUK RT 028 RW 011 DESA AIR SAGA KEC.TANJUNG PANDAN | G10: HELPER | H10: L | I10: K/2 | J10: =IF(ISBLANK(I10),"",IF(OR(I10="TK/0",I10="TK/1",I10="K/0"),"TER A",IF(I10="K/3","TER C","TER B"))) -> TER B | K10: 1 | L10: 12 | M10: =[3]PPH!K11 -> 4005820 | N10: 2160315.2 | O10: =[3]PPH!L11+[3]PPH!M11 -> 190071.64 | P10: 0 | Q10: =SUM(M10:P10) -> 6356206.8 | R10: =+PERBULAN!S12 -> 4090100 | S10: =+SETAHUN!J12 -> 600000 | T10: 0 | U10: =+SETAHUN!F12+M10+N10 -> 77376921 | V10: 0 | W10: =+SETAHUN!V12+O10 -> 2276686.3 | X10: 0 | Y10: 0 | Z10: =SUM(R10:T10) -> 4690100 | AA10: =SUM(U10:Z10) -> 84343707 | AB10: =ROUND(IF((AA10)*5%>6000000,6000000,(AA10)*5%),0) -> 4217185 | AC10: =('ASTEK-DIISI SMPAI DES'!O12+'ASTEK-DIISI SMPAI DES'!O127) -> 1404351 | AD10: =AA10-AB10-AC10 -> 78722171 | AE10: =IFERROR(VLOOKUP(I10,TARIF,3,FALSE),0) -> 67500000 | AF10: =ROUNDDOWN(IF(AD10<=AE10,0,IF(AD10>AE10,AD10-AE10)),-3) -> 11222000 | AG10: =IF(AF10>5000000000,AF10*35%-306000000,IF(AF10>500000000,AF10*30%-56000000,IF(AF10>250000000,AF10*25%-31000000,IF(AF10>60000000,AF10*15%-6000000,AF10*5%)))) -> 561100 | AH10: =ROUND(IF(E10=0,AG10*120%,AG10),0) -> 561100 | AI10: =+'PAJAK JAN-NOV'!R7 -> 516366 | AJ10: =IF(AG10<=AI10,0,IF(AG10>AI10,AG10-AI10)) -> 44734 | AL10: =AI10-AH10 -> -44734
B11: 6 | C11: =+PERBULAN!B13 -> ROSLI | D11: 1906042807800005 | E11: 97.228.635.5-305.000 | F11: DSN BUDING RT. 001 RW. 001 DS BUDING KEC KELAPA KAMPIT | G11: KARYAWAN PERAWATAN | H11: L | I11: K/2 | J11: =IF(ISBLANK(I11),"",IF(OR(I11="TK/0",I11="TK/1",I11="K/0"),"TER A",IF(I11="K/3","TER C","TER B"))) -> TER B | K11: 1 | L11: 12 | M11: =('[3]DAFTAR UPAH MAINTENANCE'!F9+'[3]DAFTAR UPAH MAINTENANCE'!J9+'[3]DAFTAR UPAH MAINTENANCE'!L9+'[3]DAFTAR UPAH MAINTENANCE'!N9+'[3]DAFTAR UPAH MAINTENANCE'!P9+'[3]DAFTAR UPAH MAINTENANCE'!R9)*129220 -> 3876600 | N11: ='[3]DAFTAR UPAH MAINTENANCE'!BN9 -> 496009.24 | O11: =[3]PPH!L12+[3]PPH!M12 -> 190241.04 | P11: 0 | Q11: =SUM(M11:P11) -> 4562850.3 | R11: =+PERBULAN!S13 -> 4093600 | S11: =+SETAHUN!J13 -> 600000 | T11: 0 | U11: =+SETAHUN!F13+M11+N11 -> 52045174 | V11: 0 | W11: =+SETAHUN!V13+O11 -> 2279470.9 | X11: 0 | Y11: 0 | Z11: =SUM(R11:T11) -> 4693600 | AA11: =SUM(U11:Z11) -> 59018245 | AB11: =ROUND(IF((AA11)*5%>6000000,6000000,(AA11)*5%),0) -> 2950912 | AC11: =('ASTEK-DIISI SMPAI DES'!O13+'ASTEK-DIISI SMPAI DES'!O128) -> 1405296 | AD11: =AA11-AB11-AC11 -> 54662037 | AE11: =IFERROR(VLOOKUP(I11,TARIF,3,FALSE),0) -> 67500000 | AF11: =ROUNDDOWN(IF(AD11<=AE11,0,IF(AD11>AE11,AD11-AE11)),-3) -> 0 | AG11: =IF(AF11>5000000000,AF11*35%-306000000,IF(AF11>500000000,AF11*30%-56000000,IF(AF11>250000000,AF11*25%-31000000,IF(AF11>60000000,AF11*15%-6000000,AF11*5%)))) -> 0 | AH11: =ROUND(IF(E11=0,AG11*120%,AG11),0) -> 0 | AI11: =+'PAJAK JAN-NOV'!R8 -> 85116 | AJ11: =IF(AG11<=AI11,0,IF(AG11>AI11,AG11-AI11)) -> 0 | AL11: =AI11-AH11 -> 85116
B12: 7 | C12: =+PERBULAN!B14 -> AMRIL | D12: 1902011404860010 | E12: 97.228.612.4-305.000 | F12: JL HASYIM IDRIS RT. 043 RW. 017 DESA PANGKAL LALANG TANJUNGPANDAN | G12: KERANI DIVISI | H12: L | I12: K/1 | J12: =IF(ISBLANK(I12),"",IF(OR(I12="TK/0",I12="TK/1",I12="K/0"),"TER A",IF(I12="K/3","TER C","TER B"))) -> TER B | K12: 1 | L12: 12 | M12: =('[3]DAFTAR UPAH MAINTENANCE'!F10+'[3]DAFTAR UPAH MAINTENANCE'!J10+'[3]DAFTAR UPAH MAINTENANCE'!L10+'[3]DAFTAR UPAH MAINTENANCE'!N10+'[3]DAFTAR UPAH MAINTENANCE'!P10+'[3]DAFTAR UPAH MAINTENANCE'!R10)*129220 -> 4005820 | N12: ='[3]DAFTAR UPAH MAINTENANCE'!BN10 -> 3705496 | O12: =[3]PPH!L13+[3]PPH!M13 -> 190071.64 | P12: 0 | Q12: =SUM(M12:P12) -> 7901387.6 | R12: =+PERBULAN!S14 -> 4063100 | S12: =+SETAHUN!J14 -> 900000 | T12: 0 | U12: =+SETAHUN!F14+M12+N12 -> 91561347 | V12: 0 | W12: =+SETAHUN!V14+O12 -> 2277614.5 | X12: 0 | Y12: 0 | Z12: =SUM(R12:T12) -> 4963100 | AA12: =SUM(U12:Z12) -> 98802062 | AB12: =ROUND(IF((AA12)*5%>6000000,6000000,(AA12)*5%),0) -> 4940103 | AC12: =('ASTEK-DIISI SMPAI DES'!O14+'ASTEK-DIISI SMPAI DES'!O129) -> 1404666 | AD12: =AA12-AB12-AC12 -> 92457293 | AE12: =IFERROR(VLOOKUP(I12,TARIF,3,FALSE),0) -> 63000000 | AF12: =ROUNDDOWN(IF(AD12<=AE12,0,IF(AD12>AE12,AD12-AE12)),-3) -> 29457000 | AG12: =IF(AF12>5000000000,AF12*35%-306000000,IF(AF12>500000000,AF12*30%-56000000,IF(AF12>250000000,AF12*25%-31000000,IF(AF12>60000000,AF12*15%-6000000,AF12*5%)))) -> 1472850 | AH12: =ROUND(IF(E12=0,AG12*120%,AG12),0) -> 1472850 | AI12: =+'PAJAK JAN-NOV'!R9 -> 1089445 | AJ12: =IF(AG12<=AI12,0,IF(AG12>AI12,AG12-AI12)) -> 383405 | AL12: =AI12-AH12 -> -383405
B13: 8 | C13: =+PERBULAN!B15 -> KARMILA | D13: 1906045009880001 | E13: 97.228.610.8-305.000 | F13: DSN CENDIL RT. 004 RW. 002 DESA CENDIL KEC KELAPA KAMPIT | G13: KARYAWAN PERAWATAN | H13: P | I13: TK/0 | J13: =IF(ISBLANK(I13),"",IF(OR(I13="TK/0",I13="TK/1",I13="K/0"),"TER A",IF(I13="K/3","TER C","TER B"))) -> TER A | K13: 1 | L13: 12 | M13: =('[3]DAFTAR UPAH MAINTENANCE'!F11+'[3]DAFTAR UPAH MAINTENANCE'!J11+'[3]DAFTAR UPAH MAINTENANCE'!L11+'[3]DAFTAR UPAH MAINTENANCE'!N11+'[3]DAFTAR UPAH MAINTENANCE'!P11+'[3]DAFTAR UPAH MAINTENANCE'!R11)*129220 -> 4005820 | N13: ='[3]DAFTAR UPAH MAINTENANCE'!BN11 -> 120250 | O13: =[3]PPH!L14+[3]PPH!M14 -> 190071.64 | P13: 0 | Q13: =SUM(M13:P13) -> 4316141.6 | R13: =+PERBULAN!S15 -> 3991100 | S13: =+SETAHUN!J15 -> 900000 | T13: 0 | U13: =+SETAHUN!F15+M13+N13 -> 48578549 | V13: 0 | W13: =+SETAHUN!V15+O13 -> 2277754.5 | X13: 0 | Y13: 0 | Z13: =SUM(R13:T13) -> 4891100 | AA13: =SUM(U13:Z13) -> 55747404 | AB13: =ROUND(IF((AA13)*5%>6000000,6000000,(AA13)*5%),0) -> 2787370 | AC13: =('ASTEK-DIISI SMPAI DES'!O15+'ASTEK-DIISI SMPAI DES'!O130) -> 1404666 | AD13: =AA13-AB13-AC13 -> 51555368 | AE13: =IFERROR(VLOOKUP(I13,TARIF,3,FALSE),0) -> 54000000 | AF13: =ROUNDDOWN(IF(AD13<=AE13,0,IF(AD13>AE13,AD13-AE13)),-3) -> 0 | AG13: =IF(AF13>5000000000,AF13*35%-306000000,IF(AF13>500000000,AF13*30%-56000000,IF(AF13>250000000,AF13*25%-31000000,IF(AF13>60000000,AF13*15%-6000000,AF13*5%)))) -> 0 | AH13: =ROUND(IF(E13=0,AG13*120%,AG13),0) -> 0 | AI13: =+'PAJAK JAN-NOV'!R10 -> 124548 | AJ13: =IF(AG13<=AI13,0,IF(AG13>AI13,AG13-AI13)) -> 0 | AL13: =AI13-AH13 -> 124548
B14: 9 | C14: =+PERBULAN!B16 -> MARTUTI | D14: 1906044911750004 | E14: 97.228.663.7-305.000 | F14: DSN CENDIL RT. 001 RW. 001 DESA CENDIL KEC KELAPA KAMPIT | G14: KARYAWAN PERAWATAN | H14: P | I14: TK/0 | J14: =IF(ISBLANK(I14),"",IF(OR(I14="TK/0",I14="TK/1",I14="K/0"),"TER A",IF(I14="K/3","TER C","TER B"))) -> TER A | K14: 1 | L14: 12 | M14: =('[3]DAFTAR UPAH MAINTENANCE'!F12+'[3]DAFTAR UPAH MAINTENANCE'!J12+'[3]DAFTAR UPAH MAINTENANCE'!L12+'[3]DAFTAR UPAH MAINTENANCE'!N12+'[3]DAFTAR UPAH MAINTENANCE'!P12+'[3]DAFTAR UPAH MAINTENANCE'!R12)*129220 -> 4005820 | N14: ='[3]DAFTAR UPAH MAINTENANCE'!BN12 -> 123750 | O14: =[3]PPH!L15+[3]PPH!M15 -> 190241.04 | P14: 0 | Q14: =SUM(M14:P14) -> 4319811 | R14: =+PERBULAN!S16 -> 3994600 | S14: =+SETAHUN!J16 -> 900000 | T14: 0 | U14: =+SETAHUN!F16+M14+N14 -> 48599549 | V14: 0 | W14: =+SETAHUN!V16+O14 -> 2278653.3 | X14: 0 | Y14: 0 | Z14: =SUM(R14:T14) -> 4894600 | AA14: =SUM(U14:Z14) -> 55772802 | AB14: =ROUND(IF((AA14)*5%>6000000,6000000,(AA14)*5%),0) -> 2788640 | AC14: =('ASTEK-DIISI SMPAI DES'!O16+'ASTEK-DIISI SMPAI DES'!O131) -> 1404876 | AD14: =AA14-AB14-AC14 -> 51579286 | AE14: =IFERROR(VLOOKUP(I14,TARIF,3,FALSE),0) -> 54000000 | AF14: =ROUNDDOWN(IF(AD14<=AE14,0,IF(AD14>AE14,AD14-AE14)),-3) -> 0 | AG14: =IF(AF14>5000000000,AF14*35%-306000000,IF(AF14>500000000,AF14*30%-56000000,IF(AF14>250000000,AF14*25%-31000000,IF(AF14>60000000,AF14*15%-6000000,AF14*5%)))) -> 0 | AH14: =ROUND(IF(E14=0,AG14*120%,AG14),0) -> 0 | AI14: =+'PAJAK JAN-NOV'!R11 -> 124655 | AJ14: =IF(AG14<=AI14,0,IF(AG14>AI14,AG14-AI14)) -> 0 | AL14: =AI14-AH14 -> 124655
B15: 10 | C15: =+PERBULAN!B17 -> HARNIAWATI | D15: 1906045811760002 | E15: 97.228.631.4-305.000 | F15: DSN CENDIL RT. 002 RW. 001 DS CENDIL KEC KELAPA KAMPIT | G15: KARYAWAN PERAWATAN | H15: P | I15: TK/0 | J15: =IF(ISBLANK(I15),"",IF(OR(I15="TK/0",I15="TK/1",I15="K/0"),"TER A",IF(I15="K/3","TER C","TER B"))) -> TER A | K15: 1 | L15: 12 | M15: =('[3]DAFTAR UPAH MAINTENANCE'!F13+'[3]DAFTAR UPAH MAINTENANCE'!J13+'[3]DAFTAR UPAH MAINTENANCE'!L13+'[3]DAFTAR UPAH MAINTENANCE'!N13+'[3]DAFTAR UPAH MAINTENANCE'!P13+'[3]DAFTAR UPAH MAINTENANCE'!R13)*129220 -> 4005820 | N15: ='[3]DAFTAR UPAH MAINTENANCE'!BN13 -> 123750 | O15: =[3]PPH!L16+[3]PPH!M16 -> 190241.04 | P15: 0 | Q15: =SUM(M15:P15) -> 4319811 | R15: =+PERBULAN!S17 -> 3994600 | S15: =+SETAHUN!J17 -> 900000 | T15: 0 | U15: =+SETAHUN!F17+M15+N15 -> 48599549 | V15: 0 | W15: =+SETAHUN!V17+O15 -> 2278653.3 | X15: 0 | Y15: 0 | Z15: =SUM(R15:T15) -> 4894600 | AA15: =SUM(U15:Z15) -> 55772802 | AB15: =ROUND(IF((AA15)*5%>6000000,6000000,(AA15)*5%),0) -> 2788640 | AC15: =('ASTEK-DIISI SMPAI DES'!O17+'ASTEK-DIISI SMPAI DES'!O132) -> 1404876 | AD15: =AA15-AB15-AC15 -> 51579286 | AE15: =IFERROR(VLOOKUP(I15,TARIF,3,FALSE),0) -> 54000000 | AF15: =ROUNDDOWN(IF(AD15<=AE15,0,IF(AD15>AE15,AD15-AE15)),-3) -> 0 | AG15: =IF(AF15>5000000000,AF15*35%-306000000,IF(AF15>500000000,AF15*30%-56000000,IF(AF15>250000000,AF15*25%-31000000,IF(AF15>60000000,AF15*15%-6000000,AF15*5%)))) -> 0 | AH15: =ROUND(IF(E15=0,AG15*120%,AG15),0) -> 0 | AI15: =+'PAJAK JAN-NOV'!R12 -> 124655 | AJ15: =IF(AG15<=AI15,0,IF(AG15>AI15,AG15-AI15)) -> 0 | AL15: =AI15-AH15 -> 124655
B16: 11 | C16: =+PERBULAN!B18 -> MARYATI | D16: 1906046103730002 | E16: 97.228.624.9-305.000 | F16: DSN CENDIL RT. 001 RW. 001 DESA CENDIL KEC. KELAPA KAMPIT | G16: KARYAWAN PERAWATAN | H16: P | I16: TK/0 | J16: =IF(ISBLANK(I16),"",IF(OR(I16="TK/0",I16="TK/1",I16="K/0"),"TER A",IF(I16="K/3","TER C","TER B"))) -> TER A | K16: 1 | L16: 12 | M16: =('[3]DAFTAR UPAH MAINTENANCE'!F14+'[3]DAFTAR UPAH MAINTENANCE'!J14+'[3]DAFTAR UPAH MAINTENANCE'!L14+'[3]DAFTAR UPAH MAINTENANCE'!N14+'[3]DAFTAR UPAH MAINTENANCE'!P14+'[3]DAFTAR UPAH MAINTENANCE'!R14)*129220 -> 4005820 | N16: ='[3]DAFTAR UPAH MAINTENANCE'!BN14 -> 123750 | O16: =[3]PPH!L17+[3]PPH!M17 -> 190241.04 | P16: 0 | Q16: =SUM(M16:P16) -> 4319811 | R16: =+PERBULAN!S18 -> 3994600 | S16: =+SETAHUN!J18 -> 900000 | T16: 0 | U16: =+SETAHUN!F18+M16+N16 -> 48482077 | V16: 0 | W16: =+SETAHUN!V18+O16 -> 2279330.9 | X16: 0 | Y16: 0 | Z16: =SUM(R16:T16) -> 4894600 | AA16: =SUM(U16:Z16) -> 55656008 | AB16: =ROUND(IF((AA16)*5%>6000000,6000000,(AA16)*5%),0) -> 2782800 | AC16: =('ASTEK-DIISI SMPAI DES'!O18+'ASTEK-DIISI SMPAI DES'!O133) -> 1405296 | AD16: =AA16-AB16-AC16 -> 51467912 | AE16: =IFERROR(VLOOKUP(I16,TARIF,3,FALSE),0) -> 54000000 | AF16: =ROUNDDOWN(IF(AD16<=AE16,0,IF(AD16>AE16,AD16-AE16)),-3) -> 0 | AG16: =IF(AF16>5000000000,AF16*35%-306000000,IF(AF16>500000000,AF16*30%-56000000,IF(AF16>250000000,AF16*25%-31000000,IF(AF16>60000000,AF16*15%-6000000,AF16*5%)))) -> 0 | AH16: =ROUND(IF(E16=0,AG16*120%,AG16),0) -> 0 | AI16: =+'PAJAK JAN-NOV'!R13 -> 124655 | AJ16: =IF(AG16<=AI16,0,IF(AG16>AI16,AG16-AI16)) -> 0 | AL16: =AI16-AH16 -> 124655
B17: 12 | C17: =+PERBULAN!B19 -> KOPRIATI | D17: 1906044405820002 | E17: 97.228.601.7-305.000 | F17: DSN CENDIL RT. 001 RW. 001 DESA CENDIL KEC. KELAPA KAMPIT | G17: KARYAWAN PERAWATAN | H17: P | I17: TK/0 | J17: =IF(ISBLANK(I17),"",IF(OR(I17="TK/0",I17="TK/1",I17="K/0"),"TER A",IF(I17="K/3","TER C","TER B"))) -> TER A | K17: 1 | L17: 12 | M17: =('[3]DAFTAR UPAH MAINTENANCE'!F15+'[3]DAFTAR UPAH MAINTENANCE'!J15+'[3]DAFTAR UPAH MAINTENANCE'!L15+'[3]DAFTAR UPAH MAINTENANCE'!N15+'[3]DAFTAR UPAH MAINTENANCE'!P15+'[3]DAFTAR UPAH MAINTENANCE'!R15)*129220 -> 4005820 | N17: ='[3]DAFTAR UPAH MAINTENANCE'!BN15 -> 155250 | O17: =[3]PPH!L18+[3]PPH!M18 -> 191765.64 | P17: 0 | Q17: =SUM(M17:P17) -> 4352835.6 | R17: =+PERBULAN!S19 -> 4029600 | S17: =+SETAHUN!J19 -> 200000 | T17: 0 | U17: =+SETAHUN!F19+M17+N17 -> 48593639 | V17: 0 | W17: =+SETAHUN!V19+O17 -> 2295898.5 | X17: 0 | Y17: 0 | Z17: =SUM(R17:T17) -> 4229600 | AA17: =SUM(U17:Z17) -> 55119138 | AB17: =ROUND(IF((AA17)*5%>6000000,6000000,(AA17)*5%),0) -> 2755957 | AC17: =('ASTEK-DIISI SMPAI DES'!O19+'ASTEK-DIISI SMPAI DES'!O134) -> 1410966 | AD17: =AA17-AB17-AC17 -> 50952215 | AE17: =IFERROR(VLOOKUP(I17,TARIF,3,FALSE),0) -> 54000000 | AF17: =ROUNDDOWN(IF(AD17<=AE17,0,IF(AD17>AE17,AD17-AE17)),-3) -> 0 | AG17: =IF(AF17>5000000000,AF17*35%-306000000,IF(AF17>500000000,AF17*30%-56000000,IF(AF17>250000000,AF17*25%-31000000,IF(AF17>60000000,AF17*15%-6000000,AF17*5%)))) -> 0 | AH17: =ROUND(IF(E17=0,AG17*120%,AG17),0) -> 0 | AI17: =+'PAJAK JAN-NOV'!R14 -> 123754 | AJ17: =IF(AG17<=AI17,0,IF(AG17>AI17,AG17-AI17)) -> 0 | AL17: =AI17-AH17 -> 123754
B18: 13 | C18: =+PERBULAN!B20 -> ASNIATI | D18: 1906014911710001 | E18: 97.228.599.3-305.000 | F18: DSN SUKADAMAI RT. 019 RW. 009 DESA MENGKUBANG KEC. DAMAR | G18: KARYAWAN PERAWATAN | H18: P | I18: TK/0 | J18: =IF(ISBLANK(I18),"",IF(OR(I18="TK/0",I18="TK/1",I18="K/0"),"TER A",IF(I18="K/3","TER C","TER B"))) -> TER A | K18: 1 | L18: 12 | M18: =('[3]DAFTAR UPAH MAINTENANCE'!F16+'[3]DAFTAR UPAH MAINTENANCE'!J16+'[3]DAFTAR UPAH MAINTENANCE'!L16+'[3]DAFTAR UPAH MAINTENANCE'!N16+'[3]DAFTAR UPAH MAINTENANCE'!P16+'[3]DAFTAR UPAH MAINTENANCE'!R16)*129220 -> 3876600 | N18: ='[3]DAFTAR UPAH MAINTENANCE'!BN16 -> 118000 | O18: =[3]PPH!L19+[3]PPH!M19 -> 190071.64 | P18: 0 | Q18: =SUM(M18:P18) -> 4184671.6 | R18: =+PERBULAN!S20 -> 3991100 | S18: =+SETAHUN!J20 -> 600000 | T18: 0 | U18: =+SETAHUN!F20+M18+N18 -> 48443579 | V18: 0 | W18: =+SETAHUN!V20+O18 -> 2277614.5 | X18: 0 | Y18: 0 | Z18: =SUM(R18:T18) -> 4591100 | AA18: =SUM(U18:Z18) -> 55312294 | AB18: =ROUND(IF((AA18)*5%>6000000,6000000,(AA18)*5%),0) -> 2765615 | AC18: =('ASTEK-DIISI SMPAI DES'!O20+'ASTEK-DIISI SMPAI DES'!O135) -> 1404666 | AD18: =AA18-AB18-AC18 -> 51142013 | AE18: =IFERROR(VLOOKUP(I18,TARIF,3,FALSE),0) -> 54000000 | AF18: =ROUNDDOWN(IF(AD18<=AE18,0,IF(AD18>AE18,AD18-AE18)),-3) -> 0 | AG18: =IF(AF18>5000000000,AF18*35%-306000000,IF(AF18>500000000,AF18*30%-56000000,IF(AF18>250000000,AF18*25%-31000000,IF(AF18>60000000,AF18*15%-6000000,AF18*5%)))) -> 0 | AH18: =ROUND(IF(E18=0,AG18*120%,AG18),0) -> 0 | AI18: =+'PAJAK JAN-NOV'!R15 -> 124548 | AJ18: =IF(AG18<=AI18,0,IF(AG18>AI18,AG18-AI18)) -> 0 | AL18: =AI18-AH18 -> 124548
B19: 14 | C19: =+PERBULAN!B21 -> ANDIWATI | D19: 1906045203900001 | E19: 97.228.617.3-305.000 | F19: DSN CENDIL RT. 003 RW. 001 DS CENDIL KEC. KELAPA KAMPIT | G19: KARYAWAN PERAWATAN | H19: P | I19: TK/0 | J19: =IF(ISBLANK(I19),"",IF(OR(I19="TK/0",I19="TK/1",I19="K/0"),"TER A",IF(I19="K/3","TER C","TER B"))) -> TER A | K19: 1 | L19: 12 | M19: =('[3]DAFTAR UPAH MAINTENANCE'!F17+'[3]DAFTAR UPAH MAINTENANCE'!J17+'[3]DAFTAR UPAH MAINTENANCE'!L17+'[3]DAFTAR UPAH MAINTENANCE'!N17+'[3]DAFTAR UPAH MAINTENANCE'!P17+'[3]DAFTAR UPAH MAINTENANCE'!R17)*129220 -> 4005820 | N19: ='[3]DAFTAR UPAH MAINTENANCE'!BN17 -> 120250 | O19: =[3]PPH!L20+[3]PPH!M20 -> 190071.64 | P19: 0 | Q19: =SUM(M19:P19) -> 4316141.6 | R19: =+PERBULAN!S21 -> 3991100 | S19: =+SETAHUN!J21 -> 600000 | T19: 0 | U19: =+SETAHUN!F21+M19+N19 -> 48564548 | V19: 0 | W19: =+SETAHUN!V21+O19 -> 2277135.7 | X19: 0 | Y19: 0 | Z19: =SUM(R19:T19) -> 4591100 | AA19: =SUM(U19:Z19) -> 55432784 | AB19: =ROUND(IF((AA19)*5%>6000000,6000000,(AA19)*5%),0) -> 2771639 | AC19: =('ASTEK-DIISI SMPAI DES'!O21+'ASTEK-DIISI SMPAI DES'!O136) -> 1404456 | AD19: =AA19-AB19-AC19 -> 51256689 | AE19: =IFERROR(VLOOKUP(I19,TARIF,3,FALSE),0) -> 54000000 | AF19: =ROUNDDOWN(IF(AD19<=AE19,0,IF(AD19>AE19,AD19-AE19)),-3) -> 0 | AG19: =IF(AF19>5000000000,AF19*35%-306000000,IF(AF19>500000000,AF19*30%-56000000,IF(AF19>250000000,AF19*25%-31000000,IF(AF19>60000000,AF19*15%-6000000,AF19*5%)))) -> 0 | AH19: =ROUND(IF(E19=0,AG19*120%,AG19),0) -> 0 | AI19: =+'PAJAK JAN-NOV'!R16 -> 124548 | AJ19: =IF(AG19<=AI19,0,IF(AG19>AI19,AG19-AI19)) -> 0 | AL19: =AI19-AH19 -> 124548
B20: 15 | C20: =+PERBULAN!B22 -> MARYANA.So | D20: 1906046309750002 | E20: 97.228.661.1-305.000 | F20: DSN CENDIL RT. 001 RW. 001 DESA CENDIL KEC. KELAPA KAMPIT | G20: KARYAWAN PERAWATAN | H20: P | I20: TK/0 | J20: =IF(ISBLANK(I20),"",IF(OR(I20="TK/0",I20="TK/1",I20="K/0"),"TER A",IF(I20="K/3","TER C","TER B"))) -> TER A | K20: 1 | L20: 12 | M20: =('[3]DAFTAR UPAH MAINTENANCE'!F18+'[3]DAFTAR UPAH MAINTENANCE'!J18+'[3]DAFTAR UPAH MAINTENANCE'!L18+'[3]DAFTAR UPAH MAINTENANCE'!N18+'[3]DAFTAR UPAH MAINTENANCE'!P18+'[3]DAFTAR UPAH MAINTENANCE'!R18)*129220 -> 4005820 | N20: ='[3]DAFTAR UPAH MAINTENANCE'!BN18 -> 120250 | O20: =[3]PPH!L21+[3]PPH!M21 -> 190071.64 | P20: 0 | Q20: =SUM(M20:P20) -> 4316141.6 | R20: =+PERBULAN!S22 -> 3991100 | S20: =+SETAHUN!J22 -> 900000 | T20: 0 | U20: =+SETAHUN!F22+M20+N20 -> 48443579 | V20: 0 | W20: =+SETAHUN!V22+O20 -> 2277614.5 | X20: 0 | Y20: 0 | Z20: =SUM(R20:T20) -> 4891100 | AA20: =SUM(U20:Z20) -> 55612294 | AB20: =ROUND(IF((AA20)*5%>6000000,6000000,(AA20)*5%),0) -> 2780615 | AC20: =('ASTEK-DIISI SMPAI DES'!O22+'ASTEK-DIISI SMPAI DES'!O137) -> 1404666 | AD20: =AA20-AB20-AC20 -> 51427013 | AE20: =IFERROR(VLOOKUP(I20,TARIF,3,FALSE),0) -> 54000000 | AF20: =ROUNDDOWN(IF(AD20<=AE20,0,IF(AD20>AE20,AD20-AE20)),-3) -> 0 | AG20: =IF(AF20>5000000000,AF20*35%-306000000,IF(AF20>500000000,AF20*30%-56000000,IF(AF20>250000000,AF20*25%-31000000,IF(AF20>60000000,AF20*15%-6000000,AF20*5%)))) -> 0 | AH20: =ROUND(IF(E20=0,AG20*120%,AG20),0) -> 0 | AI20: =+'PAJAK JAN-NOV'!R17 -> 124548 | AJ20: =IF(AG20<=AI20,0,IF(AG20>AI20,AG20-AI20)) -> 0 | AL20: =AI20-AH20 -> 124548
B21: 16 | C21: =+PERBULAN!B23 -> TUTI | D21: 1906045008740002 | E21: 97.228.664.5-305.000 | F21: DSN CENDIL RT. 006 RW. 002 DESA CENDIL KEC. KELAPA KAMPIT | G21: KARYAWAN PERAWATAN | H21: P | I21: TK/0 | J21: =IF(ISBLANK(I21),"",IF(OR(I21="TK/0",I21="TK/1",I21="K/0"),"TER A",IF(I21="K/3","TER C","TER B"))) -> TER A | K21: 1 | L21: 12 | M21: =('[3]DAFTAR UPAH MAINTENANCE'!F19+'[3]DAFTAR UPAH MAINTENANCE'!J19+'[3]DAFTAR UPAH MAINTENANCE'!L19+'[3]DAFTAR UPAH MAINTENANCE'!N19+'[3]DAFTAR UPAH MAINTENANCE'!P19+'[3]DAFTAR UPAH MAINTENANCE'!R19)*129220 -> 3876600 | N21: ='[3]DAFTAR UPAH MAINTENANCE'!BN19 -> 121500 | O21: =[3]PPH!L22+[3]PPH!M22 -> 190241.04 | P21: 0 | Q21: =SUM(M21:P21) -> 4188341 | R21: =+PERBULAN!S23 -> 3994600 | S21: =+SETAHUN!J23 -> 600000 | T21: 0 | U21: =+SETAHUN!F23+M21+N21 -> 48492577 | V21: 0 | W21: =+SETAHUN!V23+O21 -> 2279750.9 | X21: 0 | Y21: 0 | Z21: =SUM(R21:T21) -> 4594600 | AA21: =SUM(U21:Z21) -> 55366928 | AB21: =ROUND(IF((AA21)*5%>6000000,6000000,(AA21)*5%),0) -> 2768346 | AC21: =('ASTEK-DIISI SMPAI DES'!O23+'ASTEK-DIISI SMPAI DES'!O138) -> 1405296 | AD21: =AA21-AB21-AC21 -> 51193286 | AE21: =IFERROR(VLOOKUP(I21,TARIF,3,FALSE),0) -> 54000000 | AF21: =ROUNDDOWN(IF(AD21<=AE21,0,IF(AD21>AE21,AD21-AE21)),-3) -> 0 | AG21: =IF(AF21>5000000000,AF21*35%-306000000,IF(AF21>500000000,AF21*30%-56000000,IF(AF21>250000000,AF21*25%-31000000,IF(AF21>60000000,AF21*15%-6000000,AF21*5%)))) -> 0 | AH21: =ROUND(IF(E21=0,AG21*120%,AG21),0) -> 0 | AI21: =+'PAJAK JAN-NOV'!R18 -> 124655 | AJ21: =IF(AG21<=AI21,0,IF(AG21>AI21,AG21-AI21)) -> 0 | AL21: =AI21-AH21 -> 124655
B22: 17 | C22: =+PERBULAN!B24 -> AGUSTIANA | D22: 1906044208840004 | E22: 97.228.616.5-305.000 | F22: DSN CENDIL RT. 003 RW. 001 DESA CENDIL KEC. KELAPA KAMPIT | G22: KARYAWAN PERAWATAN | H22: P | I22: TK/0 | J22: =IF(ISBLANK(I22),"",IF(OR(I22="TK/0",I22="TK/1",I22="K/0"),"TER A",IF(I22="K/3","TER C","TER B"))) -> TER A | K22: 1 | L22: 12 | M22: =('[3]DAFTAR UPAH MAINTENANCE'!F20+'[3]DAFTAR UPAH MAINTENANCE'!J20+'[3]DAFTAR UPAH MAINTENANCE'!L20+'[3]DAFTAR UPAH MAINTENANCE'!N20+'[3]DAFTAR UPAH MAINTENANCE'!P20+'[3]DAFTAR UPAH MAINTENANCE'!R20)*129220 -> 4005820 | N22: ='[3]DAFTAR UPAH MAINTENANCE'!BN20 -> 123750 | O22: =[3]PPH!L23+[3]PPH!M23 -> 190241.04 | P22: 0 | Q22: =SUM(M22:P22) -> 4319811 | R22: =+PERBULAN!S24 -> 3994600 | S22: =+SETAHUN!J24 -> 600000 | T22: 0 | U22: =+SETAHUN!F24+M22+N22 -> 48610048 | V22: 0 | W22: =+SETAHUN!V24+O22 -> 2279161.5 | X22: 0 | Y22: 0 | Z22: =SUM(R22:T22) -> 4594600 | AA22: =SUM(U22:Z22) -> 55483809 | AB22: =ROUND(IF((AA22)*5%>6000000,6000000,(AA22)*5%),0) -> 2774190 | AC22: =('ASTEK-DIISI SMPAI DES'!O24+'ASTEK-DIISI SMPAI DES'!O139) -> 1405191 | AD22: =AA22-AB22-AC22 -> 51304428 | AE22: =IFERROR(VLOOKUP(I22,TARIF,3,FALSE),0) -> 54000000 | AF22: =ROUNDDOWN(IF(AD22<=AE22,0,IF(AD22>AE22,AD22-AE22)),-3) -> 0 | AG22: =IF(AF22>5000000000,AF22*35%-306000000,IF(AF22>500000000,AF22*30%-56000000,IF(AF22>250000000,AF22*25%-31000000,IF(AF22>60000000,AF22*15%-6000000,AF22*5%)))) -> 0 | AH22: =ROUND(IF(E22=0,AG22*120%,AG22),0) -> 0 | AI22: =+'PAJAK JAN-NOV'!R19 -> 124655 | AJ22: =IF(AG22<=AI22,0,IF(AG22>AI22,AG22-AI22)) -> 0 | AL22: =AI22-AH22 -> 124655
... B27: 22 | C27: =+PERBULAN!B29 -> HARYANI | D27: 1906040507710002 | E27: 97.228.648.8-305.000 | F27: DSN PESARAKAN RT. 007 RW. 003 DESA CENDIL KEC. KELAPA KAMPIT | G27: KARYAWAN PERAWATAN | H27: L | I27: K/0 | J27: =IF(ISBLANK(I27),"",IF(OR(I27="TK/0",I27="TK/1",I27="K/0"),"TER A",IF(I27="K/3","TER C","TER B"))) -> TER A | K27: 1 | L27: 12 | M27: =('[3]DAFTAR UPAH MAINTENANCE'!F25+'[3]DAFTAR UPAH MAINTENANCE'!J25+'[3]DAFTAR UPAH MAINTENANCE'!L25+'[3]DAFTAR UPAH MAINTENANCE'!N25+'[3]DAFTAR UPAH MAINTENANCE'!P25+'[3]DAFTAR UPAH MAINTENANCE'!R25)*129220 -> 4005820 | N27: ='[3]DAFTAR UPAH MAINTENANCE'!BN25 -> 172200 | O27: =[3]PPH!L28+[3]PPH!M28 -> 190410.44 | P27: 0 | Q27: =SUM(M27:P27) -> 4368430.4 | R27: =+PERBULAN!S29 -> 4038600 | S27: =+SETAHUN!J29 -> 900000 | T27: 0 | U27: =+SETAHUN!F29+M27+N27 -> 49168396 | V27: 0 | W27: =+SETAHUN!V29+O27 -> 2280679.1 | X27: 0 | Y27: 0 | Z27: =SUM(R27:T27) -> 4938600 | AA27: =SUM(U27:Z27) -> 56387675 | AB27: =ROUND(IF((AA27)*5%>6000000,6000000,(AA27)*5%),0) -> 2819384 | AC27: =('ASTEK-DIISI SMPAI DES'!O29+'ASTEK-DIISI SMPAI DES'!O144) -> 1405611 | AD27: =AA27-AB27-AC27 -> 52162680 | AE27: =IFERROR(VLOOKUP(I27,TARIF,3,FALSE),0) -> 58500000 | AF27: =ROUNDDOWN(IF(AD27<=AE27,0,IF(AD27>AE27,AD27-AE27)),-3) -> 0 | AG27: =IF(AF27>5000000000,AF27*35%-306000000,IF(AF27>500000000,AF27*30%-56000000,IF(AF27>250000000,AF27*25%-31000000,IF(AF27>60000000,AF27*15%-6000000,AF27*5%)))) -> 0 | AH27: =ROUND(IF(E27=0,AG27*120%,AG27),0) -> 0 | AI27: =+'PAJAK JAN-NOV'!R24 -> 126044 | AJ27: =IF(AG27<=AI27,0,IF(AG27>AI27,AG27-AI27)) -> 0 | AL27: =AI27-AH27 -> 126044
B28: 23 | C28: =+PERBULAN!B30 -> SUWANDI | D28: 1906042110820002 | E28: 68.076.4.347-305.000 | F28: DSN CENDIL RT. 005 RW. 001 DESA CENDIL KEC. KELAPA KAMPIT | G28: KARYAWAN PERAWATAN | H28: L | I28: K/1 | J28: =IF(ISBLANK(I28),"",IF(OR(I28="TK/0",I28="TK/1",I28="K/0"),"TER A",IF(I28="K/3","TER C","TER B"))) -> TER B | K28: 1 | L28: 12 | M28: =(4400000/30)*31 -> 4546666.7 | N28: ='[3]DAFTAR UPAH MAINTENANCE'!BN26 -> 273078.32 | O28: =[3]PPH!L29+[3]PPH!M29 -> 215404.2 | P28: 0 | Q28: =SUM(M28:P28) -> 5035149.2 | R28: =+PERBULAN!S30 -> 4590000 | S28: =+SETAHUN!J30 -> 600000 | T28: 0 | U28: =+SETAHUN!F30+M28+N28 -> 56746345 | V28: 0 | W28: =+SETAHUN!V30+O28 -> 2582165.2 | X28: 0 | Y28: 0 | Z28: =SUM(R28:T28) -> 5190000 | AA28: =SUM(U28:Z28) -> 64518510 | AB28: =ROUND(IF((AA28)*5%>6000000,6000000,(AA28)*5%),0) -> 3225926 | AC28: =('ASTEK-DIISI SMPAI DES'!O30+'ASTEK-DIISI SMPAI DES'!O145) -> 1530282 | AD28: =AA28-AB28-AC28 -> 59762302 | AE28: =IFERROR(VLOOKUP(I28,TARIF,3,FALSE),0) -> 63000000 | AF28: =ROUNDDOWN(IF(AD28<=AE28,0,IF(AD28>AE28,AD28-AE28)),-3) -> 0 | AG28: =IF(AF28>5000000000,AF28*35%-306000000,IF(AF28>500000000,AF28*30%-56000000,IF(AF28>250000000,AF28*25%-31000000,IF(AF28>60000000,AF28*15%-6000000,AF28*5%)))) -> 0 | AH28: =ROUND(IF(E28=0,AG28*120%,AG28),0) -> 0 | AI28: =+'PAJAK JAN-NOV'!R25 -> 143194 | AJ28: =IF(AG28<=AI28,0,IF(AG28>AI28,AG28-AI28)) -> 0 | AL28: =AI28-AH28 -> 143194
B29: 24 | C29: =+PERBULAN!B31 -> YUMNA M | D29: 1906046008750003 | E29: 97.228.655.3-305.000 | F29: DSN LIMAU MANIS RT. 013 RW. 005 DESA BUDING KEC. KELAPA KAMPIT | G29: KARYAWAN PERAWATAN | H29: P | I29: TK/0 | J29: =IF(ISBLANK(I29),"",IF(OR(I29="TK/0",I29="TK/1",I29="K/0"),"TER A",IF(I29="K/3","TER C","TER B"))) -> TER A | K29: 1 | L29: 12 | M29: =('[3]DAFTAR UPAH MAINTENANCE'!F27+'[3]DAFTAR UPAH MAINTENANCE'!J27+'[3]DAFTAR UPAH MAINTENANCE'!L27+'[3]DAFTAR UPAH MAINTENANCE'!N27+'[3]DAFTAR UPAH MAINTENANCE'!P27+'[3]DAFTAR UPAH MAINTENANCE'!R27)*129220 -> 3876600 | N29: ='[3]DAFTAR UPAH MAINTENANCE'!BN27 -> 118000 | O29: =[3]PPH!L30+[3]PPH!M30 -> 190071.64 | P29: 0 | Q29: =SUM(M29:P29) -> 4184671.6 | R29: =+PERBULAN!S31 -> 3991100 | S29: =+SETAHUN!J31 -> 200000 | T29: 0 | U29: =+SETAHUN!F31+M29+N29 -> 47914199 | V29: 0 | W29: =+SETAHUN!V31+O29 -> 2277474.5 | X29: 0 | Y29: 0 | Z29: =SUM(R29:T29) -> 4191100 | AA29: =SUM(U29:Z29) -> 54382774 | AB29: =ROUND(IF((AA29)*5%>6000000,6000000,(AA29)*5%),0) -> 2719139 | AC29: =('ASTEK-DIISI SMPAI DES'!O31+'ASTEK-DIISI SMPAI DES'!O146) -> 1404666 | AD29: =AA29-AB29-AC29 -> 50258969 | AE29: =IFERROR(VLOOKUP(I29,TARIF,3,FALSE),0) -> 54000000 | AF29: =ROUNDDOWN(IF(AD29<=AE29,0,IF(AD29>AE29,AD29-AE29)),-3) -> 0 | AG29: =IF(AF29>5000000000,AF29*35%-306000000,IF(AF29>500000000,AF29*30%-56000000,IF(AF29>250000000,AF29*25%-31000000,IF(AF29>60000000,AF29*15%-6000000,AF29*5%)))) -> 0 | AH29: =ROUND(IF(E29=0,AG29*120%,AG29),0) -> 0 | AI29: =+'PAJAK JAN-NOV'!R26 -> 122576 | AJ29: =IF(AG29<=AI29,0,IF(AG29>AI29,AG29-AI29)) -> 0 | AL29: =AI29-AH29 -> 122576
B30: 25 | C30: =+PERBULAN!B32 -> ANDRES | D30: 1902042807970004 | E30: - | F30: PELEPAK PUTIH RT. 005 RW. 003 DESA PELEPAK PUTE KEC. SIJUK | G30: KARYAWAN PERAWATAN | H30: L | I30: K/1 | J30: =IF(ISBLANK(I30),"",IF(OR(I30="TK/0",I30="TK/1",I30="K/0"),"TER A",IF(I30="K/3","TER C","TER B"))) -> TER B | K30: 1 | L30: 12 | M30: =('[3]DAFTAR UPAH MAINTENANCE'!F28+'[3]DAFTAR UPAH MAINTENANCE'!J28+'[3]DAFTAR UPAH MAINTENANCE'!L28+'[3]DAFTAR UPAH MAINTENANCE'!N28+'[3]DAFTAR UPAH MAINTENANCE'!P28+'[3]DAFTAR UPAH MAINTENANCE'!R28)*129220 -> 4005820 | N30: ='[3]DAFTAR UPAH MAINTENANCE'!BN28 -> 165150 | O30: =[3]PPH!L31+[3]PPH!M31 -> 188643.84 | P30: 0 | Q30: =SUM(M30:P30) -> 4359613.8 | R30: =+PERBULAN!S32 -> 4034100 | S30: =+SETAHUN!J32 -> 200000 | T30: 0 | U30: =+SETAHUN!F32+M30+N30 -> 50646127 | V30: 0 | W30: =+SETAHUN!V32+O30 -> 2262067.7 | X30: 0 | Y30: 0 | Z30: =SUM(R30:T30) -> 4234100 | AA30: =SUM(U30:Z30) -> 57142295 | AB30: =ROUND(IF((AA30)*5%>6000000,6000000,(AA30)*5%),0) -> 2857115 | AC30: =('ASTEK-DIISI SMPAI DES'!O32+'ASTEK-DIISI SMPAI DES'!O147) -> 1399356 | AD30: =AA30-AB30-AC30 -> 52885824 | AE30: =IFERROR(VLOOKUP(I30,TARIF,3,FALSE),0) -> 63000000 | AF30: =ROUNDDOWN(IF(AD30<=AE30,0,IF(AD30>AE30,AD30-AE30)),-3) -> 0 | AG30: =IF(AF30>5000000000,AF30*35%-306000000,IF(AF30>500000000,AF30*30%-56000000,IF(AF30>250000000,AF30*25%-31000000,IF(AF30>60000000,AF30*15%-6000000,AF30*5%)))) -> 0 | AH30: =ROUND(IF(E30=0,AG30*120%,AG30),0) -> 0 | AI30: =+'PAJAK JAN-NOV'!R27 -> 83904 | AJ30: =IF(AG30<=AI30,0,IF(AG30>AI30,AG30-AI30)) -> 0 | AL30: =AI30-AH30 -> 83904
B31: 26 | C31: =+PERBULAN!B33 -> SUDIAN | D31: 1902041101990004 | E31: - | F31: DESA SUNGAI PADANG,RT 05, RW 03 KEC,SIJUK | G31: MANDOR PERAWATAN | H31: L | I31: K/0 | J31: =IF(ISBLANK(I31),"",IF(OR(I31="TK/0",I31="TK/1",I31="K/0"),"TER A",IF(I31="K/3","TER C","TER B"))) -> TER A | K31: 1 | L31: 12 | M31: =('[3]DAFTAR UPAH MAINTENANCE'!F29+'[3]DAFTAR UPAH MAINTENANCE'!J29+'[3]DAFTAR UPAH MAINTENANCE'!L29+'[3]DAFTAR UPAH MAINTENANCE'!N29+'[3]DAFTAR UPAH MAINTENANCE'!P29+'[3]DAFTAR UPAH MAINTENANCE'!R29)*129220 -> 4005820 | N31: ='[3]DAFTAR UPAH MAINTENANCE'!BN29 -> 741832.08 | O31: =[3]PPH!L32+[3]PPH!M32 -> 187748.44 | P31: 0 | Q31: =SUM(M31:P31) -> 4935400.5 | R31: =+PERBULAN!S33 -> 2990700 | S31: =+SETAHUN!J33 -> 450000 | T31: 0 | U31: =+SETAHUN!F33+M31+N31 -> 52624488 | V31: 0 | W31: =+SETAHUN!V33+O31 -> 2252355.3 | X31: 0 | Y31: 0 | Z31: =SUM(R31:T31) -> 3440700 | AA31: =SUM(U31:Z31) -> 58317544 | AB31: =ROUND(IF((AA31)*5%>6000000,6000000,(AA31)*5%),0) -> 2915877 | AC31: =('ASTEK-DIISI SMPAI DES'!O33+'ASTEK-DIISI SMPAI DES'!O148) -> 1396026 | AD31: =AA31-AB31-AC31 -> 54005641 | AE31: =IFERROR(VLOOKUP(I31,TARIF,3,FALSE),0) -> 58500000 | AF31: =ROUNDDOWN(IF(AD31<=AE31,0,IF(AD31>AE31,AD31-AE31)),-3) -> 0 | AG31: =IF(AF31>5000000000,AF31*35%-306000000,IF(AF31>500000000,AF31*30%-56000000,IF(AF31>250000000,AF31*25%-31000000,IF(AF31>60000000,AF31*15%-6000000,AF31*5%)))) -> 0 | AH31: =ROUND(IF(E31=0,AG31*120%,AG31),0) -> 0 | AI31: =+'PAJAK JAN-NOV'!R28 -> 112718 | AJ31: =IF(AG31<=AI31,0,IF(AG31>AI31,AG31-AI31)) -> 0 | AL31: =AI31-AH31 -> 112718
B32: 27 | C32: =+PERBULAN!B34 -> YUDA HERMAWAN | D32: 1902011008970003 | E32: 20.512.132.0-305.000 | F32: JL. SIJUK RT.019/RW. 007 DS. AIR MERBAU KEC. TANJUNG PANDAN KAB. BELITUNG | G32: KERANI PANEN | H32: L | I32: TK/0 | J32: =IF(ISBLANK(I32),"",IF(OR(I32="TK/0",I32="TK/1",I32="K/0"),"TER A",IF(I32="K/3","TER C","TER B"))) -> TER A | K32: 1 | L32: 12 | M32: ='[3]DAFTAR UPAH HARVESTING'!X10*129220 -> 3747380 | N32: ='[3]DAFTAR UPAH HARVESTING'!CR10 -> 836922.84 | O32: =[3]PPH!L33+[3]PPH!M33 -> 187869.44 | P32: 0 | Q32: =SUM(M32:P32) -> 4772172.3 | R32: =+PERBULAN!S34 -> 3946600 | S32: =+SETAHUN!J34 -> 200000 | T32: 0 | U32: =+SETAHUN!F34+M32+N32 -> 61625018 | V32: 0 | W32: =+SETAHUN!V34+O32 -> 2253681.3 | X32: 0 | Y32: 0 | Z32: =SUM(R32:T32) -> 4146600 | AA32: =SUM(U32:Z32) -> 68025299 | AB32: =ROUND(IF((AA32)*5%>6000000,6000000,(AA32)*5%),0) -> 3401265 | AC32: =('ASTEK-DIISI SMPAI DES'!O34+'ASTEK-DIISI SMPAI DES'!O149) -> 1396476 | AD32: =AA32-AB32-AC32 -> 63227558 | AE32: =IFERROR(VLOOKUP(I32,TARIF,3,FALSE),0) -> 54000000 | AF32: =ROUNDDOWN(IF(AD32<=AE32,0,IF(AD32>AE32,AD32-AE32)),-3) -> 9227000 | AG32: =IF(AF32>5000000000,AF32*35%-306000000,IF(AF32>500000000,AF32*30%-56000000,IF(AF32>250000000,AF32*25%-31000000,IF(AF32>60000000,AF32*15%-6000000,AF32*5%)))) -> 461350 | AH32: =ROUND(IF(E32=0,AG32*120%,AG32),0) -> 461350 | AI32: =+'PAJAK JAN-NOV'!R29 -> 246913 | AJ32: =IF(AG32<=AI32,0,IF(AG32>AI32,AG32-AI32)) -> 214437 | AL32: =AI32-AH32 -> -214437
B33: 28 | C33: =+PERBULAN!B35 -> SABIBI | D33: 1906042208840001 | E33: - | F33: DSN BUKIT JAYA RT. 011 RW. 004 DESA BUDING KEC. KELAPA KAMPIT | G33: MANDOR PANEN | H33: L | I33: K/2 | J33: =IF(ISBLANK(I33),"",IF(OR(I33="TK/0",I33="TK/1",I33="K/0"),"TER A",IF(I33="K/3","TER C","TER B"))) -> TER B | K33: 1 | L33: 12 | M33: ='[3]DAFTAR UPAH HARVESTING'!X11*129220 -> 4005820 | N33: ='[3]DAFTAR UPAH HARVESTING'!CR11 -> 1700050 | O33: =[3]PPH!L34+[3]PPH!M34 -> 188934.24 | P33: 0 | Q33: =SUM(M33:P33) -> 5894804.2 | R33: =+PERBULAN!S35 -> 4067100 | S33: =+SETAHUN!J35 -> 200000 | T33: 0 | U33: =+SETAHUN!F35+M33+N33 -> 69837892 | V33: 0 | W33: =+SETAHUN!V35+O33 -> 2264599.7 | X33: 0 | Y33: 0 | Z33: =SUM(R33:T33) -> 4267100 | AA33: =SUM(U33:Z33) -> 76369591 | AB33: =ROUND(IF((AA33)*5%>6000000,6000000,(AA33)*5%),0) -> 3818480 | AC33: =('ASTEK-DIISI SMPAI DES'!O35+'ASTEK-DIISI SMPAI DES'!O150) -> 1400256 | AD33: =AA33-AB33-AC33 -> 71150855 | AE33: =IFERROR(VLOOKUP(I33,TARIF,3,FALSE),0) -> 67500000 | AF33: =ROUNDDOWN(IF(AD33<=AE33,0,IF(AD33>AE33,AD33-AE33)),-3) -> 3650000 | AG33: =IF(AF33>5000000000,AF33*35%-306000000,IF(AF33>500000000,AF33*30%-56000000,IF(AF33>250000000,AF33*25%-31000000,IF(AF33>60000000,AF33*15%-6000000,AF33*5%)))) -> 182500 | AH33: =ROUND(IF(E33=0,AG33*120%,AG33),0) -> 182500 | AI33: =+'PAJAK JAN-NOV'!R30 -> 248042 | AJ33: =IF(AG33<=AI33,0,IF(AG33>AI33,AG33-AI33)) -> 0 | AL33: =AI33-AH33 -> 65542
B34: 29 | C34: =+PERBULAN!B36 -> ADI SANJAYA | D34: 1906042909920002 | E34: - | F34: DSN CENDIL RT 002 RW. 001 DESA CENDIL KEC. KELAPA KAMPIT | G34: KARYAWAN PANEN | H34: L | I34: K/2 | J34: =IF(ISBLANK(I34),"",IF(OR(I34="TK/0",I34="TK/1",I34="K/0"),"TER A",IF(I34="K/3","TER C","TER B"))) -> TER B | K34: 1 | L34: 12 | M34: ='[3]DAFTAR UPAH HARVESTING'!X13*129220 -> 4005820 | N34: ='[3]DAFTAR UPAH HARVESTING'!CR13 -> 2443385 | O34: =[3]PPH!L35+[3]PPH!M35 -> 188934.24 | P34: 0 | Q34: =SUM(M34:P34) -> 6638139.2 | R34: =+PERBULAN!S36 -> 4067100 | S34: =+SETAHUN!J36 -> 900000 | T34: 0 | U34: =+SETAHUN!F36+M34+N34 -> 61648715 | V34: 0 | W34: =+SETAHUN!V36+O34 -> 2264549.3 | X34: 0 | Y34: 0 | Z34: =SUM(R34:T34) -> 4967100 | AA34: =SUM(U34:Z34) -> 68880364 | AB34: =ROUND(IF((AA34)*5%>6000000,6000000,(AA34)*5%),0) -> 3444018 | AC34: =('ASTEK-DIISI SMPAI DES'!O36+'ASTEK-DIISI SMPAI DES'!O151) -> 1400076 | AD34: =AA34-AB34-AC34 -> 64036270 | AE34: =IFERROR(VLOOKUP(I34,TARIF,3,FALSE),0) -> 67500000 | AF34: =ROUNDDOWN(IF(AD34<=AE34,0,IF(AD34>AE34,AD34-AE34)),-3) -> 0 | AG34: =IF(AF34>5000000000,AF34*35%-306000000,IF(AF34>500000000,AF34*30%-56000000,IF(AF34>250000000,AF34*25%-31000000,IF(AF34>60000000,AF34*15%-6000000,AF34*5%)))) -> 0 | AH34: =ROUND(IF(E34=0,AG34*120%,AG34),0) -> 0 | AI34: =+'PAJAK JAN-NOV'!R31 -> 151047 | AJ34: =IF(AG34<=AI34,0,IF(AG34>AI34,AG34-AI34)) -> 0 | AL34: =AI34-AH34 -> 151047
B35: 30 | C35: =+PERBULAN!B37 -> ANDI ( ASNA ) | D35: 1902041409850001 | E35: - | F35: AIK KALAK RT. 008 RW. 004 DESA PELEPAK PUTE KEC. SIJUK | G35: KARYAWAN PANEN | H35: L | I35: K/2 | J35: =IF(ISBLANK(I35),"",IF(OR(I35="TK/0",I35="TK/1",I35="K/0"),"TER A",IF(I35="K/3","TER C","TER B"))) -> TER B | K35: 1 | L35: 12 | M35: ='[3]DAFTAR UPAH HARVESTING'!X14*129220 -> 4005820 | N35: ='[3]DAFTAR UPAH HARVESTING'!CR14 -> 2513007 | O35: =[3]PPH!L36+[3]PPH!M36 -> 188934.24 | P35: 0 | Q35: =SUM(M35:P35) -> 6707761.2 | R35: =+PERBULAN!S37 -> 4067100 | S35: =+SETAHUN!J37 -> 600000 | T35: 0 | U35: =+SETAHUN!F37+M35+N35 -> 63357096 | V35: 0 | W35: =+SETAHUN!V37+O35 -> 2264404.1 | X35: 0 | Y35: 0 | Z35: =SUM(R35:T35) -> 4667100 | AA35: =SUM(U35:Z35) -> 70288600 | AB35: =ROUND(IF((AA35)*5%>6000000,6000000,(AA35)*5%),0) -> 3514430 | AC35: =('ASTEK-DIISI SMPAI DES'!O37+'ASTEK-DIISI SMPAI DES'!O152) -> 1399986 | AD35: =AA35-AB35-AC35 -> 65374184 | AE35: =IFERROR(VLOOKUP(I35,TARIF,3,FALSE),0) -> 67500000 | AF35: =ROUNDDOWN(IF(AD35<=AE35,0,IF(AD35>AE35,AD35-AE35)),-3) -> 0 | AG35: =IF(AF35>5000000000,AF35*35%-306000000,IF(AF35>500000000,AF35*30%-56000000,IF(AF35>250000000,AF35*25%-31000000,IF(AF35>60000000,AF35*15%-6000000,AF35*5%)))) -> 0 | AH35: =ROUND(IF(E35=0,AG35*120%,AG35),0) -> 0 | AI35: =+'PAJAK JAN-NOV'!R32 -> 168427 | AJ35: =IF(AG35<=AI35,0,IF(AG35>AI35,AG35-AI35)) -> 0 | AL35: =AI35-AH35 -> 168427
B36: 31 | C36: =+PERBULAN!B38 -> EFRIYONO | D36: 1906041907900002 | E36: - | F36: DSN CENDIL RT. 001 RW. 001 DESA CENDIL KEC. KELAPA KAMPIT | G36: KARYAWAN PANEN | H36: L | I36: K/2 | J36: =IF(ISBLANK(I36),"",IF(OR(I36="TK/0",I36="TK/1",I36="K/0"),"TER A",IF(I36="K/3","TER C","TER B"))) -> TER B | K36: 1 | L36: 12 | M36: ='[3]DAFTAR UPAH HARVESTING'!X15*129220 -> 4005820 | N36: ='[3]DAFTAR UPAH HARVESTING'!CR15 -> 2109894 | O36: =[3]PPH!L37+[3]PPH!M37 -> 188934.24 | P36: 0 | Q36: =SUM(M36:P36) -> 6304648.2 | R36: =+PERBULAN!S38 -> 4067100 | S36: =+SETAHUN!J38 -> 200000 | T36: 0 | U36: =+SETAHUN!F38+M36+N36 -> 60411279 | V36: 0 | W36: =+SETAHUN!V38+O36 -> 2265490.1 | X36: 0 | Y36: 0 | Z36: =SUM(R36:T36) -> 4267100 | AA36: =SUM(U36:Z36) -> 66943869 | AB36: =ROUND(IF((AA36)*5%>6000000,6000000,(AA36)*5%),0) -> 3347193 | AC36: =('ASTEK-DIISI SMPAI DES'!O38+'ASTEK-DIISI SMPAI DES'!O153) -> 1400436 | AD36: =AA36-AB36-AC36 -> 62196240 | AE36: =IFERROR(VLOOKUP(I36,TARIF,3,FALSE),0) -> 67500000 | AF36: =ROUNDDOWN(IF(AD36<=AE36,0,IF(AD36>AE36,AD36-AE36)),-3) -> 0 | AG36: =IF(AF36>5000000000,AF36*35%-306000000,IF(AF36>500000000,AF36*30%-56000000,IF(AF36>250000000,AF36*25%-31000000,IF(AF36>60000000,AF36*15%-6000000,AF36*5%)))) -> 0 | AH36: =ROUND(IF(E36=0,AG36*120%,AG36),0) -> 0 | AI36: =+'PAJAK JAN-NOV'!R33 -> 150068 | AJ36: =IF(AG36<=AI36,0,IF(AG36>AI36,AG36-AI36)) -> 0 | AL36: =AI36-AH36 -> 150068
B37: 32 | C37: =+PERBULAN!B39 -> ERI HANDRAYANI | D37: 1906040611820002 | E37: - | F37: DSN CENDIL RT. 006 RW. 002 DESA CENDIL KEC. KELAPA KAMPIT | G37: KARYAWAN PANEN | H37: L | I37: K/2 | J37: =IF(ISBLANK(I37),"",IF(OR(I37="TK/0",I37="TK/1",I37="K/0"),"TER A",IF(I37="K/3","TER C","TER B"))) -> TER B | K37: 1 | L37: 12 | M37: ='[3]DAFTAR UPAH HARVESTING'!X16*129220 -> 4005820 | N37: ='[3]DAFTAR UPAH HARVESTING'!CR16 -> 2371480 | O37: =[3]PPH!L38+[3]PPH!M38 -> 188934.24 | P37: 0 | Q37: =SUM(M37:P37) -> 6566234.2 | R37: =+PERBULAN!S39 -> 4067100 | S37: =+SETAHUN!J39 -> 900000 | T37: 0 | U37: =+SETAHUN!F39+M37+N37 -> 61971193 | V37: 0 | W37: =+SETAHUN!V39+O37 -> 2265490.1 | X37: 0 | Y37: 0 | Z37: =SUM(R37:T37) -> 4967100 | AA37: =SUM(U37:Z37) -> 69203783 | AB37: =ROUND(IF((AA37)*5%>6000000,6000000,(AA37)*5%),0) -> 3460189 | AC37: =('ASTEK-DIISI SMPAI DES'!O39+'ASTEK-DIISI SMPAI DES'!O154) -> 1400436 | AD37: =AA37-AB37-AC37 -> 64343158 | AE37: =IFERROR(VLOOKUP(I37,TARIF,3,FALSE),0) -> 67500000 | AF37: =ROUNDDOWN(IF(AD37<=AE37,0,IF(AD37>AE37,AD37-AE37)),-3) -> 0 | AG37: =IF(AF37>5000000000,AF37*35%-306000000,IF(AF37>500000000,AF37*30%-56000000,IF(AF37>250000000,AF37*25%-31000000,IF(AF37>60000000,AF37*15%-6000000,AF37*5%)))) -> 0 | AH37: =ROUND(IF(E37=0,AG37*120%,AG37),0) -> 0 | AI37: =+'PAJAK JAN-NOV'!R34 -> 151051 | AJ37: =IF(AG37<=AI37,0,IF(AG37>AI37,AG37-AI37)) -> 0 | AL37: =AI37-AH37 -> 151051
B38: 33 | C38: =+PERBULAN!B40 -> FERBI H | D38: 1906040509950002 | E38: - | F38: DSN CENDIL RT. 006 RW. 002 DESA CENDIL KEC. KELAPA KAMPIT | G38: KARYAWAN PANEN | H38: L | I38: K/0 | J38: =IF(ISBLANK(I38),"",IF(OR(I38="TK/0",I38="TK/1",I38="K/0"),"TER A",IF(I38="K/3","TER C","TER B"))) -> TER A | K38: 1 | L38: 12 | M38: ='[3]DAFTAR UPAH HARVESTING'!X17*129220 -> 3747380 | N38: ='[3]DAFTAR UPAH HARVESTING'!CR17 -> 2150006.2 | O38: =[3]PPH!L39+[3]PPH!M39 -> 188934.24 | P38: 0 | Q38: =SUM(M38:P38) -> 6086320.5 | R38: =+PERBULAN!S40 -> 4011600 | S38: =+SETAHUN!J40 -> 200000 | T38: 0 | U38: =+SETAHUN!F40+M38+N38 -> 56148058 | V38: 0 | W38: =+SETAHUN!V40+O38 -> 2264839.7 | X38: 0 | Y38: 0 | Z38: =SUM(R38:T38) -> 4211600 | AA38: =SUM(U38:Z38) -> 62624497 | AB38: =ROUND(IF((AA38)*5%>6000000,6000000,(AA38)*5%),0) -> 3131225 | AC38: =('ASTEK-DIISI SMPAI DES'!O40+'ASTEK-DIISI SMPAI DES'!O155) -> 1400256 | AD38: =AA38-AB38-AC38 -> 58093016 | AE38: =IFERROR(VLOOKUP(I38,TARIF,3,FALSE),0) -> 58500000 | AF38: =ROUNDDOWN(IF(AD38<=AE38,0,IF(AD38>AE38,AD38-AE38)),-3) -> 0 | AG38: =IF(AF38>5000000000,AF38*35%-306000000,IF(AF38>500000000,AF38*30%-56000000,IF(AF38>250000000,AF38*25%-31000000,IF(AF38>60000000,AF38*15%-6000000,AF38*5%)))) -> 0 | AH38: =ROUND(IF(E38=0,AG38*120%,AG38),0) -> 0 | AI38: =+'PAJAK JAN-NOV'!R35 -> 182504 | AJ38: =IF(AG38<=AI38,0,IF(AG38>AI38,AG38-AI38)) -> 0 | AL38: =AI38-AH38 -> 182504
B39: 34 | C39: =+PERBULAN!B41 -> HAIDI | D39: 1902042507880002 | E39: - | F39: JL RAYA PELEPAK PUTE RT. 006 RW. 003 DESA PELEPAK PUTE KEC. SIJUK | G39: KARYAWAN PANEN | H39: L | I39: K/2 | J39: =IF(ISBLANK(I39),"",IF(OR(I39="TK/0",I39="TK/1",I39="K/0"),"TER A",IF(I39="K/3","TER C","TER B"))) -> TER B | K39: 1 | L39: 12 | M39: ='[3]DAFTAR UPAH HARVESTING'!X18*129220 -> 3876600 | N39: ='[3]DAFTAR UPAH HARVESTING'!CR18 -> 2276091 | O39: =[3]PPH!L40+[3]PPH!M40 -> 188789.04 | P39: 0 | Q39: =SUM(M39:P39) -> 6341480 | R39: =+PERBULAN!S41 -> 4064100 | S39: =+SETAHUN!J41 -> 200000 | T39: 0 | U39: =+SETAHUN!F41+M39+N39 -> 59292133 | V39: 0 | W39: =+SETAHUN!V41+O39 -> 2263103.3 | X39: 0 | Y39: 0 | Z39: =SUM(R39:T39) -> 4264100 | AA39: =SUM(U39:Z39) -> 65819336 | AB39: =ROUND(IF((AA39)*5%>6000000,6000000,(AA39)*5%),0) -> 3290967 | AC39: =('ASTEK-DIISI SMPAI DES'!O41+'ASTEK-DIISI SMPAI DES'!O156) -> 1399626 | AD39: =AA39-AB39-AC39 -> 61128743 | AE39: =IFERROR(VLOOKUP(I39,TARIF,3,FALSE),0) -> 67500000 | AF39: =ROUNDDOWN(IF(AD39<=AE39,0,IF(AD39>AE39,AD39-AE39)),-3) -> 0 | AG39: =IF(AF39>5000000000,AF39*35%-306000000,IF(AF39>500000000,AF39*30%-56000000,IF(AF39>250000000,AF39*25%-31000000,IF(AF39>60000000,AF39*15%-6000000,AF39*5%)))) -> 0 | AH39: =ROUND(IF(E39=0,AG39*120%,AG39),0) -> 0 | AI39: =+'PAJAK JAN-NOV'!R36 -> 150114 | AJ39: =IF(AG39<=AI39,0,IF(AG39>AI39,AG39-AI39)) -> 0 | AL39: =AI39-AH39 -> 150114
B40: 35 | C40: =+PERBULAN!B42 -> IRHAS | D40: 1906011110890002 | E40: - | F40: SUNGAI PADANG RT. 008 RW. 004 DESA SUNGAI PADANG KEC. SIJUK | G40: KARYAWAN PANEN | H40: L | I40: K/2 | J40: =IF(ISBLANK(I40),"",IF(OR(I40="TK/0",I40="TK/1",I40="K/0"),"TER A",IF(I40="K/3","TER C","TER B"))) -> TER B | K40: 1 | L40: 12 | M40: ='[3]DAFTAR UPAH HARVESTING'!X19*129220 -> 3488940 | N40: ='[3]DAFTAR UPAH HARVESTING'!CR19 -> 2000839.2 | O40: =[3]PPH!L41+[3]PPH!M41 -> 188643.84 | P40: 0 | Q40: =SUM(M40:P40) -> 5678423.1 | R40: =+PERBULAN!S42 -> 4061100 | S40: =+SETAHUN!J42 -> 200000 | T40: 0 | U40: =+SETAHUN!F42+M40+N40 -> 55340874 | V40: 0 | W40: =+SETAHUN!V42+O40 -> 2262187.7 | X40: 0 | Y40: 0 | Z40: =SUM(R40:T40) -> 4261100 | AA40: =SUM(U40:Z40) -> 61864162 | AB40: =ROUND(IF((AA40)*5%>6000000,6000000,(AA40)*5%),0) -> 3093208 | AC40: =('ASTEK-DIISI SMPAI DES'!O42+'ASTEK-DIISI SMPAI DES'!O157) -> 1399356 | AD40: =AA40-AB40-AC40 -> 57371598 | AE40: =IFERROR(VLOOKUP(I40,TARIF,3,FALSE),0) -> 67500000 | AF40: =ROUNDDOWN(IF(AD40<=AE40,0,IF(AD40>AE40,AD40-AE40)),-3) -> 0 | AG40: =IF(AF40>5000000000,AF40*35%-306000000,IF(AF40>500000000,AF40*30%-56000000,IF(AF40>250000000,AF40*25%-31000000,IF(AF40>60000000,AF40*15%-6000000,AF40*5%)))) -> 0 | AH40: =ROUND(IF(E40=0,AG40*120%,AG40),0) -> 0 | AI40: =+'PAJAK JAN-NOV'!R37 -> 144615 | AJ40: =IF(AG40<=AI40,0,IF(AG40>AI40,AG40-AI40)) -> 0 | AL40: =AI40-AH40 -> 144615
B41: 36 | C41: =+PERBULAN!B43 -> YANUAR | D41: 1906042402900002 | E41: - | F41: DSN CENDIL RT. 006 RW. 002 DESA CENDIL KEC. KELAPA KAMPIT | G41: KARYAWAN PANEN | H41: L | I41: K/2 | J41: =IF(ISBLANK(I41),"",IF(OR(I41="TK/0",I41="TK/1",I41="K/0"),"TER A",IF(I41="K/3","TER C","TER B"))) -> TER B | K41: 1 | L41: 12 | M41: ='[3]DAFTAR UPAH HARVESTING'!X20*129220 -> 3876600 | N41: ='[3]DAFTAR UPAH HARVESTING'!CR20 -> 2090701.4 | O41: =[3]PPH!L42+[3]PPH!M42 -> 189224.64 | P41: 0 | Q41: =SUM(M41:P41) -> 6156526.1 | R41: =+PERBULAN!S43 -> 4032600 | S41: =+SETAHUN!J43 -> 600000 | T41: 0 | U41: =+SETAHUN!F43+M41+N41 -> 58595932 | V41: 0 | W41: =+SETAHUN!V43+O41 -> 2268022.1 | X41: 0 | Y41: 0 | Z41: =SUM(R41:T41) -> 4632600 | AA41: =SUM(U41:Z41) -> 65496554 | AB41: =ROUND(IF((AA41)*5%>6000000,6000000,(AA41)*5%),0) -> 3274828 | AC41: =('ASTEK-DIISI SMPAI DES'!O43+'ASTEK-DIISI SMPAI DES'!O158) -> 1401336 | AD41: =AA41-AB41-AC41 -> 60820390 | AE41: =IFERROR(VLOOKUP(I41,TARIF,3,FALSE),0) -> 67500000 | AF41: =ROUNDDOWN(IF(AD41<=AE41,0,IF(AD41>AE41,AD41-AE41)),-3) -> 0 | AG41: =IF(AF41>5000000000,AF41*35%-306000000,IF(AF41>500000000,AF41*30%-56000000,IF(AF41>250000000,AF41*25%-31000000,IF(AF41>60000000,AF41*15%-6000000,AF41*5%)))) -> 0 | AH41: =ROUND(IF(E41=0,AG41*120%,AG41),0) -> 0 | AI41: =+'PAJAK JAN-NOV'!R38 -> 149121 | AJ41: =IF(AG41<=AI41,0,IF(AG41>AI41,AG41-AI41)) -> 0 | AL41: =AI41-AH41 -> 149121
