Workbook
Name februari: TARIF!#REF!
Name februari: TARIF!#REF!
Name februari: TARIF!#REF!
Name februari: TARIF!#REF!
Name februari: TARIF!#REF!
Name februari: TARIF!#REF!
Name februari: TARIF!#REF!
Name februari: TARIF!#REF!
Name februari: TARIF!#REF!
Name februari: TARIF!#REF!
Name PH: [1]TARIF!#REF!
Name PH: [1]TARIF!#REF!
Name PH: [1]TARIF!#REF!
Name PH: [1]TARIF!#REF!
Name PH: [1]TARIF!#REF!
Name PH: [1]TARIF!#REF!
Name PH: [1]TARIF!#REF!
Name PH: [1]TARIF!#REF!
Name PH: [1]TARIF!#REF!
Name PH: [1]TARIF!#REF!
Name PH: [1]TARIF!#REF!
Name PH: [1]TARIF!#REF!
Name PH: TARIF!#REF!
Name PTKP: [1]TARIF!#REF!
Name PTKP: [1]TARIF!#REF!
Name PTKP: [1]TARIF!#REF!
Name PTKP: [1]TARIF!#REF!
Name PTKP: [1]TARIF!#REF!
Name PTKP: [1]TARIF!#REF!
Name PTKP: [1]TARIF!#REF!
Name PTKP: [1]TARIF!#REF!
Name PTKP: [1]TARIF!#REF!
Name PTKP: [1]TARIF!#REF!
Name PTKP: [1]TARIF!#REF!
Name PTKP: [1]TARIF!#REF!
Name PTKP: TARIF!#REF!
Name TARIF: [2]TARIF!$S$18:$U$25
Name Ter_A: [1]TARIF!$B$3:$E$46
Name Ter_A: [1]TARIF!$B$3:$E$46
Name Ter_A: [1]TARIF!$B$3:$E$46
Name Ter_A: [1]TARIF!$B$3:$E$46
Name Ter_A: [1]TARIF!$B$3:$E$46
Name Ter_A: [1]TARIF!$B$3:$E$46
Name Ter_A: [1]TARIF!$B$3:$E$46
Name Ter_A: [1]TARIF!$B$3:$E$46
Name Ter_A: [1]TARIF!$B$3:$E$46
Name Ter_A: [1]TARIF!$B$3:$E$46
Name Ter_A: [1]TARIF!$B$3:$E$46
Name Ter_A: [1]TARIF!$B$3:$E$46
Name Ter_A: TARIF!$B$3:$E$46
Name Ter_B: [1]TARIF!$H$3:$K$42
Name Ter_B: [1]TARIF!$H$3:$K$42
Name Ter_B: [1]TARIF!$H$3:$K$42
Name Ter_B: [1]TARIF!$H$3:$K$42
Name Ter_B: [1]TARIF!$H$3:$K$42
Name Ter_B: [1]TARIF!$H$3:$K$42
Name Ter_B: [1]TARIF!$H$3:$K$42
Name Ter_B: [1]TARIF!$H$3:$K$42
Name Ter_B: [1]TARIF!$H$3:$K$42
Name Ter_B: [1]TARIF!$H$3:$K$42

Sheet TARIF
A1: PTKP (TK/0, TK/1, K/0) | G1: PTKP (TK/2, TK/3, K/1, K/2) | M1: PTKP (K/3) | S1: HARIAN
A2: No | B2: Lapisan Penghasilan bruto (Rp.) | E2: TER A | G2: No | H2: Lapisan Penghasilan bruto (Rp.) | K2: TER B | M2: No | N2: Lapisan Penghasilan bruto (Rp.) | Q2: TER C | S2: Penghasilan Bruto | V2: Tarif
A3: 1 | B3: 0 | C3: s.d | D3: 5400000 | E3: 0 | G3: 1 | H3: 0 | I3: s.d | J3: 6200000 | K3: 0 | M3: 1 | N3: 0 | O3: s.d | P3: 6600000 | Q3: 0 | S3: 0 | T3: s.d | U3: 450000 | V3: 0
A4: =A3+1 -> 2 | B4: =D3+1 -> 5400001 | C4: s.d | D4: 5650000 | E4: 0.0025 | G4: =G3+1 -> 2 | H4: =J3+1 -> 6200001 | I4: s.d | J4: 6500000 | K4: 0.0025 | M4: =M3+1 -> 2 | N4: =P3+1 -> 6600001 | O4: s.d | P4: 6950000 | Q4: 0.0025 | S4: 450001 | T4: s.d | U4: 2500000 | V4: 0.005
A5: =A4+1 -> 3 | B5: =D4+1 -> 5650001 | C5: s.d | D5: 5950000 | E5: 0.005 | G5: =G4+1 -> 3 | H5: =J4+1 -> 6500001 | I5: s.d | J5: 6850000 | K5: 0.005 | M5: =M4+1 -> 3 | N5: =P4+1 -> 6950001 | O5: s.d | P5: 7350000 | Q5: 0.005
A6: =A5+1 -> 4 | B6: =D5+1 -> 5950001 | C6: s.d | D6: 6300000 | E6: 0.0075 | G6: =G5+1 -> 4 | H6: =J5+1 -> 6850001 | I6: s.d | J6: 7300000 | K6: 0.0075 | M6: =M5+1 -> 4 | N6: =P5+1 -> 7350001 | O6: s.d | P6: 7800000 | Q6: 0.0075
A7: =A6+1 -> 5 | B7: =D6+1 -> 6300001 | C7: s.d | D7: 6750000 | E7: 0.01 | G7: =G6+1 -> 5 | H7: =J6+1 -> 7300001 | I7: s.d | J7: 9200000 | K7: 0.01 | M7: =M6+1 -> 5 | N7: =P6+1 -> 7800001 | O7: s.d | P7: 8850000 | Q7: 0.01 | S7: TARIF PASAL 17 WPOP
A8: =A7+1 -> 6 | B8: =D7+1 -> 6750001 | C8: s.d | D8: 7500000 | E8: 0.0125 | G8: =G7+1 -> 6 | H8: =J7+1 -> 9200001 | I8: s.d | J8: 10750000 | K8: 0.015 | M8: =M7+1 -> 6 | N8: =P7+1 -> 8850001 | O8: s.d | P8: 9800000 | Q8: 0.0125 | S8: Lapisan PKP | V8: Tarif
A9: =A8+1 -> 7 | B9: =D8+1 -> 7500001 | C9: s.d | D9: 8550000 | E9: 0.015 | G9: =G8+1 -> 7 | H9: =J8+1 -> 10750001 | I9: s.d | J9: 11250000 | K9: 0.02 | M9: =M8+1 -> 7 | N9: =P8+1 -> 9800001 | O9: s.d | P9: 10950000 | Q9: 0.015 | S9: 0 | T9: s.d | U9: 60000000 | V9: 0.05
A10: =A9+1 -> 8 | B10: =D9+1 -> 8550001 | C10: s.d | D10: 9650000 | E10: 0.0175 | G10: =G9+1 -> 8 | H10: =J9+1 -> 11250001 | I10: s.d | J10: 11600000 | K10: 0.025 | M10: =M9+1 -> 8 | N10: =P9+1 -> 10950001 | O10: s.d | P10: 11200000 | Q10: 0.0175 | S10: =U9+1 -> 60000001 | T10: s.d | U10: 250000000 | V10: 0.15
A11: =A10+1 -> 9 | B11: =D10+1 -> 9650001 | C11: s.d | D11: 10050000 | E11: 0.02 | G11: =G10+1 -> 9 | H11: =J10+1 -> 11600001 | I11: s.d | J11: 12600000 | K11: 0.03 | M11: =M10+1 -> 9 | N11: =P10+1 -> 11200001 | O11: s.d | P11: 12050000 | Q11: 0.02 | S11: =U10+1 -> 250000001 | T11: s.d | U11: 500000000 | V11: 0.25
A12: =A11+1 -> 10 | B12: =D11+1 -> 10050001 | C12: s.d | D12: 10350000 | E12: 0.0225 | G12: =G11+1 -> 10 | H12: =J11+1 -> 12600001 | I12: s.d | J12: 13600000 | K12: 0.04 | M12: =M11+1 -> 10 | N12: =P11+1 -> 12050001 | O12: s.d | P12: 12950000 | Q12: 0.03 | S12: =U11+1 -> 500000001 | T12: s.d | U12: 5000000000 | V12: 0.3
A13: =A12+1 -> 11 | B13: =D12+1 -> 10350001 | C13: s.d | D13: 10700000 | E13: 0.025 | G13: =G12+1 -> 11 | H13: =J12+1 -> 13600001 | I13: s.d | J13: 14950000 | K13: 0.05 | M13: =M12+1 -> 11 | N13: =P12+1 -> 12950001 | O13: s.d | P13: 14150000 | Q13: 0.04 | S13: =U12+1 -> 5000000001 | T13: s.d | U13: ~~ | V13: 0.35
A14: =A13+1 -> 12 | B14: =D13+1 -> 10700001 | C14: s.d | D14: 11050000 | E14: 0.03 | G14: =G13+1 -> 12 | H14: =J13+1 -> 14950001 | I14: s.d | J14: 16400000 | K14: 0.06 | M14: =M13+1 -> 12 | N14: =P13+1 -> 14150001 | O14: s.d | P14: 1550000 | Q14: 0.05
A15: =A14+1 -> 13 | B15: =D14+1 -> 11050001 | C15: s.d | D15: 11600000 | E15: 0.035 | G15: =G14+1 -> 13 | H15: =J14+1 -> 16400001 | I15: s.d | J15: 18450000 | K15: 0.07 | M15: =M14+1 -> 13 | N15: =P14+1 -> 1550001 | O15: s.d | P15: 17050000 | Q15: 0.06
A16: =A15+1 -> 14 | B16: =D15+1 -> 11600001 | C16: s.d | D16: 12500000 | E16: 0.04 | G16: =G15+1 -> 14 | H16: =J15+1 -> 18450001 | I16: s.d | J16: 21850000 | K16: 0.08 | M16: =M15+1 -> 14 | N16: =P15+1 -> 17050001 | O16: s.d | P16: 19500000 | Q16: 0.07 | S16: PTKP
A17: =A16+1 -> 15 | B17: =D16+1 -> 12500001 | C17: s.d | D17: 13750000 | E17: 0.05 | G17: =G16+1 -> 15 | H17: =J16+1 -> 21850001 | I17: s.d | J17: 26000000 | K17: 0.09 | M17: =M16+1 -> 15 | N17: =P16+1 -> 19500001 | O17: s.d | P17: 22700000 | Q17: 0.08 | S17: Status | U17: Jumlah
A18: =A17+1 -> 16 | B18: =D17+1 -> 13750001 | C18: s.d | D18: 15100000 | E18: 0.06 | G18: =G17+1 -> 16 | H18: =J17+1 -> 26000001 | I18: s.d | J18: 27700000 | K18: 0.1 | M18: =M17+1 -> 16 | N18: =P17+1 -> 22700001 | O18: s.d | P18: 26600000 | Q18: 0.09 | S18: TK/0 | U18: 54000000
A19: =A18+1 -> 17 | B19: =D18+1 -> 15100001 | C19: s.d | D19: 16950000 | E19: 0.07 | G19: =G18+1 -> 17 | H19: =J18+1 -> 27700001 | I19: s.d | J19: 29350000 | K19: 0.11 | M19: =M18+1 -> 17 | N19: =P18+1 -> 26600001 | O19: s.d | P19: 28100000 | Q19: 0.1 | S19: TK/1 | U19: 58500000
A20: =A19+1 -> 18 | B20: =D19+1 -> 16950001 | C20: s.d | D20: 19750000 | E20: 0.08 | G20: =G19+1 -> 18 | H20: =J19+1 -> 29350001 | I20: s.d | J20: 31450000 | K20: 0.12 | M20: =M19+1 -> 18 | N20: =P19+1 -> 28100001 | O20: s.d | P20: 30100000 | Q20: 0.11 | S20: TK/2 | U20: 63000000
A21: =A20+1 -> 19 | B21: =D20+1 -> 19750001 | C21: s.d | D21: 24150000 | E21: 0.09 | G21: =G20+1 -> 19 | H21: =J20+1 -> 31450001 | I21: s.d | J21: 33950000 | K21: 0.13 | M21: =M20+1 -> 19 | N21: =P20+1 -> 30100001 | O21: s.d | P21: 32600000 | Q21: 0.12 | S21: TK/3 | U21: 67500000
A22: =A21+1 -> 20 | B22: =D21+1 -> 24150001 | C22: s.d | D22: 26450000 | E22: 0.1 | G22: =G21+1 -> 20 | H22: =J21+1 -> 33950001 | I22: s.d | J22: 37100000 | K22: 0.14 | M22: =M21+1 -> 20 | N22: =P21+1 -> 32600001 | O22: s.d | P22: 35400000 | Q22: 0.13 | S22: K/0 | U22: 58500000
A23: =A22+1 -> 21 | B23: =D22+1 -> 26450001 | C23: s.d | D23: 28000000 | E23: 0.11 | G23: =G22+1 -> 21 | H23: =J22+1 -> 37100001 | I23: s.d | J23: 41100000 | K23: 0.15 | M23: =M22+1 -> 21 | N23: =P22+1 -> 35400001 | O23: s.d | P23: 38900000 | Q23: 0.14 | S23: K/1 | U23: 63000000
A24: =A23+1 -> 22 | B24: =D23+1 -> 28000001 | C24: s.d | D24: 30050000 | E24: 0.12 | G24: =G23+1 -> 22 | H24: =J23+1 -> 41100001 | I24: s.d | J24: 45800000 | K24: 0.16 | M24: =M23+1 -> 22 | N24: =P23+1 -> 38900001 | O24: s.d | P24: 43000000 | Q24: 0.15 | S24: K/2 | U24: 67500000
A25: =A24+1 -> 23 | B25: =D24+1 -> 30050001 | C25: s.d | D25: 32400000 | E25: 0.13 | G25: =G24+1 -> 23 | H25: =J24+1 -> 45800001 | I25: s.d | J25: 49500000 | K25: 0.17 | M25: =M24+1 -> 23 | N25: =P24+1 -> 43000001 | O25: s.d | P25: 47400000 | Q25: 0.16 | S25: K/3 | U25: 72000000
A26: =A25+1 -> 24 | B26: =D25+1 -> 32400001 | C26: s.d | D26: 35400000 | E26: 0.14 | G26: =G25+1 -> 24 | H26: =J25+1 -> 49500001 | I26: s.d | J26: 53800000 | K26: 0.18 | M26: =M25+1 -> 24 | N26: =P25+1 -> 47400001 | O26: s.d | P26: 51200000 | Q26: 0.17
A27: =A26+1 -> 25 | B27: =D26+1 -> 35400001 | C27: s.d | D27: 39100000 | E27: 0.15 | G27: =G26+1 -> 25 | H27: =J26+1 -> 53800001 | I27: s.d | J27: 58500000 | K27: 0.19 | M27: =M26+1 -> 25 | N27: =P26+1 -> 51200001 | O27: s.d | P27: 55800000 | Q27: 0.18
A28: =A27+1 -> 26 | B28: =D27+1 -> 39100001 | C28: s.d | D28: 43850000 | E28: 0.16 | G28: =G27+1 -> 26 | H28: =J27+1 -> 58500001 | I28: s.d | J28: 64000000 | K28: 0.2 | M28: =M27+1 -> 26 | N28: =P27+1 -> 55800001 | O28: s.d | P28: 60400000 | Q28: 0.19
A29: =A28+1 -> 27 | B29: =D28+1 -> 43850001 | C29: s.d | D29: 47800000 | E29: 0.17 | G29: =G28+1 -> 27 | H29: =J28+1 -> 64000001 | I29: s.d | J29: 71000000 | K29: 0.21 | M29: =M28+1 -> 27 | N29: =P28+1 -> 60400001 | O29: s.d | P29: 66700000 | Q29: 0.2
A30: =A29+1 -> 28 | B30: =D29+1 -> 47800001 | C30: s.d | D30: 51400000 | E30: 0.18 | G30: =G29+1 -> 28 | H30: =J29+1 -> 71000001 | I30: s.d | J30: 80000000 | K30: 0.22 | M30: =M29+1 -> 28 | N30: =P29+1 -> 66700001 | O30: s.d | P30: 74500000 | Q30: 0.21
A31: =A30+1 -> 29 | B31: =D30+1 -> 51400001 | C31: s.d | D31: 56300000 | E31: 0.19 | G31: =G30+1 -> 29 | H31: =J30+1 -> 80000001 | I31: s.d | J31: 93000000 | K31: 0.23 | M31: =M30+1 -> 29 | N31: =P30+1 -> 74500001 | O31: s.d | P31: 83200000 | Q31: 0.22
A32: =A31+1 -> 30 | B32: =D31+1 -> 56300001 | C32: s.d | D32: 62200000 | E32: 0.2 | G32: =G31+1 -> 30 | H32: =J31+1 -> 93000001 | I32: s.d | J32: 109000000 | K32: 0.24 | M32: =M31+1 -> 30 | N32: =P31+1 -> 83200001 | O32: s.d | P32: 95600000 | Q32: 0.23
A33: =A32+1 -> 31 | B33: =D32+1 -> 62200001 | C33: s.d | D33: 68600000 | E33: 0.21 | G33: =G32+1 -> 31 | H33: =J32+1 -> 109000001 | I33: s.d | J33: 129000000 | K33: 0.25 | M33: =M32+1 -> 31 | N33: =P32+1 -> 95600001 | O33: s.d | P33: 110000000 | Q33: 0.24
A34: =A33+1 -> 32 | B34: =D33+1 -> 68600001 | C34: s.d | D34: 77500000 | E34: 0.22 | G34: =G33+1 -> 32 | H34: =J33+1 -> 129000001 | I34: s.d | J34: 163000000 | K34: 0.26 | M34: =M33+1 -> 32 | N34: =P33+1 -> 110000001 | O34: s.d | P34: 134000000 | Q34: 0.25
A35: =A34+1 -> 33 | B35: =D34+1 -> 77500001 | C35: s.d | D35: 89000000 | E35: 0.23 | G35: =G34+1 -> 33 | H35: =J34+1 -> 163000001 | I35: s.d | J35: 211000000 | K35: 0.27 | M35: =M34+1 -> 33 | N35: =P34+1 -> 134000001 | O35: s.d | P35: 169000000 | Q35: 0.26
A36: =A35+1 -> 34 | B36: =D35+1 -> 89000001 | C36: s.d | D36: 103000000 | E36: 0.24 | G36: =G35+1 -> 34 | H36: =J35+1 -> 211000001 | I36: s.d | J36: 374000000 | K36: 0.28 | M36: =M35+1 -> 34 | N36: =P35+1 -> 169000001 | O36: s.d | P36: 221000000 | Q36: 0.27
A37: =A36+1 -> 35 | B37: =D36+1 -> 103000001 | C37: s.d | D37: 125000000 | E37: 0.25 | G37: =G36+1 -> 35 | H37: =J36+1 -> 374000001 | I37: s.d | J37: 459000000 | K37: 0.29 | M37: =M36+1 -> 35 | N37: =P36+1 -> 221000001 | O37: s.d | P37: 390000000 | Q37: 0.28
... A41: =A40+1 -> 39 | B41: =D40+1 -> 337000001 | C41: s.d | D41: 454000000 | E41: 0.29 | G41: =G40+1 -> 39 | H41: =J40+1 -> 957000001 | I41: s.d | J41: 1405000000 | K41: 0.33 | M41: =M40+1 -> 39 | N41: =P40+1 -> 709000001 | O41: s.d | P41: 965000000 | Q41: 0.32
A42: =A41+1 -> 40 | B42: =D41+1 -> 454000001 | C42: s.d | D42: 550000000 | E42: 0.3 | G42: =G41+1 -> 40 | H42: =J41+1 -> 1405000001 | I42: s.d | J42: ~~ | K42: 0.34 | M42: =M41+1 -> 40 | N42: =P41+1 -> 965000001 | O42: s.d | P42: 1419000000 | Q42: 0.33
A43: =A42+1 -> 41 | B43: =D42+1 -> 550000001 | C43: s.d | D43: 695000000 | E43: 0.31 | M43: =M42+1 -> 41 | N43: =P42+1 -> 1419000001 | O43: s.d | P43: ~~ | Q43: 0.34
...

Sheet Des
C1: yang berwarna ini rumus
B2: Nomor Urut | C2: NAMA KARYAWAN | D2: N I K / PASPOR | E2: N P W P | F2: A L A M A T | G2: JABATAN | H2: STATUS KARYAWAN | M2: DESEMBER | S2: PENGHASILAN TIDAK TERATUR | V2: TOTAL GAJI POKOK | W2: TOTAL TUNJANGAN LAINNYA | X2: TOTAL PREMI ASURANSI | Y2: TOTAL TUNJANGAN PPH | Z2: TOTAL NATURA / KENIKMATAN | AA2: TOTAL THR, BONUS, TANTIEM | AB2: PENGHASILAN BRUTO SETAHUN | AC2: PENGURANG | AE2: PENGHASILAN NETTO SETAHUN | AF2: P T K P | AG2: P K P | AH2: PPH PASAL 21 | AJ2: PPH PASAL 21 JAN S.D NOP | AK2: PPH PASAL 21 DESEMBER
M3: Gaji Pokok | N3: Total Tunjangan | O3: THR NATAL | P3: Premi JKK, JKM, Kes | Q3: Tunjangan PPh | R3: Penghasilan Bruto | S3: T H R | T3: B O N U S | U3: TANTIEM
H4: L/P | I4: PTKP | J4: TER | K4: MASA KERJA | AC4: BIAYA JABATAN | AD4: TOTAL IURAN JHT/THT/JP | AH4: SETAHUN | AI4: INCLUDE NON NPWP
B5: 1 | C5: 2 | D5: 3 | E5: 4 | F5: 5 | G5: 6 | H5: 7 | I5: 8 | J5: 9 | K5: 10 | L5: 11 | M5: 12 | N5: 13 | P5: 14 | Q5: 15 | R5: 16 | S5: 17 | T5: 18 | U5: 19 | V5: 20 | W5: 21 | X5: 22 | Y5: 23 | Z5: 24 | AA5: 25 | AB5: 26 | AC5: 27 | AD5: 27 | AE5: 29 | AF5: 30 | AG5: 31 | AH5: 32 | AI5: 33 | AJ5: 34 | AK5: 35
B6: 1 | C6: =+PERBULAN!B6 -> ARYADI | D6: 1902051308710001 | E6: 97.228.371.7-305.000 | F6: DSN AIR BEGANTUNG RT. 009 RW. 003 DESA KACANG BUTOR KEC. BADAU | G6: MANDOR | H6: L | I6: TK/0 | J6: =IF(ISBLANK(I6),"",IF(OR(I6="TK/0",I6="TK/1",I6="K/0"),"TER A",IF(I6="K/3","TER C","TER B"))) -> TER A | K6: 1 | L6: 12 | M6: 3747380 | N6: 353106.64 | P6: 190071.64 | Q6: 0 | R6: =SUM(M6:Q6) -> 4290558.3 | S6: =+SETAHUN!J6 -> 3991100 | T6: =+SETAHUN!L6 -> 200000 | U6: 0 | V6: =+SETAHUN!G6+M6+N6 -> 50134091 | W6: 0 | X6: =+SETAHUN!W6+P6 -> 2277474.5 | Y6: 0 | Z6: 0 | AA6: =SUM(S6:U6) -> 4191100 | AB6: =SUM(V6:AA6) -> 56602665 | AC6: =ROUND(IF((AB6)*5%>6000000,6000000,(AB6)*5%),0) -> 2830133 | AD6: =('ASTEK 2% -DIISI SMPAI DESEMBER'!O124+'ASTEK 2% -DIISI SMPAI DESEMBER'!O5) -> 1404648 | AE6: =AB6-AC6-AD6 -> 52367884 | AF6: =IFERROR(VLOOKUP(I6,TARIF,3,FALSE),0) -> 54000000 | AG6: =ROUNDDOWN(IF(AE6<=AF6,0,IF(AE6>AF6,AE6-AF6)),-3) -> 0 | AH6: =IF(AG6>5000000000,AG6*35%-306000000,IF(AG6>500000000,AG6*30%-56000000,IF(AG6>250000000,AG6*25%-31000000,IF(AG6>60000000,AG6*15%-6000000,AG6*5%)))) -> 0 | AI6: =ROUND(IF(E6=0,AH6*120%,AH6),0) -> 0 | AJ6: =+'PAJAK JAN-NOV'!R3 -> 123670 | AK6: =IF(AH6<=AJ6,0,IF(AH6>AJ6,AH6-AJ6)) -> 0 | AL6: =+'PAJAK JAN-NOV'!B3 -> ARYADI | AM6: =AJ6-AI6 -> 123670
B7: 2 | C7: =+PERBULAN!B7 -> SUPRI | D7: 1902052505740001 | E7: 97.228.345.1-305.000 | F7: JL MANGGAR DSN AIR BEGANTUNG RT. 008 RW. 003 DESA KACANG BUTOR KEC. BADAU | G7: KARYAWAN PERAWATAN | H7: L | I7: TK/0 | J7: =IF(ISBLANK(I7),"",IF(OR(I7="TK/0",I7="TK/1",I7="K/0"),"TER A",IF(I7="K/3","TER C","TER B"))) -> TER A | K7: 1 | L7: 12 | M7: 3359720 | N7: 109000 | P7: 190071.64 | Q7: 0 | R7: =SUM(M7:Q7) -> 3658791.6 | S7: =+SETAHUN!J7 -> 3994600 | T7: =+SETAHUN!L7 -> 200000 | U7: 0 | V7: =+SETAHUN!G7+M7+N7 -> 46561690 | W7: 0 | X7: =+SETAHUN!W7+P7 -> 2278174.5 | Y7: 0 | Z7: 0 | AA7: =SUM(S7:U7) -> 4194600 | AB7: =SUM(V7:AA7) -> 53034465 | AC7: =ROUND(IF((AB7)*5%>6000000,6000000,(AB7)*5%),0) -> 2651723 | AD7: =('ASTEK 2% -DIISI SMPAI DESEMBER'!O125+'ASTEK 2% -DIISI SMPAI DESEMBER'!O6) -> 1404648 | AE7: =AB7-AC7-AD7 -> 48978094 | AF7: =IFERROR(VLOOKUP(I7,TARIF,3,FALSE),0) -> 54000000 | AG7: =ROUNDDOWN(IF(AE7<=AF7,0,IF(AE7>AF7,AE7-AF7)),-3) -> 0 | AH7: =IF(AG7>5000000000,AG7*35%-306000000,IF(AG7>500000000,AG7*30%-56000000,IF(AG7>250000000,AG7*25%-31000000,IF(AG7>60000000,AG7*15%-6000000,AG7*5%)))) -> 0 | AI7: =ROUND(IF(E7=0,AH7*120%,AH7),0) -> 0 | AJ7: =+'PAJAK JAN-NOV'!R4 -> 122683 | AK7: =IF(AH7<=AJ7,0,IF(AH7>AJ7,AH7-AJ7)) -> 0 | AL7: =+'PAJAK JAN-NOV'!B4 -> SUPRI | AM7: =AJ7-AI7 -> 122683
B8: 3 | C8: =+PERBULAN!B8 -> ROTIA | D8: 1902056802760001 | E8: 97.228.363.4-305.000 | F8: JL MANGGAR DSN PARIT GUNUNG RT. 005 RW. 003 DESA AIR BATU BUDING BADAU | G8: KARYAWAN PERAWATAN | H8: P | I8: TK/0 | J8: =IF(ISBLANK(I8),"",IF(OR(I8="TK/0",I8="TK/1",I8="K/0"),"TER A",IF(I8="K/3","TER C","TER B"))) -> TER A | K8: 1 | L8: 12 | M8: 4005820 | N8: 127250 | P8: 190410.44 | Q8: 0 | R8: =SUM(M8:Q8) -> 4323480.4 | S8: =+SETAHUN!J8 -> 3998100 | T8: =+SETAHUN!L8 -> 200000 | U8: 0 | V8: =+SETAHUN!G8+M8+N8 -> 48645046 | W8: 0 | X8: =+SETAHUN!W8+P8 -> 2280679.1 | Y8: 0 | Z8: 0 | AA8: =SUM(S8:U8) -> 4198100 | AB8: =SUM(V8:AA8) -> 55123825 | AC8: =ROUND(IF((AB8)*5%>6000000,6000000,(AB8)*5%),0) -> 2756191 | AD8: =('ASTEK 2% -DIISI SMPAI DESEMBER'!O126+'ASTEK 2% -DIISI SMPAI DESEMBER'!O7) -> 1405593 | AE8: =AB8-AC8-AD8 -> 50962041 | AF8: =IFERROR(VLOOKUP(I8,TARIF,3,FALSE),0) -> 54000000 | AG8: =ROUNDDOWN(IF(AE8<=AF8,0,IF(AE8>AF8,AE8-AF8)),-3) -> 0 | AH8: =IF(AG8>5000000000,AG8*35%-306000000,IF(AG8>500000000,AG8*30%-56000000,IF(AG8>250000000,AG8*25%-31000000,IF(AG8>60000000,AG8*15%-6000000,AG8*5%)))) -> 0 | AI8: =ROUND(IF(E8=0,AH8*120%,AH8),0) -> 0 | AJ8: =+'PAJAK JAN-NOV'!R5 -> 124762 | AK8: =IF(AH8<=AJ8,0,IF(AH8>AJ8,AH8-AJ8)) -> 0 | AL8: =+'PAJAK JAN-NOV'!B5 -> ROTIA | AM8: =AJ8-AI8 -> 124762
B9: 4 | C9: =+PERBULAN!B9 -> SURYANI | D9: 1902056503820002 | E9: 97.228.351.9-305.000 | F9: JL MANGGAR RT. 005 RW. 003 DESA AIR BATU BUDING KEC. BADAU | G9: KARYAWAN PERAWATAN | H9: P | I9: TK/0 | J9: =IF(ISBLANK(I9),"",IF(OR(I9="TK/0",I9="TK/1",I9="K/0"),"TER A",IF(I9="K/3","TER C","TER B"))) -> TER A | K9: 1 | L9: 12 | M9: 4005820 | N9: 123750 | P9: 190241.04 | Q9: 0 | R9: =SUM(M9:Q9) -> 4319811 | S9: =+SETAHUN!J9 -> 3998100 | T9: =+SETAHUN!L9 -> 200000 | U9: 0 | V9: =+SETAHUN!G9+M9+N9 -> 48709475 | W9: 0 | X9: =+SETAHUN!W9+P9 -> 2280030.9 | Y9: 0 | Z9: 0 | AA9: =SUM(S9:U9) -> 4198100 | AB9: =SUM(V9:AA9) -> 55187606 | AC9: =ROUND(IF((AB9)*5%>6000000,6000000,(AB9)*5%),0) -> 2759380 | AD9: =('ASTEK 2% -DIISI SMPAI DESEMBER'!O127+'ASTEK 2% -DIISI SMPAI DESEMBER'!O8) -> 1405278 | AE9: =AB9-AC9-AD9 -> 51022948 | AF9: =IFERROR(VLOOKUP(I9,TARIF,3,FALSE),0) -> 54000000 | AG9: =ROUNDDOWN(IF(AE9<=AF9,0,IF(AE9>AF9,AE9-AF9)),-3) -> 0 | AH9: =IF(AG9>5000000000,AG9*35%-306000000,IF(AG9>500000000,AG9*30%-56000000,IF(AG9>250000000,AG9*25%-31000000,IF(AG9>60000000,AG9*15%-6000000,AG9*5%)))) -> 0 | AI9: =ROUND(IF(E9=0,AH9*120%,AH9),0) -> 0 | AJ9: =+'PAJAK JAN-NOV'!R6 -> 124762 | AK9: =IF(AH9<=AJ9,0,IF(AH9>AJ9,AH9-AJ9)) -> 0 | AL9: =+'PAJAK JAN-NOV'!B6 -> SURYANI | AM9: =AJ9-AI9 -> 124762
B10: 5 | C10: =+PERBULAN!B10 -> SAHINA YUNI | D10: 1902055002750002 | E10: 97.228.360.0-305.000 | F10: JL MANGGAR DSN PARIT GUNUNG RT. 006 RW. 003 DESA AIR BATU BUDING BADAU | G10: KARYAWAN PERAWATAN | H10: P | I10: TK/0 | J10: =IF(ISBLANK(I10),"",IF(OR(I10="TK/0",I10="TK/1",I10="K/0"),"TER A",IF(I10="K/3","TER C","TER B"))) -> TER A | K10: 1 | L10: 12 | M10: 3876600 | N10: 121500 | P10: 190241.04 | Q10: 0 | R10: =SUM(M10:Q10) -> 4188341 | S10: =+SETAHUN!J10 -> 3994600 | T10: =+SETAHUN!L10 -> 200000 | U10: 0 | V10: =+SETAHUN!G10+M10+N10 -> 48148597 | W10: 0 | X10: =+SETAHUN!W10+P10 -> 2278483.9 | Y10: 0 | Z10: 0 | AA10: =SUM(S10:U10) -> 4194600 | AB10: =SUM(V10:AA10) -> 54621681 | AC10: =ROUND(IF((AB10)*5%>6000000,6000000,(AB10)*5%),0) -> 2731084 | AD10: =('ASTEK 2% -DIISI SMPAI DESEMBER'!O128+'ASTEK 2% -DIISI SMPAI DESEMBER'!O9) -> 1404753 | AE10: =AB10-AC10-AD10 -> 50485844 | AF10: =IFERROR(VLOOKUP(I10,TARIF,3,FALSE),0) -> 54000000 | AG10: =ROUNDDOWN(IF(AE10<=AF10,0,IF(AE10>AF10,AE10-AF10)),-3) -> 0 | AH10: =IF(AG10>5000000000,AG10*35%-306000000,IF(AG10>500000000,AG10*30%-56000000,IF(AG10>250000000,AG10*25%-31000000,IF(AG10>60000000,AG10*15%-6000000,AG10*5%)))) -> 0 | AI10: =ROUND(IF(E10=0,AH10*120%,AH10),0) -> 0 | AJ10: =+'PAJAK JAN-NOV'!R7 -> 124655 | AK10: =IF(AH10<=AJ10,0,IF(AH10>AJ10,AH10-AJ10)) -> 0 | AL10: =+'PAJAK JAN-NOV'!B7 -> SAHINA YUNI | AM10: =AJ10-AI10 -> 124655
B11: 6 | C11: =+PERBULAN!B11 -> NURLELA | D11: 1902056211790001 | E11: 97.228.384.0-305.000 | F11: JL MANGGAR RT. 008 RW. 003 DESA KACANG BUTOR KEC. BADAU | G11: KARYAWAN PERAWATAN | H11: P | I11: TK/0 | J11: =IF(ISBLANK(I11),"",IF(OR(I11="TK/0",I11="TK/1",I11="K/0"),"TER A",IF(I11="K/3","TER C","TER B"))) -> TER A | K11: 1 | L11: 12 | M11: 4005820 | N11: 165750 | P11: 192273.84 | Q11: 0 | R11: =SUM(M11:Q11) -> 4363843.8 | S11: =+SETAHUN!J11 -> 4033100 | T11: =+SETAHUN!L11 -> 200000 | U11: 0 | V11: =+SETAHUN!G11+M11+N11 -> 48826608 | W11: 0 | X11: =+SETAHUN!W11+P11 -> 2300487.7 | Y11: 0 | Z11: 0 | AA11: =SUM(S11:U11) -> 4233100 | AB11: =SUM(V11:AA11) -> 55360196 | AC11: =ROUND(IF((AB11)*5%>6000000,6000000,(AB11)*5%),0) -> 2768010 | AD11: =('ASTEK 2% -DIISI SMPAI DESEMBER'!O129+'ASTEK 2% -DIISI SMPAI DESEMBER'!O10) -> 1412838 | AE11: =AB11-AC11-AD11 -> 51179348 | AF11: =IFERROR(VLOOKUP(I11,TARIF,3,FALSE),0) -> 54000000 | AG11: =ROUNDDOWN(IF(AE11<=AF11,0,IF(AE11>AF11,AE11-AF11)),-3) -> 0 | AH11: =IF(AG11>5000000000,AG11*35%-306000000,IF(AG11>500000000,AG11*30%-56000000,IF(AG11>250000000,AG11*25%-31000000,IF(AG11>60000000,AG11*15%-6000000,AG11*5%)))) -> 0 | AI11: =ROUND(IF(E11=0,AH11*120%,AH11),0) -> 0 | AJ11: =+'PAJAK JAN-NOV'!R8 -> 125833 | AK11: =IF(AH11<=AJ11,0,IF(AH11>AJ11,AH11-AJ11)) -> 0 | AL11: =+'PAJAK JAN-NOV'!B8 -> NURLELA | AM11: =AJ11-AI11 -> 125833
B12: 7 | C12: =+PERBULAN!B12 -> SUSINARTI | D12: 1902054107830040 | E12: 97.228.356.8-305.000 | F12: JL MANGGAR RT. 009 RW. 003 DESA KACANG BUTOR KEC. BADAU | G12: KARYAWAN PERAWATAN | H12: P | I12: TK/0 | J12: =IF(ISBLANK(I12),"",IF(OR(I12="TK/0",I12="TK/1",I12="K/0"),"TER A",IF(I12="K/3","TER C","TER B"))) -> TER A | K12: 1 | L12: 12 | M12: 3876600 | N12: 118000 | P12: 190071.64 | Q12: 0 | R12: =SUM(M12:Q12) -> 4184671.6 | S12: =+SETAHUN!J12 -> 3991100 | T12: =+SETAHUN!L12 -> 200000 | U12: 0 | V12: =+SETAHUN!G12+M12+N12 -> 48298107 | W12: 0 | X12: =+SETAHUN!W12+P12 -> 2276966.3 | Y12: 0 | Z12: 0 | AA12: =SUM(S12:U12) -> 4191100 | AB12: =SUM(V12:AA12) -> 54766174 | AC12: =ROUND(IF((AB12)*5%>6000000,6000000,(AB12)*5%),0) -> 2738309 | AD12: =('ASTEK 2% -DIISI SMPAI DESEMBER'!O130+'ASTEK 2% -DIISI SMPAI DESEMBER'!O11) -> 1404333 | AE12: =AB12-AC12-AD12 -> 50623532 | AF12: =IFERROR(VLOOKUP(I12,TARIF,3,FALSE),0) -> 54000000 | AG12: =ROUNDDOWN(IF(AE12<=AF12,0,IF(AE12>AF12,AE12-AF12)),-3) -> 0 | AH12: =IF(AG12>5000000000,AG12*35%-306000000,IF(AG12>500000000,AG12*30%-56000000,IF(AG12>250000000,AG12*25%-31000000,IF(AG12>60000000,AG12*15%-6000000,AG12*5%)))) -> 0 | AI12: =ROUND(IF(E12=0,AH12*120%,AH12),0) -> 0 | AJ12: =+'PAJAK JAN-NOV'!R9 -> 124548 | AK12: =IF(AH12<=AJ12,0,IF(AH12>AJ12,AH12-AJ12)) -> 0 | AL12: =+'PAJAK JAN-NOV'!B9 -> SUSINARTI | AM12: =AJ12-AI12 -> 124548
B13: 8 | C13: =+PERBULAN!B13 -> JAHIMIN | D13: 1906040504710002 | E13: 97.228.560.5-305.000 | F13: DSN LIMAU MANIS RT. 012 RW. 005 DESA BUDING KEC. KELAPA KAMPIT | G13: KARYAWAN PERAWATAN | H13: L | I13: K/0 | J13: =IF(ISBLANK(I13),"",IF(OR(I13="TK/0",I13="TK/1",I13="K/0"),"TER A",IF(I13="K/3","TER C","TER B"))) -> TER A | K13: 1 | L13: 12 | M13: 3747380 | N13: 192800 | P13: 191765.64 | Q13: 0 | R13: =SUM(M13:Q13) -> 4131945.6 | S13: =+SETAHUN!J13 -> 4069600 | T13: =+SETAHUN!L13 -> 200000 | U13: 0 | V13: =+SETAHUN!G13+M13+N13 -> 48367645 | W13: 0 | X13: =+SETAHUN!W13+P13 -> 2295198.5 | Y13: 0 | Z13: 0 | AA13: =SUM(S13:U13) -> 4269600 | AB13: =SUM(V13:AA13) -> 54932444 | AC13: =ROUND(IF((AB13)*5%>6000000,6000000,(AB13)*5%),0) -> 2746622 | AD13: =('ASTEK 2% -DIISI SMPAI DESEMBER'!O131+'ASTEK 2% -DIISI SMPAI DESEMBER'!O12) -> 1410948 | AE13: =AB13-AC13-AD13 -> 50774874 | AF13: =IFERROR(VLOOKUP(I13,TARIF,3,FALSE),0) -> 58500000 | AG13: =ROUNDDOWN(IF(AE13<=AF13,0,IF(AE13>AF13,AE13-AF13)),-3) -> 0 | AH13: =IF(AG13>5000000000,AG13*35%-306000000,IF(AG13>500000000,AG13*30%-56000000,IF(AG13>250000000,AG13*25%-31000000,IF(AG13>60000000,AG13*15%-6000000,AG13*5%)))) -> 0 | AI13: =ROUND(IF(E13=0,AH13*120%,AH13),0) -> 0 | AJ13: =+'PAJAK JAN-NOV'!R10 -> 126945 | AK13: =IF(AH13<=AJ13,0,IF(AH13>AJ13,AH13-AJ13)) -> 0 | AL13: =+'PAJAK JAN-NOV'!B10 -> JAHIMIN | AM13: =AJ13-AI13 -> 126945
B14: 9 | C14: =+PERBULAN!B14 -> GUSTAMI | D14: 1902040505720005 | E14: 55.166.380.0-305.000 | F14: DSN SIMPANG EMPAT RT. 014 RW. 007 DESA SIJUK KEC SIJUK | G14: KARYAWAN PERAWATAN | H14: L | I14: K/1 | J14: =IF(ISBLANK(I14),"",IF(OR(I14="TK/0",I14="TK/1",I14="K/0"),"TER A",IF(I14="K/3","TER C","TER B"))) -> TER B | K14: 1 | L14: 12 | M14: 3876600 | N14: 147500 | P14: 189394.04 | Q14: 0 | R14: =SUM(M14:Q14) -> 4213494 | S14: =+SETAHUN!J14 -> 4049100 | T14: =+SETAHUN!L14 -> 200000 | U14: 0 | V14: =+SETAHUN!G14+M14+N14 -> 49313529 | W14: 0 | X14: =+SETAHUN!W14+P14 -> 2269201.9 | Y14: 0 | Z14: 0 | AA14: =SUM(S14:U14) -> 4249100 | AB14: =SUM(V14:AA14) -> 55831831 | AC14: =ROUND(IF((AB14)*5%>6000000,6000000,(AB14)*5%),0) -> 2791592 | AD14: =('ASTEK 2% -DIISI SMPAI DESEMBER'!O132+'ASTEK 2% -DIISI SMPAI DESEMBER'!O13) -> 1401603 | AE14: =AB14-AC14-AD14 -> 51638636 | AF14: =IFERROR(VLOOKUP(I14,TARIF,3,FALSE),0) -> 63000000 | AG14: =ROUNDDOWN(IF(AE14<=AF14,0,IF(AE14>AF14,AE14-AF14)),-3) -> 0 | AH14: =IF(AG14>5000000000,AG14*35%-306000000,IF(AG14>500000000,AG14*30%-56000000,IF(AG14>250000000,AG14*25%-31000000,IF(AG14>60000000,AG14*15%-6000000,AG14*5%)))) -> 0 | AI14: =ROUND(IF(E14=0,AH14*120%,AH14),0) -> 0 | AJ14: =+'PAJAK JAN-NOV'!R11 -> 84210 | AK14: =IF(AH14<=AJ14,0,IF(AH14>AJ14,AH14-AJ14)) -> 0 | AL14: =+'PAJAK JAN-NOV'!B11 -> GUSTAMI | AM14: =AJ14-AI14 -> 84210
B15: 10 | C15: =+PERBULAN!B15 -> AGUS TRIANTIKA | D15: 1906041908760003 | E15: - | F15: DSN MERDEKA RT. 001 RW. 001 DESA SENYUBUK KEC. KELAPA KAMPIT | G15: KARYAWAN PERAWATAN | H15: L | I15: K/2 | J15: =IF(ISBLANK(I15),"",IF(OR(I15="TK/0",I15="TK/1",I15="K/0"),"TER A",IF(I15="K/3","TER C","TER B"))) -> TER B | K15: 1 | L15: 12 | M15: 3747380 | N15: 187950 | P15: 188934.24 | Q15: 0 | R15: =SUM(M15:Q15) -> 4124264.2 | S15: =+SETAHUN!J15 -> 4067100 | T15: =+SETAHUN!L15 -> 200000 | U15: 0 | V15: =+SETAHUN!G15+M15+N15 -> 47333376 | W15: 0 | X15: =+SETAHUN!W15+P15 -> 2264984.9 | Y15: 0 | Z15: 0 | AA15: =SUM(S15:U15) -> 4267100 | AB15: =SUM(V15:AA15) -> 53865461 | AC15: =ROUND(IF((AB15)*5%>6000000,6000000,(AB15)*5%),0) -> 2693273 | AD15: =('ASTEK 2% -DIISI SMPAI DESEMBER'!O133+'ASTEK 2% -DIISI SMPAI DESEMBER'!O14) -> 1400328 | AE15: =AB15-AC15-AD15 -> 49771860 | AF15: =IFERROR(VLOOKUP(I15,TARIF,3,FALSE),0) -> 67500000 | AG15: =ROUNDDOWN(IF(AE15<=AF15,0,IF(AE15>AF15,AE15-AF15)),-3) -> 0 | AH15: =IF(AG15>5000000000,AG15*35%-306000000,IF(AG15>500000000,AG15*30%-56000000,IF(AG15>250000000,AG15*25%-31000000,IF(AG15>60000000,AG15*15%-6000000,AG15*5%)))) -> 0 | AI15: =ROUND(IF(E15=0,AH15*120%,AH15),0) -> 0 | AJ15: =+'PAJAK JAN-NOV'!R12 -> 83228 | AK15: =IF(AH15<=AJ15,0,IF(AH15>AJ15,AH15-AJ15)) -> 0 | AL15: =+'PAJAK JAN-NOV'!B12 -> AGUS TRIANTIKA | AM15: =AJ15-AI15 -> 83228
B16: 11 | C16: =+PERBULAN!B16 -> FIKA HOIRI | D16: 1902041110990001 | E16: - | F16: SUNGAI PADANG RT. 004 RW. 002 DESA SUNGAI PADANG KEC. SIJUK | G16: KARYAWAN PERAWATAN | H16: L | I16: K/1 | J16: =IF(ISBLANK(I16),"",IF(OR(I16="TK/0",I16="TK/1",I16="K/0"),"TER A",IF(I16="K/3","TER C","TER B"))) -> TER B | K16: 1 | L16: 12 | M16: 3747380 | N16: 147350 | P16: 188232.44 | Q16: 0 | R16: =SUM(M16:Q16) -> 4082962.4 | S16: =+SETAHUN!J16 -> 4026100 | T16: =+SETAHUN!L16 -> 200000 | U16: 0 | V16: =+SETAHUN!G16+M16+N16 -> 46171925 | W16: 0 | X16: =+SETAHUN!W16+P16 -> 2257075.3 | Y16: 0 | Z16: 0 | AA16: =SUM(S16:U16) -> 4226100 | AB16: =SUM(V16:AA16) -> 52655100 | AC16: =ROUND(IF((AB16)*5%>6000000,6000000,(AB16)*5%),0) -> 2632755 | AD16: =('ASTEK 2% -DIISI SMPAI DESEMBER'!O134+'ASTEK 2% -DIISI SMPAI DESEMBER'!O15) -> 1397508 | AE16: =AB16-AC16-AD16 -> 48624837 | AF16: =IFERROR(VLOOKUP(I16,TARIF,3,FALSE),0) -> 63000000 | AG16: =ROUNDDOWN(IF(AE16<=AF16,0,IF(AE16>AF16,AE16-AF16)),-3) -> 0 | AH16: =IF(AG16>5000000000,AG16*35%-306000000,IF(AG16>500000000,AG16*30%-56000000,IF(AG16>250000000,AG16*25%-31000000,IF(AG16>60000000,AG16*15%-6000000,AG16*5%)))) -> 0 | AI16: =ROUND(IF(E16=0,AH16*120%,AH16),0) -> 0 | AJ16: =+'PAJAK JAN-NOV'!R13 -> 81064 | AK16: =IF(AH16<=AJ16,0,IF(AH16>AJ16,AH16-AJ16)) -> 0 | AL16: =+'PAJAK JAN-NOV'!B13 -> FIKA HOIRI | AM16: =AJ16-AI16 -> 81064
B17: 12 | C17: =+PERBULAN!B17 -> NOPI HARIKA | D17: 1902014311880001 | E17: 97.228.387.3-305.000 | F17: JL KELAPA GADING RT. 017 RW. 07 KEL. PANGKAL LALANG KEC. TANJUNGPANDAN | G17: KARYAWAN PERAWATAN | H17: P | I17: TK/0 | J17: =IF(ISBLANK(I17),"",IF(OR(I17="TK/0",I17="TK/1",I17="K/0"),"TER A",IF(I17="K/3","TER C","TER B"))) -> TER A | K17: 1 | L17: 12 | M17: 3876600 | N17: 196428.32 | P17: 190071.64 | Q17: 0 | R17: =SUM(M17:Q17) -> 4263100 | S17: =+SETAHUN!J17 -> 3991100 | T17: =+SETAHUN!L17 -> 200000 | U17: 0 | V17: =+SETAHUN!G17+M17+N17 -> 48124097 | W17: 0 | X17: =+SETAHUN!W17+P17 -> 2277474.5 | Y17: 0 | Z17: 0 | AA17: =SUM(S17:U17) -> 4191100 | AB17: =SUM(V17:AA17) -> 54592672 | AC17: =ROUND(IF((AB17)*5%>6000000,6000000,(AB17)*5%),0) -> 2729634 | AD17: =('ASTEK 2% -DIISI SMPAI DESEMBER'!O135+'ASTEK 2% -DIISI SMPAI DESEMBER'!O16) -> 1404648 | AE17: =AB17-AC17-AD17 -> 50458390 | AF17: =IFERROR(VLOOKUP(I17,TARIF,3,FALSE),0) -> 54000000 | AG17: =ROUNDDOWN(IF(AE17<=AF17,0,IF(AE17>AF17,AE17-AF17)),-3) -> 0 | AH17: =IF(AG17>5000000000,AG17*35%-306000000,IF(AG17>500000000,AG17*30%-56000000,IF(AG17>250000000,AG17*25%-31000000,IF(AG17>60000000,AG17*15%-6000000,AG17*5%)))) -> 0 | AI17: =ROUND(IF(E17=0,AH17*120%,AH17),0) -> 0 | AJ17: =+'PAJAK JAN-NOV'!R14 -> 124548 | AK17: =IF(AH17<=AJ17,0,IF(AH17>AJ17,AH17-AJ17)) -> 0 | AL17: =+'PAJAK JAN-NOV'!B14 -> NOPI HARIKA | AM17: =AJ17-AI17 -> 124548
... B40: 35 | C40: =+PERBULAN!B40 -> DEDI NOPRIADI | D40: 1902040211800001 | E40: - | F40: AIK KALAK RT .007 RW. 004 DESA PELEPAK PUTE KEC. SIJUK | G40: HELPER | H40: L | I40: K/2 | J40: =IF(ISBLANK(I40),"",IF(OR(I40="TK/0",I40="TK/1",I40="K/0"),"TER A",IF(I40="K/3","TER C","TER B"))) -> TER B | K40: 1 | L40: 12 | M40: 4005820 | N40: 1927562.5 | P40: 188643.84 | Q40: 0 | R40: =SUM(M40:Q40) -> 6122026.3 | S40: =+SETAHUN!J40 -> 4061100 | T40: =+SETAHUN!L40 -> 900000 | U40: 0 | V40: =+SETAHUN!G40+M40+N40 -> 74638182 | W40: 0 | X40: =+SETAHUN!W40+P40 -> 2261657.3 | Y40: 0 | Z40: 0 | AA40: =SUM(S40:U40) -> 4961100 | AB40: =SUM(V40:AA40) -> 81860939 | AC40: =ROUND(IF((AB40)*5%>6000000,6000000,(AB40)*5%),0) -> 4093047 | AD40: =('ASTEK 2% -DIISI SMPAI DESEMBER'!O158+'ASTEK 2% -DIISI SMPAI DESEMBER'!O39) -> 1399158 | AE40: =AB40-AC40-AD40 -> 76368734 | AF40: =IFERROR(VLOOKUP(I40,TARIF,3,FALSE),0) -> 67500000 | AG40: =ROUNDDOWN(IF(AE40<=AF40,0,IF(AE40>AF40,AE40-AF40)),-3) -> 8868000 | AH40: =IF(AG40>5000000000,AG40*35%-306000000,IF(AG40>500000000,AG40*30%-56000000,IF(AG40>250000000,AG40*25%-31000000,IF(AG40>60000000,AG40*15%-6000000,AG40*5%)))) -> 443400 | AI40: =ROUND(IF(E40=0,AH40*120%,AH40),0) -> 443400 | AJ40: =+'PAJAK JAN-NOV'!R37 -> 438737 | AK40: =IF(AH40<=AJ40,0,IF(AH40>AJ40,AH40-AJ40)) -> 4663 | AL40: =+'PAJAK JAN-NOV'!B37 -> DEDI NOPRIADI | AM40: =AJ40-AI40 -> -4663
B41: 36 | C41: =+PERBULAN!B41 -> IRWANTO | D41: 1906042608880005 | E41: 97.228.308.9-305.000 | F41: DSN CENDIL RT. 005 RW. 002 DESA CENDIL KEC. KELAPA KAMPIT | G41: MANDOR | H41: L | I41: K/1 | J41: =IF(ISBLANK(I41),"",IF(OR(I41="TK/0",I41="TK/1",I41="K/0"),"TER A",IF(I41="K/3","TER C","TER B"))) -> TER B | K41: 1 | L41: 12 | M41: 3876600 | N41: 297500 | P41: 190071.64 | R41: =SUM(M41:Q41) -> 4364171.6 | S41: =+SETAHUN!J41 -> 4066600 | T41: =+SETAHUN!L41 -> 200000 | V41: =+SETAHUN!G41+M41+N41 -> 53135593 | X41: =+SETAHUN!W41+P41 -> 2278034.5 | Y41: 0 | Z41: 0 | AA41: =SUM(S41:U41) -> 4266600 | AB41: =SUM(V41:AA41) -> 59680228 | AC41: =ROUND(IF((AB41)*5%>6000000,6000000,(AB41)*5%),0) -> 2984011 | AD41: =('ASTEK 2% -DIISI SMPAI DESEMBER'!O159+'ASTEK 2% -DIISI SMPAI DESEMBER'!O40) -> 1404648 | AE41: =AB41-AC41-AD41 -> 55291569 | AF41: =IFERROR(VLOOKUP(I41,TARIF,3,FALSE),0) -> 63000000 | AG41: =ROUNDDOWN(IF(AE41<=AF41,0,IF(AE41>AF41,AE41-AF41)),-3) -> 0 | AH41: =IF(AG41>5000000000,AG41*35%-306000000,IF(AG41>500000000,AG41*30%-56000000,IF(AG41>250000000,AG41*25%-31000000,IF(AG41>60000000,AG41*15%-6000000,AG41*5%)))) -> 0 | AI41: =ROUND(IF(E41=0,AH41*120%,AH41),0) -> 0 | AJ41: =+'PAJAK JAN-NOV'!R38 -> 85372 | AK41: =IF(AH41<=AJ41,0,IF(AH41>AJ41,AH41-AJ41)) -> 0 | AL41: =+'PAJAK JAN-NOV'!B38 -> IRWANTO | AM41: =AJ41-AI41 -> 85372
B42: 37 | C42: =+PERBULAN!B42 -> ISRIN YUNUPITA | D42: 1906046301810003 | E42: 55.159.631.5-305.000 | F42: DSN JAWA RT. 001 RW. 001 DESA SENYUBUK KEC. KELAPA KAMPIT | G42: KARYAWAN PERAWATAN | H42: P | I42: TK/0 | J42: =IF(ISBLANK(I42),"",IF(OR(I42="TK/0",I42="TK/1",I42="K/0"),"TER A",IF(I42="K/3","TER C","TER B"))) -> TER A | K42: 1 | L42: 12 | M42: 3876600 | N42: 104000 | P42: 189394.04 | R42: =SUM(M42:Q42) -> 4169994 | S42: =+SETAHUN!J42 -> 3977100 | T42: =+SETAHUN!L42 -> 200000 | V42: =+SETAHUN!G42+M42+N42 -> 47479758 | X42: =+SETAHUN!W42+P42 -> 2269879.5 | Y42: 0 | Z42: 0 | AA42: =SUM(S42:U42) -> 4177100 | AB42: =SUM(V42:AA42) -> 53926737 | AC42: =ROUND(IF((AB42)*5%>6000000,6000000,(AB42)*5%),0) -> 2696337 | AD42: =('ASTEK 2% -DIISI SMPAI DESEMBER'!O160+'ASTEK 2% -DIISI SMPAI DESEMBER'!O41) -> 1402023 | AE42: =AB42-AC42-AD42 -> 49828377 | AF42: =IFERROR(VLOOKUP(I42,TARIF,3,FALSE),0) -> 54000000 | AG42: =ROUNDDOWN(IF(AE42<=AF42,0,IF(AE42>AF42,AE42-AF42)),-3) -> 0 | AH42: =IF(AG42>5000000000,AG42*35%-306000000,IF(AG42>500000000,AG42*30%-56000000,IF(AG42>250000000,AG42*25%-31000000,IF(AG42>60000000,AG42*15%-6000000,AG42*5%)))) -> 0 | AI42: =ROUND(IF(E42=0,AH42*120%,AH42),0) -> 0 | AJ42: =+'PAJAK JAN-NOV'!R39 -> 122147 | AK42: =IF(AH42<=AJ42,0,IF(AH42>AJ42,AH42-AJ42)) -> 0 | AL42: =+'PAJAK JAN-NOV'!B39 -> ISRIN YUNUPITA | AM42: =AJ42-AI42 -> 122147
B43: 38 | C43: =+PERBULAN!B43 -> ARYANI.K | D43: 1902055209790004 | E43: 75.660.309.8-305.000 | F43: JL. MANGGAR DSN PARIT GUNUNG RT. 006 RW. 003 DESA AIR BATU BUDING KEC. BADAU | G43: KARYAWAN PERAWATAN | H43: P | I43: TK/0 | J43: =IF(ISBLANK(I43),"",IF(OR(I43="TK/0",I43="TK/1",I43="K/0"),"TER A",IF(I43="K/3","TER C","TER B"))) -> TER A | K43: 1 | L43: 12 | M43: 3876600 | N43: 97500 | P43: 189079.44 | R43: =SUM(M43:Q43) -> 4163179.4 | S43: =+SETAHUN!J43 -> 3971100 | T43: =+SETAHUN!L43 -> 200000 | V43: =+SETAHUN!G43+M43+N43 -> 46879375 | X43: =+SETAHUN!W43+P43 -> 2266576.1 | Y43: 0 | Z43: 0 | AA43: =SUM(S43:U43) -> 4171100 | AB43: =SUM(V43:AA43) -> 53317051 | AC43: =ROUND(IF((AB43)*5%>6000000,6000000,(AB43)*5%),0) -> 2665853 | AD43: =('ASTEK 2% -DIISI SMPAI DESEMBER'!O161+'ASTEK 2% -DIISI SMPAI DESEMBER'!O42) -> 1400868 | AE43: =AB43-AC43-AD43 -> 49250330 | AF43: =IFERROR(VLOOKUP(I43,TARIF,3,FALSE),0) -> 54000000 | AG43: =ROUNDDOWN(IF(AE43<=AF43,0,IF(AE43>AF43,AE43-AF43)),-3) -> 0 | AH43: =IF(AG43>5000000000,AG43*35%-306000000,IF(AG43>500000000,AG43*30%-56000000,IF(AG43>250000000,AG43*25%-31000000,IF(AG43>60000000,AG43*15%-6000000,AG43*5%)))) -> 0 | AI43: =ROUND(IF(E43=0,AH43*120%,AH43),0) -> 0 | AJ43: =+'PAJAK JAN-NOV'!R40 -> 119992 | AK43: =IF(AH43<=AJ43,0,IF(AH43>AJ43,AH43-AJ43)) -> 0 | AL43: =+'PAJAK JAN-NOV'!B40 -> ARYANI.K | AM43: =AJ43-AI43 -> 119992
B44: 39 | C44: =+PERBULAN!B44 -> HARYANTI ( K ) | D44: 1906045411860001 | E44: 55.166.675.3-305.000 | F44: DSN SELINDANG RT. 007 RW. 002 DESA SENYUBUK KEC. KELAPA KAMPIT | G44: KARYAWAN PERAWATAN | H44: P | I44: TK/0 | J44: =IF(ISBLANK(I44),"",IF(OR(I44="TK/0",I44="TK/1",I44="K/0"),"TER A",IF(I44="K/3","TER C","TER B"))) -> TER A | K44: 1 | L44: 12 | M44: 3876600 | N44: 104000 | P44: 189394.04 | R44: =SUM(M44:Q44) -> 4169994 | S44: =+SETAHUN!J44 -> 3977100 | T44: =+SETAHUN!L44 -> 200000 | V44: =+SETAHUN!G44+M44+N44 -> 47348288 | X44: =+SETAHUN!W44+P44 -> 2269879.5 | Y44: 0 | Z44: 0 | AA44: =SUM(S44:U44) -> 4177100 | AB44: =SUM(V44:AA44) -> 53795267 | AC44: =ROUND(IF((AB44)*5%>6000000,6000000,(AB44)*5%),0) -> 2689763 | AD44: =('ASTEK 2% -DIISI SMPAI DESEMBER'!O162+'ASTEK 2% -DIISI SMPAI DESEMBER'!O43) -> 1402023 | AE44: =AB44-AC44-AD44 -> 49703481 | AF44: =IFERROR(VLOOKUP(I44,TARIF,3,FALSE),0) -> 54000000 | AG44: =ROUNDDOWN(IF(AE44<=AF44,0,IF(AE44>AF44,AE44-AF44)),-3) -> 0 | AH44: =IF(AG44>5000000000,AG44*35%-306000000,IF(AG44>500000000,AG44*30%-56000000,IF(AG44>250000000,AG44*25%-31000000,IF(AG44>60000000,AG44*15%-6000000,AG44*5%)))) -> 0 | AI44: =ROUND(IF(E44=0,AH44*120%,AH44),0) -> 0 | AJ44: =+'PAJAK JAN-NOV'!R41 -> 124119 | AK44: =IF(AH44<=AJ44,0,IF(AH44>AJ44,AH44-AJ44)) -> 0 | AL44: =+'PAJAK JAN-NOV'!B41 -> HARYANTI ( K ) | AM44: =AJ44-AI44 -> 124119
B45: 40 | C45: =+PERBULAN!B45 -> YUNIAR | D45: 1902056507790002 | E45: 97.228.320.4-305.000 | F45: DSN AIR BATU BUDING RT. 003 RW. 002 DESA AIR BATU BUDING KEC. BADAU | G45: KARYAWAN PERAWATAN | H45: P | I45: TK/0 | J45: =IF(ISBLANK(I45),"",IF(OR(I45="TK/0",I45="TK/1",I45="K/0"),"TER A",IF(I45="K/3","TER C","TER B"))) -> TER A | K45: 1 | L45: 12 | M45: 3747380 | N45: 119250 | P45: 190241.04 | R45: =SUM(M45:Q45) -> 4056871 | S45: =+SETAHUN!J45 -> 3998100 | T45: =+SETAHUN!L45 -> 200000 | V45: =+SETAHUN!G45+M45+N45 -> 47447817 | X45: =+SETAHUN!W45+P45 -> 2280030.9 | Y45: 0 | Z45: 0 | AA45: =SUM(S45:U45) -> 4198100 | AB45: =SUM(V45:AA45) -> 53925948 | AC45: =ROUND(IF((AB45)*5%>6000000,6000000,(AB45)*5%),0) -> 2696297 | AD45: =('ASTEK 2% -DIISI SMPAI DESEMBER'!O163+'ASTEK 2% -DIISI SMPAI DESEMBER'!O44) -> 1405278 | AE45: =AB45-AC45-AD45 -> 49824373 | AF45: =IFERROR(VLOOKUP(I45,TARIF,3,FALSE),0) -> 54000000 | AG45: =ROUNDDOWN(IF(AE45<=AF45,0,IF(AE45>AF45,AE45-AF45)),-3) -> 0 | AH45: =IF(AG45>5000000000,AG45*35%-306000000,IF(AG45>500000000,AG45*30%-56000000,IF(AG45>250000000,AG45*25%-31000000,IF(AG45>60000000,AG45*15%-6000000,AG45*5%)))) -> 0 | AI45: =ROUND(IF(E45=0,AH45*120%,AH45),0) -> 0 | AJ45: =+'PAJAK JAN-NOV'!R42 -> 124762 | AK45: =IF(AH45<=AJ45,0,IF(AH45>AJ45,AH45-AJ45)) -> 0 | AL45: =+'PAJAK JAN-NOV'!B42 -> YUNIAR | AM45: =AJ45-AI45 -> 124762
B46: 41 | C46: =+PERBULAN!B46 -> NOVELA SYAKUR | D46: 1906040711990003 | E46: - | F46: DSN CENDIL RT. 003 RW. 001 DESA CENDIL KEC. KELAPA KAMPIT | G46: KARYAWAN PERAWATAN | H46: L | I46: TK/0 | J46: =IF(ISBLANK(I46),"",IF(OR(I46="TK/0",I46="TK/1",I46="K/0"),"TER A",IF(I46="K/3","TER C","TER B"))) -> TER A | K46: 1 | L46: 12 | M46: 4005820 | N46: 93750 | P46: 188789.04 | R46: =SUM(M46:Q46) -> 4288359 | S46: =+SETAHUN!J46 -> 3965100 | T46: =+SETAHUN!L46 -> 200000 | V46: =+SETAHUN!G46+M46+N46 -> 53498549 | X46: =+SETAHUN!W46+P46 -> 2263898.9 | Y46: 0 | Z46: 0 | AA46: =SUM(S46:U46) -> 4165100 | AB46: =SUM(V46:AA46) -> 59927548 | AC46: =ROUND(IF((AB46)*5%>6000000,6000000,(AB46)*5%),0) -> 2996377 | AD46: =('ASTEK 2% -DIISI SMPAI DESEMBER'!O164+'ASTEK 2% -DIISI SMPAI DESEMBER'!O45) -> 1399878 | AE46: =AB46-AC46-AD46 -> 55531293 | AF46: =IFERROR(VLOOKUP(I46,TARIF,3,FALSE),0) -> 54000000 | AG46: =ROUNDDOWN(IF(AE46<=AF46,0,IF(AE46>AF46,AE46-AF46)),-3) -> 1531000 | AH46: =IF(AG46>5000000000,AG46*35%-306000000,IF(AG46>500000000,AG46*30%-56000000,IF(AG46>250000000,AG46*25%-31000000,IF(AG46>60000000,AG46*15%-6000000,AG46*5%)))) -> 76550 | AI46: =ROUND(IF(E46=0,AH46*120%,AH46),0) -> 76550 | AJ46: =+'PAJAK JAN-NOV'!R43 -> 183659 | AK46: =IF(AH46<=AJ46,0,IF(AH46>AJ46,AH46-AJ46)) -> 0 | AL46: =+'PAJAK JAN-NOV'!B43 -> NOVELA SYAKUR | AM46: =AJ46-AI46 -> 107109
B47: 42 | C47: =+PERBULAN!B47 -> KUDIN | D47: 5203050107700374 | E47: - | F47: DUSUN TIMBAK DESA KESIK KECAMATAN MASBAGIK | G47: KARYAWAN PERAWATAN | H47: L | I47: K/0 | J47: =IF(ISBLANK(I47),"",IF(OR(I47="TK/0",I47="TK/1",I47="K/0"),"TER A",IF(I47="K/3","TER C","TER B"))) -> TER A | K47: 1 | L47: 7 | R47: =SUM(M47:Q47) -> 0 | S47: =+SETAHUN!J47 -> 4005600 | T47: =+SETAHUN!L47 -> 600000 | V47: =+SETAHUN!G47+M47+N47 -> 24046668 | X47: =+SETAHUN!W47+P47 -> 1318583.3 | Y47: 0 | Z47: 0 | AA47: =SUM(S47:U47) -> 4605600 | AB47: =SUM(V47:AA47) -> 29970851 | AC47: =ROUND(IF((AB47)*5%>6000000,6000000,(AB47)*5%),0) -> 1498543 | AD47: =('ASTEK 2% -DIISI SMPAI DESEMBER'!O165+'ASTEK 2% -DIISI SMPAI DESEMBER'!O46) -> 814608 | AE47: =AB47-AC47-AD47 -> 27657700 | AF47: =IFERROR(VLOOKUP(I47,TARIF,3,FALSE),0) -> 58500000 | AG47: =ROUNDDOWN(IF(AE47<=AF47,0,IF(AE47>AF47,AE47-AF47)),-3) -> 0 | AH47: =IF(AG47>5000000000,AG47*35%-306000000,IF(AG47>500000000,AG47*30%-56000000,IF(AG47>250000000,AG47*25%-31000000,IF(AG47>60000000,AG47*15%-6000000,AG47*5%)))) -> 0 | AI47: =ROUND(IF(E47=0,AH47*120%,AH47),0) -> 0 | AJ47: =+'PAJAK JAN-NOV'!R44 -> 122993 | AK47: =IF(AH47<=AJ47,0,IF(AH47>AJ47,AH47-AJ47)) -> 0 | AL47: =+'PAJAK JAN-NOV'!B44 -> KUDIN | AM47: =AJ47-AI47 -> 122993
B48: 43 | C48: =+PERBULAN!B48 -> YULIATI | D48: 1902015110820006 | E48: - | F48: JL MANGGAR RT. 012 RW. 005 DS BULUH TUMBANG KEC TANJUNGPANDAN | G48: KARYAWAN PERAWATAN | H48: P | I48: TK/0 | J48: =IF(ISBLANK(I48),"",IF(OR(I48="TK/0",I48="TK/1",I48="K/0"),"TER A",IF(I48="K/3","TER C","TER B"))) -> TER A | K48: 1 | L48: 12 | M48: 3876600 | N48: 100500 | P48: 189224.64 | R48: =SUM(M48:Q48) -> 4166324.6 | S48: =+SETAHUN!J48 -> 3974100 | T48: =+SETAHUN!L48 -> 200000 | V48: =+SETAHUN!G48+M48+N48 -> 46780908 | X48: =+SETAHUN!W48+P48 -> 2268022.1 | Y48: 0 | Z48: 0 | AA48: =SUM(S48:U48) -> 4174100 | AB48: =SUM(V48:AA48) -> 53223030 | AC48: =ROUND(IF((AB48)*5%>6000000,6000000,(AB48)*5%),0) -> 2661151 | AD48: =('ASTEK 2% -DIISI SMPAI DESEMBER'!O166+'ASTEK 2% -DIISI SMPAI DESEMBER'!O47) -> 1401318 | AE48: =AB48-AC48-AD48 -> 49160561 | AF48: =IFERROR(VLOOKUP(I48,TARIF,3,FALSE),0) -> 54000000 | AG48: =ROUNDDOWN(IF(AE48<=AF48,0,IF(AE48>AF48,AE48-AF48)),-3) -> 0 | AH48: =IF(AG48>5000000000,AG48*35%-306000000,IF(AG48>500000000,AG48*30%-56000000,IF(AG48>250000000,AG48*25%-31000000,IF(AG48>60000000,AG48*15%-6000000,AG48*5%)))) -> 0 | AI48: =ROUND(IF(E48=0,AH48*120%,AH48),0) -> 0 | AJ48: =+'PAJAK JAN-NOV'!R45 -> 122055 | AK48: =IF(AH48<=AJ48,0,IF(AH48>AJ48,AH48-AJ48)) -> 0 | AL48: =+'PAJAK JAN-NOV'!B45 -> YULIATI | AM48: =AJ48-AI48 -> 122055
B49: 44 | C49: =+PERBULAN!B49 -> ROHAYA | D49: 1902014410800005 | E49: - | F49: JL RAYA BADAU PERAWAS II RT. 004 RW. 002 DESA BULUH TUMBANG KEC. TANJUNGPANDAN | G49: KARYAWAN PERAWATAN | H49: P | I49: TK/0 | J49: =IF(ISBLANK(I49),"",IF(OR(I49="TK/0",I49="TK/1",I49="K/0"),"TER A",IF(I49="K/3","TER C","TER B"))) -> TER A | K49: 1 | L49: 12 | M49: 4005820 | N49: 127750 | P49: 188934.24 | R49: =SUM(M49:Q49) -> 4322504.2 | S49: =+SETAHUN!J49 -> 3968100 | T49: =+SETAHUN!L49 -> 200000 | V49: =+SETAHUN!G49+M49+N49 -> 48564546 | X49: =+SETAHUN!W49+P49 -> 2264984.9 | Y49: 0 | Z49: 0 | AA49: =SUM(S49:U49) -> 4168100 | AB49: =SUM(V49:AA49) -> 54997631 | AC49: =ROUND(IF((AB49)*5%>6000000,6000000,(AB49)*5%),0) -> 2749882 | AD49: =('ASTEK 2% -DIISI SMPAI DESEMBER'!O167+'ASTEK 2% -DIISI SMPAI DESEMBER'!O48) -> 1400328 | AE49: =AB49-AC49-AD49 -> 50847421 | AF49: =IFERROR(VLOOKUP(I49,TARIF,3,FALSE),0) -> 54000000 | AG49: =ROUNDDOWN(IF(AE49<=AF49,0,IF(AE49>AF49,AE49-AF49)),-3) -> 0 | AH49: =IF(AG49>5000000000,AG49*35%-306000000,IF(AG49>500000000,AG49*30%-56000000,IF(AG49>250000000,AG49*25%-31000000,IF(AG49>60000000,AG49*15%-6000000,AG49*5%)))) -> 0 | AI49: =ROUND(IF(E49=0,AH49*120%,AH49),0) -> 0 | AJ49: =+'PAJAK JAN-NOV'!R46 -> 123844 | AK49: =IF(AH49<=AJ49,0,IF(AH49>AJ49,AH49-AJ49)) -> 0 | AL49: =+'PAJAK JAN-NOV'!B46 -> ROHAYA | AM49: =AJ49-AI49 -> 123844
B50: 45 | C50: =+PERBULAN!B50 -> ROSMIATI | D50: 1902044110800005 | E50: 75.694.421.1-305.000 | F50: JL JEND SUDIRMAN RT. 012 RW. 004 DS BULUH TUMBANG KEC TANJUNGPANDAN | G50: KARYAWAN PERAWATAN | H50: P | I50: TK/0 | J50: =IF(ISBLANK(I50),"",IF(OR(I50="TK/0",I50="TK/1",I50="K/0"),"TER A",IF(I50="K/3","TER C","TER B"))) -> TER A | K50: 1 | L50: 12 | M50: 4005820 | N50: 102750 | P50: 189224.64 | R50: =SUM(M50:Q50) -> 4297794.6 | S50: =+SETAHUN!J50 -> 3974100 | T50: =+SETAHUN!L50 -> 200000 | V50: =+SETAHUN!G50+M50+N50 -> 48221076 | X50: =+SETAHUN!W50+P50 -> 2267731.7 | Y50: 0 | Z50: 0 | AA50: =SUM(S50:U50) -> 4174100 | AB50: =SUM(V50:AA50) -> 54662908 | AC50: =ROUND(IF((AB50)*5%>6000000,6000000,(AB50)*5%),0) -> 2733145 | AD50: =('ASTEK 2% -DIISI SMPAI DESEMBER'!O168+'ASTEK 2% -DIISI SMPAI DESEMBER'!O49) -> 1401138 | AE50: =AB50-AC50-AD50 -> 50528625 | AF50: =IFERROR(VLOOKUP(I50,TARIF,3,FALSE),0) -> 54000000 | AG50: =ROUNDDOWN(IF(AE50<=AF50,0,IF(AE50>AF50,AE50-AF50)),-3) -> 0 | AH50: =IF(AG50>5000000000,AG50*35%-306000000,IF(AG50>500000000,AG50*30%-56000000,IF(AG50>250000000,AG50*25%-31000000,IF(AG50>60000000,AG50*15%-6000000,AG50*5%)))) -> 0 | AI50: =ROUND(IF(E50=0,AH50*120%,AH50),0) -> 0 | AJ50: =+'PAJAK JAN-NOV'!R47 -> 124027 | AK50: =IF(AH50<=AJ50,0,IF(AH50>AJ50,AH50-AJ50)) -> 0 | AL50: =+'PAJAK JAN-NOV'!B47 -> ROSMIATI | AM50: =AJ50-AI50 -> 124027
B51: 46 | C51: =+PERBULAN!B51 -> ROSMINI | D51: 1902016003970006 | E51: 75.694.309.8-305.000 | F51: JL MANGGAR RT. 017 RW. 005 DESA BULUH TUMBANG KEC. TANJUNGPANDAN | G51: KARYAWAN PERAWATAN | H51: P | I51: TK/0 | J51: =IF(ISBLANK(I51),"",IF(OR(I51="TK/0",I51="TK/1",I51="K/0"),"TER A",IF(I51="K/3","TER C","TER B"))) -> TER A | K51: 1 | L51: 12 | M51: 4005820 | N51: 96750 | P51: 188934.24 | R51: =SUM(M51:Q51) -> 4291504.2 | S51: =+SETAHUN!J51 -> 3968100 | T51: =+SETAHUN!L51 -> 200000 | V51: =+SETAHUN!G51+M51+N51 -> 48280547 | X51: =+SETAHUN!W51+P51 -> 2264549.3 | Y51: 0 | Z51: 0 | AA51: =SUM(S51:U51) -> 4168100 | AB51: =SUM(V51:AA51) -> 54713196 | AC51: =ROUND(IF((AB51)*5%>6000000,6000000,(AB51)*5%),0) -> 2735660 | AD51: =('ASTEK 2% -DIISI SMPAI DESEMBER'!O169+'ASTEK 2% -DIISI SMPAI DESEMBER'!O50) -> 1400058 | AE51: =AB51-AC51-AD51 -> 50577478 | AF51: =IFERROR(VLOOKUP(I51,TARIF,3,FALSE),0) -> 54000000 | AG51: =ROUNDDOWN(IF(AE51<=AF51,0,IF(AE51>AF51,AE51-AF51)),-3) -> 0 | AH51: =IF(AG51>5000000000,AG51*35%-306000000,IF(AG51>500000000,AG51*30%-56000000,IF(AG51>250000000,AG51*25%-31000000,IF(AG51>60000000,AG51*15%-6000000,AG51*5%)))) -> 0 | AI51: =ROUND(IF(E51=0,AH51*120%,AH51),0) -> 0 | AJ51: =+'PAJAK JAN-NOV'!R48 -> 123844 | AK51: =IF(AH51<=AJ51,0,IF(AH51>AJ51,AH51-AJ51)) -> 0 | AL51: =+'PAJAK JAN-NOV'!B48 -> ROSMINI | AM51: =AJ51-AI51 -> 123844
B52: 47 | C52: =+PERBULAN!B52 -> KURI | D52: 1902051707730004 | E52: 97.228.658.7-305.000 | F52: AIR BATU BUDING RT. 003 RW. 002 DESA AIR BATU BUDING KEC. BADAU | G52: KARYAWAN PERAWATAN | H52: L | I52: K/1 | J52: =IF(ISBLANK(I52),"",IF(OR(I52="TK/0",I52="TK/1",I52="K/0"),"TER A",IF(I52="K/3","TER C","TER B"))) -> TER B | K52: 1 | L52: 12 | M52: 3747380 | N52: 196300 | P52: 191935.04 | R52: =SUM(M52:Q52) -> 4135615 | S52: =+SETAHUN!J52 -> 4101600 | T52: =+SETAHUN!L52 -> 200000 | V52: =+SETAHUN!G52+M52+N52 -> 47354907 | X52: =+SETAHUN!W52+P52 -> 2296914.9 | Y52: 0 | Z52: 0 | AA52: =SUM(S52:U52) -> 4301600 | AB52: =SUM(V52:AA52) -> 53953422 | AC52: =ROUND(IF((AB52)*5%>6000000,6000000,(AB52)*5%),0) -> 2697671 | AD52: =('ASTEK 2% -DIISI SMPAI DESEMBER'!O170+'ASTEK 2% -DIISI SMPAI DESEMBER'!O51) -> 1411578 | AE52: =AB52-AC52-AD52 -> 49844173 | AF52: =IFERROR(VLOOKUP(I52,TARIF,3,FALSE),0) -> 63000000 | AG52: =ROUNDDOWN(IF(AE52<=AF52,0,IF(AE52>AF52,AE52-AF52)),-3) -> 0 | AH52: =IF(AG52>5000000000,AG52*35%-306000000,IF(AG52>500000000,AG52*30%-56000000,IF(AG52>250000000,AG52*25%-31000000,IF(AG52>60000000,AG52*15%-6000000,AG52*5%)))) -> 0 | AI52: =ROUND(IF(E52=0,AH52*120%,AH52),0) -> 0 | AJ52: =+'PAJAK JAN-NOV'!R49 -> 82604 | AK52: =IF(AH52<=AJ52,0,IF(AH52>AJ52,AH52-AJ52)) -> 0 | AL52: =+'PAJAK JAN-NOV'!B49 -> KURI | AM52: =AJ52-AI52 -> 82604
B53: 48 | C53: =+PERBULAN!B53 -> BASTIAR | D53: 1906041606760002 | E53: - | F53: DSN BUDING RT. 001 RW. 001 DESA BUDING KEC. KELAPA KAMPIT | G53: KARYAWAN PERAWATAN | H53: L | I53: K/1 | J53: =IF(ISBLANK(I53),"",IF(OR(I53="TK/0",I53="TK/1",I53="K/0"),"TER A",IF(I53="K/3","TER C","TER B"))) -> TER B | K53: 1 | L53: 12 | M53: 3876600 | N53: 153000 | P53: 188934.24 | R53: =SUM(M53:Q53) -> 4218534.2 | S53: =+SETAHUN!J53 -> 4026600 | T53: =+SETAHUN!L53 -> 200000 | V53: =+SETAHUN!G53+M53+N53 -> 45460886 | X53: =+SETAHUN!W53+P53 -> 2264404.1 | Y53: 0 | Z53: 0 | AA53: =SUM(S53:U53) -> 4226600 | AB53: =SUM(V53:AA53) -> 51951890 | AC53: =ROUND(IF((AB53)*5%>6000000,6000000,(AB53)*5%),0) -> 2597595 | AD53: =('ASTEK 2% -DIISI SMPAI DESEMBER'!O171+'ASTEK 2% -DIISI SMPAI DESEMBER'!O52) -> 1399968 | AE53: =AB53-AC53-AD53 -> 47954327 | AF53: =IFERROR(VLOOKUP(I53,TARIF,3,FALSE),0) -> 63000000 | AG53: =ROUNDDOWN(IF(AE53<=AF53,0,IF(AE53>AF53,AE53-AF53)),-3) -> 0 | AH53: =IF(AG53>5000000000,AG53*35%-306000000,IF(AG53>500000000,AG53*30%-56000000,IF(AG53>250000000,AG53*25%-31000000,IF(AG53>60000000,AG53*15%-6000000,AG53*5%)))) -> 0 | AI53: =ROUND(IF(E53=0,AH53*120%,AH53),0) -> 0 | AJ53: =+'PAJAK JAN-NOV'!R50 -> 81084 | AK53: =IF(AH53<=AJ53,0,IF(AH53>AJ53,AH53-AJ53)) -> 0 | AL53: =+'PAJAK JAN-NOV'!B50 -> BASTIAR | AM53: =AJ53-AI53 -> 81084
B54: 49 | C54: =+PERBULAN!B54 -> ADIYANSA | D54: 1902040909960002 | E54: - | F54: SUNGAI PADANG RT. 008 RW. 004 DESA SUNGAI PADANG KEC. SIJUK | G54: KARYAWAN PERAWATAN | H54: L | I54: K/1 | J54: =IF(ISBLANK(I54),"",IF(OR(I54="TK/0",I54="TK/1",I54="K/0"),"TER A",IF(I54="K/3","TER C","TER B"))) -> TER B | K54: 1 | L54: 12 | M54: 3876600 | N54: 187500 | P54: 188643.84 | R54: =SUM(M54:Q54) -> 4252743.8 | S54: =+SETAHUN!J54 -> 4034100 | T54: =+SETAHUN!L54 -> 200000 | V54: =+SETAHUN!G54+M54+N54 -> 48776318 | X54: =+SETAHUN!W54+P54 -> 2262067.7 | Y54: 0 | Z54: 0 | AA54: =SUM(S54:U54) -> 4234100 | AB54: =SUM(V54:AA54) -> 55272486 | AC54: =ROUND(IF((AB54)*5%>6000000,6000000,(AB54)*5%),0) -> 2763624 | AD54: =('ASTEK 2% -DIISI SMPAI DESEMBER'!O172+'ASTEK 2% -DIISI SMPAI DESEMBER'!O53) -> 1399338 | AE54: =AB54-AC54-AD54 -> 51109524 | AF54: =IFERROR(VLOOKUP(I54,TARIF,3,FALSE),0) -> 63000000 | AG54: =ROUNDDOWN(IF(AE54<=AF54,0,IF(AE54>AF54,AE54-AF54)),-3) -> 0 | AH54: =IF(AG54>5000000000,AG54*35%-306000000,IF(AG54>500000000,AG54*30%-56000000,IF(AG54>250000000,AG54*25%-31000000,IF(AG54>60000000,AG54*15%-6000000,AG54*5%)))) -> 0 | AI54: =ROUND(IF(E54=0,AH54*120%,AH54),0) -> 0 | AJ54: =+'PAJAK JAN-NOV'!R51 -> 83904 | AK54: =IF(AH54<=AJ54,0,IF(AH54>AJ54,AH54-AJ54)) -> 0 | AL54: =+'PAJAK JAN-NOV'!B51 -> ADIYANSA | AM54: =AJ54-AI54 -> 83904
B55: 50 | C55: =+PERBULAN!B55 -> RUDI SETIAWAN | D55: 1902052104980001 | E55: 12.751.440.4-305.000 | F55: JL. MANGGAR PARIT GUNUNG DS. AIR BATU BUDING KEC. BADAU KAB. BELITUNG | G55: KARYAWAN PERAWATAN | H55: L | I55: TK/0 | J55: =IF(ISBLANK(I55),"",IF(OR(I55="TK/0",I55="TK/1",I55="K/0"),"TER A",IF(I55="K/3","TER C","TER B"))) -> TER A | K55: 1 | L55: 12 | M55: 3876600 | N55: 75000 | P55: 187990.44 | R55: =SUM(M55:Q55) -> 4139590.4 | S55: =+SETAHUN!J55 -> 3949100 | T55: =+SETAHUN!L55 -> 200000 | V55: =+SETAHUN!G55+M55+N55 -> 46983815 | X55: =+SETAHUN!W55+P55 -> 2254302.3 | Y55: 0 | Z55: 0 | AA55: =SUM(S55:U55) -> 4149100 | AB55: =SUM(V55:AA55) -> 53387217 | AC55: =ROUND(IF((AB55)*5%>6000000,6000000,(AB55)*5%),0) -> 2669361 | AD55: =('ASTEK 2% -DIISI SMPAI DESEMBER'!O173+'ASTEK 2% -DIISI SMPAI DESEMBER'!O54) -> 1396533 | AE55: =AB55-AC55-AD55 -> 49321323 | AF55: =IFERROR(VLOOKUP(I55,TARIF,3,FALSE),0) -> 54000000 | AG55: =ROUNDDOWN(IF(AE55<=AF55,0,IF(AE55>AF55,AE55-AF55)),-3) -> 0 | AH55: =IF(AG55>5000000000,AG55*35%-306000000,IF(AG55>500000000,AG55*30%-56000000,IF(AG55>250000000,AG55*25%-31000000,IF(AG55>60000000,AG55*15%-6000000,AG55*5%)))) -> 0 | AI55: =ROUND(IF(E55=0,AH55*120%,AH55),0) -> 0 | AJ55: =+'PAJAK JAN-NOV'!R52 -> 121290 | AK55: =IF(AH55<=AJ55,0,IF(AH55>AJ55,AH55-AJ55)) -> 0 | AL55: =+'PAJAK JAN-NOV'!B52 -> RUDI SETIAWAN | AM55: =AJ55-AI55 -> 121290
B56: 51 | C56: =+PERBULAN!B56 -> MARYANTO | D56: 1906040106730002 | E56: 97.228.630.6-305.000 | F56: DSN BUDING RT. 003 RW. 001 DESA BUDING KEC. KELAPA KAMPIT | G56: KARYAWAN PERAWATAN | H56: L | I56: K/0 | J56: =IF(ISBLANK(I56),"",IF(OR(I56="TK/0",I56="TK/1",I56="K/0"),"TER A",IF(I56="K/3","TER C","TER B"))) -> TER A | K56: 1 | L56: 12 | M56: 3876600 | N56: 161500 | P56: 190071.64 | R56: =SUM(M56:Q56) -> 4228171.6 | S56: =+SETAHUN!J56 -> 4034600 | T56: =+SETAHUN!L56 -> 200000 | V56: =+SETAHUN!G56+M56+N56 -> 48766966 | X56: =+SETAHUN!W56+P56 -> 2276966.3 | Y56: 0 | Z56: 0 | AA56: =SUM(S56:U56) -> 4234600 | AB56: =SUM(V56:AA56) -> 55278533 | AC56: =ROUND(IF((AB56)*5%>6000000,6000000,(AB56)*5%),0) -> 2763927 | AD56: =('ASTEK 2% -DIISI SMPAI DESEMBER'!O174+'ASTEK 2% -DIISI SMPAI DESEMBER'!O55) -> 1404333 | AE56: =AB56-AC56-AD56 -> 51110273 | AF56: =IFERROR(VLOOKUP(I56,TARIF,3,FALSE),0) -> 58500000 | AG56: =ROUNDDOWN(IF(AE56<=AF56,0,IF(AE56>AF56,AE56-AF56)),-3) -> 0 | AH56: =IF(AG56>5000000000,AG56*35%-306000000,IF(AG56>500000000,AG56*30%-56000000,IF(AG56>250000000,AG56*25%-31000000,IF(AG56>60000000,AG56*15%-6000000,AG56*5%)))) -> 0 | AI56: =ROUND(IF(E56=0,AH56*120%,AH56),0) -> 0 | AJ56: =+'PAJAK JAN-NOV'!R53 -> 125874 | AK56: =IF(AH56<=AJ56,0,IF(AH56>AJ56,AH56-AJ56)) -> 0 | AL56: =+'PAJAK JAN-NOV'!B53 -> MARYANTO | AM56: =AJ56-AI56 -> 125874
B57: 52 | C57: =+PERBULAN!B57 -> SRI REJEKI | D57: 1902054407740002 | E57: 97.228.346.9-305.000 | F57: JL MANGGAR DSN PARIT GUNUNG RT. 005 RW. 003 DESA AIR BATU BUDING BADAU | G57: KARYAWAN PERAWATAN | H57: P | I57: TK/0 | J57: =IF(ISBLANK(I57),"",IF(OR(I57="TK/0",I57="TK/1",I57="K/0"),"TER A",IF(I57="K/3","TER C","TER B"))) -> TER A | K57: 1 | L57: 12 | M57: 4005820 | N57: 127250 | P57: 190410.44 | R57: =SUM(M57:Q57) -> 4323480.4 | S57: =+SETAHUN!J57 -> 3998100 | T57: =+SETAHUN!L57 -> 200000 | V57: =+SETAHUN!G57+M57+N57 -> 48382106 | X57: =+SETAHUN!W57+P57 -> 2280679.1 | Y57: 0 | Z57: 0 | AA57: =SUM(S57:U57) -> 4198100 | AB57: =SUM(V57:AA57) -> 54860885 | AC57: =ROUND(IF((AB57)*5%>6000000,6000000,(AB57)*5%),0) -> 2743044 | AD57: =('ASTEK 2% -DIISI SMPAI DESEMBER'!O175+'ASTEK 2% -DIISI SMPAI DESEMBER'!O56) -> 1405593 | AE57: =AB57-AC57-AD57 -> 50712248 | AF57: =IFERROR(VLOOKUP(I57,TARIF,3,FALSE),0) -> 54000000 | AG57: =ROUNDDOWN(IF(AE57<=AF57,0,IF(AE57>AF57,AE57-AF57)),-3) -> 0 | AH57: =IF(AG57>5000000000,AG57*35%-306000000,IF(AG57>500000000,AG57*30%-56000000,IF(AG57>250000000,AG57*25%-31000000,IF(AG57>60000000,AG57*15%-6000000,AG57*5%)))) -> 0 | AI57: =ROUND(IF(E57=0,AH57*120%,AH57),0) -> 0 | AJ57: =+'PAJAK JAN-NOV'!R54 -> 124762 | AK57: =IF(AH57<=AJ57,0,IF(AH57>AJ57,AH57-AJ57)) -> 0 | AL57: =+'PAJAK JAN-NOV'!B54 -> SRI REJEKI | AM57: =AJ57-AI57 -> 124762
B58: 53 | C58: =+PERBULAN!B58 -> SARTIKA | D58: 1902054508880002 | E58: 97.228.347.7-305.000 | F58: JL MANGGAR RT. 009 RW. 003 DESA KACANG BUTOR KEC. BADAU | G58: KARYAWAN PERAWATAN | H58: P | I58: TK/0 | J58: =IF(ISBLANK(I58),"",IF(OR(I58="TK/0",I58="TK/1",I58="K/0"),"TER A",IF(I58="K/3","TER C","TER B"))) -> TER A | K58: 1 | L58: 12 | M58: 4005820 | N58: 120250 | P58: 190071.64 | R58: =SUM(M58:Q58) -> 4316141.6 | S58: =+SETAHUN!J58 -> 3991100 | T58: =+SETAHUN!L58 -> 200000 | V58: =+SETAHUN!G58+M58+N58 -> 48561047 | X58: =+SETAHUN!W58+P58 -> 2276966.3 | Y58: 0 | Z58: 0 | AA58: =SUM(S58:U58) -> 4191100 | AB58: =SUM(V58:AA58) -> 55029114 | AC58: =ROUND(IF((AB58)*5%>6000000,6000000,(AB58)*5%),0) -> 2751456 | AD58: =('ASTEK 2% -DIISI SMPAI DESEMBER'!O176+'ASTEK 2% -DIISI SMPAI DESEMBER'!O57) -> 1404333 | AE58: =AB58-AC58-AD58 -> 50873325 | AF58: =IFERROR(VLOOKUP(I58,TARIF,3,FALSE),0) -> 54000000 | AG58: =ROUNDDOWN(IF(AE58<=AF58,0,IF(AE58>AF58,AE58-AF58)),-3) -> 0 | AH58: =IF(AG58>5000000000,AG58*35%-306000000,IF(AG58>500000000,AG58*30%-56000000,IF(AG58>250000000,AG58*25%-31000000,IF(AG58>60000000,AG58*15%-6000000,AG58*5%)))) -> 0 | AI58: =ROUND(IF(E58=0,AH58*120%,AH58),0) -> 0 | AJ58: =+'PAJAK JAN-NOV'!R55 -> 124548 | AK58: =IF(AH58<=AJ58,0,IF(AH58>AJ58,AH58-AJ58)) -> 0 | AL58: =+'PAJAK JAN-NOV'!B55 -> SARTIKA | AM58: =AJ58-AI58 -> 124548
B59: 54 | C59: =+PERBULAN!B59 -> MIRNA | D59: 1906044910940002 | E59: 55.161.258.3-305.000 | F59: DSN SELINDANG RT. 007 RW. 002 DESA SENYUBUK KEC. KELAPA KAMPIT | G59: KARYAWAN PERAWATAN | H59: P | I59: TK/0 | J59: =IF(ISBLANK(I59),"",IF(OR(I59="TK/0",I59="TK/1",I59="K/0"),"TER A",IF(I59="K/3","TER C","TER B"))) -> TER A | K59: 1 | L59: 12 | M59: 3876600 | N59: 104000 | P59: 189394.04 | R59: =SUM(M59:Q59) -> 4169994 | S59: =+SETAHUN!J59 -> 3977100 | T59: =+SETAHUN!L59 -> 200000 | V59: =+SETAHUN!G59+M59+N59 -> 46296528 | X59: =+SETAHUN!W59+P59 -> 2269879.5 | Y59: 0 | Z59: 0 | AA59: =SUM(S59:U59) -> 4177100 | AB59: =SUM(V59:AA59) -> 52743507 | AC59: =ROUND(IF((AB59)*5%>6000000,6000000,(AB59)*5%),0) -> 2637175 | AD59: =('ASTEK 2% -DIISI SMPAI DESEMBER'!O177+'ASTEK 2% -DIISI SMPAI DESEMBER'!O58) -> 1402023 | AE59: =AB59-AC59-AD59 -> 48704309 | AF59: =IFERROR(VLOOKUP(I59,TARIF,3,FALSE),0) -> 54000000 | AG59: =ROUNDDOWN(IF(AE59<=AF59,0,IF(AE59>AF59,AE59-AF59)),-3) -> 0 | AH59: =IF(AG59>5000000000,AG59*35%-306000000,IF(AG59>500000000,AG59*30%-56000000,IF(AG59>250000000,AG59*25%-31000000,IF(AG59>60000000,AG59*15%-6000000,AG59*5%)))) -> 0 | AI59: =ROUND(IF(E59=0,AH59*120%,AH59),0) -> 0 | AJ59: =+'PAJAK JAN-NOV'!R56 -> 124119 | AK59: =IF(AH59<=AJ59,0,IF(AH59>AJ59,AH59-AJ59)) -> 0 | AL59: =+'PAJAK JAN-NOV'!B56 -> MIRNA | AM59: =AJ59-AI59 -> 124119
... B63: 58 | C63: =+PERBULAN!B63 -> AGUSTIONO | D63: 1902013101810007 | E63: 97.237.680.0-305.000 | F63: JL MERDEKA NO. 37 RT. 009 RW. 002 KOTA TANJUNGPANDAN KEC. TANJUNGPANDAN | G63: KARYAWAN PERAWATAN | H63: L | I63: K/2 | J63: =IF(ISBLANK(I63),"",IF(OR(I63="TK/0",I63="TK/1",I63="K/0"),"TER A",IF(I63="K/3","TER C","TER B"))) -> TER B | K63: 1 | L63: 12 | M63: 4005820 | N63: 222550 | P63: 190071.64 | R63: =SUM(M63:Q63) -> 4418441.6 | S63: =+SETAHUN!J63 -> 4093600 | T63: =+SETAHUN!L63 -> 200000 | V63: =+SETAHUN!G63+M63+N63 -> 49522859 | X63: =+SETAHUN!W63+P63 -> 2278314.5 | Y63: 0 | Z63: 0 | AA63: =SUM(S63:U63) -> 4293600 | AB63: =SUM(V63:AA63) -> 56094774 | AC63: =ROUND(IF((AB63)*5%>6000000,6000000,(AB63)*5%),0) -> 2804739 | AD63: =('ASTEK 2% -DIISI SMPAI DESEMBER'!O181+'ASTEK 2% -DIISI SMPAI DESEMBER'!O62) -> 1404648 | AE63: =AB63-AC63-AD63 -> 51885387 | AF63: =IFERROR(VLOOKUP(I63,TARIF,3,FALSE),0) -> 67500000 | AG63: =ROUNDDOWN(IF(AE63<=AF63,0,IF(AE63>AF63,AE63-AF63)),-3) -> 0 | AH63: =IF(AG63>5000000000,AG63*35%-306000000,IF(AG63>500000000,AG63*30%-56000000,IF(AG63>250000000,AG63*25%-31000000,IF(AG63>60000000,AG63*15%-6000000,AG63*5%)))) -> 0 | AI63: =ROUND(IF(E63=0,AH63*120%,AH63),0) -> 0 | AJ63: =+'PAJAK JAN-NOV'!R60 -> 85116 | AK63: =IF(AH63<=AJ63,0,IF(AH63>AJ63,AH63-AJ63)) -> 0 | AL63: =+'PAJAK JAN-NOV'!B60 -> AGUSTIONO | AM63: =AJ63-AI63 -> 85116
B64: 59 | C64: =+PERBULAN!B64 -> TONGAM PARNINGTON SAMOSIR | D64: 1902011302790002 | E64: 97.237.703.0-305.000 | F64: JL MERPATI III NO. 150 PERUMNAS RT. 012 RW. 002 DESA AIK PELEMPANG JAYA KEC. TANJUNGPANDAN | G64: KARYAWAN PERAWATAN | H64: L | I64: K/3 | J64: =IF(ISBLANK(I64),"",IF(OR(I64="TK/0",I64="TK/1",I64="K/0"),"TER A",IF(I64="K/3","TER C","TER B"))) -> TER C | K64: 1 | L64: 12 | M64: 3747380 | N64: 204450 | O64: 4086600 | P64: 189732.84 | R64: =SUM(M64:Q64) -> 8228162.8 | S64: =+O64 -> 4086600 | T64: =+SETAHUN!L64 -> 200000 | V64: =+SETAHUN!G64+M64+N64 -> 46373315 | X64: =+SETAHUN!W64+P64 -> 2273084.1 | Y64: 0 | Z64: 0 | AA64: =SUM(S64:U64) -> 4286600 | AB64: =SUM(V64:AA64) -> 52932999 | AC64: =ROUND(IF((AB64)*5%>6000000,6000000,(AB64)*5%),0) -> 2646650 | AD64: =('ASTEK 2% -DIISI SMPAI DESEMBER'!O182+'ASTEK 2% -DIISI SMPAI DESEMBER'!O63) -> 1402968 | AE64: =AB64-AC64-AD64 -> 48883381 | AF64: =IFERROR(VLOOKUP(I64,TARIF,3,FALSE),0) -> 72000000 | AG64: =ROUNDDOWN(IF(AE64<=AF64,0,IF(AE64>AF64,AE64-AF64)),-3) -> 0 | AH64: =IF(AG64>5000000000,AG64*35%-306000000,IF(AG64>500000000,AG64*30%-56000000,IF(AG64>250000000,AG64*25%-31000000,IF(AG64>60000000,AG64*15%-6000000,AG64*5%)))) -> 0 | AI64: =ROUND(IF(E64=0,AH64*120%,AH64),0) -> 0 | AJ64: =+'PAJAK JAN-NOV'!R61 -> 0 | AK64: =IF(AH64<=AJ64,0,IF(AH64>AJ64,AH64-AJ64)) -> 0 | AL64: =+'PAJAK JAN-NOV'!B61 -> TONGAM PARNINGTON SAMOSIR | AM64: =AJ64-AI64 -> 0
