Workbook
Name februari: TARIF!#REF!
Name februari: TARIF!#REF!
Name februari: TARIF!#REF!
Name februari: TARIF!#REF!
Name februari: TARIF!#REF!
Name februari: TARIF!#REF!
Name februari: TARIF!#REF!
Name februari: TARIF!#REF!
Name februari: TARIF!#REF!
Name februari: TARIF!#REF!
Name PH: [1]TARIF!#REF!
Name PH: [1]TARIF!#REF!
Name PH: [1]TARIF!#REF!
Name PH: [1]TARIF!#REF!
Name PH: [1]TARIF!#REF!
Name PH: [1]TARIF!#REF!
Name PH: [1]TARIF!#REF!
Name PH: [1]TARIF!#REF!
Name PH: [1]TARIF!#REF!
Name PH: [1]TARIF!#REF!
Name PH: [1]TARIF!#REF!
Name PH: [1]TARIF!#REF!
Name PH: TARIF!#REF!
Name PTKP: [1]TARIF!#REF!
Name PTKP: [1]TARIF!#REF!
Name PTKP: [1]TARIF!#REF!
Name PTKP: [1]TARIF!#REF!
Name PTKP: [1]TARIF!#REF!
Name PTKP: [1]TARIF!#REF!
Name PTKP: [1]TARIF!#REF!
Name PTKP: [1]TARIF!#REF!
Name PTKP: [1]TARIF!#REF!
Name PTKP: [1]TARIF!#REF!
Name PTKP: [1]TARIF!#REF!
Name PTKP: [1]TARIF!#REF!
Name PTKP: TARIF!#REF!
Name TARIF: [2]TARIF!$S$18:$U$25
Name Ter_A: [1]TARIF!$B$3:$E$46
Name Ter_A: [1]TARIF!$B$3:$E$46
Name Ter_A: [1]TARIF!$B$3:$E$46
Name Ter_A: [1]TARIF!$B$3:$E$46
Name Ter_A: [1]TARIF!$B$3:$E$46
Name Ter_A: [1]TARIF!$B$3:$E$46
Name Ter_A: [1]TARIF!$B$3:$E$46
Name Ter_A: [1]TARIF!$B$3:$E$46
Name Ter_A: [1]TARIF!$B$3:$E$46
Name Ter_A: [1]TARIF!$B$3:$E$46
Name Ter_A: [1]TARIF!$B$3:$E$46
Name Ter_A: [1]TARIF!$B$3:$E$46
Name Ter_A: TARIF!$B$3:$E$46
Name Ter_B: [1]TARIF!$H$3:$K$42
Name Ter_B: [1]TARIF!$H$3:$K$42
Name Ter_B: [1]TARIF!$H$3:$K$42
Name Ter_B: [1]TARIF!$H$3:$K$42
Name Ter_B: [1]TARIF!$H$3:$K$42
Name Ter_B: [1]TARIF!$H$3:$K$42
Name Ter_B: [1]TARIF!$H$3:$K$42
Name Ter_B: [1]TARIF!$H$3:$K$42
Name Ter_B: [1]TARIF!$H$3:$K$42
Name Ter_B: [1]TARIF!$H$3:$K$42

Sheet TARIF
A1: PTKP (TK/0, TK/1, K/0) | G1: PTKP (TK/2, TK/3, K/1, K/2) | M1: PTKP (K/3) | S1: HARIAN
A2: No | B2: Lapisan Penghasilan bruto (Rp.) | E2: TER A | G2: No | H2: Lapisan Penghasilan bruto (Rp.) | K2: TER B | M2: No | N2: Lapisan Penghasilan bruto (Rp.) | Q2: TER C | S2: Penghasilan Bruto | V2: Tarif
A3: 1 | B3: 0 | C3: s.d | D3: 5400000 | E3: 0 | G3: 1 | H3: 0 | I3: s.d | J3: 6200000 | K3: 0 | M3: 1 | N3: 0 | O3: s.d | P3: 6600000 | Q3: 0 | S3: 0 | T3: s.d | U3: 450000 | V3: 0
A4: =A3+1 -> 2 | B4: =D3+1 -> 5400001 | C4: s.d | D4: 5650000 | E4: 0.0025 | G4: =G3+1 -> 2 | H4: =J3+1 -> 6200001 | I4: s.d | J4: 6500000 | K4: 0.0025 | M4: =M3+1 -> 2 | N4: =P3+1 -> 6600001 | O4: s.d | P4: 6950000 | Q4: 0.0025 | S4: 450001 | T4: s.d | U4: 2500000 | V4: 0.005
A5: =A4+1 -> 3 | B5: =D4+1 -> 5650001 | C5: s.d | D5: 5950000 | E5: 0.005 | G5: =G4+1 -> 3 | H5: =J4+1 -> 6500001 | I5: s.d | J5: 6850000 | K5: 0.005 | M5: =M4+1 -> 3 | N5: =P4+1 -> 6950001 | O5: s.d | P5: 7350000 | Q5: 0.005
A6: =A5+1 -> 4 | B6: =D5+1 -> 5950001 | C6: s.d | D6: 6300000 | E6: 0.0075 | G6: =G5+1 -> 4 | H6: =J5+1 -> 6850001 | I6: s.d | J6: 7300000 | K6: 0.0075 | M6: =M5+1 -> 4 | N6: =P5+1 -> 7350001 | O6: s.d | P6: 7800000 | Q6: 0.0075
A7: =A6+1 -> 5 | B7: =D6+1 -> 6300001 | C7: s.d | D7: 6750000 | E7: 0.01 | G7: =G6+1 -> 5 | H7: =J6+1 -> 7300001 | I7: s.d | J7: 9200000 | K7: 0.01 | M7: =M6+1 -> 5 | N7: =P6+1 -> 7800001 | O7: s.d | P7: 8850000 | Q7: 0.01 | S7: TARIF PASAL 17 WPOP
A8: =A7+1 -> 6 | B8: =D7+1 -> 6750001 | C8: s.d | D8: 7500000 | E8: 0.0125 | G8: =G7+1 -> 6 | H8: =J7+1 -> 9200001 | I8: s.d | J8: 10750000 | K8: 0.015 | M8: =M7+1 -> 6 | N8: =P7+1 -> 8850001 | O8: s.d | P8: 9800000 | Q8: 0.0125 | S8: Lapisan PKP | V8: Tarif
A9: =A8+1 -> 7 | B9: =D8+1 -> 7500001 | C9: s.d | D9: 8550000 | E9: 0.015 | G9: =G8+1 -> 7 | H9: =J8+1 -> 10750001 | I9: s.d | J9: 11250000 | K9: 0.02 | M9: =M8+1 -> 7 | N9: =P8+1 -> 9800001 | O9: s.d | P9: 10950000 | Q9: 0.015 | S9: 0 | T9: s.d | U9: 60000000 | V9: 0.05
A10: =A9+1 -> 8 | B10: =D9+1 -> 8550001 | C10: s.d | D10: 9650000 | E10: 0.0175 | G10: =G9+1 -> 8 | H10: =J9+1 -> 11250001 | I10: s.d | J10: 11600000 | K10: 0.025 | M10: =M9+1 -> 8 | N10: =P9+1 -> 10950001 | O10: s.d | P10: 11200000 | Q10: 0.0175 | S10: =U9+1 -> 60000001 | T10: s.d | U10: 250000000 | V10: 0.15
A11: =A10+1 -> 9 | B11: =D10+1 -> 9650001 | C11: s.d | D11: 10050000 | E11: 0.02 | G11: =G10+1 -> 9 | H11: =J10+1 -> 11600001 | I11: s.d | J11: 12600000 | K11: 0.03 | M11: =M10+1 -> 9 | N11: =P10+1 -> 11200001 | O11: s.d | P11: 12050000 | Q11: 0.02 | S11: =U10+1 -> 250000001 | T11: s.d | U11: 500000000 | V11: 0.25
A12: =A11+1 -> 10 | B12: =D11+1 -> 10050001 | C12: s.d | D12: 10350000 | E12: 0.0225 | G12: =G11+1 -> 10 | H12: =J11+1 -> 12600001 | I12: s.d | J12: 13600000 | K12: 0.04 | M12: =M11+1 -> 10 | N12: =P11+1 -> 12050001 | O12: s.d | P12: 12950000 | Q12: 0.03 | S12: =U11+1 -> 500000001 | T12: s.d | U12: 5000000000 | V12: 0.3
A13: =A12+1 -> 11 | B13: =D12+1 -> 10350001 | C13: s.d | D13: 10700000 | E13: 0.025 | G13: =G12+1 -> 11 | H13: =J12+1 -> 13600001 | I13: s.d | J13: 14950000 | K13: 0.05 | M13: =M12+1 -> 11 | N13: =P12+1 -> 12950001 | O13: s.d | P13: 14150000 | Q13: 0.04 | S13: =U12+1 -> 5000000001 | T13: s.d | U13: ~~ | V13: 0.35
A14: =A13+1 -> 12 | B14: =D13+1 -> 10700001 | C14: s.d | D14: 11050000 | E14: 0.03 | G14: =G13+1 -> 12 | H14: =J13+1 -> 14950001 | I14: s.d | J14: 16400000 | K14: 0.06 | M14: =M13+1 -> 12 | N14: =P13+1 -> 14150001 | O14: s.d | P14: 1550000 | Q14: 0.05
A15: =A14+1 -> 13 | B15: =D14+1 -> 11050001 | C15: s.d | D15: 11600000 | E15: 0.035 | G15: =G14+1 -> 13 | H15: =J14+1 -> 16400001 | I15: s.d | J15: 18450000 | K15: 0.07 | M15: =M14+1 -> 13 | N15: =P14+1 -> 1550001 | O15: s.d | P15: 17050000 | Q15: 0.06
A16: =A15+1 -> 14 | B16: =D15+1 -> 11600001 | C16: s.d | D16: 12500000 | E16: 0.04 | G16: =G15+1 -> 14 | H16: =J15+1 -> 18450001 | I16: s.d | J16: 21850000 | K16: 0.08 | M16: =M15+1 -> 14 | N16: =P15+1 -> 17050001 | O16: s.d | P16: 19500000 | Q16: 0.07 | S16: PTKP
A17: =A16+1 -> 15 | B17: =D16+1 -> 12500001 | C17: s.d | D17: 13750000 | E17: 0.05 | G17: =G16+1 -> 15 | H17: =J16+1 -> 21850001 | I17: s.d | J17: 26000000 | K17: 0.09 | M17: =M16+1 -> 15 | N17: =P16+1 -> 19500001 | O17: s.d | P17: 22700000 | Q17: 0.08 | S17: Status | U17: Jumlah
A18: =A17+1 -> 16 | B18: =D17+1 -> 13750001 | C18: s.d | D18: 15100000 | E18: 0.06 | G18: =G17+1 -> 16 | H18: =J17+1 -> 26000001 | I18: s.d | J18: 27700000 | K18: 0.1 | M18: =M17+1 -> 16 | N18: =P17+1 -> 22700001 | O18: s.d | P18: 26600000 | Q18: 0.09 | S18: TK/0 | U18: 54000000
A19: =A18+1 -> 17 | B19: =D18+1 -> 15100001 | C19: s.d | D19: 16950000 | E19: 0.07 | G19: =G18+1 -> 17 | H19: =J18+1 -> 27700001 | I19: s.d | J19: 29350000 | K19: 0.11 | M19: =M18+1 -> 17 | N19: =P18+1 -> 26600001 | O19: s.d | P19: 28100000 | Q19: 0.1 | S19: TK/1 | U19: 58500000
A20: =A19+1 -> 18 | B20: =D19+1 -> 16950001 | C20: s.d | D20: 19750000 | E20: 0.08 | G20: =G19+1 -> 18 | H20: =J19+1 -> 29350001 | I20: s.d | J20: 31450000 | K20: 0.12 | M20: =M19+1 -> 18 | N20: =P19+1 -> 28100001 | O20: s.d | P20: 30100000 | Q20: 0.11 | S20: TK/2 | U20: 63000000
A21: =A20+1 -> 19 | B21: =D20+1 -> 19750001 | C21: s.d | D21: 24150000 | E21: 0.09 | G21: =G20+1 -> 19 | H21: =J20+1 -> 31450001 | I21: s.d | J21: 33950000 | K21: 0.13 | M21: =M20+1 -> 19 | N21: =P20+1 -> 30100001 | O21: s.d | P21: 32600000 | Q21: 0.12 | S21: TK/3 | U21: 67500000
A22: =A21+1 -> 20 | B22: =D21+1 -> 24150001 | C22: s.d | D22: 26450000 | E22: 0.1 | G22: =G21+1 -> 20 | H22: =J21+1 -> 33950001 | I22: s.d | J22: 37100000 | K22: 0.14 | M22: =M21+1 -> 20 | N22: =P21+1 -> 32600001 | O22: s.d | P22: 35400000 | Q22: 0.13 | S22: K/0 | U22: 58500000
A23: =A22+1 -> 21 | B23: =D22+1 -> 26450001 | C23: s.d | D23: 28000000 | E23: 0.11 | G23: =G22+1 -> 21 | H23: =J22+1 -> 37100001 | I23: s.d | J23: 41100000 | K23: 0.15 | M23: =M22+1 -> 21 | N23: =P22+1 -> 35400001 | O23: s.d | P23: 38900000 | Q23: 0.14 | S23: K/1 | U23: 63000000
A24: =A23+1 -> 22 | B24: =D23+1 -> 28000001 | C24: s.d | D24: 30050000 | E24: 0.12 | G24: =G23+1 -> 22 | H24: =J23+1 -> 41100001 | I24: s.d | J24: 45800000 | K24: 0.16 | M24: =M23+1 -> 22 | N24: =P23+1 -> 38900001 | O24: s.d | P24: 43000000 | Q24: 0.15 | S24: K/2 | U24: 67500000
A25: =A24+1 -> 23 | B25: =D24+1 -> 30050001 | C25: s.d | D25: 32400000 | E25: 0.13 | G25: =G24+1 -> 23 | H25: =J24+1 -> 45800001 | I25: s.d | J25: 49500000 | K25: 0.17 | M25: =M24+1 -> 23 | N25: =P24+1 -> 43000001 | O25: s.d | P25: 47400000 | Q25: 0.16 | S25: K/3 | U25: 72000000
A26: =A25+1 -> 24 | B26: =D25+1 -> 32400001 | C26: s.d | D26: 35400000 | E26: 0.14 | G26: =G25+1 -> 24 | H26: =J25+1 -> 49500001 | I26: s.d | J26: 53800000 | K26: 0.18 | M26: =M25+1 -> 24 | N26: =P25+1 -> 47400001 | O26: s.d | P26: 51200000 | Q26: 0.17
A27: =A26+1 -> 25 | B27: =D26+1 -> 35400001 | C27: s.d | D27: 39100000 | E27: 0.15 | G27: =G26+1 -> 25 | H27: =J26+1 -> 53800001 | I27: s.d | J27: 58500000 | K27: 0.19 | M27: =M26+1 -> 25 | N27: =P26+1 -> 51200001 | O27: s.d | P27: 55800000 | Q27: 0.18
A28: =A27+1 -> 26 | B28: =D27+1 -> 39100001 | C28: s.d | D28: 43850000 | E28: 0.16 | G28: =G27+1 -> 26 | H28: =J27+1 -> 58500001 | I28: s.d | J28: 64000000 | K28: 0.2 | M28: =M27+1 -> 26 | N28: =P27+1 -> 55800001 | O28: s.d | P28: 60400000 | Q28: 0.19
A29: =A28+1 -> 27 | B29: =D28+1 -> 43850001 | C29: s.d | D29: 47800000 | E29: 0.17 | G29: =G28+1 -> 27 | H29: =J28+1 -> 64000001 | I29: s.d | J29: 71000000 | K29: 0.21 | M29: =M28+1 -> 27 | N29: =P28+1 -> 60400001 | O29: s.d | P29: 66700000 | Q29: 0.2
A30: =A29+1 -> 28 | B30: =D29+1 -> 47800001 | C30: s.d | D30: 51400000 | E30: 0.18 | G30: =G29+1 -> 28 | H30: =J29+1 -> 71000001 | I30: s.d | J30: 80000000 | K30: 0.22 | M30: =M29+1 -> 28 | N30: =P29+1 -> 66700001 | O30: s.d | P30: 74500000 | Q30: 0.21
A31: =A30+1 -> 29 | B31: =D30+1 -> 51400001 | C31: s.d | D31: 56300000 | E31: 0.19 | G31: =G30+1 -> 29 | H31: =J30+1 -> 80000001 | I31: s.d | J31: 93000000 | K31: 0.23 | M31: =M30+1 -> 29 | N31: =P30+1 -> 74500001 | O31: s.d | P31: 83200000 | Q31: 0.22
A32: =A31+1 -> 30 | B32: =D31+1 -> 56300001 | C32: s.d | D32: 62200000 | E32: 0.2 | G32: =G31+1 -> 30 | H32: =J31+1 -> 93000001 | I32: s.d | J32: 109000000 | K32: 0.24 | M32: =M31+1 -> 30 | N32: =P31+1 -> 83200001 | O32: s.d | P32: 95600000 | Q32: 0.23
A33: =A32+1 -> 31 | B33: =D32+1 -> 62200001 | C33: s.d | D33: 68600000 | E33: 0.21 | G33: =G32+1 -> 31 | H33: =J32+1 -> 109000001 | I33: s.d | J33: 129000000 | K33: 0.25 | M33: =M32+1 -> 31 | N33: =P32+1 -> 95600001 | O33: s.d | P33: 110000000 | Q33: 0.24
A34: =A33+1 -> 32 | B34: =D33+1 -> 68600001 | C34: s.d | D34: 77500000 | E34: 0.22 | G34: =G33+1 -> 32 | H34: =J33+1 -> 129000001 | I34: s.d | J34: 163000000 | K34: 0.26 | M34: =M33+1 -> 32 | N34: =P33+1 -> 110000001 | O34: s.d | P34: 134000000 | Q34: 0.25
A35: =A34+1 -> 33 | B35: =D34+1 -> 77500001 | C35: s.d | D35: 89000000 | E35: 0.23 | G35: =G34+1 -> 33 | H35: =J34+1 -> 163000001 | I35: s.d | J35: 211000000 | K35: 0.27 | M35: =M34+1 -> 33 | N35: =P34+1 -> 134000001 | O35: s.d | P35: 169000000 | Q35: 0.26
A36: =A35+1 -> 34 | B36: =D35+1 -> 89000001 | C36: s.d | D36: 103000000 | E36: 0.24 | G36: =G35+1 -> 34 | H36: =J35+1 -> 211000001 | I36: s.d | J36: 374000000 | K36: 0.28 | M36: =M35+1 -> 34 | N36: =P35+1 -> 169000001 | O36: s.d | P36: 221000000 | Q36: 0.27
A37: =A36+1 -> 35 | B37: =D36+1 -> 103000001 | C37: s.d | D37: 125000000 | E37: 0.25 | G37: =G36+1 -> 35 | H37: =J36+1 -> 374000001 | I37: s.d | J37: 459000000 | K37: 0.29 | M37: =M36+1 -> 35 | N37: =P36+1 -> 221000001 | O37: s.d | P37: 390000000 | Q37: 0.28
... A41: =A40+1 -> 39 | B41: =D40+1 -> 337000001 | C41: s.d | D41: 454000000 | E41: 0.29 | G41: =G40+1 -> 39 | H41: =J40+1 -> 957000001 | I41: s.d | J41: 1405000000 | K41: 0.33 | M41: =M40+1 -> 39 | N41: =P40+1 -> 709000001 | O41: s.d | P41: 965000000 | Q41: 0.32
A42: =A41+1 -> 40 | B42: =D41+1 -> 454000001 | C42: s.d | D42: 550000000 | E42: 0.3 | G42: =G41+1 -> 40 | H42: =J41+1 -> 1405000001 | I42: s.d | J42: ~~ | K42: 0.34 | M42: =M41+1 -> 40 | N42: =P41+1 -> 965000001 | O42: s.d | P42: 1419000000 | Q42: 0.33
A43: =A42+1 -> 41 | B43: =D42+1 -> 550000001 | C43: s.d | D43: 695000000 | E43: 0.31 | M43: =M42+1 -> 41 | N43: =P42+1 -> 1419000001 | O43: s.d | P43: ~~ | Q43: 0.34
...

Sheet Des
C1: yang berwarna ini rumus
B2: Nomor Urut | C2: NAMA KARYAWAN | D2: N I K / PASPOR | E2: N P W P | F2: A L A M A T | G2: JABATAN | H2: STATUS KARYAWAN | M2: DESEMBER | R2: PENGHASILAN TIDAK TERATUR | U2: TOTAL GAJI POKOK | V2: TOTAL TUNJANGAN LAINNYA | W2: TOTAL PREMI ASURANSI | X2: TOTAL TUNJANGAN PPH | Y2: TOTAL NATURA / KENIKMATAN | Z2: TOTAL THR, BONUS, TANTIEM | AA2: PENGHASILAN BRUTO SETAHUN | AB2: PENGURANG | AD2: PENGHASILAN NETTO SETAHUN | AE2: P T K P | AF2: P K P | AG2: PPH PASAL 21 | AI2: PPH PASAL 21 JAN S.D NOP | AJ2: PPH PASAL 21 DESEMBER
M3: Gaji Pokok | N3: Total Tunjangan | O3: Premi JKK, JKM, Kes | P3: Tunjangan PPh | Q3: Penghasilan Bruto | R3: T H R | S3: B O N U S | T3: TANTIEM
H4: L/P | I4: PTKP | J4: TER | K4: MASA KERJA | AB4: BIAYA JABATAN | AC4: TOTAL IURAN JHT/THT/JP | AG4: SETAHUN | AH4: INCLUDE NON NPWP
B5: 1 | C5: 2 | D5: 3 | E5: 4 | F5: 5 | G5: 6 | H5: 7 | I5: 8 | J5: 9 | K5: 10 | L5: 11 | M5: 12 | N5: 13 | O5: 14 | P5: 15 | Q5: 16 | R5: 17 | S5: 18 | T5: 19 | U5: 20 | V5: 21 | W5: 22 | X5: 23 | Y5: 24 | Z5: 25 | AA5: 26 | AB5: 27 | AC5: 27 | AD5: 29 | AE5: 30 | AF5: 31 | AG5: 32 | AH5: 33 | AI5: 34 | AJ5: 35
B6: 1 | C6: =+PERBULAN!B6 -> SARWANDI | D6: 1902050708780007 | E6: 97.228.383.2-305.000 | F6: DSN AIR BEGANTUNG RT. 009 RW. 003 DESA KACANG BUTOR KEC. BADAU | G6: KARYAWAN PERAWATAN | H6: L | I6: K/1 | J6: =IF(ISBLANK(I6),"",IF(OR(I6="TK/0",I6="TK/1",I6="K/0"),"TER A",IF(I6="K/3","TER C","TER B"))) -> TER B | K6: 1 | M6: =[3]NURSERY!$AJ10-[3]NURSERY!$BK10 -> 9256268.9 | O6: =[3]NURSERY!$BK10 -> 54000 | P6: 0 | Q6: =SUM(M6:P6) -> 9310268.9 | R6: =+PERBULAN!S6 -> 4053100 | S6: =+SETAHUN!K7 -> 600000 | T6: 0 | U6: =+SETAHUN!F7+M6+N6 -> 1.0115867e+08 | W6: =+SETAHUN!U7+O6 -> 2142242.8 | X6: 0 | Y6: 0 | Z6: =SUM(R6:T6) -> 4653100 | AA6: =SUM(U6:Z6) -> 1.0795401e+08 | AB6: =ROUND(IF((AA6)*5%>6000000,6000000,(AA6)*5%),0) -> 5397701 | AC6: =('ASTEK+PENSIUN'!O8+'ASTEK+PENSIUN'!O51)+[3]NURSERY!$BM10 -> 1449245.8 | AD6: =AA6-AB6-AC6 -> 1.0110707e+08 | AE6: =IFERROR(VLOOKUP(I6,TARIF,3,FALSE),0) -> 63000000 | AF6: =ROUNDDOWN(IF(AD6<=AE6,0,IF(AD6>AE6,AD6-AE6)),-3) -> 38107000 | AG6: =IF(AF6>5000000000,AF6*35%-306000000,IF(AF6>500000000,AF6*30%-56000000,IF(AF6>250000000,AF6*25%-31000000,IF(AF6>60000000,AF6*15%-6000000,AF6*5%)))) -> 1905350 | AH6: =ROUND(IF(E6=0,AG6*120%,AG6),0) -> 1905350 | AI6: ='PAJAK JAN-NOV'!R3-'PAJAK JAN-NOV'!Q3 -> 1582520 | AJ6: =IF(AG6<=AI6,0,IF(AG6>AI6,AG6-AI6)) -> 322830 | AL6: =AI6-AH6 -> -322830
B7: 2 | C7: =+PERBULAN!B7 -> SUHARMAN | D7: 1902051909730001 | E7: 97.228.314.7-305.000 | F7: DSN. AIR BEGANTUNG RT.009 RW.003 DESA KACANG BUTOR KEC. BADAU | G7: KARYAWAN PERAWATAN | H7: L | I7: K/0 | J7: =IF(ISBLANK(I7),"",IF(OR(I7="TK/0",I7="TK/1",I7="K/0"),"TER A",IF(I7="K/3","TER C","TER B"))) -> TER A | K7: 1 | M7: =[3]NURSERY!$AJ11-[3]NURSERY!$BK11 -> 5888013.2 | O7: =[3]NURSERY!$BK11 -> 89000 | P7: 0 | Q7: =SUM(M7:P7) -> 5977013.2 | R7: =+PERBULAN!S7 -> 4059600 | S7: =+SETAHUN!K8 -> 200000 | T7: 0 | U7: =+SETAHUN!F8+M7+N7 -> 67471593 | W7: =+SETAHUN!U8+O7 -> 2194119.8 | X7: 0 | Y7: 0 | Z7: =SUM(R7:T7) -> 4259600 | AA7: =SUM(U7:Z7) -> 73925313 | AB7: =ROUND(IF((AA7)*5%>6000000,6000000,(AA7)*5%),0) -> 3696266 | AC7: =('ASTEK+PENSIUN'!O9+'ASTEK+PENSIUN'!O52)+[3]NURSERY!$BM11 -> 1456420.8 | AD7: =AA7-AB7-AC7 -> 68772626 | AE7: =IFERROR(VLOOKUP(I7,TARIF,3,FALSE),0) -> 58500000 | AF7: =ROUNDDOWN(IF(AD7<=AE7,0,IF(AD7>AE7,AD7-AE7)),-3) -> 10272000 | AG7: =IF(AF7>5000000000,AF7*35%-306000000,IF(AF7>500000000,AF7*30%-56000000,IF(AF7>250000000,AF7*25%-31000000,IF(AF7>60000000,AF7*15%-6000000,AF7*5%)))) -> 513600 | AH7: =ROUND(IF(E7=0,AG7*120%,AG7),0) -> 513600 | AI7: ='PAJAK JAN-NOV'!R4-'PAJAK JAN-NOV'!Q4 -> 563003 | AJ7: =IF(AG7<=AI7,0,IF(AG7>AI7,AG7-AI7)) -> 0 | AL7: =AI7-AH7 -> 49403
B8: 3 | C8: =+PERBULAN!B8 -> DARMAWAN | D8: 1902050708720001 | E8: 97.237.829.3-305.000 | F8: DSN AIR BATU BUDING RT. 004 RW. 002 DESA AIR BATU BUDING KEC. BADAU | G8: KARYAWAN PERAWATAN | H8: L | I8: K/1 | J8: =IF(ISBLANK(I8),"",IF(OR(I8="TK/0",I8="TK/1",I8="K/0"),"TER A",IF(I8="K/3","TER C","TER B"))) -> TER B | K8: 1 | M8: =[3]NURSERY!$AJ12-[3]NURSERY!$BK12 -> 6077065.8 | O8: =[3]NURSERY!$BK12 -> 92500 | P8: 0 | Q8: =SUM(M8:P8) -> 6169565.8 | R8: =+PERBULAN!S8 -> 4105100 | S8: =+SETAHUN!K9 -> 600000 | T8: 0 | U8: =+SETAHUN!F9+M8+N8 -> 69191070 | W8: =+SETAHUN!U9+O8 -> 2199166.8 | X8: 0 | Y8: 0 | Z8: =SUM(R8:T8) -> 4705100 | AA8: =SUM(U8:Z8) -> 76095337 | AB8: =ROUND(IF((AA8)*5%>6000000,6000000,(AA8)*5%),0) -> 3804767 | AC8: =('ASTEK+PENSIUN'!O10+'ASTEK+PENSIUN'!O53)+[3]NURSERY!$BM12 -> 1457085.8 | AD8: =AA8-AB8-AC8 -> 70833484 | AE8: =IFERROR(VLOOKUP(I8,TARIF,3,FALSE),0) -> 63000000 | AF8: =ROUNDDOWN(IF(AD8<=AE8,0,IF(AD8>AE8,AD8-AE8)),-3) -> 7833000 | AG8: =IF(AF8>5000000000,AF8*35%-306000000,IF(AF8>500000000,AF8*30%-56000000,IF(AF8>250000000,AF8*25%-31000000,IF(AF8>60000000,AF8*15%-6000000,AF8*5%)))) -> 391650 | AH8: =ROUND(IF(E8=0,AG8*120%,AG8),0) -> 391650 | AI8: ='PAJAK JAN-NOV'!R5-'PAJAK JAN-NOV'!Q5 -> 318239 | AJ8: =IF(AG8<=AI8,0,IF(AG8>AI8,AG8-AI8)) -> 73411 | AL8: =AI8-AH8 -> -73411
B9: 4 | C9: =+PERBULAN!B9 -> SUMARDI | D9: 1902050109770001 | E9: 97.228.327.9-305.000 | F9: DSN AIR BATU BUDING RT. 004 RW. 002 DESA AIR BATU BUDING KEC. BADAU | G9: KARYAWAN PERAWATAN | H9: L | I9: K/1 | J9: =IF(ISBLANK(I9),"",IF(OR(I9="TK/0",I9="TK/1",I9="K/0"),"TER A",IF(I9="K/3","TER C","TER B"))) -> TER B | K9: 1 | M9: =[3]NURSERY!$AJ13-[3]NURSERY!$BK13 -> 6626064.1 | O9: =[3]NURSERY!$BK13 -> 92500 | P9: 0 | Q9: =SUM(M9:P9) -> 6718564.1 | R9: =+PERBULAN!S9 -> 4105100 | S9: =+SETAHUN!K10 -> 600000 | T9: 0 | U9: =+SETAHUN!F10+M9+N9 -> 68055256 | W9: =+SETAHUN!U10+O9 -> 2199446.8 | X9: 0 | Y9: 0 | Z9: =SUM(R9:T9) -> 4705100 | AA9: =SUM(U9:Z9) -> 74959803 | AB9: =ROUND(IF((AA9)*5%>6000000,6000000,(AA9)*5%),0) -> 3747990 | AC9: =('ASTEK+PENSIUN'!O11+'ASTEK+PENSIUN'!O54)+[3]NURSERY!$BM13 -> 1457085.8 | AD9: =AA9-AB9-AC9 -> 69754727 | AE9: =IFERROR(VLOOKUP(I9,TARIF,3,FALSE),0) -> 63000000 | AF9: =ROUNDDOWN(IF(AD9<=AE9,0,IF(AD9>AE9,AD9-AE9)),-3) -> 6754000 | AG9: =IF(AF9>5000000000,AF9*35%-306000000,IF(AF9>500000000,AF9*30%-56000000,IF(AF9>250000000,AF9*25%-31000000,IF(AF9>60000000,AF9*15%-6000000,AF9*5%)))) -> 337700 | AH9: =ROUND(IF(E9=0,AG9*120%,AG9),0) -> 337700 | AI9: ='PAJAK JAN-NOV'!R6-'PAJAK JAN-NOV'!Q6 -> 292553 | AJ9: =IF(AG9<=AI9,0,IF(AG9>AI9,AG9-AI9)) -> 45147 | AL9: =AI9-AH9 -> -45147
B10: 5 | C10: =+PERBULAN!B10 -> EKI SUMANTRI | D10: 1607051709920004 | E10: - | F10: DESA TAJA RAYA I RT 008 RW 003 KEC. BETUNG KAB. BANYUASIN | G10: KARYAWAN PERAWATAN | H10: L | I10: K/1 | J10: =IF(ISBLANK(I10),"",IF(OR(I10="TK/0",I10="TK/1",I10="K/0"),"TER A",IF(I10="K/3","TER C","TER B"))) -> TER B | K10: 1 | M10: =[3]NURSERY!$AJ14-[3]NURSERY!$BK14 -> 8093794.1 | O10: =[3]NURSERY!$BK14 -> 18000 | P10: 0 | Q10: =SUM(M10:P10) -> 8111794.1 | R10: =+PERBULAN!S10 -> 4031100 | S10: =+SETAHUN!K11 -> 600000 | T10: 0 | U10: =+SETAHUN!F11+M10+N10 -> 71882948 | W10: =+SETAHUN!U11+O10 -> 2089857.8 | X10: 0 | Y10: 0 | Z10: =SUM(R10:T10) -> 4631100 | AA10: =SUM(U10:Z10) -> 78603906 | AB10: =ROUND(IF((AA10)*5%>6000000,6000000,(AA10)*5%),0) -> 3930195 | AC10: =('ASTEK+PENSIUN'!O12+'ASTEK+PENSIUN'!O55)+[3]NURSERY!$BM14 -> 1442930.8 | AD10: =AA10-AB10-AC10 -> 73230780 | AE10: =IFERROR(VLOOKUP(I10,TARIF,3,FALSE),0) -> 63000000 | AF10: =ROUNDDOWN(IF(AD10<=AE10,0,IF(AD10>AE10,AD10-AE10)),-3) -> 10230000 | AG10: =IF(AF10>5000000000,AF10*35%-306000000,IF(AF10>500000000,AF10*30%-56000000,IF(AF10>250000000,AF10*25%-31000000,IF(AF10>60000000,AF10*15%-6000000,AF10*5%)))) -> 511500 | AH10: =ROUND(IF(E10=0,AG10*120%,AG10),0) -> 511500 | AI10: ='PAJAK JAN-NOV'!R7-'PAJAK JAN-NOV'!Q7 -> 359120 | AJ10: =IF(AG10<=AI10,0,IF(AG10>AI10,AG10-AI10)) -> 152380 | AL10: =AI10-AH10 -> -152380
B11: 6 | C11: =+PERBULAN!B11 -> SULISTIYANI SAPUTRI | D11: 1906046307740004 | E11: 97.228.324.6-305.000 | F11: DSN PESARAKAN RT. 008 RW. 003 DESA CENDIL KEC. KELAPA KAMPIT | G11: KARYAWAN PERAWATAN | H11: P | I11: TK/0 | J11: =IF(ISBLANK(I11),"",IF(OR(I11="TK/0",I11="TK/1",I11="K/0"),"TER A",IF(I11="K/3","TER C","TER B"))) -> TER A | K11: 1 | M11: =[3]NURSERY!$AJ15-[3]NURSERY!$BK15 -> 4000120.2 | O11: =[3]NURSERY!$BK15 -> 50500 | P11: 0 | Q11: =SUM(M11:P11) -> 4050620.2 | R11: =+PERBULAN!S11 -> 3991100 | S11: =+SETAHUN!K12 -> 200000 | T11: 0 | U11: =+SETAHUN!F12+M11+N11 -> 47349212 | W11: =+SETAHUN!U12+O11 -> 2137733.4 | X11: 0 | Y11: 0 | Z11: =SUM(R11:T11) -> 4191100 | AA11: =SUM(U11:Z11) -> 53678045 | AB11: =ROUND(IF((AA11)*5%>6000000,6000000,(AA11)*5%),0) -> 2683902 | AC11: =('ASTEK+PENSIUN'!O13+'ASTEK+PENSIUN'!O56)+[3]NURSERY!$BM15 -> 1449000.8 | AD11: =AA11-AB11-AC11 -> 49545142 | AE11: =IFERROR(VLOOKUP(I11,TARIF,3,FALSE),0) -> 54000000 | AF11: =ROUNDDOWN(IF(AD11<=AE11,0,IF(AD11>AE11,AD11-AE11)),-3) -> 0 | AG11: =IF(AF11>5000000000,AF11*35%-306000000,IF(AF11>500000000,AF11*30%-56000000,IF(AF11>250000000,AF11*25%-31000000,IF(AF11>60000000,AF11*15%-6000000,AF11*5%)))) -> 0 | AH11: =ROUND(IF(E11=0,AG11*120%,AG11),0) -> 0 | AI11: ='PAJAK JAN-NOV'!R8-'PAJAK JAN-NOV'!Q8 -> 122576 | AJ11: =IF(AG11<=AI11,0,IF(AG11>AI11,AG11-AI11)) -> 0 | AL11: =AI11-AH11 -> 122576
B12: 7 | C12: =+PERBULAN!B12 -> TRISNAWATI | D12: 1906046011770002 | E12: - | F12: DSN KOPERASI RT. 005 RW. 002 DESA PEMBAHARUAN KEC. KELAPA KAMPIT | G12: KARYAWAN PERAWATAN | H12: P | I12: TK/0 | J12: =IF(ISBLANK(I12),"",IF(OR(I12="TK/0",I12="TK/1",I12="K/0"),"TER A",IF(I12="K/3","TER C","TER B"))) -> TER A | K12: 1 | M12: =[3]NURSERY!$AJ16-[3]NURSERY!$BK16 -> 4131590.2 | O12: =[3]NURSERY!$BK16 -> 21000 | P12: 0 | Q12: =SUM(M12:P12) -> 4152590.2 | R12: =+PERBULAN!S12 -> 3962100 | S12: =+SETAHUN!K13 -> 200000 | T12: 0 | U12: =+SETAHUN!F13+M12+N12 -> 47749764 | W12: =+SETAHUN!U13+O12 -> 2093868.2 | X12: 0 | Y12: 0 | Z12: =SUM(R12:T12) -> 4162100 | AA12: =SUM(U12:Z12) -> 54005732 | AB12: =ROUND(IF((AA12)*5%>6000000,6000000,(AA12)*5%),0) -> 2700287 | AC12: =('ASTEK+PENSIUN'!O14+'ASTEK+PENSIUN'!O57)+[3]NURSERY!$BM16 -> 1443230.8 | AD12: =AA12-AB12-AC12 -> 49862214 | AE12: =IFERROR(VLOOKUP(I12,TARIF,3,FALSE),0) -> 54000000 | AF12: =ROUNDDOWN(IF(AD12<=AE12,0,IF(AD12>AE12,AD12-AE12)),-3) -> 0 | AG12: =IF(AF12>5000000000,AF12*35%-306000000,IF(AF12>500000000,AF12*30%-56000000,IF(AF12>250000000,AF12*25%-31000000,IF(AF12>60000000,AF12*15%-6000000,AF12*5%)))) -> 0 | AH12: =ROUND(IF(E12=0,AG12*120%,AG12),0) -> 0 | AI12: ='PAJAK JAN-NOV'!R9-'PAJAK JAN-NOV'!Q9 -> 121688 | AJ12: =IF(AG12<=AI12,0,IF(AG12>AI12,AG12-AI12)) -> 0 | AL12: =AI12-AH12 -> 121688
B13: 8 | C13: =+PERBULAN!B13 -> ELNI | D13: 1906046603820002 | E13: 55.166.633.2-305.000 | F13: DSN LALANG RT. 002 RW. 001 DESA MENTAWAK KEC. KELAPA KAMPIT | G13: KARYAWAN PERAWATAN | H13: P | I13: TK/0 | J13: =IF(ISBLANK(I13),"",IF(OR(I13="TK/0",I13="TK/1",I13="K/0"),"TER A",IF(I13="K/3","TER C","TER B"))) -> TER A | K13: 1 | M13: =[3]NURSERY!$AJ17-[3]NURSERY!$BK17 -> 4131590.2 | O13: =[3]NURSERY!$BK17 -> 36500 | P13: 0 | Q13: =SUM(M13:P13) -> 4168090.2 | R13: =+PERBULAN!S13 -> 3977100 | S13: =+SETAHUN!K14 -> 200000 | T13: 0 | U13: =+SETAHUN!F14+M13+N13 -> 48398053 | W13: =+SETAHUN!U14+O13 -> 2116307.8 | X13: 0 | Y13: 0 | Z13: =SUM(R13:T13) -> 4177100 | AA13: =SUM(U13:Z13) -> 54691461 | AB13: =ROUND(IF((AA13)*5%>6000000,6000000,(AA13)*5%),0) -> 2734573 | AC13: =('ASTEK+PENSIUN'!O15+'ASTEK+PENSIUN'!O58)+[3]NURSERY!$BM17 -> 1445920.8 | AD13: =AA13-AB13-AC13 -> 50510967 | AE13: =IFERROR(VLOOKUP(I13,TARIF,3,FALSE),0) -> 54000000 | AF13: =ROUNDDOWN(IF(AD13<=AE13,0,IF(AD13>AE13,AD13-AE13)),-3) -> 0 | AG13: =IF(AF13>5000000000,AF13*35%-306000000,IF(AF13>500000000,AF13*30%-56000000,IF(AF13>250000000,AF13*25%-31000000,IF(AF13>60000000,AF13*15%-6000000,AF13*5%)))) -> 0 | AH13: =ROUND(IF(E13=0,AG13*120%,AG13),0) -> 0 | AI13: ='PAJAK JAN-NOV'!R10-'PAJAK JAN-NOV'!Q10 -> 122147 | AJ13: =IF(AG13<=AI13,0,IF(AG13>AI13,AG13-AI13)) -> 0 | AL13: =AI13-AH13 -> 122147
B14: 9 | C14: =+PERBULAN!B14 -> YUSTIANA | D14: 1906046609780003 | E14: 97.228.361.8-305.000 | F14: DSN BUDING RT. 003 RW. 001 DESA BUDING KEC. KELAPA KAMPIT | G14: KARYAWAN PERAWATAN | H14: P | I14: TK/0 | J14: =IF(ISBLANK(I14),"",IF(OR(I14="TK/0",I14="TK/1",I14="K/0"),"TER A",IF(I14="K/3","TER C","TER B"))) -> TER A | K14: 1 | M14: =[3]NURSERY!$AJ18-[3]NURSERY!$BK18 -> 4131590.2 | O14: =[3]NURSERY!$BK18 -> 57500 | P14: 0 | Q14: =SUM(M14:P14) -> 4189090.2 | R14: =+PERBULAN!S14 -> 3998100 | S14: =+SETAHUN!K15 -> 600000 | T14: 0 | U14: =+SETAHUN!F15+M14+N14 -> 49495077 | W14: =+SETAHUN!U15+O14 -> 2147768.6 | X14: 0 | Y14: 0 | Z14: =SUM(R14:T14) -> 4598100 | AA14: =SUM(U14:Z14) -> 56240945 | AB14: =ROUND(IF((AA14)*5%>6000000,6000000,(AA14)*5%),0) -> 2812047 | AC14: =('ASTEK+PENSIUN'!O16+'ASTEK+PENSIUN'!O59)+[3]NURSERY!$BM18 -> 1450120.8 | AD14: =AA14-AB14-AC14 -> 51978777 | AE14: =IFERROR(VLOOKUP(I14,TARIF,3,FALSE),0) -> 54000000 | AF14: =ROUNDDOWN(IF(AD14<=AE14,0,IF(AD14>AE14,AD14-AE14)),-3) -> 0 | AG14: =IF(AF14>5000000000,AF14*35%-306000000,IF(AF14>500000000,AF14*30%-56000000,IF(AF14>250000000,AF14*25%-31000000,IF(AF14>60000000,AF14*15%-6000000,AF14*5%)))) -> 0 | AH14: =ROUND(IF(E14=0,AG14*120%,AG14),0) -> 0 | AI14: ='PAJAK JAN-NOV'!R11-'PAJAK JAN-NOV'!Q11 -> 124762 | AJ14: =IF(AG14<=AI14,0,IF(AG14>AI14,AG14-AI14)) -> 0 | AL14: =AI14-AH14 -> 124762
B15: 10 | C15: =+PERBULAN!B15 -> YULIANA | D15: 1906044807940004 | E15: 55.166.797.5.305.000 | F15: JL TANJUNG KELAYANG RT. 030 RW. 006 DESA TANJUNG BINGA KEC. SIJUK | G15: KARYAWAN PERAWATAN | H15: P | I15: TK/0 | J15: =IF(ISBLANK(I15),"",IF(OR(I15="TK/0",I15="TK/1",I15="K/0"),"TER A",IF(I15="K/3","TER C","TER B"))) -> TER A | K15: 1 | M15: =[3]NURSERY!$AJ19-[3]NURSERY!$BK19 -> 4131590.2 | O15: =[3]NURSERY!$BK19 -> 36500 | P15: 0 | Q15: =SUM(M15:P15) -> 4168090.2 | R15: =+PERBULAN!S15 -> 3977100 | S15: =+SETAHUN!K16 -> 600000 | T15: 0 | U15: =+SETAHUN!F16+M15+N15 -> 49290689 | W15: =+SETAHUN!U16+O15 -> 2116307.8 | X15: 0 | Y15: 0 | Z15: =SUM(R15:T15) -> 4577100 | AA15: =SUM(U15:Z15) -> 55984097 | AB15: =ROUND(IF((AA15)*5%>6000000,6000000,(AA15)*5%),0) -> 2799205 | AC15: =('ASTEK+PENSIUN'!O17+'ASTEK+PENSIUN'!O60)+[3]NURSERY!$BM19 -> 1445920.8 | AD15: =AA15-AB15-AC15 -> 51738971 | AE15: =IFERROR(VLOOKUP(I15,TARIF,3,FALSE),0) -> 54000000 | AF15: =ROUNDDOWN(IF(AD15<=AE15,0,IF(AD15>AE15,AD15-AE15)),-3) -> 0 | AG15: =IF(AF15>5000000000,AF15*35%-306000000,IF(AF15>500000000,AF15*30%-56000000,IF(AF15>250000000,AF15*25%-31000000,IF(AF15>60000000,AF15*15%-6000000,AF15*5%)))) -> 0 | AH15: =ROUND(IF(E15=0,AG15*120%,AG15),0) -> 0 | AI15: ='PAJAK JAN-NOV'!R12-'PAJAK JAN-NOV'!Q12 -> 124119 | AJ15: =IF(AG15<=AI15,0,IF(AG15>AI15,AG15-AI15)) -> 0 | AL15: =AI15-AH15 -> 124119
B16: 11 | C16: =+PERBULAN!B16 -> SALMIA | D16: 1906044210780002 | E16: 97.228.362.6-305.000 | F16: DSN BUDING RT. 001 RW. 001 DESA BUDING KEC. KELAPA KAMPIT | G16: KARYAWAN PERAWATAN | H16: P | I16: TK/0 | J16: =IF(ISBLANK(I16),"",IF(OR(I16="TK/0",I16="TK/1",I16="K/0"),"TER A",IF(I16="K/3","TER C","TER B"))) -> TER A | K16: 1 | M16: =[3]NURSERY!$AJ20-[3]NURSERY!$BK20 -> 4131590.2 | O16: =[3]NURSERY!$BK20 -> 57500 | P16: 0 | Q16: =SUM(M16:P16) -> 4189090.2 | R16: =+PERBULAN!S16 -> 3998100 | S16: =+SETAHUN!K17 -> 600000 | T16: 0 | U16: =+SETAHUN!F17+M16+N16 -> 49528689 | W16: =+SETAHUN!U17+O16 -> 2147768.6 | X16: 0 | Y16: 0 | Z16: =SUM(R16:T16) -> 4598100 | AA16: =SUM(U16:Z16) -> 56274557 | AB16: =ROUND(IF((AA16)*5%>6000000,6000000,(AA16)*5%),0) -> 2813728 | AC16: =('ASTEK+PENSIUN'!O18+'ASTEK+PENSIUN'!O61)+[3]NURSERY!$BM20 -> 1450120.8 | AD16: =AA16-AB16-AC16 -> 52010708 | AE16: =IFERROR(VLOOKUP(I16,TARIF,3,FALSE),0) -> 54000000 | AF16: =ROUNDDOWN(IF(AD16<=AE16,0,IF(AD16>AE16,AD16-AE16)),-3) -> 0 | AG16: =IF(AF16>5000000000,AF16*35%-306000000,IF(AF16>500000000,AF16*30%-56000000,IF(AF16>250000000,AF16*25%-31000000,IF(AF16>60000000,AF16*15%-6000000,AF16*5%)))) -> 0 | AH16: =ROUND(IF(E16=0,AG16*120%,AG16),0) -> 0 | AI16: ='PAJAK JAN-NOV'!R13-'PAJAK JAN-NOV'!Q13 -> 124762 | AJ16: =IF(AG16<=AI16,0,IF(AG16>AI16,AG16-AI16)) -> 0 | AL16: =AI16-AH16 -> 124762
B17: 12 | C17: =+PERBULAN!B17 -> SISWANDI | D17: 1906042509710002 | E17: 97.228.330.3-305.000 | F17: DSN PADANG RT. 002 RW. 001 DESA MENTAWAK KEC. KELAPA KAMPIT | G17: KARYAWAN PERAWATAN | H17: L | I17: K/0 | J17: =IF(ISBLANK(I17),"",IF(OR(I17="TK/0",I17="TK/1",I17="K/0"),"TER A",IF(I17="K/3","TER C","TER B"))) -> TER A | K17: 1 | M17: =[3]NURSERY!$AJ21-[3]NURSERY!$BK21 -> 3868650.2 | O17: =[3]NURSERY!$BK21 -> 50500 | P17: 0 | Q17: =SUM(M17:P17) -> 3919150.2 | R17: =+PERBULAN!S17 -> 4034600 | S17: =+SETAHUN!K18 -> 200000 | T17: 0 | U17: =+SETAHUN!F18+M17+N17 -> 48583333 | W17: =+SETAHUN!U18+O17 -> 2137225.2 | X17: 0 | Y17: 0 | Z17: =SUM(R17:T17) -> 4234600 | AA17: =SUM(U17:Z17) -> 54955158 | AB17: =ROUND(IF((AA17)*5%>6000000,6000000,(AA17)*5%),0) -> 2747758 | AC17: =('ASTEK+PENSIUN'!O19+'ASTEK+PENSIUN'!O62)+[3]NURSERY!$BM21 -> 1448685.8 | AD17: =AA17-AB17-AC17 -> 50758714 | AE17: =IFERROR(VLOOKUP(I17,TARIF,3,FALSE),0) -> 58500000 | AF17: =ROUNDDOWN(IF(AD17<=AE17,0,IF(AD17>AE17,AD17-AE17)),-3) -> 0 | AG17: =IF(AF17>5000000000,AF17*35%-306000000,IF(AF17>500000000,AF17*30%-56000000,IF(AF17>250000000,AF17*25%-31000000,IF(AF17>60000000,AF17*15%-6000000,AF17*5%)))) -> 0 | AH17: =ROUND(IF(E17=0,AG17*120%,AG17),0) -> 0 | AI17: ='PAJAK JAN-NOV'!R14-'PAJAK JAN-NOV'!Q14 -> 125874 | AJ17: =IF(AG17<=AI17,0,IF(AG17>AI17,AG17-AI17)) -> 0 | AL17: =AI17-AH17 -> 125874
... B21: 16 | C21: =+PERBULAN!B21 -> ARLINI | D21: 1902016004770002 | E21: 97.228.571.2-305.000 | F21: JL SIJUK RT. 017 RW. 005 DESA AIR KETEKOK KEC. TANJUNGPANDAN | G21: KERANI | H21: P | I21: TK/0 | J21: =IF(ISBLANK(I21),"",IF(OR(I21="TK/0",I21="TK/1",I21="K/0"),"TER A",IF(I21="K/3","TER C","TER B"))) -> TER A | K21: 1 | M21: =[3]NURSERY!$AJ25-[3]NURSERY!$BK25 -> 4455487.3 | O21: =[3]NURSERY!$BK25 -> 50500 | P21: 0 | Q21: =SUM(M21:P21) -> 4505987.3 | R21: =+PERBULAN!S21 -> 3994600 | S21: =+SETAHUN!K22 -> 600000 | T21: 0 | U21: =+SETAHUN!F22+M21+N21 -> 64269510 | W21: =+SETAHUN!U22+O21 -> 2138742.8 | X21: 0 | Y21: 0 | Z21: =SUM(R21:T21) -> 4594600 | AA21: =SUM(U21:Z21) -> 71002852 | AB21: =ROUND(IF((AA21)*5%>6000000,6000000,(AA21)*5%),0) -> 3550143 | AC21: =('ASTEK+PENSIUN'!O23+'ASTEK+PENSIUN'!O66)+[3]NURSERY!$BM25 -> 1449105.8 | AD21: =AA21-AB21-AC21 -> 66003604 | AE21: =IFERROR(VLOOKUP(I21,TARIF,3,FALSE),0) -> 54000000 | AF21: =ROUNDDOWN(IF(AD21<=AE21,0,IF(AD21>AE21,AD21-AE21)),-3) -> 12003000 | AG21: =IF(AF21>5000000000,AF21*35%-306000000,IF(AF21>500000000,AF21*30%-56000000,IF(AF21>250000000,AF21*25%-31000000,IF(AF21>60000000,AF21*15%-6000000,AF21*5%)))) -> 600150 | AH21: =ROUND(IF(E21=0,AG21*120%,AG21),0) -> 600150 | AI21: ='PAJAK JAN-NOV'!R18-'PAJAK JAN-NOV'!Q18 -> 455121 | AJ21: =IF(AG21<=AI21,0,IF(AG21>AI21,AG21-AI21)) -> 145029 | AL21: =AI21-AH21 -> -145029
B22: 17 | C22: =+PERBULAN!B22 -> 0 | J22: =IF(ISBLANK(I22),"",IF(OR(I22="TK/0",I22="TK/1",I22="K/0"),"TER A",IF(I22="K/3","TER C","TER B"))) | P22: 0 | Q22: =SUM(M22:P22) -> 0 | R22: =+PERBULAN!S22 -> 0 | S22: =+SETAHUN!K23 -> 0 | T22: 0 | U22: =+SETAHUN!F23+M22+N22 -> 0 | W22: =+SETAHUN!U23+O22 -> 0 | X22: 0 | Y22: 0 | Z22: =SUM(R22:T22) -> 0 | AA22: =SUM(U22:Z22) -> 0 | AB22: =ROUND(IF((AA22)*5%>6000000,6000000,(AA22)*5%),0) -> 0 | AC22: =('ASTEK+PENSIUN'!O24+'ASTEK+PENSIUN'!O67) -> 0 | AD22: =AA22-AB22-AC22 -> 0 | AE22: =IFERROR(VLOOKUP(I22,TARIF,3,FALSE),0) -> 0 | AF22: =ROUNDDOWN(IF(AD22<=AE22,0,IF(AD22>AE22,AD22-AE22)),-3) -> 0 | AG22: =IF(AF22>5000000000,AF22*35%-306000000,IF(AF22>500000000,AF22*30%-56000000,IF(AF22>250000000,AF22*25%-31000000,IF(AF22>60000000,AF22*15%-6000000,AF22*5%)))) -> 0 | AH22: =ROUND(IF(E22=0,AG22*120%,AG22),0) -> 0 | AI22: =+'PAJAK JAN-NOV'!R19 -> 0 | AJ22: =IF(AG22<=AI22,0,IF(AG22>AI22,AG22-AI22)) -> 0 | AL22: =AI22-AH22 -> 0
B23: 18 | C23: =+PERBULAN!B23 -> 0 | J23: =IF(ISBLANK(I23),"",IF(OR(I23="TK/0",I23="TK/1",I23="K/0"),"TER A",IF(I23="K/3","TER C","TER B"))) | P23: 0 | Q23: =SUM(M23:P23) -> 0 | R23: =+PERBULAN!S23 -> 0 | S23: =+SETAHUN!K24 -> 0 | T23: 0 | U23: =+SETAHUN!F24+M23+N23 -> 0 | W23: =+SETAHUN!U24+O23 -> 0 | X23: 0 | Y23: 0 | Z23: =SUM(R23:T23) -> 0 | AA23: =SUM(U23:Z23) -> 0 | AB23: =ROUND(IF((AA23)*5%>6000000,6000000,(AA23)*5%),0) -> 0 | AC23: =('ASTEK+PENSIUN'!O25+'ASTEK+PENSIUN'!O68) -> 0 | AD23: =AA23-AB23-AC23 -> 0 | AE23: =IFERROR(VLOOKUP(I23,TARIF,3,FALSE),0) -> 0 | AF23: =ROUNDDOWN(IF(AD23<=AE23,0,IF(AD23>AE23,AD23-AE23)),-3) -> 0 | AG23: =IF(AF23>5000000000,AF23*35%-306000000,IF(AF23>500000000,AF23*30%-56000000,IF(AF23>250000000,AF23*25%-31000000,IF(AF23>60000000,AF23*15%-6000000,AF23*5%)))) -> 0 | AH23: =ROUND(IF(E23=0,AG23*120%,AG23),0) -> 0 | AI23: =+'PAJAK JAN-NOV'!R20 -> 0 | AJ23: =IF(AG23<=AI23,0,IF(AG23>AI23,AG23-AI23)) -> 0 | AL23: =AI23-AH23 -> 0
B24: 19 | C24: =+PERBULAN!B24 -> 0 | J24: =IF(ISBLANK(I24),"",IF(OR(I24="TK/0",I24="TK/1",I24="K/0"),"TER A",IF(I24="K/3","TER C","TER B"))) | P24: 0 | Q24: =SUM(M24:P24) -> 0 | R24: =+PERBULAN!S24 -> 0 | S24: =+SETAHUN!K25 -> 0 | T24: 0 | U24: =+SETAHUN!F25+M24+N24 -> 0 | W24: =+SETAHUN!U25+O24 -> 0 | X24: 0 | Y24: 0 | Z24: =SUM(R24:T24) -> 0 | AA24: =SUM(U24:Z24) -> 0 | AB24: =ROUND(IF((AA24)*5%>6000000,6000000,(AA24)*5%),0) -> 0 | AC24: =('ASTEK+PENSIUN'!O26+'ASTEK+PENSIUN'!O69) -> 0 | AD24: =AA24-AB24-AC24 -> 0 | AE24: =IFERROR(VLOOKUP(I24,TARIF,3,FALSE),0) -> 0 | AF24: =ROUNDDOWN(IF(AD24<=AE24,0,IF(AD24>AE24,AD24-AE24)),-3) -> 0 | AG24: =IF(AF24>5000000000,AF24*35%-306000000,IF(AF24>500000000,AF24*30%-56000000,IF(AF24>250000000,AF24*25%-31000000,IF(AF24>60000000,AF24*15%-6000000,AF24*5%)))) -> 0 | AH24: =ROUND(IF(E24=0,AG24*120%,AG24),0) -> 0 | AI24: =+'PAJAK JAN-NOV'!R21 -> 0 | AJ24: =IF(AG24<=AI24,0,IF(AG24>AI24,AG24-AI24)) -> 0 | AL24: =AI24-AH24 -> 0
B25: 20 | C25: =+PERBULAN!B25 -> 0 | J25: =IF(ISBLANK(I25),"",IF(OR(I25="TK/0",I25="TK/1",I25="K/0"),"TER A",IF(I25="K/3","TER C","TER B"))) | P25: 0 | Q25: =SUM(M25:P25) -> 0 | R25: =+PERBULAN!S25 -> 0 | S25: =+SETAHUN!K26 -> 0 | T25: 0 | U25: =+SETAHUN!F26+M25+N25 -> 0 | W25: =+SETAHUN!U26+O25 -> 0 | X25: 0 | Y25: 0 | Z25: =SUM(R25:T25) -> 0 | AA25: =SUM(U25:Z25) -> 0 | AB25: =ROUND(IF((AA25)*5%>6000000,6000000,(AA25)*5%),0) -> 0 | AC25: =('ASTEK+PENSIUN'!O27+'ASTEK+PENSIUN'!O70) -> 0 | AD25: =AA25-AB25-AC25 -> 0 | AE25: =IFERROR(VLOOKUP(I25,TARIF,3,FALSE),0) -> 0 | AF25: =ROUNDDOWN(IF(AD25<=AE25,0,IF(AD25>AE25,AD25-AE25)),-3) -> 0 | AG25: =IF(AF25>5000000000,AF25*35%-306000000,IF(AF25>500000000,AF25*30%-56000000,IF(AF25>250000000,AF25*25%-31000000,IF(AF25>60000000,AF25*15%-6000000,AF25*5%)))) -> 0 | AH25: =ROUND(IF(E25=0,AG25*120%,AG25),0) -> 0 | AI25: =+'PAJAK JAN-NOV'!R22 -> 0 | AJ25: =IF(AG25<=AI25,0,IF(AG25>AI25,AG25-AI25)) -> 0 | AL25: =AI25-AH25 -> 0
B26: 21 | C26: =+PERBULAN!B26 -> 0 | J26: =IF(ISBLANK(I26),"",IF(OR(I26="TK/0",I26="TK/1",I26="K/0"),"TER A",IF(I26="K/3","TER C","TER B"))) | P26: 0 | Q26: =SUM(M26:P26) -> 0 | R26: =+PERBULAN!S26 -> 0 | S26: =+SETAHUN!K27 -> 0 | T26: 0 | U26: =+SETAHUN!F27+M26+N26 -> 0 | W26: =+SETAHUN!U27+O26 -> 0 | X26: 0 | Y26: 0 | Z26: =SUM(R26:T26) -> 0 | AA26: =SUM(U26:Z26) -> 0 | AB26: =ROUND(IF((AA26)*5%>6000000,6000000,(AA26)*5%),0) -> 0 | AC26: =('ASTEK+PENSIUN'!O28+'ASTEK+PENSIUN'!O71) -> 0 | AD26: =AA26-AB26-AC26 -> 0 | AE26: =IFERROR(VLOOKUP(I26,TARIF,3,FALSE),0) -> 0 | AF26: =ROUNDDOWN(IF(AD26<=AE26,0,IF(AD26>AE26,AD26-AE26)),-3) -> 0 | AG26: =IF(AF26>5000000000,AF26*35%-306000000,IF(AF26>500000000,AF26*30%-56000000,IF(AF26>250000000,AF26*25%-31000000,IF(AF26>60000000,AF26*15%-6000000,AF26*5%)))) -> 0 | AH26: =ROUND(IF(E26=0,AG26*120%,AG26),0) -> 0 | AI26: =+'PAJAK JAN-NOV'!R23 -> 0 | AJ26: =IF(AG26<=AI26,0,IF(AG26>AI26,AG26-AI26)) -> 0 | AL26: =AI26-AH26 -> 0
B27: 22 | C27: =+PERBULAN!B27 -> 0 | J27: =IF(ISBLANK(I27),"",IF(OR(I27="TK/0",I27="TK/1",I27="K/0"),"TER A",IF(I27="K/3","TER C","TER B"))) | P27: 0 | Q27: =SUM(M27:P27) -> 0 | R27: =+PERBULAN!S27 -> 0 | S27: =+SETAHUN!K28 -> 0 | T27: 0 | U27: =+SETAHUN!F28+M27+N27 -> 0 | W27: =+SETAHUN!U28+O27 -> 0 | X27: 0 | Y27: 0 | Z27: =SUM(R27:T27) -> 0 | AA27: =SUM(U27:Z27) -> 0 | AB27: =ROUND(IF((AA27)*5%>6000000,6000000,(AA27)*5%),0) -> 0 | AC27: =('ASTEK+PENSIUN'!O29+'ASTEK+PENSIUN'!O72) -> 0 | AD27: =AA27-AB27-AC27 -> 0 | AE27: =IFERROR(VLOOKUP(I27,TARIF,3,FALSE),0) -> 0 | AF27: =ROUNDDOWN(IF(AD27<=AE27,0,IF(AD27>AE27,AD27-AE27)),-3) -> 0 | AG27: =IF(AF27>5000000000,AF27*35%-306000000,IF(AF27>500000000,AF27*30%-56000000,IF(AF27>250000000,AF27*25%-31000000,IF(AF27>60000000,AF27*15%-6000000,AF27*5%)))) -> 0 | AH27: =ROUND(IF(E27=0,AG27*120%,AG27),0) -> 0 | AI27: =+'PAJAK JAN-NOV'!R24 -> 0 | AJ27: =IF(AG27<=AI27,0,IF(AG27>AI27,AG27-AI27)) -> 0 | AL27: =AI27-AH27 -> 0
B28: 23 | C28: =+PERBULAN!B28 -> 0 | J28: =IF(ISBLANK(I28),"",IF(OR(I28="TK/0",I28="TK/1",I28="K/0"),"TER A",IF(I28="K/3","TER C","TER B"))) | P28: 0 | Q28: =SUM(M28:P28) -> 0 | R28: =+PERBULAN!S28 -> 0 | S28: =+SETAHUN!K29 -> 0 | T28: 0 | U28: =+SETAHUN!F29+M28+N28 -> 0 | W28: =+SETAHUN!U29+O28 -> 0 | X28: 0 | Y28: 0 | Z28: =SUM(R28:T28) -> 0 | AA28: =SUM(U28:Z28) -> 0 | AB28: =ROUND(IF((AA28)*5%>6000000,6000000,(AA28)*5%),0) -> 0 | AC28: =('ASTEK+PENSIUN'!O30+'ASTEK+PENSIUN'!O73) -> 0 | AD28: =AA28-AB28-AC28 -> 0 | AE28: =IFERROR(VLOOKUP(I28,TARIF,3,FALSE),0) -> 0 | AF28: =ROUNDDOWN(IF(AD28<=AE28,0,IF(AD28>AE28,AD28-AE28)),-3) -> 0 | AG28: =IF(AF28>5000000000,AF28*35%-306000000,IF(AF28>500000000,AF28*30%-56000000,IF(AF28>250000000,AF28*25%-31000000,IF(AF28>60000000,AF28*15%-6000000,AF28*5%)))) -> 0 | AH28: =ROUND(IF(E28=0,AG28*120%,AG28),0) -> 0 | AI28: =+'PAJAK JAN-NOV'!R25 -> 0 | AJ28: =IF(AG28<=AI28,0,IF(AG28>AI28,AG28-AI28)) -> 0 | AL28: =AI28-AH28 -> 0
B29: 24 | C29: =+PERBULAN!B29 -> 0 | J29: =IF(ISBLANK(I29),"",IF(OR(I29="TK/0",I29="TK/1",I29="K/0"),"TER A",IF(I29="K/3","TER C","TER B"))) | P29: 0 | Q29: =SUM(M29:P29) -> 0 | R29: =+PERBULAN!S29 -> 0 | S29: =+SETAHUN!K30 -> 0 | U29: =+SETAHUN!F30 -> 0 | W29: =+SETAHUN!U30 -> 0 | X29: 0 | Y29: 0 | Z29: =SUM(R29:T29) -> 0 | AA29: =SUM(U29:Z29) -> 0 | AB29: =ROUND(IF((AA29)*5%>6000000,6000000,(AA29)*5%),0) -> 0 | AC29: =('ASTEK+PENSIUN'!O31+'ASTEK+PENSIUN'!O74) -> 0 | AD29: =AA29-AB29-AC29 -> 0 | AE29: =IFERROR(VLOOKUP(I29,TARIF,3,FALSE),0) -> 0 | AF29: =ROUNDDOWN(IF(AQ29>AR29,AQ29-AR29,0),-3) -> 0 | AG29: =IF(AF29>5000000000,AF29*35%-306000000,IF(AF29>500000000,AF29*30%-56000000,IF(AF29>250000000,AF29*25%-31000000,IF(AF29>60000000,AF29*15%-6000000,AF29*5%)))) -> 0 | AH29: =ROUND(IF(E29=0,AG29*120%,AG29),0) -> 0 | AI29: =+'PAJAK JAN-NOV'!R26 -> 0 | AJ29: =IF(AG29<=AI29,0,IF(AG29>AI29,AG29-AI29)) -> 0 | AL29: =AI29-AH29 -> 0
B30: 25 | C30: =+PERBULAN!B30 -> 0 | J30: =IF(ISBLANK(I30),"",IF(OR(I30="TK/0",I30="TK/1",I30="K/0"),"TER A",IF(I30="K/3","TER C","TER B"))) | R30: =+PERBULAN!S30 -> 0 | S30: =+SETAHUN!K31 -> 0 | U30: =+SETAHUN!F31 -> 0 | W30: =+SETAHUN!U31 -> 0 | X30: 0 | Y30: 0 | Z30: =SUM(R30:T30) -> 0 | AA30: =SUM(U30:Z30) -> 0 | AB30: =ROUND(IF((AA30)*5%>6000000,6000000,(AA30)*5%),0) -> 0 | AC30: =('ASTEK+PENSIUN'!O32+'ASTEK+PENSIUN'!O75) -> 0 | AD30: =AA30-AB30-AC30 -> 0 | AE30: =IFERROR(VLOOKUP(I30,TARIF,3,FALSE),0) -> 0 | AF30: =ROUNDDOWN(IF(AQ30>AR30,AQ30-AR30,0),-3) -> 0 | AG30: =IF(AF30>5000000000,AF30*35%-306000000,IF(AF30>500000000,AF30*30%-56000000,IF(AF30>250000000,AF30*25%-31000000,IF(AF30>60000000,AF30*15%-6000000,AF30*5%)))) -> 0 | AH30: =ROUND(IF(E30=0,AG30*120%,AG30),0) -> 0 | AI30: =+'PAJAK JAN-NOV'!R27 -> 0 | AJ30: =IF(AG30<=AI30,0,IF(AG30>AI30,AG30-AI30)) -> 0 | AL30: =AI30-AH30 -> 0
B31: 26 | C31: =+PERBULAN!B31 -> 0 | J31: =IF(ISBLANK(I31),"",IF(OR(I31="TK/0",I31="TK/1",I31="K/0"),"TER A",IF(I31="K/3","TER C","TER B"))) | R31: =+PERBULAN!S31 -> 0 | U31: =+SETAHUN!F32 -> 0 | W31: =+SETAHUN!U32 -> 0 | X31: 0 | Y31: 0 | Z31: =SUM(R31:T31) -> 0 | AA31: =SUM(U31:Z31) -> 0 | AB31: =ROUND(IF((AA31)*5%>6000000,6000000,(AA31)*5%),0) -> 0 | AC31: =('ASTEK+PENSIUN'!O33+'ASTEK+PENSIUN'!O76) -> 0 | AD31: =AA31-AB31-AC31 -> 0 | AE31: =IFERROR(VLOOKUP(I31,TARIF,3,FALSE),0) -> 0 | AF31: =ROUNDDOWN(IF(AQ31>AR31,AQ31-AR31,0),-3) -> 0 | AG31: =IF(AF31>5000000000,AF31*35%-306000000,IF(AF31>500000000,AF31*30%-56000000,IF(AF31>250000000,AF31*25%-31000000,IF(AF31>60000000,AF31*15%-6000000,AF31*5%)))) -> 0 | AH31: =ROUND(IF(E31=0,AG31*120%,AG31),0) -> 0 | AI31: =+'PAJAK JAN-NOV'!R28 -> 0 | AJ31: =IF(AG31<=AI31,0,IF(AG31>AI31,AG31-AI31)) -> 0 | AL31: =AI31-AH31 -> 0
B32: 27 | C32: =+PERBULAN!B32 -> 0 | J32: =IF(ISBLANK(I32),"",IF(OR(I32="TK/0",I32="TK/1",I32="K/0"),"TER A",IF(I32="K/3","TER C","TER B"))) | R32: =+PERBULAN!S32 -> 0 | U32: =+SETAHUN!F33 -> 0 | W32: =+SETAHUN!U33 -> 0 | X32: 0 | Y32: 0 | Z32: =SUM(R32:T32) -> 0 | AA32: =SUM(U32:Z32) -> 0 | AB32: =ROUND(IF((AA32)*5%>6000000,6000000,(AA32)*5%),0) -> 0 | AC32: =('ASTEK+PENSIUN'!O34+'ASTEK+PENSIUN'!O77) -> 0 | AD32: =AA32-AB32-AC32 -> 0 | AE32: =IFERROR(VLOOKUP(I32,TARIF,3,FALSE),0) -> 0 | AF32: =ROUNDDOWN(IF(AQ32>AR32,AQ32-AR32,0),-3) -> 0 | AG32: =IF(AF32>5000000000,AF32*35%-306000000,IF(AF32>500000000,AF32*30%-56000000,IF(AF32>250000000,AF32*25%-31000000,IF(AF32>60000000,AF32*15%-6000000,AF32*5%)))) -> 0 | AH32: =ROUND(IF(E32=0,AG32*120%,AG32),0) -> 0 | AI32: =+'PAJAK JAN-NOV'!R29 -> 0 | AJ32: =IF(AG32<=AI32,0,IF(AG32>AI32,AG32-AI32)) -> 0 | AL32: =AI32-AH32 -> 0
B33: 28 | C33: =+PERBULAN!B33 -> 0 | R33: =+PERBULAN!S33 -> 0 | U33: =+SETAHUN!F34 -> 0 | W33: =+SETAHUN!U34 -> 0 | X33: 0 | Y33: 0 | Z33: =SUM(R33:T33) -> 0 | AA33: =SUM(U33:Z33) -> 0 | AB33: =ROUND(IF((AA33)*5%>6000000,6000000,(AA33)*5%),0) -> 0 | AC33: =('ASTEK+PENSIUN'!O35+'ASTEK+PENSIUN'!O78) -> 0 | AD33: =AA33-AB33-AC33 -> 0 | AE33: =IFERROR(VLOOKUP(I33,TARIF,3,FALSE),0) -> 0 | AF33: =ROUNDDOWN(IF(AQ33>AR33,AQ33-AR33,0),-3) -> 0 | AG33: =IF(AF33>5000000000,AF33*35%-306000000,IF(AF33>500000000,AF33*30%-56000000,IF(AF33>250000000,AF33*25%-31000000,IF(AF33>60000000,AF33*15%-6000000,AF33*5%)))) -> 0 | AH33: =ROUND(IF(E33=0,AG33*120%,AG33),0) -> 0 | AI33: =+'PAJAK JAN-NOV'!R30 -> 0 | AJ33: =IF(AG33<=AI33,0,IF(AG33>AI33,AG33-AI33)) -> 0 | AL33: =AI33-AH33 -> 0
B34: 29 | C34: =+PERBULAN!B34 -> 0 | R34: =+PERBULAN!S34 -> 0 | U34: =+SETAHUN!F35 -> 0 | W34: =+SETAHUN!U35 -> 0 | X34: 0 | Y34: 0 | Z34: =SUM(R34:T34) -> 0 | AA34: =SUM(U34:Z34) -> 0 | AB34: =ROUND(IF((AA34)*5%>6000000,6000000,(AA34)*5%),0) -> 0 | AC34: =('ASTEK+PENSIUN'!O36+'ASTEK+PENSIUN'!O79) -> 0 | AD34: =AA34-AB34-AC34 -> 0 | AE34: =IFERROR(VLOOKUP(I34,TARIF,3,FALSE),0) -> 0 | AF34: =ROUNDDOWN(IF(AQ34>AR34,AQ34-AR34,0),-3) -> 0 | AG34: =IF(AF34>5000000000,AF34*35%-306000000,IF(AF34>500000000,AF34*30%-56000000,IF(AF34>250000000,AF34*25%-31000000,IF(AF34>60000000,AF34*15%-6000000,AF34*5%)))) -> 0 | AH34: =ROUND(IF(E34=0,AG34*120%,AG34),0) -> 0 | AI34: =+'PAJAK JAN-NOV'!R31 -> 0 | AJ34: =IF(AG34<=AI34,0,IF(AG34>AI34,AG34-AI34)) -> 0 | AL34: =AI34-AH34 -> 0
B35: 30 | C35: =+PERBULAN!B35 -> 0 | R35: =+PERBULAN!S35 -> 0 | U35: =+SETAHUN!F36 -> 0 | W35: =+SETAHUN!U36 -> 0 | X35: 0 | Y35: 0 | Z35: =SUM(R35:T35) -> 0 | AA35: =SUM(U35:Z35) -> 0 | AB35: =ROUND(IF((AA35)*5%>6000000,6000000,(AA35)*5%),0) -> 0 | AC35: =('ASTEK+PENSIUN'!O37+'ASTEK+PENSIUN'!O80) -> 0 | AD35: =AA35-AB35-AC35 -> 0 | AE35: =IFERROR(VLOOKUP(I35,TARIF,3,FALSE),0) -> 0 | AF35: =ROUNDDOWN(IF(AQ35>AR35,AQ35-AR35,0),-3) -> 0 | AG35: =IF(AF35>5000000000,AF35*35%-306000000,IF(AF35>500000000,AF35*30%-56000000,IF(AF35>250000000,AF35*25%-31000000,IF(AF35>60000000,AF35*15%-6000000,AF35*5%)))) -> 0 | AH35: =ROUND(IF(E35=0,AG35*120%,AG35),0) -> 0 | AI35: =+'PAJAK JAN-NOV'!R32 -> 0 | AJ35: =IF(AG35<=AI35,0,IF(AG35>AI35,AG35-AI35)) -> 0 | AL35: =AI35-AH35 -> 0
B36: 31 | C36: =+PERBULAN!B36 -> 0 | R36: =+PERBULAN!S36 -> 0 | U36: =+SETAHUN!F37 -> 0 | W36: =+SETAHUN!U37 -> 0 | X36: 0 | Y36: 0 | Z36: =SUM(R36:T36) -> 0 | AA36: =SUM(U36:Z36) -> 0 | AB36: =ROUND(IF((AA36)*5%>6000000,6000000,(AA36)*5%),0) -> 0 | AC36: =('ASTEK+PENSIUN'!O38+'ASTEK+PENSIUN'!O81) -> 0 | AD36: =AA36-AB36-AC36 -> 0 | AE36: =IFERROR(VLOOKUP(I36,TARIF,3,FALSE),0) -> 0 | AF36: =ROUNDDOWN(IF(AQ36>AR36,AQ36-AR36,0),-3) -> 0 | AG36: =IF(AF36>5000000000,AF36*35%-306000000,IF(AF36>500000000,AF36*30%-56000000,IF(AF36>250000000,AF36*25%-31000000,IF(AF36>60000000,AF36*15%-6000000,AF36*5%)))) -> 0 | AH36: =ROUND(IF(E36=0,AG36*120%,AG36),0) -> 0 | AI36: =+'PAJAK JAN-NOV'!R33 -> 0 | AJ36: =IF(AG36<=AI36,0,IF(AG36>AI36,AG36-AI36)) -> 0 | AL36: =AI36-AH36 -> 0
B37: 32 | C37: =+PERBULAN!B37 -> 0 | R37: =+PERBULAN!S37 -> 0 | U37: =+SETAHUN!F38 -> 0 | W37: =+SETAHUN!U38 -> 0 | X37: 0 | Y37: 0 | Z37: =SUM(R37:T37) -> 0 | AA37: =SUM(U37:Z37) -> 0 | AB37: =ROUND(IF((AA37)*5%>6000000,6000000,(AA37)*5%),0) -> 0 | AC37: =('ASTEK+PENSIUN'!O39+'ASTEK+PENSIUN'!O82) -> 0 | AD37: =AA37-AB37-AC37 -> 0 | AE37: =IFERROR(VLOOKUP(I37,TARIF,3,FALSE),0) -> 0 | AF37: =ROUNDDOWN(IF(AQ37>AR37,AQ37-AR37,0),-3) -> 0 | AG37: =IF(AF37>5000000000,AF37*35%-306000000,IF(AF37>500000000,AF37*30%-56000000,IF(AF37>250000000,AF37*25%-31000000,IF(AF37>60000000,AF37*15%-6000000,AF37*5%)))) -> 0 | AH37: =ROUND(IF(E37=0,AG37*120%,AG37),0) -> 0 | AI37: =+'PAJAK JAN-NOV'!R34 -> 0 | AJ37: =IF(AG37<=AI37,0,IF(AG37>AI37,AG37-AI37)) -> 0 | AL37: =AI37-AH37 -> 0
B38: 33
M39: =SUM(M6:M37) -> 84845598 | N39: =SUM(N6:N37) -> 0 | O39: =SUM(O6:O37) -> 811500 | P39: =SUM(P6:P37) -> 0 | Q39: =SUM(Q6:Q37) -> 85657098 | R39: =SUM(R6:R37) -> 64418600 | S39: =SUM(S6:S37) -> 6800000 | T39: =SUM(T6:T37) -> 0 | ... AJ39: =SUM(AJ6:AJ37) -> 907252 | AL39: =SUM(AL6:AL32) -> 213359
B41: Catatan : | Q41: =[3]NURSERY!$AJ$26 -> 85657098
B42: 1. yang berwarna adalah rumus
B43: 2. dalam hal terdapat tunjangan PPh, maka ceklis "enable iterative calculation" pada menu (option => formula => pada bagian kanan atas)
B44: 3. kolom pengurang JHT/JP tetap wajib diisi, sebagai pengurang pada masa pajak desember
...

Sheet Jan'24
B1: PT. REBINMAS JAYA
B2: INCOME TAX ARTICLE 21 FOR JAN 2024
B3: INFRASTRUKTUR
C4: yang berwarna ini rumus
B5: NO. | C5: NAMA KARYAWAN | D5: N I K / PASPOR | E5: N P W P | F5: A L A M A T | G5: JABATAN | H5: L/P | I5: PTKP | J5: TER | K5: Gaji Pokok | L5: Astek Ins (0,84%) | M5: BPJS KESEHATAN (4%) | N5: Transport Allow | O5: Rice Allow | P5: Structural Allow | Q5: Service Time Allow | R5: Tunjangan Stand - By | S5: Tunjangan PPh | T5: Others Kinerja | U5: THR | V5: EX-GRATIA | W5: Penghasilan Bruto | X5: Tarif TER | Y5: PPh 21 | Z5: PPh 21 Pot Jan'24 | AA5: Selisih | AB5: Keterangan | AD5: BPJS
B6: 1 | C6: YOYO | D6: 1902010509730003 | E6: 972282958305000 | F6: JL MURAI RT. 029 RW. 010 DS PERAWAS TANJUNGPANDAN | H6: L | I6: K/0 | J6: =IF(ISBLANK(I6),"",IF(OR(I6="TK/0",I6="TK/1",I6="K/0"),"TER A",IF(I6="K/3","TER C","TER B"))) -> TER A | K6: 4186418.9 | L6: 30576 | M6: 148040 | S6: 0 | W6: =SUM(K6:V6) -> 4365034.9 | X6: =IF($J6="TER A",VLOOKUP(W6,Ter_A,4,TRUE),IF($J6="TER B",VLOOKUP(W6,Ter_B,4,TRUE),VLOOKUP(W6,Ter_C,4,TRUE))) -> 0 | Y6: =ROUND(IF($E6=0,W6*X6*120%,W6*X6),0) -> 0 | Z6: 0 | AA6: =Z6-Y6 -> 0 | AD6: =SUM(L6+M6) -> 178616
B7: 2 | C7: JAMILA | D7: 1902056811690001 | E7: 972282982305000 | F7: JL MANGGAR RT. 005 RW. 003 DS AIR BATU BUDING KEC. BADAU | H7: P | I7: TK/0 | J7: =IF(ISBLANK(I7),"",IF(OR(I7="TK/0",I7="TK/1",I7="K/0"),"TER A",IF(I7="K/3","TER C","TER B"))) -> TER A | K7: 6238094.6 | L7: 30576 | M7: 148040 | S7: 0 | W7: =SUM(K7:V7) -> 6416710.6 | X7: =IF($J7="TER A",VLOOKUP(W7,Ter_A,4,TRUE),IF($J7="TER B",VLOOKUP(W7,Ter_B,4,TRUE),VLOOKUP(W7,Ter_C,4,TRUE))) -> 0.01 | Y7: =ROUND(IF($E7=0,W7*X7*120%,W7*X7),0) -> 64167 | Z7: 74333.755 | AA7: =Z7-Y7 -> 10166.755 | AB7: Lebih Pot | AD7: =SUM(L7+M7) -> 178616
B8: 3 | C8: JUNI MI'UN | D8: 1902050107700052 | E8: 972283055305000 | F8: JL MANGGAR DSN KEPAYANG RT. 004 RW. 002 DS KACANG BUTOR BADAU | H8: L | I8: K/1 | J8: =IF(ISBLANK(I8),"",IF(OR(I8="TK/0",I8="TK/1",I8="K/0"),"TER A",IF(I8="K/3","TER C","TER B"))) -> TER B | K8: 5122599.1 | L8: 30576 | M8: 147340 | S8: 0 | W8: =SUM(K8:V8) -> 5300515.1 | X8: =IF($J8="TER A",VLOOKUP(W8,Ter_A,4,TRUE),IF($J8="TER B",VLOOKUP(W8,Ter_B,4,TRUE),VLOOKUP(W8,Ter_C,4,TRUE))) -> 0 | Y8: =ROUND(IF($E8=0,W8*X8*120%,W8*X8),0) -> 0 | Z8: 0 | AA8: =Z8-Y8 -> 0 | AD8: =SUM(L8+M8) -> 177916
B9: 4 | C9: SUHANDI | D9: 1906042606860003 | E9: 972282974305000 | F9: JL KOPERASI RT. 004 RW. 002 DESA PEMBAHARUAN KEC. KELAPA KAMPIT | H9: L | I9: K/1 | J9: =IF(ISBLANK(I9),"",IF(OR(I9="TK/0",I9="TK/1",I9="K/0"),"TER A",IF(I9="K/3","TER C","TER B"))) -> TER B | K9: 4540833.3 | L9: 30576 | M9: 147200 | S9: 0 | W9: =SUM(K9:V9) -> 4718609.3 | X9: =IF($J9="TER A",VLOOKUP(W9,Ter_A,4,TRUE),IF($J9="TER B",VLOOKUP(W9,Ter_B,4,TRUE),VLOOKUP(W9,Ter_C,4,TRUE))) -> 0 | Y9: =ROUND(IF($E9=0,W9*X9*120%,W9*X9),0) -> 0 | Z9: 0 | AA9: =Z9-Y9 -> 0 | AD9: =SUM(L9+M9) -> 177776
B10: 5 | C10: MINARNI | D10: 1902056103760002 | E10: 972280226305000 | F10: AIR BATU BUDING RT. 004 RW. 002 DS AIR BATU BUDING KEC. BADAU | H10: P | I10: TK/0 | J10: =IF(ISBLANK(I10),"",IF(OR(I10="TK/0",I10="TK/1",I10="K/0"),"TER A",IF(I10="K/3","TER C","TER B"))) -> TER A | K10: 5185010.9 | L10: 30576 | M10: 147340 | W10: =SUM(K10:V10) -> 5362926.9 | X10: =IF($J10="TER A",VLOOKUP(W10,Ter_A,4,TRUE),IF($J10="TER B",VLOOKUP(W10,Ter_B,4,TRUE),VLOOKUP(W10,Ter_C,4,TRUE))) -> 0 | Y10: =ROUND(IF($E10=0,W10*X10*120%,W10*X10),0) -> 0 | Z10: 24279.029 | AA10: =Z10-Y10 -> 24279.029 | AB10: Lebih Pot | AD10: =SUM(L10+M10) -> 177916
B11: 6 | C11: SUPRIADI | D11: 1902052812870001 | E11: 972283014305000 | F11: JL AIR BEGANTUNG RT. 009 RW. 003 DS KACANG BUTOR KEC.BADAU | H11: L | I11: K/2 | J11: =IF(ISBLANK(I11),"",IF(OR(I11="TK/0",I11="TK/1",I11="K/0"),"TER A",IF(I11="K/3","TER C","TER B"))) -> TER B | K11: 3975733.3 | L11: 30576 | M11: 147480 | W11: =SUM(K11:V11) -> 4153789.3 | X11: =IF($J11="TER A",VLOOKUP(W11,Ter_A,4,TRUE),IF($J11="TER B",VLOOKUP(W11,Ter_B,4,TRUE),VLOOKUP(W11,Ter_C,4,TRUE))) -> 0 | Y11: =ROUND(IF($E11=0,W11*X11*120%,W11*X11),0) -> 0 | Z11: 0 | AA11: =Z11-Y11 -> 0 | AD11: =SUM(L11+M11) -> 178056
B12: 7 | C12: HARIAH | D12: 1902014909730007 | E12: 972283048305000 | F12: PELATARAN AIR KETEKOK RT. 001 RW. 001 DS AIR KETEKOK TANJUNGPANDAN | H12: P | I12: TK/0 | J12: =IF(ISBLANK(I12),"",IF(OR(I12="TK/0",I12="TK/1",I12="K/0"),"TER A",IF(I12="K/3","TER C","TER B"))) -> TER A | K12: 6497640.8 | L12: 30576 | M12: 147060 | W12: =SUM(K12:V12) -> 6675276.8 | X12: =IF($J12="TER A",VLOOKUP(W12,Ter_A,4,TRUE),IF($J12="TER B",VLOOKUP(W12,Ter_B,4,TRUE),VLOOKUP(W12,Ter_C,4,TRUE))) -> 0.01 | Y12: =ROUND(IF($E12=0,W12*X12*120%,W12*X12),0) -> 66753 | Z12: 86615.65 | AA12: =Z12-Y12 -> 19862.65 | AB12: Lebih Pot | AD12: =SUM(L12+M12) -> 177636
B13: 8 | C13: YUSMARDIAN | D13: 1906042403820005 | E13: 972280150305000 | F13: DSN SENYUBUK RT. 001 RW. 001 DESA MENTAWAK KEC. KELAPA KAMPIT | H13: L | I13: K/2 | J13: =IF(ISBLANK(I13),"",IF(OR(I13="TK/0",I13="TK/1",I13="K/0"),"TER A",IF(I13="K/3","TER C","TER B"))) -> TER B | K13: 4399572.2 | L13: 30576 | M13: 147200 | W13: =SUM(K13:V13) -> 4577348.2 | X13: =IF($J13="TER A",VLOOKUP(W13,Ter_A,4,TRUE),IF($J13="TER B",VLOOKUP(W13,Ter_B,4,TRUE),VLOOKUP(W13,Ter_C,4,TRUE))) -> 0 | Y13: =ROUND(IF($E13=0,W13*X13*120%,W13*X13),0) -> 0 | Z13: 0 | AA13: =Z13-Y13 -> 0 | AD13: =SUM(L13+M13) -> 177776
B14: 11 | C14: YULHANI | D14: 1902051010760007 | E14: 972285720305000 | F14: JL MANGGAR AIR BEGANTUNG RT. 008 RW. 003 DESA KACANG BUTOR BADAU | H14: L | I14: K/0 | J14: =IF(ISBLANK(I14),"",IF(OR(I14="TK/0",I14="TK/1",I14="K/0"),"TER A",IF(I14="K/3","TER C","TER B"))) -> TER A | K14: 3933933.3 | L14: 30576 | M14: 148040 | W14: =SUM(K14:V14) -> 4112549.3 | X14: =IF($J14="TER A",VLOOKUP(W14,Ter_A,4,TRUE),IF($J14="TER B",VLOOKUP(W14,Ter_B,4,TRUE),VLOOKUP(W14,Ter_C,4,TRUE))) -> 0 | Y14: =ROUND(IF($E14=0,W14*X14*120%,W14*X14),0) -> 0 | Z14: 0 | AA14: =Z14-Y14 -> 0 | AD14: =SUM(L14+M14) -> 178616
B15: 12 | C15: HENDRIX | D15: 1906041308920003 | E15: 743653768305000 | F15: DSN MERDEKA RT. 006 RW. 002 DS SENYUBUK KEC. KELAPA KAMPIT | H15: L | I15: K/1 | J15: =IF(ISBLANK(I15),"",IF(OR(I15="TK/0",I15="TK/1",I15="K/0"),"TER A",IF(I15="K/3","TER C","TER B"))) -> TER B | K15: 3930833.3 | L15: 30576 | M15: 146800 | W15: =SUM(K15:V15) -> 4108209.3 | X15: =IF($J15="TER A",VLOOKUP(W15,Ter_A,4,TRUE),IF($J15="TER B",VLOOKUP(W15,Ter_B,4,TRUE),VLOOKUP(W15,Ter_C,4,TRUE))) -> 0 | Y15: =ROUND(IF($E15=0,W15*X15*120%,W15*X15),0) -> 0 | Z15: 0 | AA15: =Z15-Y15 -> 0 | AD15: =SUM(L15+M15) -> 177376
B16: 13 | C16: ARIANTO.B | D16: 1902052202690002 | E16: 972283287305000 | F16: DSN KACANG BUTOR RT. 001 RW. 001 DESA KACANG BUTOR KEC. BADAU | H16: L | I16: K/1 | J16: =IF(ISBLANK(I16),"",IF(OR(I16="TK/0",I16="TK/1",I16="K/0"),"TER A",IF(I16="K/3","TER C","TER B"))) -> TER B | K16: 3961833.3 | L16: 30576 | M16: 148040 | W16: =SUM(K16:V16) -> 4140449.3 | X16: =IF($J16="TER A",VLOOKUP(W16,Ter_A,4,TRUE),IF($J16="TER B",VLOOKUP(W16,Ter_B,4,TRUE),VLOOKUP(W16,Ter_C,4,TRUE))) -> 0 | Y16: =ROUND(IF($E16=0,W16*X16*120%,W16*X16),0) -> 0 | Z16: 0 | AA16: =Z16-Y16 -> 0 | AD16: =SUM(L16+M16) -> 178616
B17: 14 | C17: NANDI | D17: 1902053006780001 | E17: 972282966305000 | F17: JL. MANGGAR DSN. KACANG BUTOR RT.001 RW.001 DS. KACANG BUTOR KEC. BADAU | H17: L | I17: K/1 | J17: =IF(ISBLANK(I17),"",IF(OR(I17="TK/0",I17="TK/1",I17="K/0"),"TER A",IF(I17="K/3","TER C","TER B"))) -> TER B | K17: 3996000 | L17: 30576 | M17: 148040 | W17: =SUM(K17:V17) -> 4174616 | X17: =IF($J17="TER A",VLOOKUP(W17,Ter_A,4,TRUE),IF($J17="TER B",VLOOKUP(W17,Ter_B,4,TRUE),VLOOKUP(W17,Ter_C,4,TRUE))) -> 0 | Y17: =ROUND(IF($E17=0,W17*X17*120%,W17*X17),0) -> 0 | Z17: 0 | AA17: =Z17-Y17 -> 0 | AD17: =SUM(L17+M17) -> 178616
B18: 9 | C18: KAMELIA | D18: 1902051606760003 | E18: 972280218305000 | F18: JL MANGGAR DSN PARIT GUNUNG RT. 006 RW. 003 DS AIR BATU BUDING BADAU | H18: L | I18: K/0 | J18: =IF(ISBLANK(I18),"",IF(OR(I18="TK/0",I18="TK/1",I18="K/0"),"TER A",IF(I18="K/3","TER C","TER B"))) -> TER A | K18: 3791500 | L18: 30576 | M18: 147340 | W18: =SUM(K18:V18) -> 3969416 | X18: =IF($J18="TER A",VLOOKUP(W18,Ter_A,4,TRUE),IF($J18="TER B",VLOOKUP(W18,Ter_B,4,TRUE),VLOOKUP(W18,Ter_C,4,TRUE))) -> 0 | Y18: =ROUND(IF($E18=0,W18*X18*120%,W18*X18),0) -> 0 | Z18: 0 | AA18: =Z18-Y18 -> 0 | AD18: =SUM(L18+M18) -> 177916
B19: 15 | C19: SISWANTO | D19: 1902051902910001 | E19: 972285506305000 | F19: JL. MANGGAR DSN. PARIT GUNUNG RT.006 RW.003 DS. AIR BATU BUDING KEC. BADAU | H19: L | I19: K/1 | J19: =IF(ISBLANK(I19),"",IF(OR(I19="TK/0",I19="TK/1",I19="K/0"),"TER A",IF(I19="K/3","TER C","TER B"))) -> TER B | K19: 3913591.5 | L19: 30576 | M19: 147340 | W19: =SUM(K19:V19) -> 4091507.5 | X19: =IF($J19="TER A",VLOOKUP(W19,Ter_A,4,TRUE),IF($J19="TER B",VLOOKUP(W19,Ter_B,4,TRUE),VLOOKUP(W19,Ter_C,4,TRUE))) -> 0 | Y19: =ROUND(IF($E19=0,W19*X19*120%,W19*X19),0) -> 0 | Z19: 0 | AA19: =Z19-Y19 -> 0 | AD19: =SUM(L19+M19) -> 177916
B20: 17 | C20: DARMA JAYA | D20: 1902051907880002 | E20: 972374425305000 | F20: DSN AIR BATU BUDING RT.001 RW.001 DESA AIR BATU BUDING KEC. BADAU | H20: L | I20: K/2 | J20: =IF(ISBLANK(I20),"",IF(OR(I20="TK/0",I20="TK/1",I20="K/0"),"TER A",IF(I20="K/3","TER C","TER B"))) -> TER B | K20: 7005559.6 | L20: 30576 | M20: 147480 | S20: 0 | W20: =SUM(K20:V20) -> 7183615.6 | X20: =IF($J20="TER A",VLOOKUP(W20,Ter_A,4,TRUE),IF($J20="TER B",VLOOKUP(W20,Ter_B,4,TRUE),VLOOKUP(W20,Ter_C,4,TRUE))) -> 0.0075 | Y20: =ROUND(IF($E20=0,W20*X20*120%,W20*X20),0) -> 53877 | Z20: 54511.74 | AA20: =Z20-Y20 -> 634.73973 | AB20: Lebih Pot | AD20: =SUM(L20+M20) -> 178056
B21: 20 | C21: YUSMARNO | D21: 1902012406780003 | E21: 972285704305000 | F21: JL PASIR PUTIH RT. 012 RW. 005 DS AIR RAYAK KEC. TANJUNGPANDAN | H21: L | I21: K/1 | J21: =IF(ISBLANK(I21),"",IF(OR(I21="TK/0",I21="TK/1",I21="K/0"),"TER A",IF(I21="K/3","TER C","TER B"))) -> TER B | K21: 3836818.9 | L21: 30576 | M21: 148040 | S21: 0 | W21: =SUM(K21:V21) -> 4015434.9 | X21: =IF($J21="TER A",VLOOKUP(W21,Ter_A,4,TRUE),IF($J21="TER B",VLOOKUP(W21,Ter_B,4,TRUE),VLOOKUP(W21,Ter_C,4,TRUE))) -> 0 | Y21: =ROUND(IF($E21=0,W21*X21*120%,W21*X21),0) -> 0 | Z21: 0 | AA21: =Z21-Y21 -> 0 | AD21: =SUM(L21+M21) -> 178616
B22: 21 | C22: MEGI EPRISA | D22: 1604220103030001 | E22: - | F22: DS. TANJUNG AGUNG KEL. TANJUNG AGUNG KEC. PAGAR GUNUNG KAB. LAHAT | H22: L | I22: TK/0 | J22: =IF(ISBLANK(I22),"",IF(OR(I22="TK/0",I22="TK/1",I22="K/0"),"TER A",IF(I22="K/3","TER C","TER B"))) -> TER A | K22: 6004796.9 | L22: 31206 | M22: 148700 | S22: 0 | W22: =SUM(K22:V22) -> 6184702.9 | X22: =IF($J22="TER A",VLOOKUP(W22,Ter_A,4,TRUE),IF($J22="TER B",VLOOKUP(W22,Ter_B,4,TRUE),VLOOKUP(W22,Ter_C,4,TRUE))) -> 0.0075 | Y22: =ROUND(IF($E22=0,W22*X22*120%,W22*X22),0) -> 46385 | Z22: 75841.067 | AA22: =Z22-Y22 -> 29456.067 | AB22: Lebih Pot | AD22: =SUM(L22+M22) -> 179906
B23: 24 | C23: SURATMAN | D23: 1902052707850001 | E23: 972285225305000 | F23: DUSUN KEPAYANG RT. 004 RW. 002 DESA KACANG BUTOR KEC. BADAU | H23: L | I23: K/0 | J23: =IF(ISBLANK(I23),"",IF(OR(I23="TK/0",I23="TK/1",I23="K/0"),"TER A",IF(I23="K/3","TER C","TER B"))) -> TER A | K23: 4354121.2 | L23: 30576 | M23: 147340 | S23: 0 | W23: =SUM(K23:V23) -> 4532037.2 | X23: =IF($J23="TER A",VLOOKUP(W23,Ter_A,4,TRUE),IF($J23="TER B",VLOOKUP(W23,Ter_B,4,TRUE),VLOOKUP(W23,Ter_C,4,TRUE))) -> 0 | Y23: =ROUND(IF($E23=0,W23*X23*120%,W23*X23),0) -> 0 | Z23: 0 | AA23: =Z23-Y23 -> 0 | AD23: =SUM(L23+M23) -> 177916
B24: 10 | C24: ARDI | D24: 1902050512820004 | E24: 972280259305000 | F24: JL.MANGGAR RT.009 RW.003 DESA KACANG BUTOR KEC. BADAU | H24: L | I24: K/2 | J24: =IF(ISBLANK(I24),"",IF(OR(I24="TK/0",I24="TK/1",I24="K/0"),"TER A",IF(I24="K/3","TER C","TER B"))) -> TER B | K24: 8003339.8 | L24: 30576 | M24: 147480 | W24: =SUM(K24:V24) -> 8181395.8 | X24: =IF($J24="TER A",VLOOKUP(W24,Ter_A,4,TRUE),IF($J24="TER B",VLOOKUP(W24,Ter_B,4,TRUE),VLOOKUP(W24,Ter_C,4,TRUE))) -> 0.01 | Y24: =ROUND(IF($E24=0,W24*X24*120%,W24*X24),0) -> 81814 | Z24: 101906.3 | AA24: =Z24-Y24 -> 20092.301 | AB24: Lebih Pot | AD24: =SUM(L24+M24) -> 178056
B25: 16 | C25: EDI ISHAK | D25: 1902051212790002 | E25: 972286066305000 | F25: DSN AIR BEGANTUNG RT. 010 RW. 003 DS KACANG BUTOR KEC. BADAU | H25: L | I25: K/2 | J25: =IF(ISBLANK(I25),"",IF(OR(I25="TK/0",I25="TK/1",I25="K/0"),"TER A",IF(I25="K/3","TER C","TER B"))) -> TER B | K25: 8312946.7 | L25: 30576 | M25: 148040 | S25: 0 | W25: =SUM(K25:V25) -> 8491562.7 | X25: =IF($J25="TER A",VLOOKUP(W25,Ter_A,4,TRUE),IF($J25="TER B",VLOOKUP(W25,Ter_B,4,TRUE),VLOOKUP(W25,Ter_C,4,TRUE))) -> 0.01 | Y25: =ROUND(IF($E25=0,W25*X25*120%,W25*X25),0) -> 84916 | Z25: 116639.23 | AA25: =Z25-Y25 -> 31723.229 | AB25: Lebih Pot | AD25: =SUM(L25+M25) -> 178616
B26: 18 | C26: SUDIRMAN | D26: 1902051205770002 | E26: 743653420305000 | F26: JL. MANGGAR RT. 004 RW. 002 DESA AIR BATU BUDING BADAU | H26: L | I26: K/0 | J26: =IF(ISBLANK(I26),"",IF(OR(I26="TK/0",I26="TK/1",I26="K/0"),"TER A",IF(I26="K/3","TER C","TER B"))) -> TER A | K26: 7483251.4 | L26: 30576 | M26: 146560 | S26: 0 | W26: =SUM(K26:V26) -> 7660387.4 | X26: =IF($J26="TER A",VLOOKUP(W26,Ter_A,4,TRUE),IF($J26="TER B",VLOOKUP(W26,Ter_B,4,TRUE),VLOOKUP(W26,Ter_C,4,TRUE))) -> 0.015 | Y26: =ROUND(IF($E26=0,W26*X26*120%,W26*X26),0) -> 114906 | Z26: 114658.4 | AA26: =Z26-Y26 -> -247.59977 | AB26: Kurang Pot | AD26: =SUM(L26+M26) -> 177136
B27: 19 | C27: APRIYADI | D27: 1902051707890001 | E27: 972285597305000 | F27: JL MANGGAR AIR BEGANTUNG RT. 008 RW. 003 DESA KACANG BUTOR BADAU | H27: L | I27: K/1 | J27: =IF(ISBLANK(I27),"",IF(OR(I27="TK/0",I27="TK/1",I27="K/0"),"TER A",IF(I27="K/3","TER C","TER B"))) -> TER B | K27: 4258024.8 | L27: 30576 | M27: 147200 | S27: 0 | W27: =SUM(K27:V27) -> 4435800.8 | X27: =IF($J27="TER A",VLOOKUP(W27,Ter_A,4,TRUE),IF($J27="TER B",VLOOKUP(W27,Ter_B,4,TRUE),VLOOKUP(W27,Ter_C,4,TRUE))) -> 0 | Y27: =ROUND(IF($E27=0,W27*X27*120%,W27*X27),0) -> 0 | Z27: 0 | AA27: =Z27-Y27 -> 0 | AD27: =SUM(L27+M27) -> 177776
