Workbook

Sheet MAIN DIV 1 AIR JNGKAT
A2: PT.REBINMAS JAYA
A3: DAFTAR THR
A5: MARET'2025 | K5: Perkebunan : | M5: PARIT GUNUNG
I6: TUNJANGAN / PREMI | M6: JUMLAH | P6: JUMLAH | Q6: TANDA
A7: NO. | B7: NO | C7: L/P | D7: NAMA | E7: TANGGAL MASUK | F7: HARI | G7: UPAH | H7: UPAH | I7: BERAS | K7: masa | M7: UPAH | N7: PAJAK | O7: KELAYAKAN | P7: UPAH | Q7: TANGAN
A8: URUT | B8: INDUK | D8: KARYAWAN | E8: KERJA | F8: KERJA | G8: DASAR | H8: POKOK | I8: (Rp)/ | J8: Jumlah | K8: JUMLAH | M8: KOTOR | N8: THR | O8: THR | P8: BERSIH | Q8: PENERIMA
B9: KARYAWAN | G9: (Rp) | H9: (Rp) | I9: HK | J9: (Rp) | K9: THN | L9: (Rp) | M9: (Rp) | P9: (Rp) | Q9: GAJI
A10: 1 | C10: L | D10: GUNAWAN | E10: 41283 | F10: 30 | G10: 129220 | H10: =F10*G10 -> 3876600 | I10: 5550 | J10: =F10*I10 -> 166500 | K10: 11 | L10: 30000 | M10: =H10+J10+L10 -> 4073100 | N10: 170040 | P10: =M10-N10-O10 -> 3903060 | S10: 30000 | T10: =L10-S10 -> 0
A11: 2 | C11: L | D11: RILYANI | E11: 13/03/1997 | F11: 30 | G11: 129220 | H11: =F11*G11 -> 3876600 | I11: 3250 | J11: =F11*I11 -> 97500 | K11: 28 | L11: 89000 | M11: =H11+J11+L11 -> 4063100 | N11: 121994 | P11: =M11-N11-O11 -> 3941106 | S11: 89000 | T11: =L11-S11 -> 0
A12: 3 | C12: L | D12: JUNAIDI | E12: 35065 | F12: 30 | G12: 129220 | H12: =F12*G12 -> 3876600 | I12: 3250 | J12: =F12*I12 -> 97500 | K12: 29 | L12: 92500 | M12: =H12+J12+L12 -> 4066600 | N12: 120894 | P12: =M12-N12-O12 -> 3945706 | S12: 92500 | T12: =L12-S12 -> 0
A13: 4 | C13: P | D13: UMIYATI | E13: 35248 | F13: 30 | G13: 129220 | H13: =F13*G13 -> 3876600 | I13: 2250 | J13: =F13*I13 -> 67500 | K13: 29 | L13: 92500 | M13: =H13+J13+L13 -> 4036600 | N13: 120024 | P13: =M13-N13-O13 -> 3916576 | S13: 92500 | T13: =L13-S13 -> 0
A14: 5 | C14: P | D14: ASUNTI | E14: 39455 | F14: 30 | G14: 129220 | H14: =F14*G14 -> 3876600 | I14: 2250 | J14: =F14*I14 -> 67500 | K14: 16 | L14: 47000 | M14: =H14+J14+L14 -> 3991100 | N14: 118632 | P14: =M14-N14-O14 -> 3872468 | S14: 47000 | T14: =L14-S14 -> 0
A15: 6 | C15: L | D15: JONI | E15: 18/7/2007 | F15: 30 | G15: 129220 | H15: =F15*G15 -> 3876600 | I15: 4650 | J15: =F15*I15 -> 139500 | K15: 17 | L15: 50500 | M15: =H15+J15+L15 -> 4066600 | N15: 80551 | P15: =M15-N15-O15 -> 3986049 | S15: 50500 | T15: =L15-S15 -> 0
A16: 7 | C16: L | D16: THAHA.S | E16: 39270 | F16: 30 | G16: 129220 | H16: =F16*G16 -> 3876600 | I16: 4650 | J16: =F16*I16 -> 139500 | K16: 17 | L16: 50500 | M16: =H16+J16+L16 -> 4066600 | N16: 80551 | P16: =M16-N16-O16 -> 3986049 | S16: 50500 | T16: =L16-S16 -> 0
A17: 8 | C17: L | D17: ALEX | E17: 41283 | F17: 30 | G17: 129220 | H17: =F17*G17 -> 3876600 | I17: 5550 | J17: =F17*I17 -> 166500 | K17: 11 | L17: 30000 | M17: =H17+J17+L17 -> 4073100 | N17: 80655 | P17: =M17-N17-O17 -> 3992445 | S17: 30000 | T17: =L17-S17 -> 0
A18: 9 | C18: L | D18: SANDY | E18: 41283 | F18: 30 | G18: 129220 | H18: =F18*G18 -> 3876600 | I18: 4650 | J18: =F18*I18 -> 139500 | K18: 11 | L18: 30000 | M18: =H18+J18+L18 -> 4046100 | N18: 80133 | P18: =M18-N18-O18 -> 3965967 | S18: 30000 | T18: =L18-S18 -> 0
A19: 10 | C19: L | D19: ANTON | E19: 19/7/2007 | F19: 30 | G19: 129220 | H19: =F19*G19 -> 3876600 | I19: 4650 | J19: =F19*I19 -> 139500 | K19: 17 | L19: 50500 | M19: =H19+J19+L19 -> 4066600 | N19: 79212 | P19: =M19-N19-O19 -> 3987388 | S19: 50500 | T19: =L19-S19 -> 0
A20: 11 | C20: P | D20: EKA NOVIANTI | E20: 16/7/2008 | F20: 30 | G20: 129220 | H20: =F20*G20 -> 3876600 | I20: 2250 | J20: =F20*I20 -> 67500 | K20: 16 | L20: 47000 | M20: =H20+J20+L20 -> 3991100 | N20: 118632 | P20: =M20-N20-O20 -> 3872468 | S20: 47000 | T20: =L20-S20 -> 0
A21: 12 | B21: 14 | C21: 14 | D21: YANTI NOVITA | E21: 39611 | F21: 30 | G21: 129220 | H21: =F21*G21 -> 3876600 | I21: 2250 | J21: =F21*I21 -> 67500 | K21: 16 | L21: 47000 | M21: =H21+J21+L21 -> 3991100 | N21: 118632 | P21: =M21-N21-O21 -> 3872468 | S21: 47000 | T21: =L21-S21 -> 0
A22: 13 | B22: 15 | C22: 15 | D22: JUMIATI | E22: 18/7/2007 | F22: 30 | G22: 129220 | H22: =F22*G22 -> 3876600 | I22: 2250 | J22: =F22*I22 -> 67500 | K22: 17 | L22: 50500 | M22: =H22+J22+L22 -> 3994600 | N22: 118739 | P22: =M22-N22-O22 -> 3875861 | S22: 50500 | T22: =L22-S22 -> 0
A23: 14 | C23: L | D23: SUPARDI | E23: 41306 | F23: 30 | G23: 129220 | H23: =F23*G23 -> 3876600 | I23: 5550 | J23: =F23*I23 -> 166500 | K23: 12 | L23: 33000 | M23: =H23+J23+L23 -> 4076100 | N23: 81500 | P23: =M23-N23-O23 -> 3994600 | S23: 33000 | T23: =L23-S23 -> 0
A24: 15 | C24: L | D24: PARDI | E24: 35887 | F24: 30 | G24: 129220 | H24: =F24*G24 -> 3876600 | I24: 4650 | J24: =F24*I24 -> 139500 | K24: 27 | L24: 85500 | M24: =H24+J24+L24 -> 4101600 | N24: 81265 | P24: =M24-N24-O24 -> 4020335 | S24: 85500 | T24: =L24-S24 -> 0
A25: 16 | C25: L | D25: SUMARDI | E25: 39544 | F25: 30 | G25: 129220 | H25: =F25*G25 -> 3876600 | I25: 5550 | J25: =F25*I25 -> 166500 | K25: 16 | L25: 47000 | M25: =H25+J25+L25 -> 4090100 | N25: 81002 | P25: =M25-N25-O25 -> 4009098 | S25: 47000 | T25: =L25-S25 -> 0
A26: 17 | C26: L | D26: WIDODO.J.P | E26: 13/6/2008 | F26: 30 | G26: 129220 | H26: =F26*G26 -> 3876600 | I26: 2250 | J26: =F26*I26 -> 67500 | K26: 16 | L26: 47000 | M26: =H26+J26+L26 -> 3991100 | N26: 166485 | P26: =M26-N26-O26 -> 3824615 | S26: 47000 | T26: =L26-S26 -> 0
A27: 18 | C27: L | D27: ASBI | E27: 42954 | F27: 30 | G27: 129220 | H27: =F27*G27 -> 3876600 | I27: 4650 | J27: =F27*I27 -> 139500 | K27: 7 | L27: 18000 | M27: =H27+J27+L27 -> 4034100 | N27: 79888 | P27: =M27-N27-O27 -> 3954212 | S27: 18000 | T27: =L27-S27 -> 0
A28: 19 | C28: L | D28: YANDI | E28: 41306 | F28: 30 | G28: 129220 | H28: =F28*G28 -> 3876600 | I28: 3700 | J28: =F28*I28 -> 111000 | K28: 12 | L28: 33000 | M28: =H28+J28+L28 -> 4020600 | N28: 119465 | P28: =M28-N28-O28 -> 3901135 | S28: 33000 | T28: =L28-S28 -> 0
A29: 20 | C29: L | D29: RIDHO | E29: 41283 | F29: 30 | G29: 129220 | H29: =F29*G29 -> 3876600 | I29: 4650 | J29: =F29*I29 -> 139500 | K29: 11 | L29: 30000 | M29: =H29+J29+L29 -> 4046100 | N29: 80133 | P29: =M29-N29-O29 -> 3965967 | S29: 30000 | T29: =L29-S29 -> 0
A30: 21 | C30: L | D30: APRIZAL | E30: 41283 | F30: 30 | G30: 129220 | H30: =F30*G30 -> 3876600 | I30: 4650 | J30: =F30*I30 -> 139500 | K30: 11 | L30: 30000 | M30: =H30+J30+L30 -> 4046100 | N30: 80133 | P30: =M30-N30-O30 -> 3965967 | S30: 30000 | T30: =L30-S30 -> 0
A31: 22 | C31: L | D31: ERRY SAPUTRA | E31: 39630 | F31: 30 | G31: 129220 | H31: =F31*G31 -> 3876600 | I31: 4650 | J31: =F31*I31 -> 139500 | K31: 17 | L31: 50500 | M31: =H31+J31+L31 -> 4066600 | N31: 80551 | P31: =M31-N31-O31 -> 3986049 | S31: 50500 | T31: =L31-S31 -> 0
D32: TOTAL | F32: =SUM(F10:F31) -> 660 | G32: =SUM(G10:G31) -> 2842840 | H32: =SUM(H10:H31) -> 85285200 | J32: =SUM(J10:J31) -> 2632500 | K32: =SUM(K10:K31) -> 364 | L32: =SUM(L10:L31) -> 1081000 | M32: =SUM(M10:M31) -> 88998700 | N32: =SUM(N10:N31) -> 2259111 | O32: =SUM(O10:O31) -> 0 | P32: =SUM(P10:P31) -> 86739589 | Q32: =SUM(Q10:R31) -> 0
D34: Dibuat oleh, | F34: Diperiksa oleh, | L34: Disetujui Oleh | O34: Disahkan Oleh
D38: Gunawan | F38: Galeh Haykal | I38: Marwan | L38: Gohi Maruli L Toruan,SP | O38: Chandra Dinata Pribadi
D39: KRANDIV IIA | F39: Asst Mgr | I39: Askep 2A | L39: Esatate Manager | O39: Senior Manager

Sheet PANEN AIR JANGKAT 1
A2: PT.REBINMAS JAYA
A3: DAFTAR THR
A5: Bulan : | D5: MARET' 2025 | K5: Perkebunan : | N5: PARIT GUNUNG
I6: TUNJANGAN / PREMI | M6: KOREKSI | N6: JUMLAH | Q6: JUMLAH | R6: TANDA
A7: NO. | B7: NO | C7: L/P | D7: NAMA | E7: TANGGA MASUK | F7: HARI | G7: UPAH | H7: UPAH | I7: BERAS | N7: UPAH | O7: PPH21 | P7: KELAYAKAN | Q7: THR | R7: TANGAN
A8: URUT | B8: INDUK | D8: KARYAWAN | E8: KERJA | F8: KERJA | G8: DASAR | H8: POKOK | I8: (Rp)/ | J8: Jumlah | K8: JUMLAH | M8: SEPTEMBER | N8: KOTOR | P8: THR | Q8: BERSIH | R8: PENERIMA
B9: KARYAWAN | G9: (Rp) | H9: (Rp) | I9: HK | J9: (Rp) | K9: THN | L9: (Rp) | N9: (Rp) | R9: GAJI
A10: 1 | C10: L | D10: RIO RESFATI | E10: 41275 | F10: 30 | G10: 129220 | H10: =SUM(G10*F10) -> 3876600 | I10: 4200 | J10: =F10*I10 -> 126000 | K10: 12 | L10: 33000 | N10: =H10+J10+L10 -> 4035600 | O10: 86942 | Q10: =N10-O10 -> 3948658
A11: 1 | C11: L | D11: DICKY PRATAMA | E11: 13/04/2023 | F11: 30 | G11: 129220 | H11: =SUM(G11*F11) -> 3876600 | I11: 3700 | J11: =F11*I11 -> 111000 | K11: 1 | L11: 2500 | N11: =H11+J11+L11 -> 3990100 | O11: 165898 | Q11: =N11-O11 -> 3824202
A12: 2 | C12: L | D12: SUIP | E12: 42685 | F12: 30 | G12: 129220 | H12: =SUM(G12*F12) -> 3876600 | I12: 4650 | J12: =F12*I12 -> 139500 | K12: 8 | L12: 21000 | N12: =H12+J12+L12 -> 4037100 | O12: 87173 | Q12: =N12-O12 -> 3949927
A13: 3 | C13: L | D13: ROBIN DINATA | E13: 42685 | F13: 30 | G13: 129220 | H13: =SUM(G13*F13) -> 3876600 | I13: 5550 | J13: =F13*I13 -> 166500 | K13: 8 | L13: 21000 | N13: =H13+J13+L13 -> 4064100 | O13: 89079 | Q13: =N13-O13 -> 3975021
A14: 4 | C14: L | D14: MUSNI | E14: 21/11/2016 | F14: 30 | G14: 129220 | H14: =SUM(G14*F14) -> 3876600 | I14: 3700 | J14: =F14*I14 -> 111000 | K14: 8 | L14: 21000 | N14: =H14+J14+L14 -> 4008600 | O14: 154945 | Q14: =N14-O14 -> 3853655
A15: 5 | C15: L | D15: SAPARUDIN | E15: 42773 | F15: 30 | G15: 129220 | H15: =SUM(G15*F15) -> 3876600 | I15: 5550 | J15: =F15*I15 -> 166500 | K15: 7 | L15: 18000 | N15: =H15+J15+L15 -> 4061100 | O15: 90405 | Q15: =N15-O15 -> 3970695
A16: 6 | C16: L | D16: ARPANDI | E16: 42954 | F16: 30 | G16: 129220 | H16: =SUM(G16*F16) -> 3876600 | I16: 4650 | J16: =F16*I16 -> 139500 | K16: 7 | L16: 18000 | N16: =H16+J16+L16 -> 4034100 | O16: 89922 | Q16: =N16-O16 -> 3944178
A17: 7 | C17: L | D17: MASRI | E17: 22/4/2015 | F17: 30 | G17: 129220 | H17: =SUM(G17*F17) -> 3876600 | I17: 4650 | J17: =F17*I17 -> 139500 | K17: 9 | L17: 24000 | N17: =H17+J17+L17 -> 4040100 | O17: 87934 | Q17: =N17-O17 -> 3952166
A18: 8 | C18: L | D18: SULTAN | E18: 42743 | F18: 30 | G18: 129220 | H18: =SUM(G18*F18) -> 3876600 | I18: 5550 | J18: =F18*I18 -> 166500 | K18: 7 | L18: 18000 | N18: =H18+J18+L18 -> 4061100 | O18: 90995 | Q18: =N18-O18 -> 3970105
A19: 9 | C19: L | D19: MANSUR | E19: 19/11/2019 | F19: 30 | G19: 129220 | H19: =SUM(G19*F19) -> 3876600 | I19: 4650 | J19: =F19*I19 -> 139500 | K19: 5 | L19: 12500 | N19: =H19+J19+L19 -> 4028600 | O19: 144280 | Q19: =N19-O19 -> 3884320
A20: 10 | C20: L | D20: HARDIANSYAH | E20: 15/06/2020 | F20: 30 | G20: 129220 | H20: =SUM(G20*F20) -> 3876600 | I20: 5550 | J20: =F20*I20 -> 166500 | K20: 4 | L20: 10000 | N20: =H20+J20+L20 -> 4053100 | O20: 89327 | Q20: =N20-O20 -> 3963773
A21: 11 | C21: L | D21: RIDUAN | E21: 44112 | F21: 30 | G21: 129220 | H21: =SUM(G21*F21) -> 3876600 | I21: 4650 | J21: =F21*I21 -> 139500 | K21: 4 | L21: 10000 | N21: =H21+J21+L21 -> 4026100 | O21: 86335 | Q21: =N21-O21 -> 3939765
A22: 12 | C22: L | D22: SUNARDI | E22: 22/02/2021 | F22: 30 | G22: 129220 | H22: =SUM(G22*F22) -> 3876600 | I22: 5550 | J22: =F22*I22 -> 166500 | K22: 4 | L22: 10000 | N22: =H22+J22+L22 -> 4053100 | O22: 86994 | Q22: =N22-O22 -> 3966106
A23: 13 | C23: L | D23: SONJA PRIYOGA | E23: 44260 | F23: 30 | G23: 129220 | H23: =SUM(G23*F23) -> 3876600 | I23: 4650 | J23: =F23*I23 -> 139500 | K23: 3 | L23: 7500 | N23: =H23+J23+L23 -> 4023600 | O23: 145440 | Q23: =N23-O23 -> 3878160
A24: 14 | C24: L | D24: M.FAUZI | E24: 44835 | F24: 30 | G24: 129220 | H24: =SUM(G24*F24) -> 3876600 | I24: 2250 | J24: =F24*I24 -> 67500 | K24: 3 | L24: 7500 | N24: =H24+J24+L24 -> 3951600 | O24: 123817 | Q24: =N24-O24 -> 3827783
A25: 15 | C25: L | D25: DANI | E25: 14/5/2022 | F25: 30 | G25: 129220 | H25: =SUM(G25*F25) -> 3876600 | I25: 4650 | J25: =F25*I25 -> 139500 | K25: 2 | L25: 5000 | N25: =H25+J25+L25 -> 4021100 | O25: 88132 | Q25: =N25-O25 -> 3932968
A26: 16 | C26: L | D26: AHAP | E26: 44689 | F26: 30 | G26: 129220 | H26: =SUM(G26*F26) -> 3876600 | I26: 4650 | J26: =F26*I26 -> 139500 | K26: 2 | L26: 5000 | N26: =H26+J26+L26 -> 4021100 | O26: 89678 | Q26: =N26-O26 -> 3931422
A27: 17 | C27: L | D27: SALEH | E27: 44968 | F27: 30 | G27: 129220 | H27: =SUM(G27*F27) -> 3876600 | I27: 3700 | J27: =F27*I27 -> 111000 | K27: 1 | L27: 2500 | N27: =H27+J27+L27 -> 3990100 | O27: 154293 | Q27: =N27-O27 -> 3835807
A28: 18 | C28: L | D28: IHSAN | E28: 45566 | F28: 30 | G28: 129220 | H28: =SUM(G28*F28) -> 3876600 | I28: 2250 | J28: =F28*I28 -> 67500 | K28: 1 | L28: 2500 | N28: =H28+J28+L28 -> 3946600 | O28: 125799 | Q28: =N28-O28 -> 3820801
A29: 19 | C29: L | D29: BAGUSTIN | E29: 45566 | F29: 30 | G29: 129220 | H29: =SUM(G29*F29) -> 3876600 | I29: 2250 | J29: =F29*I29 -> 67500 | K29: 1 | L29: 2500 | N29: =H29+J29+L29 -> 3946600 | O29: 124220 | Q29: =N29-O29 -> 3822380
A30: 20 | C30: L | D30: HELDI | E30: 45566 | F30: 30 | G30: 129220 | H30: =SUM(G30*F30) -> 3876600 | I30: 5550 | J30: =F30*I30 -> 166500 | K30: 1 | L30: 2500 | N30: =H30+J30+L30 -> 4045600 | O30: 80837 | Q30: =N30-O30 -> 3964763
A31: 21 | C31: L | D31: HARTONO | E31: 45293 | F31: 30 | G31: 129220 | H31: =SUM(G31*F31) -> 3876600 | I31: 2250 | J31: =F31*I31 -> 67500 | K31: 1 | L31: 2500 | N31: =H31+J31+L31 -> 3946600 | O31: 125210 | Q31: =N31-O31 -> 3821390
A32: 22 | C32: L | D32: QISTAHAM | E32: 45293 | F32: 30 | G32: 129220 | H32: =SUM(G32*F32) -> 3876600 | I32: 5550 | J32: =F32*I32 -> 166500 | K32: 1 | L32: 2500 | N32: =H32+J32+L32 -> 4045600 | O32: 295651 | Q32: =N32-O32 -> 3749949
A33: 23 | C33: L | D33: JAYADI | E33: 13/03/2024 | F33: 30 | G33: 129220 | H33: =SUM(G33*F33) -> 3876600 | I33: 5550 | J33: =F33*I33 -> 166500 | K33: 1 | L33: 2500 | N33: =H33+J33+L33 -> 4045600 | O33: 90108 | Q33: =N33-O33 -> 3955492
A34: 24 | C34: L | D34: JUPRI | E34: 24-06-2021 | F34: 30 | G34: 129220 | H34: =SUM(G34*F34) -> 3876600 | I34: 5550 | J34: =F34*I34 -> 166500 | K34: 3 | L34: 7500 | N34: =H34+J34+L34 -> 4050600 | O34: 85155 | Q34: =N34-O34 -> 3965445
A35: 25 | C35: L | D35: MUHAMMAD AMIN | E35: 45356 | F35: 30 | G35: 129220 | H35: =SUM(G35*F35) -> 3876600 | I35: 5550 | J35: =F35*I35 -> 166500 | N35: =(H35+J35+L35)/12*10 -> 3369250 | O35: 83391 | P35: 10 BULAN | Q35: =N35-O35 -> 3285859
A36: 26 | C36: L | D36: ZAMALUDIN | E36: 17/09/2024 | F36: 30 | G36: 129220 | H36: =SUM(G36*F36) -> 3876600 | I36: 4650 | J36: =F36*I36 -> 139500 | N36: =(H36+J36+L36)/12*6 -> 2008050 | O36: 16159 | P36: 6 BULAN | Q36: =N36-O36 -> 1991891
A37: 27 | C37: L | D37: SAMSUL HADI | E37: 13/11/2024 | F37: 30 | G37: 129220 | H37: =SUM(G37*F37) -> 3876600 | I37: 5550 | J37: =F37*I37 -> 166500 | N37: =(H37+J37+L37)/12*4 -> 1347700 | O37: 61798 | P37: 4 BULAN | Q37: =N37-O37 -> 1285902
A38: 28 | C38: L | D38: SAPARUDIN | E38: 22/11/2024 | F38: 30 | G38: 129220 | H38: =SUM(G38*F38) -> 3876600 | I38: 5550 | J38: =F38*I38 -> 166500 | N38: =(H38+J38+L38)/12*4 -> 1347700 | O38: 0 | P38: 4 BULAN | Q38: =N38-O38 -> 1347700
A39: 29 | C39: L | D39: MUHAMMAD FAUZI | E39: 22/11/2024 | F39: 30 | G39: 129220 | H39: =SUM(G39*F39) -> 3876600 | I39: 2250 | J39: =F39*I39 -> 67500 | N39: =(H39+J39+L39)/12*4 -> 1314700 | O39: 13691 | P39: 4 BULAN | Q39: =N39-O39 -> 1301009
A40: 30 | C40: L | D40: MAHYUDIN | E40: 22/11/2024 | F40: 30 | G40: 129220 | H40: =SUM(G40*F40) -> 3876600 | I40: 4650 | J40: =F40*I40 -> 139500 | N40: =(H40+J40+L40)/12*4 -> 1338700 | O40: 0 | P40: 4 BULAN | Q40: =N40-O40 -> 1338700
A41: 31 | C41: L | D41: ASRI | E41: 16/12/2024 | F41: 30 | G41: 129220 | H41: =SUM(G41*F41) -> 3876600 | I41: 2250 | J41: =F41*I41 -> 67500 | N41: =(H41+J41+L41)/12*3 -> 986025 | O41: 45475 | P41: 3 BULAN | Q41: =N41-O41 -> 940550
D42: TOTAL | F42: =SUM(F10:F41) -> 960 | H42: =SUM(H10:H41) -> 124051200 | J42: =SUM(J10:J41) -> 4257000 | K42: =SUM(K10:K41) -> 104 | L42: =SUM(L10:L41) -> 269000 | M42: =SUM(M10:M41) -> 0 | N42: =SUM(N10:N41) -> 112239625 | O42: =SUM(O10:O41) -> 3099083 | P42: =SUM(P10:P41) -> 0 | Q42: =SUM(Q10:Q41) -> 109140542 | R42: =SUM(R11:R41) -> 0
...

Sheet BRI
A1: DAFTAR THR KARYAWAN DIVISI IIA
A2: KE BANK BRI
F3: BULAN : MARET 2025
A4: NO | B4: KODE KARYAWAN | C4: NO REKENING | D4: AMOUNT APRIL 26-30 | E4: AMOUNT | F4: NAMA KARYAWAN
A5: 1 | B5: C0001 | C5: 13101020059507 | D5: ='[1]MAIN DIV 1 AIR JNGKAT'!AW10 -> 1095631.8 | E5: ='MAIN DIV 1 AIR JNGKAT'!P10 -> 3903060 | F5: GUNAWAN
A6: 2 | B6: C0002 | C6: 13101019821505 | D6: ='[1]MAIN DIV 1 AIR JNGKAT'!AW11 -> 601647.35 | E6: ='MAIN DIV 1 AIR JNGKAT'!P11 -> 3941106 | F6: RILYANI
A7: 3 | B7: C0003 | C7: 13101019710500 | D7: ='[1]MAIN DIV 1 AIR JNGKAT'!AW12 -> 562147.35 | E7: ='MAIN DIV 1 AIR JNGKAT'!P12 -> 3945706 | F7: JUNAIDI
A8: 4 | B8: C0004 | C8: 13101019875504 | D8: ='[1]MAIN DIV 1 AIR JNGKAT'!AW13 -> 555397.35 | E8: ='MAIN DIV 1 AIR JNGKAT'!P13 -> 3916576 | F8: UMIYATI
A9: 5 | B9: C0005 | C9: 13101019735500 | D9: ='[1]MAIN DIV 1 AIR JNGKAT'!AW14 -> 555397.35 | E9: ='MAIN DIV 1 AIR JNGKAT'!P14 -> 3872468 | F9: ASUNTI
A10: 6 | B10: C0007 | C10: 13101019814508 | D10: ='[1]MAIN DIV 1 AIR JNGKAT'!AW16 -> 566647.35 | E10: ='MAIN DIV 1 AIR JNGKAT'!P15 -> 3986049 | F10: JONI
A11: 7 | B11: C0008 | C11: 13101019817506 | D11: ='[1]MAIN DIV 1 AIR JNGKAT'!AW17 -> 453317.88 | E11: ='MAIN DIV 1 AIR JNGKAT'!P16 -> 3986049 | F11: THAHA.S
A12: 8 | B12: C0009 | C12: 13101020056509 | D12: ='[1]MAIN DIV 1 AIR JNGKAT'!AW18 -> 571147.35 | E12: ='MAIN DIV 1 AIR JNGKAT'!P17 -> 3992445 | F12: ALEX
A13: 9 | B13: C0010 | C13: 13101020058501 | D13: ='[1]MAIN DIV 1 AIR JNGKAT'!AW19 -> 453317.88 | E13: ='MAIN DIV 1 AIR JNGKAT'!P18 -> 3965967 | F13: SANDY
A14: 10 | B14: C0011 | C14: 13101019832506 | D14: ='[1]MAIN DIV 1 AIR JNGKAT'!AW20 -> 566647.35 | E14: ='MAIN DIV 1 AIR JNGKAT'!P19 -> 3987388 | F14: ANTON
A15: 11 | B15: C0013 | C15: 13101019851500 | D15: ='[1]MAIN DIV 1 AIR JNGKAT'!AW22 -> 555397.35 | E15: ='MAIN DIV 1 AIR JNGKAT'!P20 -> 3872468 | F15: EKA NOVIANTI
A16: 12 | B16: C0015 | C16: 13101019857506 | D16: ='[1]MAIN DIV 1 AIR JNGKAT'!AW23 -> 555397.35 | E16: ='MAIN DIV 1 AIR JNGKAT'!P21 -> 3872468 | F16: YANTI NOVITA
A17: 13 | B17: C0016 | C17: 13101019799504 | D17: ='[1]MAIN DIV 1 AIR JNGKAT'!AW24 -> 555397.35 | E17: ='MAIN DIV 1 AIR JNGKAT'!P22 -> 3875861 | F17: JUMIATI
A18: 14 | B18: C0019 | C18: 13101019840509 | D18: ='[1]MAIN DIV 1 AIR JNGKAT'!AW26 -> 580597.35 | E18: ='MAIN DIV 1 AIR JNGKAT'!P23 -> 3994600 | F18: SUPARDI
A19: 15 | B19: C0020 | C19: 13101019824503 | D19: ='[1]MAIN DIV 1 AIR JNGKAT'!AW27 -> 566647.35 | E19: ='MAIN DIV 1 AIR JNGKAT'!P24 -> 4020335 | F19: PARDI
A20: 16 | B20: C0025 | C20: 13101019887501 | D20: ='[1]MAIN DIV 1 AIR JNGKAT'!AW31 -> 571147.35 | E20: ='MAIN DIV 1 AIR JNGKAT'!P25 -> 4009098 | F20: SUMARDI
A21: 17 | B21: C0026 | C21: 013101002804538 | D21: ='[1]MAIN DIV 1 AIR JNGKAT'!AW32 -> 555397.35 | E21: ='MAIN DIV 1 AIR JNGKAT'!P26 -> 3824615 | F21: WIDODO.JP
A22: 18 | B22: C0028 | C22: 013101029706509 | D22: ='[1]MAIN DIV 1 AIR JNGKAT'!AW33 -> 555397.35 | E22: ='MAIN DIV 1 AIR JNGKAT'!P27 -> 3954212 | F22: ASBI
A23: 19 | B23: C0030 | C23: 013101047898500 | E23: ='MAIN DIV 1 AIR JNGKAT'!P28 -> 3901135 | F23: YANDI
A24: 20 | B24: C0032 | C24: 013101020054507 | E24: ='MAIN DIV 1 AIR JNGKAT'!P29 -> 3965967 | F24: RIDHO
A25: 21 | B25: C0033 | C25: 13101020063506 | E25: ='MAIN DIV 1 AIR JNGKAT'!P30 -> 3965967 | F25: APRIZAL
A26: 22 | B26: C0102 | C26: 013101019825509 | E26: ='MAIN DIV 1 AIR JNGKAT'!P31 -> 3986049 | F26: ERRY SAPUTRA
A27: TOTAL | D27: =SUM(D5:D22) -> 10476678 | E27: =SUM(E5:E26) -> 86739589
A28: 23 | B28: C0178 | C28: 013101019752502 | D28: =[1]OPERATOR!AX11 -> 1380426.7 | E28: =OPERATOR!Q11 -> 3671234 | F28: ARWANDI
A29: 24 | B29: C0179 | C29: 013101020061504 | D29: =[1]OPERATOR!AX12 -> 576647.35 | E29: =OPERATOR!Q12 -> 3753754 | F29: RENDI PERJAYA
A30: 25 | B30: C0510 | C30: 013101027088507 | E30: =OPERATOR!Q13 -> 3826266 | F30: ANDI
A31: 26 | B31: C0511 | C31: 013101029262505 | E31: =OPERATOR!Q14 -> 3852406 | F31: JULI
A32: TOTAL | D32: =SUM(D28:D31) -> 1957074.1 | E32: =SUM(E28:E31) -> 15103660
A34: NO | B34: KODE KARYAWAN | C34: NO REKENING | E34: AMOUNT | F34: NAMA KARYAWAN
A35: 27 | B35: C0365 | C35: 013101019633504 | D35: ='[1]PANEN AIR JANGKAT 1'!BA10 -> 744821.85 | E35: ='PANEN AIR JANGKAT 1'!Q10 -> 3948658 | F35: RIO RESFATI
A36: 28 | B36: C0526 | C36: 013101046647508 | E36: ='PANEN AIR JANGKAT 1'!Q11 -> 3824202 | F36: DICKY PRATAMA
A37: 29 | B37: C0050 | C37: 013101028423506 | D37: ='[1]PANEN AIR JANGKAT 1'!BA12 -> 625447.35 | E37: ='PANEN AIR JANGKAT 1'!Q12 -> 3949927 | F37: SUIP
A38: 30 | B38: C0051 | C38: 013101028425508 | D38: ='[1]PANEN AIR JANGKAT 1'!BA13 -> 636247.35 | E38: ='PANEN AIR JANGKAT 1'!Q13 -> 3975021 | F38: ROBIN DINATA
A39: 31 | B39: C0053 | C39: 013101028421504 | D39: ='[1]PANEN AIR JANGKAT 1'!BA14 -> 648447.35 | E39: ='PANEN AIR JANGKAT 1'!Q14 -> 3853655 | F39: MUSNI
A40: 32 | B40: C0054 | C40: 013101029502507 | D40: ='[1]PANEN AIR JANGKAT 1'!BA15 -> 644107.35 | E40: ='PANEN AIR JANGKAT 1'!Q15 -> 3970695 | F40: SAPARUDIN
A41: 33 | B41: C0055 | C41: 013101029880507 | D41: ='[1]PANEN AIR JANGKAT 1'!BA16 -> 668947.35 | E41: ='PANEN AIR JANGKAT 1'!Q16 -> 3944178 | F41: ARPANDI
...

Sheet OPERATOR
A2: PT.REBINMAS JAYA
A3: DAFTAR THR
A5: Bulan : | D5: MARET | E5: 2025 | M5: Perkebunan : | N5: PARIT GUNUNG
I7: TUNJANGAN / PREMI | N7: JUMLAH | Q7: JUMLAH
A8: NO. | B8: NO | C8: L/P | D8: NAMA | F8: HARI | G8: UPAH | H8: UPAH | I8: BERAS | K8: MASA KERJA | N8: UPAH | O8: PPH | P8: KELAYAKAN THR | Q8: UPAH
A9: URUT | B9: INDUK | D9: KARYAWAN | E9: TANGGAL MASUK KERJA | F9: KERJA | G9: DASAR | H9: POKOK | I9: (Rp)/ | J9: Jumlah | K9: (Rp)/ | L9: JUMLAH | N9: KOTOR | O9: 0.05 | Q9: BERSIH
B10: KARYAWAN | G10: (Rp) | H10: (Rp) | I10: HK | J10: (Rp) | K10: THN | L10: THN | M10: (Rp) | N10: (Rp) | Q10: (Rp)
A11: 1 | B11: C0178 | C11: L | D11: ARWANDI | E11: 35281 | F11: 30 | G11: 129220 | H11: =F11*G11 -> 3876600 | I11: 4200 | J11: =F11*I11 -> 126000 | K11: 2500 | L11: 28 | M11: 89000 | N11: =H11+J11+M11 -> 4091600 | O11: 420366 | Q11: =N11-O11-P11 -> 3671234
A12: 2 | B12: C0179 | C12: L | D12: RENDI PERJAYA | E12: 41283 | F12: 30 | G12: 129220 | H12: =F12*G12 -> 3876600 | I12: 4200 | J12: =F12*I12 -> 126000 | K12: 2500 | L12: 11 | M12: 30000 | N12: =H12+J12+M12 -> 4032600 | O12: 278846 | Q12: =N12-O12-P12 -> 3753754
A13: 3 | B13: C0180 | C13: L | D13: ANDI | E13: 14/06/1997 | F13: 30 | G13: 129220 | H13: =F13*G13 -> 3876600 | I13: 4650 | J13: =F13*I13 -> 139500 | K13: 2500 | L13: 27 | M13: 85500 | N13: =H13+J13+M13 -> 4101600 | O13: 275334 | Q13: =N13-O13-P13 -> 3826266
A14: 4 | B14: C0181 | C14: L | D14: JULI | E14: 01/01/1996 | F14: 30 | G14: 129220 | H14: =F14*G14 -> 3876600 | I14: 5550 | J14: =F14*I14 -> 166500 | K14: 2500 | L14: 29 | M14: 92500 | N14: =H14+J14+M14 -> 4135600 | O14: 283194 | Q14: =N14-O14-P14 -> 3852406
F15: =SUM(F11:F14) -> 120 | G15: =SUM(G11:G14) -> 516880 | H15: =SUM(H11:H14) -> 15506400 | J15: =SUM(J11:J14) -> 558000 | M15: =SUM(M11:M14) -> 297000 | N15: =SUM(N11:N14) -> 16361400 | O15: =SUM(O11:O14) -> 1257740 | P15: =SUM(P11:P14) -> 0 | Q15: =SUM(Q11:Q14) -> 15103660
B18: Dibuat oleh, | D18: Diperiksa oleh, | J18: Disetujui Oleh | N18: Disahkan Oleh
B22: Gunawan | D22: Galeh Haykal | G22: Marwan | J22: Gohi Maruli L Toruan,SP | N22: Chandra Dinata Pribadi
B23: KRANDIV IIA | D23: Asst Mgr | G23: Askep 2A | J23: Esatate Manager | N23: Senior Manager
N39: =#REF!*#REF! -> #REF!
N40: =#REF!*#REF! -> #REF!
N47: =#REF!+#REF! -> #REF!
